Workbook
Name Print_Area_MI: #REF!
Name Print_Area_MI: #REF!
Name Print_Area_MI: #REF!
Name Print_Area_MI: #REF!
Name Print_Area_MI: #REF!
Name Print_Area_MI: #REF!

Sheet Summary
A1: (ENTER PROJECT NAME)
A3: ALTERNATES
A5: ALTERNATE # | B5: DESCRIPTION | C5: AMOUNT
A8: 1 | B8: ='Alt01'!B4 -> 0 | C8: ='Alt01'!B1 -> 0
A10: 2 | B10: ='Alt02'!B4 -> 0 | C10: ='Alt02'!B1 -> 0
A12: 3 | B12: ='Alt03'!B4 -> 0 | C12: ='Alt03'!B1 -> 0
A14: 4 | B14: ='Alt04'!B4 -> 0 | C14: ='Alt04'!B1 -> 0
A16: 5 | B16: ='Alt05'!B4 -> 0 | C16: ='Alt05'!B1 -> 0
A18: 6 | B18: ='Alt06'!B4 -> 0 | C18: ='Alt06'!B1 -> 0
A20: 7 | B20: ='Alt07'!B4 -> 0 | C20: ='Alt07'!B1 -> 0
A22: 8 | B22: ='Alt08'!B4 -> Specifics | C22: ='Alt08'!B1 -> 0
A24: 9 | B24: ='Alt09'!B4 -> Specifics | C24: ='Alt09'!B1 -> 0
A26: 10 | B26: ='Alt10'!B4 -> Specifics | C26: ='Alt10'!B1 -> 0
A28: 11 | B28: ='Alt11'!B4 -> Specifics | C28: ='Alt11'!B1 -> 0
A30: 12 | B30: ='Alt12'!B4 -> Specifics | C30: ='Alt12'!B1 -> 0
A32: 13 | B32: ='Alt13'!B4 -> Specifics | C32: ='Alt13'!B1 -> 0

Sheet Alt01
B1: =K45 -> 0 | L1: Job No.: | M1: -
B3: Alternate No. 1-
B5: =+NOW() -> 44537.429
B6: =NOW() -> 44537.429 | I6: 1.07 | J6: 1 | M6: 1
A7: - | B7: - | C7: - | D7: - | H7: - | I7: - | J7: - | K7: - | L7: - | M7: -
A8: SPEC | E8: UNIT | F8: UNIT | G8: UNIT | M8: COST/
A9: SECTION | B9: DESCRIPTION | C9: QTY | D9: UNIT | E9: SUB | F9: MATL | G9: LABOR | H9: SUB | I9: MATL | J9: LABOR | K9: TOTAL: | L9: SUBCONTRACTOR | M9: SF
A10: - | B10: - | C10: - | D10: - | H10: - | I10: - | J10: - | K10: - | L10: - | M10: -
H11: =+C11*E11 -> 0 | I11: =+C11*F11*$I$6 -> 0 | J11: =+C11*G11*$J$6 -> 0 | K11: =SUM(H11+I11+J11) -> 0 | M11: =K11/$M$6 -> 0
H12: =+C12*E12 -> 0 | I12: =+C12*F12*$I$6 -> 0 | J12: =+C12*G12*$J$6 -> 0 | K12: =SUM(H12+I12+J12) -> 0 | M12: =K12/$M$6 -> 0
H13: =+C13*E13 -> 0 | I13: =+C13*F13*$I$6 -> 0 | J13: =+C13*G13*$J$6 -> 0 | K13: =SUM(H13+I13+J13) -> 0 | M13: =K13/$M$6 -> 0
H14: =+C14*E14 -> 0 | I14: =+C14*F14*$I$6 -> 0 | J14: =+C14*G14*$J$6 -> 0 | K14: =SUM(H14+I14+J14) -> 0 | M14: =K14/$M$6 -> 0
H15: =+C15*E15 -> 0 | I15: =+C15*F15*$I$6 -> 0 | J15: =+C15*G15*$J$6 -> 0 | K15: =SUM(H15+I15+J15) -> 0 | M15: =K15/$M$6 -> 0
H16: =+C16*E16 -> 0 | I16: =+C16*F16*$I$6 -> 0 | J16: =+C16*G16*$J$6 -> 0 | K16: =SUM(H16+I16+J16) -> 0 | M16: =K16/$M$6 -> 0
H17: =+C17*E17 -> 0 | I17: =+C17*F17*$I$6 -> 0 | J17: =+C17*G17*$J$6 -> 0 | K17: =SUM(H17+I17+J17) -> 0 | M17: =K17/$M$6 -> 0
H18: =+C18*E18 -> 0 | I18: =+C18*F18*$I$6 -> 0 | J18: =+C18*G18*$J$6 -> 0 | K18: =SUM(H18+I18+J18) -> 0 | M18: =K18/$M$6 -> 0
H19: =+C19*E19 -> 0 | I19: =+C19*F19*$I$6 -> 0 | J19: =+C19*G19*$J$6 -> 0 | K19: =SUM(H19+I19+J19) -> 0 | M19: =K19/$M$6 -> 0
H20: =+C20*E20 -> 0 | I20: =+C20*F20*$I$6 -> 0 | J20: =+C20*G20*$J$6 -> 0 | K20: =SUM(H20+I20+J20) -> 0 | M20: =K20/$M$6 -> 0
H21: =+C21*E21 -> 0 | I21: =+C21*F21*$I$6 -> 0 | J21: =+C21*G21*$J$6 -> 0 | K21: =SUM(H21+I21+J21) -> 0 | M21: =K21/$M$6 -> 0
H22: =+C22*E22 -> 0 | I22: =+C22*F22*$I$6 -> 0 | J22: =+C22*G22*$J$6 -> 0 | K22: =SUM(H22+I22+J22) -> 0 | M22: =K22/$M$6 -> 0
H23: =+C23*E23 -> 0 | I23: =+C23*F23*$I$6 -> 0 | J23: =+C23*G23*$J$6 -> 0 | K23: =SUM(H23+I23+J23) -> 0 | M23: =K23/$M$6 -> 0
A24: - | B24: - | C24: - | D24: - | H24: - | I24: - | J24: - | K24: - | L24: - | M24: -
B25: SUB-TOTAL: | H25: =SUM(H11:H23) -> 0 | I25: =SUM(I11:I23) -> 0 | J25: =SUM(J11:J23) -> 0 | K25: =SUM(K11:K23) -> 0 | M25: =K25/$M$6 -> 0
B26: SALES TAX/PAYROLL TAXES: | D26: INCL | I26: 0 | J26: 0 | K26: =+H26+I26+J26 -> 0 | M26: =K26/$M$6 -> 0
A27: - | B27: - | C27: - | D27: - | H27: - | I27: - | J27: - | K27: - | L27: - | M27: -
B28: SUB-TOTAL: | K28: =SUM(K25:K26) -> 0 | M28: =K28/$M$6 -> 0
M29: =K29/$M$6 -> 0
B30: CONTRACTOR FEE: | C30: 10 | D30: % | K30: =C30*K28/100 -> 0 | M30: =K30/$M$6 -> 0
H32: =+C32*E32 -> 0 | I32: =+C32*F32 -> 0 | J32: =+E32*G32 -> 0 | K32: =SUM(H32+I32+J32) -> 0 | M32: =K32/$M$6 -> 0
H33: =+C33*E33 -> 0 | I33: =+C33*F33 -> 0 | J33: =+E33*G33 -> 0 | K33: =SUM(H33+I33+J33) -> 0 | M33: =K33/$M$6 -> 0
H34: =+C34*E34 -> 0 | I34: =+C34*F34 -> 0 | J34: =+E34*G34 -> 0 | K34: =SUM(H34+I34+J34) -> 0 | M34: =K34/$M$6 -> 0
B35: BUILDER'S RISK INSURANCE (2.1%) | C35: 0 | D35: % | K35: =SUM(K28:K33)*C35/100 -> 0 | M35: =K35/$M$6 -> 0
M36: =K36/$M$6 -> 0
B37: GENERAL LIABILITY INSURANCE | C37: 1.3 | D37: % | K37: =SUM(K28:K36)*C37/100 -> 0 | M37: =K37/$M$6 -> 0
B38: IT FEE | C38: 0.25 | D38: % | K38: =(K28)*C38/100 -> 0 | M38: =K38/$M$6 -> 0
B39: CONTINGENCY | C39: 5 | D39: % | K39: =(K28)*C39/100 -> 0 | M39: =K39/$M$6 -> 0
M42: =K42/$M$6 -> 0
B43: BOND | C43: 0 | D43: % | K43: =SUM(K28:K42)*C43/100 -> 0 | M43: =K43/$M$6 -> 0
A44: - | B44: - | C44: - | D44: - | H44: - | I44: - | J44: - | K44: - | L44: - | M44: -
B45: TOTAL: | K45: =SUM(K28:K43) -> 0 | M45: =K45/$M$6 -> 0

Sheet Alt02
B1: =K45 -> 0 | L1: Job No.: | M1: ='Alt01'!M1 -> -
B3: Alternate No. 2-
B5: =+NOW() -> 44537.429
B6: =NOW() -> 44537.429 | I6: 1.07 | J6: 1 | M6: 1
A7: - | B7: - | C7: - | D7: - | H7: - | I7: - | J7: - | K7: - | L7: - | M7: -
A8: SPEC | E8: UNIT | F8: UNIT | G8: UNIT | M8: COST/
A9: SECTION | B9: DESCRIPTION | C9: QTY | D9: UNIT | E9: SUB | F9: MATL | G9: LABOR | H9: SUB | I9: MATL | J9: LABOR | K9: TOTAL: | L9: SUBCONTRACTOR | M9: SF
A10: - | B10: - | C10: - | D10: - | H10: - | I10: - | J10: - | K10: - | L10: - | M10: -
H11: =+C11*E11 -> 0 | I11: =+C11*F11*$I$6 -> 0 | J11: =+C11*G11*$J$6 -> 0 | K11: =SUM(H11+I11+J11) -> 0 | M11: =K11/$M$6 -> 0
H12: =+C12*E12 -> 0 | I12: =+C12*F12*$I$6 -> 0 | J12: =+C12*G12*$J$6 -> 0 | K12: =SUM(H12+I12+J12) -> 0 | M12: =K12/$M$6 -> 0
H13: =+C13*E13 -> 0 | I13: =+C13*F13*$I$6 -> 0 | J13: =+C13*G13*$J$6 -> 0 | K13: =SUM(H13+I13+J13) -> 0 | M13: =K13/$M$6 -> 0
H14: =+C14*E14 -> 0 | I14: =+C14*F14*$I$6 -> 0 | J14: =+C14*G14*$J$6 -> 0 | K14: =SUM(H14+I14+J14) -> 0 | M14: =K14/$M$6 -> 0
H15: =+C15*E15 -> 0 | I15: =+C15*F15*$I$6 -> 0 | J15: =+C15*G15*$J$6 -> 0 | K15: =SUM(H15+I15+J15) -> 0 | M15: =K15/$M$6 -> 0
H16: =+C16*E16 -> 0 | I16: =+C16*F16*$I$6 -> 0 | J16: =+C16*G16*$J$6 -> 0 | K16: =SUM(H16+I16+J16) -> 0 | M16: =K16/$M$6 -> 0
H17: =+C17*E17 -> 0 | I17: =+C17*F17*$I$6 -> 0 | J17: =+C17*G17*$J$6 -> 0 | K17: =SUM(H17+I17+J17) -> 0 | M17: =K17/$M$6 -> 0
H18: =+C18*E18 -> 0 | I18: =+C18*F18*$I$6 -> 0 | J18: =+C18*G18*$J$6 -> 0 | K18: =SUM(H18+I18+J18) -> 0 | M18: =K18/$M$6 -> 0
H19: =+C19*E19 -> 0 | I19: =+C19*F19*$I$6 -> 0 | J19: =+C19*G19*$J$6 -> 0 | K19: =SUM(H19+I19+J19) -> 0 | M19: =K19/$M$6 -> 0
H20: =+C20*E20 -> 0 | I20: =+C20*F20*$I$6 -> 0 | J20: =+C20*G20*$J$6 -> 0 | K20: =SUM(H20+I20+J20) -> 0 | M20: =K20/$M$6 -> 0
H21: =+C21*E21 -> 0 | I21: =+C21*F21*$I$6 -> 0 | J21: =+C21*G21*$J$6 -> 0 | K21: =SUM(H21+I21+J21) -> 0 | M21: =K21/$M$6 -> 0
H22: =+C22*E22 -> 0 | I22: =+C22*F22*$I$6 -> 0 | J22: =+C22*G22*$J$6 -> 0 | K22: =SUM(H22+I22+J22) -> 0 | M22: =K22/$M$6 -> 0
H23: =+C23*E23 -> 0 | I23: =+C23*F23*$I$6 -> 0 | J23: =+C23*G23*$J$6 -> 0 | K23: =SUM(H23+I23+J23) -> 0 | M23: =K23/$M$6 -> 0
A24: - | B24: - | C24: - | D24: - | H24: - | I24: - | J24: - | K24: - | L24: - | M24: -
B25: SUB-TOTAL: | H25: =SUM(H11:H23) -> 0 | I25: =SUM(I11:I23) -> 0 | J25: =SUM(J11:J23) -> 0 | K25: =SUM(K11:K23) -> 0 | M25: =K25/$M$6 -> 0
B26: SALES TAX/PAYROLL TAXES: | D26: INCL | I26: 0 | J26: 0 | K26: =+H26+I26+J26 -> 0 | M26: =K26/$M$6 -> 0
A27: - | B27: - | C27: - | D27: - | H27: - | I27: - | J27: - | K27: - | L27: - | M27: -
B28: SUB-TOTAL: | K28: =SUM(K25:K26) -> 0 | M28: =K28/$M$6 -> 0
M29: =K29/$M$6 -> 0
B30: CONTRACTOR FEE: | C30: 10 | D30: % | K30: =C30*K28/100 -> 0 | M30: =K30/$M$6 -> 0
H32: =+C32*E32 -> 0 | I32: =+C32*F32 -> 0 | J32: =+E32*G32 -> 0 | K32: =SUM(H32+I32+J32) -> 0 | M32: =K32/$M$6 -> 0
H33: =+C33*E33 -> 0 | I33: =+C33*F33 -> 0 | J33: =+E33*G33 -> 0 | K33: =SUM(H33+I33+J33) -> 0 | M33: =K33/$M$6 -> 0
H34: =+C34*E34 -> 0 | I34: =+C34*F34 -> 0 | J34: =+E34*G34 -> 0 | K34: =SUM(H34+I34+J34) -> 0 | M34: =K34/$M$6 -> 0
B35: BUILDER'S RISK INSURANCE (2.1%) | C35: 0 | D35: % | K35: =SUM(K28:K33)*C35/100 -> 0 | M35: =K35/$M$6 -> 0
M36: =K36/$M$6 -> 0
B37: GENERAL LIABILITY INSURANCE | C37: 1.3 | D37: % | K37: =SUM(K28:K36)*C37/100 -> 0 | M37: =K37/$M$6 -> 0
B38: IT FEE | C38: 0.25 | D38: % | K38: =(K28)*C38/100 -> 0 | M38: =K38/$M$6 -> 0
B39: CONTINGENCY | C39: 5 | D39: % | K39: =(K28)*C39/100 -> 0 | M39: =K39/$M$6 -> 0
M42: =K42/$M$6 -> 0
B43: BOND | C43: 0 | D43: % | K43: =SUM(K28:K42)*C43/100 -> 0 | M43: =K43/$M$6 -> 0
A44: - | B44: - | C44: - | D44: - | H44: - | I44: - | J44: - | K44: - | L44: - | M44: -
B45: TOTAL: | K45: =SUM(K28:K43) -> 0 | M45: =K45/$M$6 -> 0

Sheet Alt03
B1: =K45 -> 0 | L1: Job No.: | M1: ='Alt01'!M1 -> -
B3: Alternate No. 3-
B5: =+NOW() -> 44537.429
B6: =NOW() -> 44537.429 | I6: 1.07 | J6: 1 | M6: 1
A7: - | B7: - | C7: - | D7: - | H7: - | I7: - | J7: - | K7: - | L7: - | M7: -
A8: SPEC | E8: UNIT | F8: UNIT | G8: UNIT | M8: COST/
A9: SECTION | B9: DESCRIPTION | C9: QTY | D9: UNIT | E9: SUB | F9: MATL | G9: LABOR | H9: SUB | I9: MATL | J9: LABOR | K9: TOTAL: | L9: SUBCONTRACTOR | M9: SF
A10: - | B10: - | C10: - | D10: - | H10: - | I10: - | J10: - | K10: - | L10: - | M10: -
H11: =+C11*E11 -> 0 | I11: =+C11*F11*$I$6 -> 0 | J11: =+C11*G11*$J$6 -> 0 | K11: =SUM(H11+I11+J11) -> 0 | M11: =K11/$M$6 -> 0
H12: =+C12*E12 -> 0 | I12: =+C12*F12*$I$6 -> 0 | J12: =+C12*G12*$J$6 -> 0 | K12: =SUM(H12+I12+J12) -> 0 | M12: =K12/$M$6 -> 0
H13: =+C13*E13 -> 0 | I13: =+C13*F13*$I$6 -> 0 | J13: =+C13*G13*$J$6 -> 0 | K13: =SUM(H13+I13+J13) -> 0 | M13: =K13/$M$6 -> 0
H14: =+C14*E14 -> 0 | I14: =+C14*F14*$I$6 -> 0 | J14: =+C14*G14*$J$6 -> 0 | K14: =SUM(H14+I14+J14) -> 0 | M14: =K14/$M$6 -> 0
H15: =+C15*E15 -> 0 | I15: =+C15*F15*$I$6 -> 0 | J15: =+C15*G15*$J$6 -> 0 | K15: =SUM(H15+I15+J15) -> 0 | M15: =K15/$M$6 -> 0
H16: =+C16*E16 -> 0 | I16: =+C16*F16*$I$6 -> 0 | J16: =+C16*G16*$J$6 -> 0 | K16: =SUM(H16+I16+J16) -> 0 | M16: =K16/$M$6 -> 0
H17: =+C17*E17 -> 0 | I17: =+C17*F17*$I$6 -> 0 | J17: =+C17*G17*$J$6 -> 0 | K17: =SUM(H17+I17+J17) -> 0 | M17: =K17/$M$6 -> 0
H18: =+C18*E18 -> 0 | I18: =+C18*F18*$I$6 -> 0 | J18: =+C18*G18*$J$6 -> 0 | K18: =SUM(H18+I18+J18) -> 0 | M18: =K18/$M$6 -> 0
H19: =+C19*E19 -> 0 | I19: =+C19*F19*$I$6 -> 0 | J19: =+C19*G19*$J$6 -> 0 | K19: =SUM(H19+I19+J19) -> 0 | M19: =K19/$M$6 -> 0
H20: =+C20*E20 -> 0 | I20: =+C20*F20*$I$6 -> 0 | J20: =+C20*G20*$J$6 -> 0 | K20: =SUM(H20+I20+J20) -> 0 | M20: =K20/$M$6 -> 0
H21: =+C21*E21 -> 0 | I21: =+C21*F21*$I$6 -> 0 | J21: =+C21*G21*$J$6 -> 0 | K21: =SUM(H21+I21+J21) -> 0 | M21: =K21/$M$6 -> 0
H22: =+C22*E22 -> 0 | I22: =+C22*F22*$I$6 -> 0 | J22: =+C22*G22*$J$6 -> 0 | K22: =SUM(H22+I22+J22) -> 0 | M22: =K22/$M$6 -> 0
H23: =+C23*E23 -> 0 | I23: =+C23*F23*$I$6 -> 0 | J23: =+C23*G23*$J$6 -> 0 | K23: =SUM(H23+I23+J23) -> 0 | M23: =K23/$M$6 -> 0
A24: - | B24: - | C24: - | D24: - | H24: - | I24: - | J24: - | K24: - | L24: - | M24: -
B25: SUB-TOTAL: | H25: =SUM(H11:H23) -> 0 | I25: =SUM(I11:I23) -> 0 | J25: =SUM(J11:J23) -> 0 | K25: =SUM(K11:K23) -> 0 | M25: =K25/$M$6 -> 0
B26: SALES TAX/PAYROLL TAXES: | D26: INCL | I26: 0 | J26: 0 | K26: =+H26+I26+J26 -> 0 | M26: =K26/$M$6 -> 0
A27: - | B27: - | C27: - | D27: - | H27: - | I27: - | J27: - | K27: - | L27: - | M27: -
B28: SUB-TOTAL: | K28: =SUM(K25:K26) -> 0 | M28: =K28/$M$6 -> 0
M29: =K29/$M$6 -> 0
B30: CONTRACTOR FEE: | C30: 10 | D30: % | K30: =C30*K28/100 -> 0 | M30: =K30/$M$6 -> 0
H32: =+C32*E32 -> 0 | I32: =+C32*F32 -> 0 | J32: =+E32*G32 -> 0 | K32: =SUM(H32+I32+J32) -> 0 | M32: =K32/$M$6 -> 0
H33: =+C33*E33 -> 0 | I33: =+C33*F33 -> 0 | J33: =+E33*G33 -> 0 | K33: =SUM(H33+I33+J33) -> 0 | M33: =K33/$M$6 -> 0
H34: =+C34*E34 -> 0 | I34: =+C34*F34 -> 0 | J34: =+E34*G34 -> 0 | K34: =SUM(H34+I34+J34) -> 0 | M34: =K34/$M$6 -> 0
B35: BUILDER'S RISK INSURANCE (2.1%) | C35: 0 | D35: % | K35: =SUM(K28:K33)*C35/100 -> 0 | M35: =K35/$M$6 -> 0
M36: =K36/$M$6 -> 0
B37: GENERAL LIABILITY INSURANCE | C37: 1.3 | D37: % | K37: =SUM(K28:K36)*C37/100 -> 0 | M37: =K37/$M$6 -> 0
B38: IT FEE | C38: 0.25 | D38: % | K38: =(K28)*C38/100 -> 0 | M38: =K38/$M$6 -> 0
B39: CONTINGENCY | C39: 5 | D39: % | K39: =(K28)*C39/100 -> 0 | M39: =K39/$M$6 -> 0
M42: =K42/$M$6 -> 0
B43: BOND | C43: 0 | D43: % | K43: =SUM(K28:K42)*C43/100 -> 0 | M43: =K43/$M$6 -> 0
A44: - | B44: - | C44: - | D44: - | H44: - | I44: - | J44: - | K44: - | L44: - | M44: -
B45: TOTAL: | K45: =SUM(K28:K43) -> 0 | M45: =K45/$M$6 -> 0

Sheet Alt04
B1: =K45 -> 0 | L1: Job No.: | M1: ='Alt01'!M1 -> -
B3: Alternate No. 4
B5: =+NOW() -> 44537.429
B6: =NOW() -> 44537.429 | I6: 1.07 | J6: 1 | M6: 1
A7: - | B7: - | C7: - | D7: - | H7: - | I7: - | J7: - | K7: - | L7: - | M7: -
A8: SPEC | E8: UNIT | F8: UNIT | G8: UNIT | M8: COST/
A9: SECTION | B9: DESCRIPTION | C9: QTY | D9: UNIT | E9: SUB | F9: MATL | G9: LABOR | H9: SUB | I9: MATL | J9: LABOR | K9: TOTAL: | L9: SUBCONTRACTOR | M9: SF
A10: - | B10: - | C10: - | D10: - | H10: - | I10: - | J10: - | K10: - | M10: -
H11: =+C11*E11 -> 0 | I11: =+C11*F11*$I$6 -> 0 | J11: =+C11*G11*$J$6 -> 0 | K11: =SUM(H11+I11+J11) -> 0 | M11: =K11/$M$6 -> 0
H12: =+C12*E12 -> 0 | I12: =+C12*F12*$I$6 -> 0 | J12: =+C12*G12*$J$6 -> 0 | K12: =SUM(H12+I12+J12) -> 0 | M12: =K12/$M$6 -> 0
H13: =+C13*E13 -> 0 | I13: =+C13*F13*$I$6 -> 0 | J13: =+C13*G13*$J$6 -> 0 | K13: =SUM(H13+I13+J13) -> 0 | M13: =K13/$M$6 -> 0
H14: =+C14*E14 -> 0 | I14: =+C14*F14*$I$6 -> 0 | J14: =+C14*G14*$J$6 -> 0 | K14: =SUM(H14+I14+J14) -> 0 | M14: =K14/$M$6 -> 0
H15: =+C15*E15 -> 0 | I15: =+C15*F15*$I$6 -> 0 | J15: =+C15*G15*$J$6 -> 0 | K15: =SUM(H15+I15+J15) -> 0 | M15: =K15/$M$6 -> 0
H16: =+C16*E16 -> 0 | I16: =+C16*F16*$I$6 -> 0 | J16: =+C16*G16*$J$6 -> 0 | K16: =SUM(H16+I16+J16) -> 0 | M16: =K16/$M$6 -> 0
H17: =+C17*E17 -> 0 | I17: =+C17*F17*$I$6 -> 0 | J17: =+C17*G17*$J$6 -> 0 | K17: =SUM(H17+I17+J17) -> 0 | M17: =K17/$M$6 -> 0
H18: =+C18*E18 -> 0 | I18: =+C18*F18*$I$6 -> 0 | J18: =+C18*G18*$J$6 -> 0 | K18: =SUM(H18+I18+J18) -> 0 | M18: =K18/$M$6 -> 0
H19: =+C19*E19 -> 0 | I19: =+C19*F19*$I$6 -> 0 | J19: =+C19*G19*$J$6 -> 0 | K19: =SUM(H19+I19+J19) -> 0 | M19: =K19/$M$6 -> 0
H20: =+C20*E20 -> 0 | I20: =+C20*F20*$I$6 -> 0 | J20: =+C20*G20*$J$6 -> 0 | K20: =SUM(H20+I20+J20) -> 0 | M20: =K20/$M$6 -> 0
H21: =+C21*E21 -> 0 | I21: =+C21*F21*$I$6 -> 0 | J21: =+C21*G21*$J$6 -> 0 | K21: =SUM(H21+I21+J21) -> 0 | M21: =K21/$M$6 -> 0
H22: =+C22*E22 -> 0 | I22: =+C22*F22*$I$6 -> 0 | J22: =+C22*G22*$J$6 -> 0 | K22: =SUM(H22+I22+J22) -> 0 | M22: =K22/$M$6 -> 0
H23: =+C23*E23 -> 0 | I23: =+C23*F23*$I$6 -> 0 | J23: =+C23*G23*$J$6 -> 0 | K23: =SUM(H23+I23+J23) -> 0 | M23: =K23/$M$6 -> 0
A24: - | B24: - | C24: - | D24: - | H24: - | I24: - | J24: - | K24: - | L24: - | M24: -
B25: SUB-TOTAL: | H25: =SUM(H11:H23) -> 0 | I25: =SUM(I11:I23) -> 0 | J25: =SUM(J11:J23) -> 0 | K25: =SUM(K11:K23) -> 0 | M25: =K25/$M$6 -> 0
B26: SALES TAX/PAYROLL TAXES: | D26: INCL | I26: 0 | J26: 0 | K26: =+H26+I26+J26 -> 0 | M26: =K26/$M$6 -> 0
A27: - | B27: - | C27: - | D27: - | H27: - | I27: - | J27: - | K27: - | L27: - | M27: -
B28: SUB-TOTAL: | K28: =SUM(K25:K26) -> 0 | M28: =K28/$M$6 -> 0
M29: =K29/$M$6 -> 0
B30: CONTRACTOR FEE: | C30: 10 | D30: % | K30: =C30*K28/100 -> 0 | M30: =K30/$M$6 -> 0
H32: =+C32*E32 -> 0 | I32: =+C32*F32 -> 0 | J32: =+E32*G32 -> 0 | K32: =SUM(H32+I32+J32) -> 0 | M32: =K32/$M$6 -> 0
H33: =+C33*E33 -> 0 | I33: =+C33*F33 -> 0 | J33: =+E33*G33 -> 0 | K33: =SUM(H33+I33+J33) -> 0 | M33: =K33/$M$6 -> 0
H34: =+C34*E34 -> 0 | I34: =+C34*F34 -> 0 | J34: =+E34*G34 -> 0 | K34: =SUM(H34+I34+J34) -> 0 | M34: =K34/$M$6 -> 0
B35: BUILDER'S RISK INSURANCE (2.1%) | C35: 0 | D35: % | K35: =SUM(K28:K33)*C35/100 -> 0 | M35: =K35/$M$6 -> 0
M36: =K36/$M$6 -> 0
B37: GENERAL LIABILITY INSURANCE | C37: 1.3 | D37: % | K37: =SUM(K28:K36)*C37/100 -> 0 | M37: =K37/$M$6 -> 0
B38: IT FEE | C38: 0.25 | D38: % | K38: =(K28)*C38/100 -> 0 | M38: =K38/$M$6 -> 0
B39: CONTINGENCY | C39: 5 | D39: % | K39: =(K28)*C39/100 -> 0 | M39: =K39/$M$6 -> 0
M42: =K42/$M$6 -> 0
B43: BOND | C43: 0 | D43: % | K43: =SUM(K28:K42)*C43/100 -> 0 | M43: =K43/$M$6 -> 0
A44: - | B44: - | C44: - | D44: - | H44: - | I44: - | J44: - | K44: - | L44: - | M44: -
B45: TOTAL: | K45: =SUM(K28:K43) -> 0 | M45: =K45/$M$6 -> 0

Sheet Alt05
B1: =K45 -> 0 | L1: Job No.: | M1: ='Alt01'!M1 -> -
B3: Alternate No. 5-
B5: =+NOW() -> 44537.429
B6: =NOW() -> 44537.429 | I6: 1.07 | J6: 1 | M6: 1
A7: - | B7: - | C7: - | D7: - | H7: - | I7: - | J7: - | K7: - | L7: - | M7: -
A8: SPEC | E8: UNIT | F8: UNIT | G8: UNIT | M8: COST/
A9: SECTION | B9: DESCRIPTION | C9: QTY | D9: UNIT | E9: SUB | F9: MATL | G9: LABOR | H9: SUB | I9: MATL | J9: LABOR | K9: TOTAL: | L9: SUBCONTRACTOR | M9: SF
A10: - | B10: - | C10: - | D10: - | H10: - | I10: - | J10: - | K10: - | L10: - | M10: -
H11: =+C11*E11 -> 0 | I11: =+C11*F11*$I$6 -> 0 | J11: =+C11*G11*$J$6 -> 0 | K11: =SUM(H11+I11+J11) -> 0 | M11: =K11/$M$6 -> 0
H12: =+C12*E12 -> 0 | I12: =+C12*F12*$I$6 -> 0 | J12: =+C12*G12*$J$6 -> 0 | K12: =SUM(H12+I12+J12) -> 0 | M12: =K12/$M$6 -> 0
H13: =+C13*E13 -> 0 | I13: =+C13*F13*$I$6 -> 0 | J13: =+C13*G13*$J$6 -> 0 | K13: =SUM(H13+I13+J13) -> 0 | M13: =K13/$M$6 -> 0
H14: =+C14*E14 -> 0 | I14: =+C14*F14*$I$6 -> 0 | J14: =+C14*G14*$J$6 -> 0 | K14: =SUM(H14+I14+J14) -> 0 | M14: =K14/$M$6 -> 0
H15: =+C15*E15 -> 0 | I15: =+C15*F15*$I$6 -> 0 | J15: =+C15*G15*$J$6 -> 0 | K15: =SUM(H15+I15+J15) -> 0 | M15: =K15/$M$6 -> 0
H16: =+C16*E16 -> 0 | I16: =+C16*F16*$I$6 -> 0 | J16: =+C16*G16*$J$6 -> 0 | K16: =SUM(H16+I16+J16) -> 0 | M16: =K16/$M$6 -> 0
H17: =+C17*E17 -> 0 | I17: =+C17*F17*$I$6 -> 0 | J17: =+C17*G17*$J$6 -> 0 | K17: =SUM(H17+I17+J17) -> 0 | M17: =K17/$M$6 -> 0
H18: =+C18*E18 -> 0 | I18: =+C18*F18*$I$6 -> 0 | J18: =+C18*G18*$J$6 -> 0 | K18: =SUM(H18+I18+J18) -> 0 | M18: =K18/$M$6 -> 0
H19: =+C19*E19 -> 0 | I19: =+C19*F19*$I$6 -> 0 | J19: =+C19*G19*$J$6 -> 0 | K19: =SUM(H19+I19+J19) -> 0 | M19: =K19/$M$6 -> 0
H20: =+C20*E20 -> 0 | I20: =+C20*F20*$I$6 -> 0 | J20: =+C20*G20*$J$6 -> 0 | K20: =SUM(H20+I20+J20) -> 0 | M20: =K20/$M$6 -> 0
H21: =+C21*E21 -> 0 | I21: =+C21*F21*$I$6 -> 0 | J21: =+C21*G21*$J$6 -> 0 | K21: =SUM(H21+I21+J21) -> 0 | M21: =K21/$M$6 -> 0
H22: =+C22*E22 -> 0 | I22: =+C22*F22*$I$6 -> 0 | J22: =+C22*G22*$J$6 -> 0 | K22: =SUM(H22+I22+J22) -> 0 | M22: =K22/$M$6 -> 0
H23: =+C23*E23 -> 0 | I23: =+C23*F23*$I$6 -> 0 | J23: =+C23*G23*$J$6 -> 0 | K23: =SUM(H23+I23+J23) -> 0 | M23: =K23/$M$6 -> 0
A24: - | B24: - | C24: - | D24: - | H24: - | I24: - | J24: - | K24: - | L24: - | M24: -
B25: SUB-TOTAL: | H25: =SUM(H11:H23) -> 0 | I25: =SUM(I11:I23) -> 0 | J25: =SUM(J11:J23) -> 0 | K25: =SUM(K11:K23) -> 0 | M25: =K25/$M$6 -> 0
B26: SALES TAX/PAYROLL TAXES: | D26: INCL | I26: 0 | J26: 0 | K26: =+H26+I26+J26 -> 0 | M26: =K26/$M$6 -> 0
A27: - | B27: - | C27: - | D27: - | H27: - | I27: - | J27: - | K27: - | L27: - | M27: -
B28: SUB-TOTAL: | K28: =SUM(K25:K26) -> 0 | M28: =K28/$M$6 -> 0
M29: =K29/$M$6 -> 0
B30: CONTRACTOR FEE: | C30: 10 | D30: % | K30: =C30*K28/100 -> 0 | M30: =K30/$M$6 -> 0
H32: =+C32*E32 -> 0 | I32: =+C32*F32 -> 0 | J32: =+E32*G32 -> 0 | K32: =SUM(H32+I32+J32) -> 0 | M32: =K32/$M$6 -> 0
H33: =+C33*E33 -> 0 | I33: =+C33*F33 -> 0 | J33: =+E33*G33 -> 0 | K33: =SUM(H33+I33+J33) -> 0 | M33: =K33/$M$6 -> 0
H34: =+C34*E34 -> 0 | I34: =+C34*F34 -> 0 | J34: =+E34*G34 -> 0 | K34: =SUM(H34+I34+J34) -> 0 | M34: =K34/$M$6 -> 0
B35: BUILDER'S RISK INSURANCE (2.1%) | C35: 0 | D35: % | K35: =SUM(K28:K33)*C35/100 -> 0 | M35: =K35/$M$6 -> 0
M36: =K36/$M$6 -> 0
B37: GENERAL LIABILITY INSURANCE | C37: 1.3 | D37: % | K37: =SUM(K28:K36)*C37/100 -> 0 | M37: =K37/$M$6 -> 0
B38: IT FEE | C38: 0.25 | D38: % | K38: =(K28)*C38/100 -> 0 | M38: =K38/$M$6 -> 0
B39: CONTINGENCY | C39: 5 | D39: % | K39: =(K28)*C39/100 -> 0 | M39: =K39/$M$6 -> 0
M42: =K42/$M$6 -> 0
B43: BOND | C43: 0 | D43: % | K43: =SUM(K28:K42)*C43/100 -> 0 | M43: =K43/$M$6 -> 0
A44: - | B44: - | C44: - | D44: - | H44: - | I44: - | J44: - | K44: - | L44: - | M44: -
B45: TOTAL: | K45: =SUM(K28:K43) -> 0 | M45: =K45/$M$6 -> 0

Sheet Alt06
B1: =K45 -> 0 | L1: Job No.: | M1: ='Alt01'!M1 -> -
B3: Alternate No. 6-
B5: =+NOW() -> 44537.429
B6: =NOW() -> 44537.429 | I6: 1.07 | J6: 1 | M6: 1
A7: - | B7: - | C7: - | D7: - | H7: - | I7: - | J7: - | K7: - | L7: - | M7: -
A8: SPEC | E8: UNIT | F8: UNIT | G8: UNIT | M8: COST/
A9: SECTION | B9: DESCRIPTION | C9: QTY | D9: UNIT | E9: SUB | F9: MATL | G9: LABOR | H9: SUB | I9: MATL | J9: LABOR | K9: TOTAL: | L9: SUBCONTRACTOR | M9: SF
A10: - | B10: - | C10: - | D10: - | H10: - | I10: - | J10: - | K10: - | L10: - | M10: -
H11: =+C11*E11 -> 0 | I11: =+C11*F11*$I$6 -> 0 | J11: =+C11*G11*$J$6 -> 0 | K11: =SUM(H11+I11+J11) -> 0 | M11: =K11/$M$6 -> 0
H12: =+C12*E12 -> 0 | I12: =+C12*F12*$I$6 -> 0 | J12: =+C12*G12*$J$6 -> 0 | K12: =SUM(H12+I12+J12) -> 0 | M12: =K12/$M$6 -> 0
H13: =+C13*E13 -> 0 | I13: =+C13*F13*$I$6 -> 0 | J13: =+C13*G13*$J$6 -> 0 | K13: =SUM(H13+I13+J13) -> 0 | M13: =K13/$M$6 -> 0
H14: =+C14*E14 -> 0 | I14: =+C14*F14*$I$6 -> 0 | J14: =+C14*G14*$J$6 -> 0 | K14: =SUM(H14+I14+J14) -> 0 | M14: =K14/$M$6 -> 0
H15: =+C15*E15 -> 0 | I15: =+C15*F15*$I$6 -> 0 | J15: =+C15*G15*$J$6 -> 0 | K15: =SUM(H15+I15+J15) -> 0 | M15: =K15/$M$6 -> 0
H16: =+C16*E16 -> 0 | I16: =+C16*F16*$I$6 -> 0 | J16: =+C16*G16*$J$6 -> 0 | K16: =SUM(H16+I16+J16) -> 0 | M16: =K16/$M$6 -> 0
H17: =+C17*E17 -> 0 | I17: =+C17*F17*$I$6 -> 0 | J17: =+C17*G17*$J$6 -> 0 | K17: =SUM(H17+I17+J17) -> 0 | M17: =K17/$M$6 -> 0
H18: =+C18*E18 -> 0 | I18: =+C18*F18*$I$6 -> 0 | J18: =+C18*G18*$J$6 -> 0 | K18: =SUM(H18+I18+J18) -> 0 | M18: =K18/$M$6 -> 0
H19: =+C19*E19 -> 0 | I19: =+C19*F19*$I$6 -> 0 | J19: =+C19*G19*$J$6 -> 0 | K19: =SUM(H19+I19+J19) -> 0 | M19: =K19/$M$6 -> 0
H20: =+C20*E20 -> 0 | I20: =+C20*F20*$I$6 -> 0 | J20: =+C20*G20*$J$6 -> 0 | K20: =SUM(H20+I20+J20) -> 0 | M20: =K20/$M$6 -> 0
H21: =+C21*E21 -> 0 | I21: =+C21*F21*$I$6 -> 0 | J21: =+C21*G21*$J$6 -> 0 | K21: =SUM(H21+I21+J21) -> 0 | M21: =K21/$M$6 -> 0
H22: =+C22*E22 -> 0 | I22: =+C22*F22*$I$6 -> 0 | J22: =+C22*G22*$J$6 -> 0 | K22: =SUM(H22+I22+J22) -> 0 | M22: =K22/$M$6 -> 0
H23: =+C23*E23 -> 0 | I23: =+C23*F23*$I$6 -> 0 | J23: =+C23*G23*$J$6 -> 0 | K23: =SUM(H23+I23+J23) -> 0 | M23: =K23/$M$6 -> 0
A24: - | B24: - | C24: - | D24: - | H24: - | I24: - | J24: - | K24: - | L24: - | M24: -
B25: SUB-TOTAL: | H25: =SUM(H11:H23) -> 0 | I25: =SUM(I11:I23) -> 0 | J25: =SUM(J11:J23) -> 0 | K25: =SUM(K11:K23) -> 0 | M25: =K25/$M$6 -> 0
B26: SALES TAX/PAYROLL TAXES: | D26: INCL | I26: 0 | J26: 0 | K26: =+H26+I26+J26 -> 0 | M26: =K26/$M$6 -> 0
A27: - | B27: - | C27: - | D27: - | H27: - | I27: - | J27: - | K27: - | L27: - | M27: -
B28: SUB-TOTAL: | K28: =SUM(K25:K26) -> 0 | M28: =K28/$M$6 -> 0
M29: =K29/$M$6 -> 0
B30: CONTRACTOR FEE: | C30: 10 | D30: % | K30: =C30*K28/100 -> 0 | M30: =K30/$M$6 -> 0
H32: =+C32*E32 -> 0 | I32: =+C32*F32 -> 0 | J32: =+E32*G32 -> 0 | K32: =SUM(H32+I32+J32) -> 0 | M32: =K32/$M$6 -> 0
H33: =+C33*E33 -> 0 | I33: =+C33*F33 -> 0 | J33: =+E33*G33 -> 0 | K33: =SUM(H33+I33+J33) -> 0 | M33: =K33/$M$6 -> 0
H34: =+C34*E34 -> 0 | I34: =+C34*F34 -> 0 | J34: =+E34*G34 -> 0 | K34: =SUM(H34+I34+J34) -> 0 | M34: =K34/$M$6 -> 0
B35: BUILDER'S RISK INSURANCE (2.1%) | C35: 0 | D35: % | K35: =SUM(K28:K33)*C35/100 -> 0 | M35: =K35/$M$6 -> 0
M36: =K36/$M$6 -> 0
B37: GENERAL LIABILITY INSURANCE | C37: 1.3 | D37: % | K37: =SUM(K28:K36)*C37/100 -> 0 | M37: =K37/$M$6 -> 0
B38: IT FEE | C38: 0.25 | D38: % | K38: =(K28)*C38/100 -> 0 | M38: =K38/$M$6 -> 0
B39: CONTINGENCY | C39: 5 | D39: % | K39: =(K28)*C39/100 -> 0 | M39: =K39/$M$6 -> 0
M42: =K42/$M$6 -> 0
B43: BOND | C43: 0 | D43: % | K43: =SUM(K28:K42)*C43/100 -> 0 | M43: =K43/$M$6 -> 0
A44: - | B44: - | C44: - | D44: - | H44: - | I44: - | J44: - | K44: - | L44: - | M44: -
B45: TOTAL: | K45: =SUM(K28:K43) -> 0 | M45: =K45/$M$6 -> 0

Sheet Alt07
B1: =K45 -> 0 | L1: Job No.: | M1: ='Alt01'!M1 -> -
B3: Alternate No. 7-
B5: =+NOW() -> 44537.429
B6: =NOW() -> 44537.429 | I6: 1.07 | J6: 1 | M6: 1
A7: - | B7: - | C7: - | D7: - | H7: - | I7: - | J7: - | K7: - | L7: - | M7: -
A8: SPEC | E8: UNIT | F8: UNIT | G8: UNIT | M8: COST/
A9: SECTION | B9: DESCRIPTION | C9: QTY | D9: UNIT | E9: SUB | F9: MATL | G9: LABOR | H9: SUB | I9: MATL | J9: LABOR | K9: TOTAL: | L9: SUBCONTRACTOR | M9: SF
A10: - | B10: - | C10: - | D10: - | H10: - | I10: - | J10: - | K10: - | L10: - | M10: -
H11: =+C11*E11 -> 0 | I11: =+C11*F11*$I$6 -> 0 | J11: =+C11*G11*$J$6 -> 0 | K11: =SUM(H11+I11+J11) -> 0 | M11: =K11/$M$6 -> 0
H12: =+C12*E12 -> 0 | I12: =+C12*F12*$I$6 -> 0 | J12: =+C12*G12*$J$6 -> 0 | K12: =SUM(H12+I12+J12) -> 0 | M12: =K12/$M$6 -> 0
H13: =+C13*E13 -> 0 | I13: =+C13*F13*$I$6 -> 0 | J13: =+C13*G13*$J$6 -> 0 | K13: =SUM(H13+I13+J13) -> 0 | M13: =K13/$M$6 -> 0
H14: =+C14*E14 -> 0 | I14: =+C14*F14*$I$6 -> 0 | J14: =+C14*G14*$J$6 -> 0 | K14: =SUM(H14+I14+J14) -> 0 | M14: =K14/$M$6 -> 0
H15: =+C15*E15 -> 0 | I15: =+C15*F15*$I$6 -> 0 | J15: =+C15*G15*$J$6 -> 0 | K15: =SUM(H15+I15+J15) -> 0 | M15: =K15/$M$6 -> 0
H16: =+C16*E16 -> 0 | I16: =+C16*F16*$I$6 -> 0 | J16: =+C16*G16*$J$6 -> 0 | K16: =SUM(H16+I16+J16) -> 0 | M16: =K16/$M$6 -> 0
H17: =+C17*E17 -> 0 | I17: =+C17*F17*$I$6 -> 0 | J17: =+C17*G17*$J$6 -> 0 | K17: =SUM(H17+I17+J17) -> 0 | M17: =K17/$M$6 -> 0
H18: =+C18*E18 -> 0 | I18: =+C18*F18*$I$6 -> 0 | J18: =+C18*G18*$J$6 -> 0 | K18: =SUM(H18+I18+J18) -> 0 | M18: =K18/$M$6 -> 0
H19: =+C19*E19 -> 0 | I19: =+C19*F19*$I$6 -> 0 | J19: =+C19*G19*$J$6 -> 0 | K19: =SUM(H19+I19+J19) -> 0 | M19: =K19/$M$6 -> 0
H20: =+C20*E20 -> 0 | I20: =+C20*F20*$I$6 -> 0 | J20: =+C20*G20*$J$6 -> 0 | K20: =SUM(H20+I20+J20) -> 0 | M20: =K20/$M$6 -> 0
H21: =+C21*E21 -> 0 | I21: =+C21*F21*$I$6 -> 0 | J21: =+C21*G21*$J$6 -> 0 | K21: =SUM(H21+I21+J21) -> 0 | M21: =K21/$M$6 -> 0
H22: =+C22*E22 -> 0 | I22: =+C22*F22*$I$6 -> 0 | J22: =+C22*G22*$J$6 -> 0 | K22: =SUM(H22+I22+J22) -> 0 | M22: =K22/$M$6 -> 0
H23: =+C23*E23 -> 0 | I23: =+C23*F23*$I$6 -> 0 | J23: =+C23*G23*$J$6 -> 0 | K23: =SUM(H23+I23+J23) -> 0 | M23: =K23/$M$6 -> 0
A24: - | B24: - | C24: - | D24: - | H24: - | I24: - | J24: - | K24: - | L24: - | M24: -
B25: SUB-TOTAL: | H25: =SUM(H11:H23) -> 0 | I25: =SUM(I11:I23) -> 0 | J25: =SUM(J11:J23) -> 0 | K25: =SUM(K11:K23) -> 0 | M25: =K25/$M$6 -> 0
B26: SALES TAX/PAYROLL TAXES: | D26: INCL | I26: 0 | J26: 0 | K26: =+H26+I26+J26 -> 0 | M26: =K26/$M$6 -> 0
A27: - | B27: - | C27: - | D27: - | H27: - | I27: - | J27: - | K27: - | L27: - | M27: -
B28: SUB-TOTAL: | K28: =SUM(K25:K26) -> 0 | M28: =K28/$M$6 -> 0
M29: =K29/$M$6 -> 0
B30: CONTRACTOR FEE: | C30: 10 | D30: % | K30: =C30*K28/100 -> 0 | M30: =K30/$M$6 -> 0
H32: =+C32*E32 -> 0 | I32: =+C32*F32 -> 0 | J32: =+E32*G32 -> 0 | K32: =SUM(H32+I32+J32) -> 0 | M32: =K32/$M$6 -> 0
H33: =+C33*E33 -> 0 | I33: =+C33*F33 -> 0 | J33: =+E33*G33 -> 0 | K33: =SUM(H33+I33+J33) -> 0 | M33: =K33/$M$6 -> 0
H34: =+C34*E34 -> 0 | I34: =+C34*F34 -> 0 | J34: =+E34*G34 -> 0 | K34: =SUM(H34+I34+J34) -> 0 | M34: =K34/$M$6 -> 0
B35: BUILDER'S RISK INSURANCE (2.1%) | C35: 0 | D35: % | K35: =SUM(K28:K33)*C35/100 -> 0 | M35: =K35/$M$6 -> 0
M36: =K36/$M$6 -> 0
B37: GENERAL LIABILITY INSURANCE | C37: 1.3 | D37: % | K37: =SUM(K28:K36)*C37/100 -> 0 | M37: =K37/$M$6 -> 0
B38: IT FEE | C38: 0.25 | D38: % | K38: =(K28)*C38/100 -> 0 | M38: =K38/$M$6 -> 0
B39: CONTINGENCY | C39: 5 | D39: % | K39: =(K28)*C39/100 -> 0 | M39: =K39/$M$6 -> 0
M42: =K42/$M$6 -> 0
B43: BOND | C43: 0 | D43: % | K43: =SUM(K28:K42)*C43/100 -> 0 | M43: =K43/$M$6 -> 0
A44: - | B44: - | C44: - | D44: - | H44: - | I44: - | J44: - | K44: - | L44: - | M44: -
B45: TOTAL: | K45: =SUM(K28:K43) -> 0 | M45: =K45/$M$6 -> 0

Sheet Alt08
B1: =K45 -> 0 | L1: Job No.: | M1: ='Alt01'!M1 -> -
B3: Alternate No. 8-
B4: Specifics
B5: =+NOW() -> 44537.429
B6: =NOW() -> 44537.429 | I6: 1.07 | J6: 1 | M6: 1
A7: - | B7: - | C7: - | D7: - | H7: - | I7: - | J7: - | K7: - | L7: - | M7: -
A8: SPEC | E8: UNIT | F8: UNIT | G8: UNIT | M8: COST/
A9: SECTION | B9: DESCRIPTION | C9: QTY | D9: UNIT | E9: SUB | F9: MATL | G9: LABOR | H9: SUB | I9: MATL | J9: LABOR | K9: TOTAL: | L9: SUBCONTRACTOR | M9: SF
A10: - | B10: - | C10: - | D10: - | H10: - | I10: - | J10: - | K10: - | L10: - | M10: -
H11: =+C11*E11 -> 0 | I11: =+C11*F11*$I$6 -> 0 | J11: =+C11*G11*$J$6 -> 0 | K11: =SUM(H11+I11+J11) -> 0 | M11: =K11/$M$6 -> 0
H12: =+C12*E12 -> 0 | I12: =+C12*F12*$I$6 -> 0 | J12: =+C12*G12*$J$6 -> 0 | K12: =SUM(H12+I12+J12) -> 0 | M12: =K12/$M$6 -> 0
H13: =+C13*E13 -> 0 | I13: =+C13*F13*$I$6 -> 0 | J13: =+C13*G13*$J$6 -> 0 | K13: =SUM(H13+I13+J13) -> 0 | M13: =K13/$M$6 -> 0
H14: =+C14*E14 -> 0 | I14: =+C14*F14*$I$6 -> 0 | J14: =+C14*G14*$J$6 -> 0 | K14: =SUM(H14+I14+J14) -> 0 | M14: =K14/$M$6 -> 0
H15: =+C15*E15 -> 0 | I15: =+C15*F15*$I$6 -> 0 | J15: =+C15*G15*$J$6 -> 0 | K15: =SUM(H15+I15+J15) -> 0 | M15: =K15/$M$6 -> 0
H16: =+C16*E16 -> 0 | I16: =+C16*F16*$I$6 -> 0 | J16: =+C16*G16*$J$6 -> 0 | K16: =SUM(H16+I16+J16) -> 0 | M16: =K16/$M$6 -> 0
H17: =+C17*E17 -> 0 | I17: =+C17*F17*$I$6 -> 0 | J17: =+C17*G17*$J$6 -> 0 | K17: =SUM(H17+I17+J17) -> 0 | M17: =K17/$M$6 -> 0
H18: =+C18*E18 -> 0 | I18: =+C18*F18*$I$6 -> 0 | J18: =+C18*G18*$J$6 -> 0 | K18: =SUM(H18+I18+J18) -> 0 | M18: =K18/$M$6 -> 0
H19: =+C19*E19 -> 0 | I19: =+C19*F19*$I$6 -> 0 | J19: =+C19*G19*$J$6 -> 0 | K19: =SUM(H19+I19+J19) -> 0 | M19: =K19/$M$6 -> 0
H20: =+C20*E20 -> 0 | I20: =+C20*F20*$I$6 -> 0 | J20: =+C20*G20*$J$6 -> 0 | K20: =SUM(H20+I20+J20) -> 0 | M20: =K20/$M$6 -> 0
H21: =+C21*E21 -> 0 | I21: =+C21*F21*$I$6 -> 0 | J21: =+C21*G21*$J$6 -> 0 | K21: =SUM(H21+I21+J21) -> 0 | M21: =K21/$M$6 -> 0
H22: =+C22*E22 -> 0 | I22: =+C22*F22*$I$6 -> 0 | J22: =+C22*G22*$J$6 -> 0 | K22: =SUM(H22+I22+J22) -> 0 | M22: =K22/$M$6 -> 0
H23: =+C23*E23 -> 0 | I23: =+C23*F23*$I$6 -> 0 | J23: =+C23*G23*$J$6 -> 0 | K23: =SUM(H23+I23+J23) -> 0 | M23: =K23/$M$6 -> 0
A24: - | B24: - | C24: - | D24: - | H24: - | I24: - | J24: - | K24: - | L24: - | M24: -
B25: SUB-TOTAL: | H25: =SUM(H11:H23) -> 0 | I25: =SUM(I11:I23) -> 0 | J25: =SUM(J11:J23) -> 0 | K25: =SUM(K11:K23) -> 0 | M25: =K25/$M$6 -> 0
B26: SALES TAX/PAYROLL TAXES: | D26: INCL | I26: 0 | J26: 0 | K26: =+H26+I26+J26 -> 0 | M26: =K26/$M$6 -> 0
A27: - | B27: - | C27: - | D27: - | H27: - | I27: - | J27: - | K27: - | L27: - | M27: -
B28: SUB-TOTAL: | K28: =SUM(K25:K26) -> 0 | M28: =K28/$M$6 -> 0
M29: =K29/$M$6 -> 0
B30: CONTRACTOR FEE: | C30: 10 | D30: % | K30: =C30*K28/100 -> 0 | M30: =K30/$M$6 -> 0
H32: =+C32*E32 -> 0 | I32: =+C32*F32 -> 0 | J32: =+E32*G32 -> 0 | K32: =SUM(H32+I32+J32) -> 0 | M32: =K32/$M$6 -> 0
H33: =+C33*E33 -> 0 | I33: =+C33*F33 -> 0 | J33: =+E33*G33 -> 0 | K33: =SUM(H33+I33+J33) -> 0 | M33: =K33/$M$6 -> 0
H34: =+C34*E34 -> 0 | I34: =+C34*F34 -> 0 | J34: =+E34*G34 -> 0 | K34: =SUM(H34+I34+J34) -> 0 | M34: =K34/$M$6 -> 0
B35: BUILDER'S RISK INSURANCE (2.1%) | C35: 0 | D35: % | K35: =SUM(K28:K33)*C35/100 -> 0 | M35: =K35/$M$6 -> 0
M36: =K36/$M$6 -> 0
B37: GENERAL LIABILITY INSURANCE | C37: 1.3 | D37: % | K37: =SUM(K28:K36)*C37/100 -> 0 | M37: =K37/$M$6 -> 0
B38: IT FEE | C38: 0.25 | D38: % | K38: =(K28)*C38/100 -> 0 | M38: =K38/$M$6 -> 0
B39: CONTINGENCY | C39: 5 | D39: % | K39: =(K28)*C39/100 -> 0 | M39: =K39/$M$6 -> 0
M42: =K42/$M$6 -> 0
B43: BOND | C43: 0 | D43: % | K43: =SUM(K28:K42)*C43/100 -> 0 | M43: =K43/$M$6 -> 0
A44: - | B44: - | C44: - | D44: - | H44: - | I44: - | J44: - | K44: - | L44: - | M44: -
...

Sheet Alt09
B1: =K45 -> 0 | L1: Job No.: | M1: ='Alt01'!M1 -> -
B3: Alternate No. 9-
B4: Specifics
B5: =+NOW() -> 44537.429
B6: =NOW() -> 44537.429 | I6: 1.07 | J6: 1 | M6: 1
A7: - | B7: - | C7: - | D7: - | H7: - | I7: - | J7: - | K7: - | L7: - | M7: -
A8: SPEC | E8: UNIT | F8: UNIT | G8: UNIT | M8: COST/
A9: SECTION | B9: DESCRIPTION | C9: QTY | D9: UNIT | E9: SUB | F9: MATL | G9: LABOR | H9: SUB | I9: MATL | J9: LABOR | K9: TOTAL: | L9: SUBCONTRACTOR | M9: SF
A10: - | B10: - | C10: - | D10: - | H10: - | I10: - | J10: - | K10: - | L10: - | M10: -
H11: =+C11*E11 -> 0 | I11: =+C11*F11*$I$6 -> 0 | J11: =+C11*G11*$J$6 -> 0 | K11: =SUM(H11+I11+J11) -> 0 | M11: =K11/$M$6 -> 0
H12: =+C12*E12 -> 0 | I12: =+C12*F12*$I$6 -> 0 | J12: =+C12*G12*$J$6 -> 0 | K12: =SUM(H12+I12+J12) -> 0 | M12: =K12/$M$6 -> 0
H13: =+C13*E13 -> 0 | I13: =+C13*F13*$I$6 -> 0 | J13: =+C13*G13*$J$6 -> 0 | K13: =SUM(H13+I13+J13) -> 0 | M13: =K13/$M$6 -> 0
H14: =+C14*E14 -> 0 | I14: =+C14*F14*$I$6 -> 0 | J14: =+C14*G14*$J$6 -> 0 | K14: =SUM(H14+I14+J14) -> 0 | M14: =K14/$M$6 -> 0
H15: =+C15*E15 -> 0 | I15: =+C15*F15*$I$6 -> 0 | J15: =+C15*G15*$J$6 -> 0 | K15: =SUM(H15+I15+J15) -> 0 | M15: =K15/$M$6 -> 0
H16: =+C16*E16 -> 0 | I16: =+C16*F16*$I$6 -> 0 | J16: =+C16*G16*$J$6 -> 0 | K16: =SUM(H16+I16+J16) -> 0 | M16: =K16/$M$6 -> 0
H17: =+C17*E17 -> 0 | I17: =+C17*F17*$I$6 -> 0 | J17: =+C17*G17*$J$6 -> 0 | K17: =SUM(H17+I17+J17) -> 0 | M17: =K17/$M$6 -> 0
H18: =+C18*E18 -> 0 | I18: =+C18*F18*$I$6 -> 0 | J18: =+C18*G18*$J$6 -> 0 | K18: =SUM(H18+I18+J18) -> 0 | M18: =K18/$M$6 -> 0
H19: =+C19*E19 -> 0 | I19: =+C19*F19*$I$6 -> 0 | J19: =+C19*G19*$J$6 -> 0 | K19: =SUM(H19+I19+J19) -> 0 | M19: =K19/$M$6 -> 0
H20: =+C20*E20 -> 0 | I20: =+C20*F20*$I$6 -> 0 | J20: =+C20*G20*$J$6 -> 0 | K20: =SUM(H20+I20+J20) -> 0 | M20: =K20/$M$6 -> 0
H21: =+C21*E21 -> 0 | I21: =+C21*F21*$I$6 -> 0 | J21: =+C21*G21*$J$6 -> 0 | K21: =SUM(H21+I21+J21) -> 0 | M21: =K21/$M$6 -> 0
H22: =+C22*E22 -> 0 | I22: =+C22*F22*$I$6 -> 0 | J22: =+C22*G22*$J$6 -> 0 | K22: =SUM(H22+I22+J22) -> 0 | M22: =K22/$M$6 -> 0
H23: =+C23*E23 -> 0 | I23: =+C23*F23*$I$6 -> 0 | J23: =+C23*G23*$J$6 -> 0 | K23: =SUM(H23+I23+J23) -> 0 | M23: =K23/$M$6 -> 0
A24: - | B24: - | C24: - | D24: - | H24: - | I24: - | J24: - | K24: - | L24: - | M24: -
B25: SUB-TOTAL: | H25: =SUM(H11:H23) -> 0 | I25: =SUM(I11:I23) -> 0 | J25: =SUM(J11:J23) -> 0 | K25: =SUM(K11:K23) -> 0 | M25: =K25/$M$6 -> 0
B26: SALES TAX/PAYROLL TAXES: | D26: INCL | I26: 0 | J26: 0 | K26: =+H26+I26+J26 -> 0 | M26: =K26/$M$6 -> 0
A27: - | B27: - | C27: - | D27: - | H27: - | I27: - | J27: - | K27: - | L27: - | M27: -
B28: SUB-TOTAL: | K28: =SUM(K25:K26) -> 0 | M28: =K28/$M$6 -> 0
M29: =K29/$M$6 -> 0
B30: CONTRACTOR FEE: | C30: 10 | D30: % | K30: =C30*K28/100 -> 0 | M30: =K30/$M$6 -> 0
H32: =+C32*E32 -> 0 | I32: =+C32*F32 -> 0 | J32: =+E32*G32 -> 0 | K32: =SUM(H32+I32+J32) -> 0 | M32: =K32/$M$6 -> 0
H33: =+C33*E33 -> 0 | I33: =+C33*F33 -> 0 | J33: =+E33*G33 -> 0 | K33: =SUM(H33+I33+J33) -> 0 | M33: =K33/$M$6 -> 0
H34: =+C34*E34 -> 0 | I34: =+C34*F34 -> 0 | J34: =+E34*G34 -> 0 | K34: =SUM(H34+I34+J34) -> 0 | M34: =K34/$M$6 -> 0
B35: BUILDER'S RISK INSURANCE (2.1%) | C35: 0 | D35: % | K35: =SUM(K28:K33)*C35/100 -> 0 | M35: =K35/$M$6 -> 0
M36: =K36/$M$6 -> 0
B37: GENERAL LIABILITY INSURANCE | C37: 1.3 | D37: % | K37: =SUM(K28:K36)*C37/100 -> 0 | M37: =K37/$M$6 -> 0
B38: IT FEE | C38: 0.25 | D38: % | K38: =(K28)*C38/100 -> 0 | M38: =K38/$M$6 -> 0
B39: CONTINGENCY | C39: 5 | D39: % | K39: =(K28)*C39/100 -> 0 | M39: =K39/$M$6 -> 0
M42: =K42/$M$6 -> 0
B43: BOND | C43: 0 | D43: % | K43: =SUM(K28:K42)*C43/100 -> 0 | M43: =K43/$M$6 -> 0
A44: - | B44: - | C44: - | D44: - | H44: - | I44: - | J44: - | K44: - | L44: - | M44: -
...

Sheet Alt10
B1: =K45 -> 0 | L1: Job No.: | M1: ='Alt01'!M1 -> -
B3: Alternate No. 10-
B4: Specifics
B5: =+NOW() -> 44537.429
B6: =NOW() -> 44537.429 | I6: 1.07 | J6: 1 | M6: 1
A7: - | B7: - | C7: - | D7: - | H7: - | I7: - | J7: - | K7: - | L7: - | M7: -
A8: SPEC | E8: UNIT | F8: UNIT | G8: UNIT | M8: COST/
A9: SECTION | B9: DESCRIPTION | C9: QTY | D9: UNIT | E9: SUB | F9: MATL | G9: LABOR | H9: SUB | I9: MATL | J9: LABOR | K9: TOTAL: | L9: SUBCONTRACTOR | M9: SF
A10: - | B10: - | C10: - | D10: - | H10: - | I10: - | J10: - | K10: - | L10: - | M10: -
H11: =+C11*E11 -> 0 | I11: =+C11*F11*$I$6 -> 0 | J11: =+C11*G11*$J$6 -> 0 | K11: =SUM(H11+I11+J11) -> 0 | M11: =K11/$M$6 -> 0
H12: =+C12*E12 -> 0 | I12: =+C12*F12*$I$6 -> 0 | J12: =+C12*G12*$J$6 -> 0 | K12: =SUM(H12+I12+J12) -> 0 | M12: =K12/$M$6 -> 0
H13: =+C13*E13 -> 0 | I13: =+C13*F13*$I$6 -> 0 | J13: =+C13*G13*$J$6 -> 0 | K13: =SUM(H13+I13+J13) -> 0 | M13: =K13/$M$6 -> 0
H14: =+C14*E14 -> 0 | I14: =+C14*F14*$I$6 -> 0 | J14: =+C14*G14*$J$6 -> 0 | K14: =SUM(H14+I14+J14) -> 0 | M14: =K14/$M$6 -> 0
H15: =+C15*E15 -> 0 | I15: =+C15*F15*$I$6 -> 0 | J15: =+C15*G15*$J$6 -> 0 | K15: =SUM(H15+I15+J15) -> 0 | M15: =K15/$M$6 -> 0
H16: =+C16*E16 -> 0 | I16: =+C16*F16*$I$6 -> 0 | J16: =+C16*G16*$J$6 -> 0 | K16: =SUM(H16+I16+J16) -> 0 | M16: =K16/$M$6 -> 0
H17: =+C17*E17 -> 0 | I17: =+C17*F17*$I$6 -> 0 | J17: =+C17*G17*$J$6 -> 0 | K17: =SUM(H17+I17+J17) -> 0 | M17: =K17/$M$6 -> 0
H18: =+C18*E18 -> 0 | I18: =+C18*F18*$I$6 -> 0 | J18: =+C18*G18*$J$6 -> 0 | K18: =SUM(H18+I18+J18) -> 0 | M18: =K18/$M$6 -> 0
H19: =+C19*E19 -> 0 | I19: =+C19*F19*$I$6 -> 0 | J19: =+C19*G19*$J$6 -> 0 | K19: =SUM(H19+I19+J19) -> 0 | M19: =K19/$M$6 -> 0
H20: =+C20*E20 -> 0 | I20: =+C20*F20*$I$6 -> 0 | J20: =+C20*G20*$J$6 -> 0 | K20: =SUM(H20+I20+J20) -> 0 | M20: =K20/$M$6 -> 0
H21: =+C21*E21 -> 0 | I21: =+C21*F21*$I$6 -> 0 | J21: =+C21*G21*$J$6 -> 0 | K21: =SUM(H21+I21+J21) -> 0 | M21: =K21/$M$6 -> 0
H22: =+C22*E22 -> 0 | I22: =+C22*F22*$I$6 -> 0 | J22: =+C22*G22*$J$6 -> 0 | K22: =SUM(H22+I22+J22) -> 0 | M22: =K22/$M$6 -> 0
H23: =+C23*E23 -> 0 | I23: =+C23*F23*$I$6 -> 0 | J23: =+C23*G23*$J$6 -> 0 | K23: =SUM(H23+I23+J23) -> 0 | M23: =K23/$M$6 -> 0
A24: - | B24: - | C24: - | D24: - | H24: - | I24: - | J24: - | K24: - | L24: - | M24: -
B25: SUB-TOTAL: | H25: =SUM(H11:H23) -> 0 | I25: =SUM(I11:I23) -> 0 | J25: =SUM(J11:J23) -> 0 | K25: =SUM(K11:K23) -> 0 | M25: =K25/$M$6 -> 0
B26: SALES TAX/PAYROLL TAXES: | D26: INCL | I26: 0 | J26: 0 | K26: =+H26+I26+J26 -> 0 | M26: =K26/$M$6 -> 0
A27: - | B27: - | C27: - | D27: - | H27: - | I27: - | J27: - | K27: - | L27: - | M27: -
B28: SUB-TOTAL: | K28: =SUM(K25:K26) -> 0 | M28: =K28/$M$6 -> 0
M29: =K29/$M$6 -> 0
B30: CONTRACTOR FEE: | C30: 10 | D30: % | K30: =C30*K28/100 -> 0 | M30: =K30/$M$6 -> 0
H32: =+C32*E32 -> 0 | I32: =+C32*F32 -> 0 | J32: =+E32*G32 -> 0 | K32: =SUM(H32+I32+J32) -> 0 | M32: =K32/$M$6 -> 0
H33: =+C33*E33 -> 0 | I33: =+C33*F33 -> 0 | J33: =+E33*G33 -> 0 | K33: =SUM(H33+I33+J33) -> 0 | M33: =K33/$M$6 -> 0
H34: =+C34*E34 -> 0 | I34: =+C34*F34 -> 0 | J34: =+E34*G34 -> 0 | K34: =SUM(H34+I34+J34) -> 0 | M34: =K34/$M$6 -> 0
B35: BUILDER'S RISK INSURANCE (2.1%) | C35: 0 | D35: % | K35: =SUM(K28:K33)*C35/100 -> 0 | M35: =K35/$M$6 -> 0
M36: =K36/$M$6 -> 0
B37: GENERAL LIABILITY INSURANCE | C37: 1.3 | D37: % | K37: =SUM(K28:K36)*C37/100 -> 0 | M37: =K37/$M$6 -> 0
B38: IT FEE | C38: 0.25 | D38: % | K38: =(K28)*C38/100 -> 0 | M38: =K38/$M$6 -> 0
B39: CONTINGENCY | C39: 5 | D39: % | K39: =(K28)*C39/100 -> 0 | M39: =K39/$M$6 -> 0
M42: =K42/$M$6 -> 0
B43: BOND | C43: 0 | D43: % | K43: =SUM(K28:K42)*C43/100 -> 0 | M43: =K43/$M$6 -> 0
A44: - | B44: - | C44: - | D44: - | H44: - | I44: - | J44: - | K44: - | L44: - | M44: -
...

Sheet Alt11
B1: =K45 -> 0 | L1: Job No.: | M1: ='Alt01'!M1 -> -
B3: Alternate No. 11-
B4: Specifics
B5: =+NOW() -> 44537.429
B6: =NOW() -> 44537.429 | I6: 1.07 | J6: 1 | M6: 1
A7: - | B7: - | C7: - | D7: - | H7: - | I7: - | J7: - | K7: - | L7: - | M7: -
A8: SPEC | E8: UNIT | F8: UNIT | G8: UNIT | M8: COST/
A9: SECTION | B9: DESCRIPTION | C9: QTY | D9: UNIT | E9: SUB | F9: MATL | G9: LABOR | H9: SUB | I9: MATL | J9: LABOR | K9: TOTAL: | L9: SUBCONTRACTOR | M9: SF
A10: - | B10: - | C10: - | D10: - | H10: - | I10: - | J10: - | K10: - | L10: - | M10: -
H11: =+C11*E11 -> 0 | I11: =+C11*F11*$I$6 -> 0 | J11: =+C11*G11*$J$6 -> 0 | K11: =SUM(H11+I11+J11) -> 0 | M11: =K11/$M$6 -> 0
H12: =+C12*E12 -> 0 | I12: =+C12*F12*$I$6 -> 0 | J12: =+C12*G12*$J$6 -> 0 | K12: =SUM(H12+I12+J12) -> 0 | M12: =K12/$M$6 -> 0
H13: =+C13*E13 -> 0 | I13: =+C13*F13*$I$6 -> 0 | J13: =+C13*G13*$J$6 -> 0 | K13: =SUM(H13+I13+J13) -> 0 | M13: =K13/$M$6 -> 0
H14: =+C14*E14 -> 0 | I14: =+C14*F14*$I$6 -> 0 | J14: =+C14*G14*$J$6 -> 0 | K14: =SUM(H14+I14+J14) -> 0 | M14: =K14/$M$6 -> 0
H15: =+C15*E15 -> 0 | I15: =+C15*F15*$I$6 -> 0 | J15: =+C15*G15*$J$6 -> 0 | K15: =SUM(H15+I15+J15) -> 0 | M15: =K15/$M$6 -> 0
H16: =+C16*E16 -> 0 | I16: =+C16*F16*$I$6 -> 0 | J16: =+C16*G16*$J$6 -> 0 | K16: =SUM(H16+I16+J16) -> 0 | M16: =K16/$M$6 -> 0
H17: =+C17*E17 -> 0 | I17: =+C17*F17*$I$6 -> 0 | J17: =+C17*G17*$J$6 -> 0 | K17: =SUM(H17+I17+J17) -> 0 | M17: =K17/$M$6 -> 0
H18: =+C18*E18 -> 0 | I18: =+C18*F18*$I$6 -> 0 | J18: =+C18*G18*$J$6 -> 0 | K18: =SUM(H18+I18+J18) -> 0 | M18: =K18/$M$6 -> 0
H19: =+C19*E19 -> 0 | I19: =+C19*F19*$I$6 -> 0 | J19: =+C19*G19*$J$6 -> 0 | K19: =SUM(H19+I19+J19) -> 0 | M19: =K19/$M$6 -> 0
H20: =+C20*E20 -> 0 | I20: =+C20*F20*$I$6 -> 0 | J20: =+C20*G20*$J$6 -> 0 | K20: =SUM(H20+I20+J20) -> 0 | M20: =K20/$M$6 -> 0
H21: =+C21*E21 -> 0 | I21: =+C21*F21*$I$6 -> 0 | J21: =+C21*G21*$J$6 -> 0 | K21: =SUM(H21+I21+J21) -> 0 | M21: =K21/$M$6 -> 0
H22: =+C22*E22 -> 0 | I22: =+C22*F22*$I$6 -> 0 | J22: =+C22*G22*$J$6 -> 0 | K22: =SUM(H22+I22+J22) -> 0 | M22: =K22/$M$6 -> 0
H23: =+C23*E23 -> 0 | I23: =+C23*F23*$I$6 -> 0 | J23: =+C23*G23*$J$6 -> 0 | K23: =SUM(H23+I23+J23) -> 0 | M23: =K23/$M$6 -> 0
A24: - | B24: - | C24: - | D24: - | H24: - | I24: - | J24: - | K24: - | L24: - | M24: -
B25: SUB-TOTAL: | H25: =SUM(H11:H23) -> 0 | I25: =SUM(I11:I23) -> 0 | J25: =SUM(J11:J23) -> 0 | K25: =SUM(K11:K23) -> 0 | M25: =K25/$M$6 -> 0
B26: SALES TAX/PAYROLL TAXES: | D26: INCL | I26: 0 | J26: 0 | K26: =+H26+I26+J26 -> 0 | M26: =K26/$M$6 -> 0
A27: - | B27: - | C27: - | D27: - | H27: - | I27: - | J27: - | K27: - | L27: - | M27: -
B28: SUB-TOTAL: | K28: =SUM(K25:K26) -> 0 | M28: =K28/$M$6 -> 0
M29: =K29/$M$6 -> 0
B30: CONTRACTOR FEE: | C30: 10 | D30: % | K30: =C30*K28/100 -> 0 | M30: =K30/$M$6 -> 0
H32: =+C32*E32 -> 0 | I32: =+C32*F32 -> 0 | J32: =+E32*G32 -> 0 | K32: =SUM(H32+I32+J32) -> 0 | M32: =K32/$M$6 -> 0
H33: =+C33*E33 -> 0 | I33: =+C33*F33 -> 0 | J33: =+E33*G33 -> 0 | K33: =SUM(H33+I33+J33) -> 0 | M33: =K33/$M$6 -> 0
H34: =+C34*E34 -> 0 | I34: =+C34*F34 -> 0 | J34: =+E34*G34 -> 0 | K34: =SUM(H34+I34+J34) -> 0 | M34: =K34/$M$6 -> 0
B35: BUILDER'S RISK INSURANCE (2.1%) | C35: 0 | D35: % | K35: =SUM(K28:K33)*C35/100 -> 0 | M35: =K35/$M$6 -> 0
M36: =K36/$M$6 -> 0
B37: GENERAL LIABILITY INSURANCE | C37: 1.3 | D37: % | K37: =SUM(K28:K36)*C37/100 -> 0 | M37: =K37/$M$6 -> 0
B38: IT FEE | C38: 0.25 | D38: % | K38: =(K28)*C38/100 -> 0 | M38: =K38/$M$6 -> 0
B39: CONTINGENCY | C39: 5 | D39: % | K39: =(K28)*C39/100 -> 0 | M39: =K39/$M$6 -> 0
M42: =K42/$M$6 -> 0
B43: BOND | C43: 0 | D43: % | K43: =SUM(K28:K42)*C43/100 -> 0 | M43: =K43/$M$6 -> 0
A44: - | B44: - | C44: - | D44: - | H44: - | I44: - | J44: - | K44: - | L44: - | M44: -
...

Sheet Alt12
B1: =K45 -> 0 | L1: Job No.: | M1: ='Alt01'!M1 -> -
B3: Alternate No. 12-
B4: Specifics
B5: =+NOW() -> 44537.429
B6: =NOW() -> 44537.429 | I6: 1.07 | J6: 1 | M6: 1
A7: - | B7: - | C7: - | D7: - | H7: - | I7: - | J7: - | K7: - | L7: - | M7: -
A8: SPEC | E8: UNIT | F8: UNIT | G8: UNIT | M8: COST/
A9: SECTION | B9: DESCRIPTION | C9: QTY | D9: UNIT | E9: SUB | F9: MATL | G9: LABOR | H9: SUB | I9: MATL | J9: LABOR | K9: TOTAL: | L9: SUBCONTRACTOR | M9: SF
A10: - | B10: - | C10: - | D10: - | H10: - | I10: - | J10: - | K10: - | L10: - | M10: -
H11: =+C11*E11 -> 0 | I11: =+C11*F11*$I$6 -> 0 | J11: =+C11*G11*$J$6 -> 0 | K11: =SUM(H11+I11+J11) -> 0 | M11: =K11/$M$6 -> 0
H12: =+C12*E12 -> 0 | I12: =+C12*F12*$I$6 -> 0 | J12: =+C12*G12*$J$6 -> 0 | K12: =SUM(H12+I12+J12) -> 0 | M12: =K12/$M$6 -> 0
H13: =+C13*E13 -> 0 | I13: =+C13*F13*$I$6 -> 0 | J13: =+C13*G13*$J$6 -> 0 | K13: =SUM(H13+I13+J13) -> 0 | M13: =K13/$M$6 -> 0
H14: =+C14*E14 -> 0 | I14: =+C14*F14*$I$6 -> 0 | J14: =+C14*G14*$J$6 -> 0 | K14: =SUM(H14+I14+J14) -> 0 | M14: =K14/$M$6 -> 0
H15: =+C15*E15 -> 0 | I15: =+C15*F15*$I$6 -> 0 | J15: =+C15*G15*$J$6 -> 0 | K15: =SUM(H15+I15+J15) -> 0 | M15: =K15/$M$6 -> 0
H16: =+C16*E16 -> 0 | I16: =+C16*F16*$I$6 -> 0 | J16: =+C16*G16*$J$6 -> 0 | K16: =SUM(H16+I16+J16) -> 0 | M16: =K16/$M$6 -> 0
H17: =+C17*E17 -> 0 | I17: =+C17*F17*$I$6 -> 0 | J17: =+C17*G17*$J$6 -> 0 | K17: =SUM(H17+I17+J17) -> 0 | M17: =K17/$M$6 -> 0
H18: =+C18*E18 -> 0 | I18: =+C18*F18*$I$6 -> 0 | J18: =+C18*G18*$J$6 -> 0 | K18: =SUM(H18+I18+J18) -> 0 | M18: =K18/$M$6 -> 0
H19: =+C19*E19 -> 0 | I19: =+C19*F19*$I$6 -> 0 | J19: =+C19*G19*$J$6 -> 0 | K19: =SUM(H19+I19+J19) -> 0 | M19: =K19/$M$6 -> 0
H20: =+C20*E20 -> 0 | I20: =+C20*F20*$I$6 -> 0 | J20: =+C20*G20*$J$6 -> 0 | K20: =SUM(H20+I20+J20) -> 0 | M20: =K20/$M$6 -> 0
H21: =+C21*E21 -> 0 | I21: =+C21*F21*$I$6 -> 0 | J21: =+C21*G21*$J$6 -> 0 | K21: =SUM(H21+I21+J21) -> 0 | M21: =K21/$M$6 -> 0
H22: =+C22*E22 -> 0 | I22: =+C22*F22*$I$6 -> 0 | J22: =+C22*G22*$J$6 -> 0 | K22: =SUM(H22+I22+J22) -> 0 | M22: =K22/$M$6 -> 0
H23: =+C23*E23 -> 0 | I23: =+C23*F23*$I$6 -> 0 | J23: =+C23*G23*$J$6 -> 0 | K23: =SUM(H23+I23+J23) -> 0 | M23: =K23/$M$6 -> 0
A24: - | B24: - | C24: - | D24: - | H24: - | I24: - | J24: - | K24: - | L24: - | M24: -
B25: SUB-TOTAL: | H25: =SUM(H11:H23) -> 0 | I25: =SUM(I11:I23) -> 0 | J25: =SUM(J11:J23) -> 0 | K25: =SUM(K11:K23) -> 0 | M25: =K25/$M$6 -> 0
B26: SALES TAX/PAYROLL TAXES: | D26: INCL | I26: 0 | J26: 0 | K26: =+H26+I26+J26 -> 0 | M26: =K26/$M$6 -> 0
A27: - | B27: - | C27: - | D27: - | H27: - | I27: - | J27: - | K27: - | L27: - | M27: -
B28: SUB-TOTAL: | K28: =SUM(K25:K26) -> 0 | M28: =K28/$M$6 -> 0
M29: =K29/$M$6 -> 0
B30: CONTRACTOR FEE: | C30: 10 | D30: % | K30: =C30*K28/100 -> 0 | M30: =K30/$M$6 -> 0
H32: =+C32*E32 -> 0 | I32: =+C32*F32 -> 0 | J32: =+E32*G32 -> 0 | K32: =SUM(H32+I32+J32) -> 0 | M32: =K32/$M$6 -> 0
H33: =+C33*E33 -> 0 | I33: =+C33*F33 -> 0 | J33: =+E33*G33 -> 0 | K33: =SUM(H33+I33+J33) -> 0 | M33: =K33/$M$6 -> 0
H34: =+C34*E34 -> 0 | I34: =+C34*F34 -> 0 | J34: =+E34*G34 -> 0 | K34: =SUM(H34+I34+J34) -> 0 | M34: =K34/$M$6 -> 0
B35: BUILDER'S RISK INSURANCE (2.1%) | C35: 0 | D35: % | K35: =SUM(K28:K33)*C35/100 -> 0 | M35: =K35/$M$6 -> 0
M36: =K36/$M$6 -> 0
B37: GENERAL LIABILITY INSURANCE | C37: 1.3 | D37: % | K37: =SUM(K28:K36)*C37/100 -> 0 | M37: =K37/$M$6 -> 0
B38: IT FEE | C38: 0.25 | D38: % | K38: =(K28)*C38/100 -> 0 | M38: =K38/$M$6 -> 0
B39: CONTINGENCY | C39: 5 | D39: % | K39: =(K28)*C39/100 -> 0 | M39: =K39/$M$6 -> 0
M42: =K42/$M$6 -> 0
B43: BOND | C43: 0 | D43: % | K43: =SUM(K28:K42)*C43/100 -> 0 | M43: =K43/$M$6 -> 0
A44: - | B44: - | C44: - | D44: - | H44: - | I44: - | J44: - | K44: - | L44: - | M44: -
...

Sheet Alt13
B1: =K45 -> 0 | L1: Job No.: | M1: ='Alt01'!M1 -> -
B3: Alternate No. 13-
B4: Specifics
B5: =+NOW() -> 44537.429
B6: =NOW() -> 44537.429 | I6: 1.07 | J6: 1 | M6: 1
A7: - | B7: - | C7: - | D7: - | H7: - | I7: - | J7: - | K7: - | L7: - | M7: -
A8: SPEC | E8: UNIT | F8: UNIT | G8: UNIT | M8: COST/
A9: SECTION | B9: DESCRIPTION | C9: QTY | D9: UNIT | E9: SUB | F9: MATL | G9: LABOR | H9: SUB | I9: MATL | J9: LABOR | K9: TOTAL: | L9: SUBCONTRACTOR | M9: SF
A10: - | B10: - | C10: - | D10: - | H10: - | I10: - | J10: - | K10: - | L10: - | M10: -
H11: =+C11*E11 -> 0 | I11: =+C11*F11*$I$6 -> 0 | J11: =+C11*G11*$J$6 -> 0 | K11: =SUM(H11+I11+J11) -> 0 | M11: =K11/$M$6 -> 0
H12: =+C12*E12 -> 0 | I12: =+C12*F12*$I$6 -> 0 | J12: =+C12*G12*$J$6 -> 0 | K12: =SUM(H12+I12+J12) -> 0 | M12: =K12/$M$6 -> 0
H13: =+C13*E13 -> 0 | I13: =+C13*F13*$I$6 -> 0 | J13: =+C13*G13*$J$6 -> 0 | K13: =SUM(H13+I13+J13) -> 0 | M13: =K13/$M$6 -> 0
H14: =+C14*E14 -> 0 | I14: =+C14*F14*$I$6 -> 0 | J14: =+C14*G14*$J$6 -> 0 | K14: =SUM(H14+I14+J14) -> 0 | M14: =K14/$M$6 -> 0
H15: =+C15*E15 -> 0 | I15: =+C15*F15*$I$6 -> 0 | J15: =+C15*G15*$J$6 -> 0 | K15: =SUM(H15+I15+J15) -> 0 | M15: =K15/$M$6 -> 0
H16: =+C16*E16 -> 0 | I16: =+C16*F16*$I$6 -> 0 | J16: =+C16*G16*$J$6 -> 0 | K16: =SUM(H16+I16+J16) -> 0 | M16: =K16/$M$6 -> 0
H17: =+C17*E17 -> 0 | I17: =+C17*F17*$I$6 -> 0 | J17: =+C17*G17*$J$6 -> 0 | K17: =SUM(H17+I17+J17) -> 0 | M17: =K17/$M$6 -> 0
H18: =+C18*E18 -> 0 | I18: =+C18*F18*$I$6 -> 0 | J18: =+C18*G18*$J$6 -> 0 | K18: =SUM(H18+I18+J18) -> 0 | M18: =K18/$M$6 -> 0
H19: =+C19*E19 -> 0 | I19: =+C19*F19*$I$6 -> 0 | J19: =+C19*G19*$J$6 -> 0 | K19: =SUM(H19+I19+J19) -> 0 | M19: =K19/$M$6 -> 0
H20: =+C20*E20 -> 0 | I20: =+C20*F20*$I$6 -> 0 | J20: =+C20*G20*$J$6 -> 0 | K20: =SUM(H20+I20+J20) -> 0 | M20: =K20/$M$6 -> 0
H21: =+C21*E21 -> 0 | I21: =+C21*F21*$I$6 -> 0 | J21: =+C21*G21*$J$6 -> 0 | K21: =SUM(H21+I21+J21) -> 0 | M21: =K21/$M$6 -> 0
H22: =+C22*E22 -> 0 | I22: =+C22*F22*$I$6 -> 0 | J22: =+C22*G22*$J$6 -> 0 | K22: =SUM(H22+I22+J22) -> 0 | M22: =K22/$M$6 -> 0
H23: =+C23*E23 -> 0 | I23: =+C23*F23*$I$6 -> 0 | J23: =+C23*G23*$J$6 -> 0 | K23: =SUM(H23+I23+J23) -> 0 | M23: =K23/$M$6 -> 0
A24: - | B24: - | C24: - | D24: - | H24: - | I24: - | J24: - | K24: - | L24: - | M24: -
B25: SUB-TOTAL: | H25: =SUM(H11:H23) -> 0 | I25: =SUM(I11:I23) -> 0 | J25: =SUM(J11:J23) -> 0 | K25: =SUM(K11:K23) -> 0 | M25: =K25/$M$6 -> 0
B26: SALES TAX/PAYROLL TAXES: | D26: INCL | I26: 0 | J26: 0 | K26: =+H26+I26+J26 -> 0 | M26: =K26/$M$6 -> 0
A27: - | B27: - | C27: - | D27: - | H27: - | I27: - | J27: - | K27: - | L27: - | M27: -
B28: SUB-TOTAL: | K28: =SUM(K25:K26) -> 0 | M28: =K28/$M$6 -> 0
M29: =K29/$M$6 -> 0
B30: CONTRACTOR FEE: | C30: 10 | D30: % | K30: =C30*K28/100 -> 0 | M30: =K30/$M$6 -> 0
H32: =+C32*E32 -> 0 | I32: =+C32*F32 -> 0 | J32: =+E32*G32 -> 0 | K32: =SUM(H32+I32+J32) -> 0 | M32: =K32/$M$6 -> 0
H33: =+C33*E33 -> 0 | I33: =+C33*F33 -> 0 | J33: =+E33*G33 -> 0 | K33: =SUM(H33+I33+J33) -> 0 | M33: =K33/$M$6 -> 0
H34: =+C34*E34 -> 0 | I34: =+C34*F34 -> 0 | J34: =+E34*G34 -> 0 | K34: =SUM(H34+I34+J34) -> 0 | M34: =K34/$M$6 -> 0
B35: BUILDER'S RISK INSURANCE (2.1%) | C35: 0 | D35: % | K35: =SUM(K28:K33)*C35/100 -> 0 | M35: =K35/$M$6 -> 0
M36: =K36/$M$6 -> 0
B37: GENERAL LIABILITY INSURANCE | C37: 1.3 | D37: % | K37: =SUM(K28:K36)*C37/100 -> 0 | M37: =K37/$M$6 -> 0
B38: IT FEE | C38: 0.25 | D38: % | K38: =(K28)*C38/100 -> 0 | M38: =K38/$M$6 -> 0
B39: CONTINGENCY | C39: 5 | D39: % | K39: =(K28)*C39/100 -> 0 | M39: =K39/$M$6 -> 0
M42: =K42/$M$6 -> 0
B43: BOND | C43: 0 | D43: % | K43: =SUM(K28:K42)*C43/100 -> 0 | M43: =K43/$M$6 -> 0
A44: - | B44: - | C44: - | D44: - | H44: - | I44: - | J44: - | K44: - | L44: - | M44: -
...
