Workbook
Name FCP: 'Bond Calculator'!$B$7

Sheet Area Calculations
B2: PROJECT AREA CALCULATIONS
B4: Project Name | H4: Gross (sf) | I4: =G35 -> 0 | J4: FORMULA OFF GCS
B5: Location | H5: AC (sf) | I5: =E35 -> 0
H6: Rentable (sf) | I6: =F35 -> 0
H7: Site (acres) | I7: 1 | J7: FORMULA OFF GCS
H8: Parking Spaces | I8: 1
B9: =NOW() -> 46146.225 | H9: Build Duration (months) | I9: 1 | J9: FORMULA OFF GCS
B10: Drawings Date
A13: I. | B13: Floor | C13: Building | D13: Room | E13: ACSF | F13: RSF | G13: Gross SF | H13: GROSS%
H14: =G14/$I$4 -> #DIV/0!
H15: =G15/$I$4 -> #DIV/0!
H16: =G16/$I$4 -> #DIV/0!
H17: =G17/$I$4 -> #DIV/0!
H18: =G18/$I$4 -> #DIV/0!
H19: =G19/$I$4 -> #DIV/0!
H20: =G20/$I$4 -> #DIV/0!
H21: =G21/$I$4 -> #DIV/0!
H22: =G22/$I$4 -> #DIV/0!
H23: =G23/$I$4 -> #DIV/0!
H24: =G24/$I$4 -> #DIV/0!
H25: =G25/$I$4 -> #DIV/0!
... H34: =G34/$I$4 -> #DIV/0!
B35: TOTAL | E35: =SUM(E14:E34) -> 0 | F35: =SUM(F14:F34) -> 0 | G35: =SUM(G14:G34) -> 0 | H35: =SUM(H14:H34) -> #DIV/0!
A37: II. | C37: Units | E37: Site SF | G37: Site(acres) | I37: %
H40: =SUM(G41:G45) -> 0
I41: =G41/$I$7 -> 0
I42: =G42/$I$7 -> 0
I43: =G43/$I$7 -> 0
I44: =G44/$I$7 -> 0
I45: =G45/$I$7 -> 0
H46: =SUM(G47:G49) -> 0
I47: =G47/$I$7 -> 0
I48: =G48/$I$7 -> 0
I49: =G49/$I$7 -> 0
B51: TOTAL | E51: =SUM(E41:E49) -> 0 | G51: =SUM(G40:G50) -> 0 | I51: =SUM(I40:I50) -> 0
C53: Levels | G53: GSF | I53: %
I56: =G56/$I$4 -> #DIV/0!
I57: =G57/$I$4 -> #DIV/0!
I58: =G58/$I$4 -> #DIV/0!
B60: TOTAL GSF | G60: =SUM(G55:G59) -> 0 | I60: =SUM(I55:I59) -> #DIV/0!
...

Sheet Bond Calculator
A1: Hedrick Brothers Construction
A3: Performance / Payment Bond | E3: Performance / Payment Bond
A4: General Construction | E4: Design Build
A5: 42888 | E5: 42053
B6: =IF(B13>500000,500000,B13) -> 500000 | C6: 0.0091 | D6: =B6*C6 -> 4550 | F6: 0 | G6: 0.01875 | H6: =SUM(F6*G6) -> 0
B7: =IF(B13<2500000,(B13-B6),IF(B13>B6,2000000,0)) -> 1720594.1 | C7: 0.00725 | D7: =B7*C7 -> 12474.307 | F7: 0 | G7: 0.015 | H7: =SUM(F7*G7) -> 0
B8: =IF(B13<5000000,MAX(0,B13-2500000),IF(B13>2500000,2500000)) -> 0 | C8: 0.0063 | D8: =B8*C8 -> 0 | F8: 0 | G8: 0.01125 | H8: =SUM(F8*G8) -> 0
B9: =IF(B13<7500000,MAX(0,B13-5000000),IF(B13>7500000,2500000,0)) -> 0 | C9: 0.00555 | D9: =B9*C9 -> 0 | F9: 0 | G9: 0.009 | H9: =SUM(F9*G9) -> 0
B10: =IF(B13<7500000,MAX(0,B13-7500000),IF(B13>7500000,(B13-7500000))) -> 0 | C10: 0.0051 | D10: =B10*C10 -> 0 | F10: 0 | G10: 0.00825 | H10: =SUM(F10*G10) -> 0
D11: =B11*C11 -> 0 | F11: 0 | G11: 0.0075 | H11: =SUM(F11*G11) -> 0
A12: Contract Value | B12: ='Cost Summary'!D123 -> 0 | C12: Total | D12: =SUM(D6:D11) -> 17024.307 | E12: Contract Value | F12: =SUM(F6+F7+F8+F9+F10+F11) -> 0 | G12: Total | H12: =SUM(H6:H11) -> 0
A13: Cost Summary | B13: 2220594.1 | D13: =SUM(D12/B12) -> #DIV/0! | H13: =SUM(H12/F12) -> #DIV/0!
B14: =B12-B13 -> -2220594.1

Sheet Allowances
A7: ='Area Calculations'!B4 -> Project Name | C7: ='Area Calculations'!B5 -> Location
A9: Allowances
A10: =TODAY() -> 46146
A12: NO. | B12: DESCRIPTION | C12: VALUE
A13: 1 | C13: 0
A14: =A13+1 -> 2 | C14: 0
A15: =A14+1 -> 3 | C15: 0
A16: =A15+1 -> 4 | C16: 0
A17: =A16+1 -> 5 | C17: 0
A18: =A17+1 -> 6 | C18: 0
A19: =A18+1 -> 7 | C19: 0
A20: =A19+1 -> 8 | C20: 0
A21: =A20+1 -> 9 | C21: 0
A22: =A21+1 -> 10 | C22: 0
A23: =A22+1 -> 11 | C23: 0
A24: =A23+1 -> 12 | C24: 0
A25: =A24+1 -> 13 | C25: 0
... A28: =A27+1 -> 16 | C28: 0
A29: =A28+1 -> 17
A30: =A29+1 -> 18
A31: =A30+1 -> 19 | B31: Total | C31: =SUM(C13:C30) -> 0
B33: *All ALLOWANCES IN BID TABS MUST BE LISTED HERE

Sheet Alternates
A7: ='Area Calculations'!B4 -> Project Name | C7: ='Area Calculations'!B5 -> Location
A9: Alternates
A10: =TODAY() -> 46146
A12: NO. | B12: DESCRIPTION | C12: VALUE
A13: ALT. #1 | B13: Description | C13: 0
A14: ALT. #2 | B14: Description | C14: 0
A15: ALT. #3 | B15: Description | C15: 0
A16: ALT. #4 | B16: Description | C16: 0
A17: ALT. #5 | B17: Description | C17: 0
A18: ALT. #6 | B18: Description | C18: 0
A19: ALT. #7 | B19: Description | C19: 0
A20: ALT. #8 | B20: Description | C20: 0
A21: ALT. #9 | B21: Description | C21: 0
A22: ALT. #10 | B22: Description | C22: 0
A23: ALT. #11 | B23: Description | C23: 0
A24: ALT. #12 | B24: Description | C24: 0
... A27: ALT. #15 | B27: Description | C27: 0
B28: Total | C28: =SUM(C13:C27) -> 0

Sheet Labor Rates Calculator
A5: Hedrick Brothers Construction Co., Inc.
A6: Salaries and Burden Calculations
A7: As of 8/22/24
C8: MARK-UP | F8: 0.15
E9: Burdened Rate | F9: Mark-up | G9: Total | I9: ANNUAL BURDENED AMOUNT | J9: ANNUAL BURDENED AMOUNT (W/ M/U)
B10: 1 | C10: Proj Exec | E10: 157.66656 | F10: =E10*$F$8 -> 23.649984 | G10: =SUM(E10:F10) -> 181.31655 | I10: =E10*2080 -> 327946.45 | J10: =G10*2080 -> 377138.42
B11: 2 | C11: Sr PM | E11: 130.67475 | F11: =E11*$F$8 -> 19.601212 | G11: =SUM(E11:F11) -> 150.27596 | I11: =E11*2080 -> 271803.48 | J11: =G11*2080 -> 312574
B12: 3 | C12: PM 3 | E12: 120.34132 | F12: =E12*$F$8 -> 18.051199 | G12: =SUM(E12:F12) -> 138.39252 | I12: =E12*2080 -> 250309.95 | J12: =G12*2080 -> 287856.45
B13: 4 | C13: PM 2 | E13: 110.14476 | F13: =E13*$F$8 -> 16.521714 | G13: =SUM(E13:F13) -> 126.66647 | I13: =E13*2080 -> 229101.1 | J13: =G13*2080 -> 263466.26
B14: 5 | C14: PM 1 | E14: 94.265604 | F14: =E14*$F$8 -> 14.139841 | G14: =SUM(E14:F14) -> 108.40544 | I14: =E14*2080 -> 196072.46 | J14: =G14*2080 -> 225483.32
B15: 6 | C15: Proj Admin | E15: 66.505247 | F15: =E15*$F$8 -> 9.9757871 | G15: =SUM(E15:F15) -> 76.481034 | I15: =E15*2080 -> 138330.91 | J15: =G15*2080 -> 159080.55
B16: 7 | C16: Proj Acct | E16: 85.81004 | F16: =E16*$F$8 -> 12.871506 | G16: =SUM(E16:F16) -> 98.681546 | I16: =E16*2080 -> 178484.88 | J16: =G16*2080 -> 205257.62
B17: 8 | C17: Asst PM | E17: 82.733564 | F17: =E17*$F$8 -> 12.410035 | G17: =SUM(E17:F17) -> 95.143598 | I17: =E17*2080 -> 172085.81 | J17: =G17*2080 -> 197898.68
B18: 9 | C18: Supt 3 | E18: 131.75199 | F18: =E18*$F$8 -> 19.762798 | G18: =SUM(E18:F18) -> 151.51479 | I18: =E18*2080 -> 274044.14 | J18: =G18*2080 -> 315150.76
B19: 10 | C19: Supt 2 | E19: 110.59223 | F19: =E19*$F$8 -> 16.588834 | G19: =SUM(E19:F19) -> 127.18106 | I19: =E19*2080 -> 230031.83 | J19: =G19*2080 -> 264536.61
B20: 11 | C20: Supt 1 | E20: 90.514804 | F20: =E20*$F$8 -> 13.577221 | G20: =SUM(E20:F20) -> 104.09203 | I20: =E20*2080 -> 188270.79 | J20: =G20*2080 -> 216511.41
B21: 12 | C21: Asst Supt | E21: 59.915466 | F21: =E21*$F$8 -> 8.9873199 | G21: =SUM(E21:F21) -> 68.902786 | I21: =E21*2080 -> 124624.17 | J21: =G21*2080 -> 143317.79
... B26: 17 | C26: Safety | E26: 79.733968 | F26: =E26*$F$8 -> 11.960095 | G26: =SUM(E26:F26) -> 91.694063 | I26: =E26*2080 -> 165846.65 | J26: =G26*2080 -> 190723.65
C27: Labor | E27: 32.408056 | F27: =E27*$F$8 -> 4.8612084 | G27: =SUM(E27:F27) -> 37.269264 | I27: =E27*2080 -> 67408.756 | J27: =G27*2080 -> 77520.069
C28: Apprentice | E28: 32.978211 | F28: =E28*$F$8 -> 4.9467316 | G28: =SUM(E28:F28) -> 37.924942 | I28: =E28*2080 -> 68594.678 | J28: =G28*2080 -> 78883.88
C29: Carpenter | E29: 45.013251 | F29: =E29*$F$8 -> 6.7519877 | G29: =SUM(E29:F29) -> 51.765239 | I29: =E29*2080 -> 93627.563 | J29: =G29*2080 -> 107671.7
C30: Driver | E30: 35.486876 | F30: =E30*$F$8 -> 5.3230314 | G30: =SUM(E30:F30) -> 40.809908 | I30: =E30*2080 -> 73812.702 | J30: =G30*2080 -> 84884.608
C31: Leadman | E31: 46.605242 | F31: =E31*$F$8 -> 6.9907863 | G31: =SUM(E31:F31) -> 53.596029 | I31: =E31*2080 -> 96938.904 | J31: =G31*2080 -> 111479.74
C32: Supt MEP | E32: 0 | F32: =E32*$F$8 -> 0 | G32: =SUM(E32:F32) -> 0 | I32: =E32*2080 -> 0 | J32: =G32*2080 -> 0
C33: Gen Supt | E33: 130.4108 | F33: =E33*$F$8 -> 19.561621 | G33: =SUM(E33:F33) -> 149.97242 | I33: =E33*2080 -> 271254.47 | J33: =G33*2080 -> 311942.64
C34: Cons Mgr | E34: 135.45804 | F34: =E34*$F$8 -> 20.318705 | G34: =SUM(E34:F34) -> 155.77674 | I34: =E34*2080 -> 281752.72 | J34: =G34*2080 -> 324015.62
C35: Proj Coor | E35: 0 | F35: =E35*$F$8 -> 0 | G35: =SUM(E35:F35) -> 0 | I35: =E35*2080 -> 0 | J35: =G35*2080 -> 0
C36: Mktg | E36: 85.41309 | F36: =E36*$F$8 -> 12.811964 | G36: =SUM(E36:F36) -> 98.225054 | I36: =E36*2080 -> 177659.23 | J36: =G36*2080 -> 204308.11
C37: Bus Dev | E37: 121.55329 | F37: =E37*$F$8 -> 18.232993 | G37: =SUM(E37:F37) -> 139.78628 | I37: =E37*2080 -> 252830.84 | J37: =G37*2080 -> 290755.47
C38: Chief, 3 & 2 | E38: 140.9198 | F38: =E38*$F$8 -> 21.13797 | G38: =SUM(E38:F38) -> 162.05777 | I38: =E38*2080 -> 293113.19 | J38: =G38*2080 -> 337080.17
... C40: Exec Asst | E40: 69.670191 | F40: =E40*$F$8 -> 10.450529 | G40: =SUM(E40:F40) -> 80.12072 | I40: =E40*2080 -> 144914 | J40: =G40*2080 -> 166651.1
D41: TOTAL | E41: =SUM(E10:E40) -> 2612.4097 | F41: =SUM(F10:F40) -> 391.86145 | G41: =SUM(G10:G40) -> 3004.2711 | I41: =SUM(I10:I40) -> 5433812.1 | J41: =SUM(J10:J40) -> 6248883.9
G42: =E41/G41 -> 0.86956522 | I42: =I41/J41 -> 0.86956522

Sheet GCs & GRs
A1: Contract Reference | B1: General Condition Ref. | C1: ='Area Calculations'!B4 -> Project Name
C3: Construction | F3: Activity | H3: Start | I3: Finish | J3: Days | K3: Weeks | L3: Months | M3: % Time | N3: Remarks | Q3: Demo to building pad
F4: Construction | H4: 0 | I4: 0 | J4: =SUM(I4-H4) -> 0 | K4: =SUM(J4/7) -> 0 | L4: =SUM(J4/30) -> 0 | Q4: Activity | S4: Start | T4: Finish | U4: Days | V4: Weeks | W4: Months
F5: Close Out | H5: 0 | I5: 0 | J5: =SUM(I5-H5) -> 0 | K5: =SUM(J5/7) -> 0 | L5: =SUM(J5/30) -> 0 | Q5: Construction | S5: 0 | T5: 0 | U5: =SUM(T5-S5) -> 0 | V5: =SUM(U5/7) -> 0 | W5: =SUM(U5/30) -> 0
F6: General Conditions | H6: General Req. - Field Office | J6: General Req. | L6: Total | Q6: Building
C7: Description | D7: Qty. | E7: U | F7: Unit | G7: Const. | H7: Unit | I7: General | J7: Unit | K7: General | O7: LABOR RATE FY 2025 *Updated 09.26.24 | P7: LABOR RATE (MIAMI/FT. LAUDERDALE) | Q7: Activity | S7: Start | T7: Finish | U7: Days | V7: Weeks | W7: Months | X7: LABOR RATE (MF CENTRAL FLORIDA)
F8: Cost | G8: Cond. | H8: Cost | I8: Req. | J8: Cost | K8: Req. | Q8: Construction | S8: 0 | T8: 0 | U8: =SUM(T8-S8) -> 0 | V8: =SUM(U8/7) -> 0 | W8: =SUM(U8/30) -> 0
C9: Field Labor - Construction | L9: =SUM(L10:L25) -> 0
C10: Project Executive | D10: =$K$4 -> 0 | E10: wks | F10: =(O10*40)*M10 -> 0 | G10: =SUM(D10*F10) -> 0 | L10: =SUM(G10+I10+K10) -> 0 | M10: 0 | O10: ='Labor Rates Calculator'!G10 -> 181.31655 | P10: 253 | X10: 216
C11: Senior Project Manager | D11: =$K$4 -> 0 | E11: wks | F11: =(O11*40)*M11 -> 0 | G11: =SUM(D11*F11) -> 0 | L11: =SUM(G11+I11+K11) -> 0 | M11: 0 | O11: ='Labor Rates Calculator'!G11 -> 150.27596 | P11: 195 | X11: 175
C12: Project Manager - Level 3 | D12: =$K$4 -> 0 | E12: wks | F12: =(O12*40)*M12 -> 0 | G12: =SUM(D12*F12) -> 0 | L12: =SUM(G12+I12+K12) -> 0 | M12: 0 | O12: ='Labor Rates Calculator'!G12 -> 138.39252
C13: Project Manager - Level 2 | D13: =$K$4 -> 0 | E13: wks | F13: =(O13*40)*M13 -> 0 | G13: =SUM(D13*F13) -> 0 | L13: =SUM(G13+I13+K13) -> 0 | M13: 0 | O13: ='Labor Rates Calculator'!G13 -> 126.66647 | P13: 185 | X13: 155
C14: Project Manager - Level 1 | D14: =$K$4 -> 0 | E14: wks | F14: =(O14*40)*M14 -> 0 | G14: =SUM(D14*F14) -> 0 | L14: =SUM(G14+I14+K14) -> 0 | M14: 0 | O14: ='Labor Rates Calculator'!G14 -> 108.40544 | P14: 163 | X14: 130
C15: Project Administator | D15: =$K$4 -> 0 | E15: wks | F15: =(O15*40)*M15 -> 0 | G15: =SUM(D15*F15) -> 0 | L15: =SUM(G15+I15+K15) -> 0 | M15: 0 | O15: ='Labor Rates Calculator'!G15 -> 76.481034 | P15: 95 | X15: 65
C16: Project Accountant | D16: =$K$4 -> 0 | E16: wks | F16: =(O16*40)*M16 -> 0 | G16: =SUM(D16*F16) -> 0 | L16: =SUM(G16+I16+K16) -> 0 | M16: 0 | O16: ='Labor Rates Calculator'!G16 -> 98.681546 | P16: 81 | X16: 60
C17: Assistant Project Manager | D17: =$K$4 -> 0 | E17: wks | F17: =(O17*40)*M17 -> 0 | G17: =SUM(D17*F17) -> 0 | L17: =SUM(G17+I17+K17) -> 0 | M17: 0 | O17: ='Labor Rates Calculator'!G17 -> 95.143598 | P17: 118 | X17: 95
C18: Superintendent - Level 3 | D18: =$K$4 -> 0 | E18: wks | F18: =(O18*40)*M18 -> 0 | G18: =SUM(D18*F18) -> 0 | L18: =SUM(G18+I18+K18) -> 0 | M18: 0 | O18: ='Labor Rates Calculator'!G18 -> 151.51479 | P18: 183 | X18: 194
C19: Superintendent - Level 2 | D19: =$K$4 -> 0 | E19: wks | F19: =(O19*40)*M19 -> 0 | G19: =SUM(D19*F19) -> 0 | L19: =SUM(G19+I19+K19) -> 0 | M19: 0 | O19: ='Labor Rates Calculator'!G19 -> 127.18106 | P19: 161 | X19: 173
C20: Superintendent - Level 1 | D20: =$K$4 -> 0 | E20: wks | F20: =(O20*40)*M20 -> 0 | G20: =SUM(D20*F20) -> 0 | L20: =SUM(G20+I20+K20) -> 0 | M20: 0 | O20: ='Labor Rates Calculator'!G20 -> 104.09203 | P20: 121 | X20: 155
C21: Assistant Superinterndent | D21: =$K$4 -> 0 | E21: wks | F21: =(O21*40)*M21 -> 0 | G21: =SUM(D21*F21) -> 0 | L21: =SUM(G21+I21+K21) -> 0 | M21: 0 | O21: ='Labor Rates Calculator'!G21 -> 68.902786 | P21: 84 | X21: 95
C22: Quality Control Manager | D22: =$K$4 -> 0 | E22: wks | F22: =(O22*40)*M22 -> 0 | G22: =SUM(D22*F22) -> 0 | L22: =SUM(G22+I22+K22) -> 0 | M22: 0 | O22: ='Labor Rates Calculator'!G22 -> 118.37225
C23: Foreman | D23: =$K$4 -> 0 | E23: wks | F23: =(O23*40)*M23 -> 0 | G23: =SUM(D23*F23) -> 0 | L23: =SUM(G23+I23+K23) -> 0 | M23: 0 | O23: ='Labor Rates Calculator'!G23 -> 47.75772 | P23: 65 | X23: 65
C24: Accounting | D24: =$K$4 -> 0 | E24: wks | F24: =(O24*40)*M24 -> 0 | G24: =SUM(D24*F24) -> 0 | L24: =SUM(G24+I24+K24) -> 0 | M24: 0 | O24: ='Labor Rates Calculator'!G24 -> 133.32852 | P24: 80 | X24: 90
C25: Safety Supervisor/Inspector | D25: =K4 -> 0 | E25: wks | F25: =(O25*40)*M25 -> 0 | G25: =SUM(D25*F25) -> 0 | L25: =SUM(G25+I25+K25) -> 0 | M25: 0 | O25: ='Labor Rates Calculator'!G26 -> 91.694063 | P25: 96 | X25: 96
C26: Field Labor - Close Out | L26: =SUM(L27:L41) -> 0
C27: Project Executive | D27: =$K$5 -> 0 | E27: wks | F27: =(40*O27)*M27 -> 0 | G27: =SUM(D27*F27) -> 0 | L27: =SUM(G27+I27+K27) -> 0 | M27: 0 | O27: =+O10 -> 181.31655 | P27: =+P10 -> 253 | X27: =+X10 -> 216
C28: Senior Project Manager | D28: =$K$5 -> 0 | E28: wks | F28: =(40*O28)*M28 -> 0 | G28: =SUM(D28*F28) -> 0 | L28: =SUM(G28+I28+K28) -> 0 | M28: =+M11 -> 0 | O28: =+O11 -> 150.27596 | P28: =+P11 -> 195 | X28: =+X11 -> 175
C29: Project Manager - Level 3 | D29: =$K$5 -> 0 | E29: wks | F29: =(40*O29)*M29 -> 0 | G29: =SUM(D29*F29) -> 0 | L29: =SUM(G29+I29+K29) -> 0 | M29: =+M12 -> 0 | O29: =O12 -> 138.39252
C30: Project Manager - Level 2 | D30: =$K$5 -> 0 | E30: wks | F30: =(40*O30)*M30 -> 0 | G30: =SUM(D30*F30) -> 0 | L30: =SUM(G30+I30+K30) -> 0 | M30: =+M13 -> 0 | O30: =+O13 -> 126.66647 | P30: =+P13 -> 185 | X30: =+X13 -> 155
C31: Project Manager - Level 1 | D31: =$K$5 -> 0 | E31: wks | F31: =(40*O31)*M31 -> 0 | G31: =SUM(D31*F31) -> 0 | L31: =SUM(G31+I31+K31) -> 0 | M31: =+M14 -> 0 | O31: =+O14 -> 108.40544 | P31: =+P14 -> 163 | X31: =+X14 -> 130
C32: Project Administator | D32: =$K$5 -> 0 | E32: wks | F32: =(40*O32)*M32 -> 0 | G32: =SUM(D32*F32) -> 0 | L32: =SUM(G32+I32+K32) -> 0 | M32: =+M15 -> 0 | O32: =+O15 -> 76.481034 | P32: =+P15 -> 95 | X32: =+X15 -> 65
C33: Project Coordinator | D33: =$K$5 -> 0 | E33: wks | F33: =(40*O33)*M33 -> 0 | G33: =SUM(D33*F33) -> 0 | L33: =SUM(G33+I33+K33) -> 0 | M33: =+M16 -> 0 | O33: =+O16 -> 98.681546 | P33: =+P16 -> 81 | X33: =+X16 -> 60
C34: Assistant Project Manager | D34: =$K$5 -> 0 | E34: wks | F34: =(40*O34)*M34 -> 0 | G34: =SUM(D34*F34) -> 0 | L34: =SUM(G34+I34+K34) -> 0 | M34: =+M17 -> 0 | O34: =+O17 -> 95.143598 | P34: =+P17 -> 118 | X34: =+X17 -> 95
C35: Superintendent - Level 3 | D35: =$K$5 -> 0 | E35: wks | F35: =(40*O35)*M35 -> 0 | G35: =SUM(D35*F35) -> 0 | L35: =SUM(G35+I35+K35) -> 0 | M35: =+M18 -> 0 | O35: =+O18 -> 151.51479 | P35: =+P18 -> 183 | X35: =+X18 -> 194
C36: Superintendent - Level 2 | D36: =$K$5 -> 0 | E36: wks | F36: =(40*O36)*M36 -> 0 | G36: =SUM(D36*F36) -> 0 | L36: =SUM(G36+I36+K36) -> 0 | M36: =+M19 -> 0 | O36: =+O19 -> 127.18106 | P36: =+P19 -> 161 | X36: =+X19 -> 173
C37: Superintendent - Level 1 | D37: =$K$5 -> 0 | E37: wks | F37: =(40*O37)*M37 -> 0 | G37: =SUM(D37*F37) -> 0 | L37: =SUM(G37+I37+K37) -> 0 | M37: =+M20 -> 0 | O37: =+O20 -> 104.09203 | P37: =+P20 -> 121 | X37: =+X20 -> 155
C38: Assistant Superinterndent | D38: =$K$5 -> 0 | E38: wks | F38: =(40*O38)*M38 -> 0 | G38: =SUM(D38*F38) -> 0 | L38: =SUM(G38+I38+K38) -> 0 | M38: =+M21 -> 0 | O38: =+O21 -> 68.902786 | P38: =+P21 -> 84 | X38: =+X21 -> 95
C39: Foreman | D39: =$K$5 -> 0 | E39: wks | F39: =(40*O39)*M39 -> 0 | G39: =SUM(D39*F39) -> 0 | L39: =SUM(G39+I39+K39) -> 0 | M39: =+M23 -> 0 | O39: =+O23 -> 47.75772 | P39: =+P23 -> 65 | X39: =+X23 -> 65
C40: Accounting | D40: =$K$5 -> 0 | E40: wks | F40: =(40*O40)*M40 -> 0 | G40: =SUM(D40*F40) -> 0 | L40: =SUM(G40+I40+K40) -> 0 | M40: =+M24 -> 0 | O40: =+O24 -> 133.32852 | P40: =+P24 -> 80 | X40: =+X24 -> 90
C41: Safety Supervisor/Inspector | D41: =$K$5 -> 0 | E41: wks | F41: =(40*O41)*M41 -> 0 | G41: =SUM(D41*F41) -> 0 | L41: =SUM(G41+I41+K41) -> 0 | M41: =+M25 -> 0 | O41: =+O25 -> 91.694063 | P41: =+P25 -> 96 | X41: =+X25 -> 96
...

Sheet Cost Summary
A1: COST ESTIMATE (ROM)
A6: ='Area Calculations'!B4 -> Project Name
A7: ='Area Calculations'!B5 -> Location | F7: Gross (sf) | G7: ='Area Calculations'!I4 -> 0
F8: A/C (SF
F9: Build Duration (months) | G9: ='Area Calculations'!I5 -> 0
A11: =NOW() -> 46146.225
A13: CSI | B13: CSI DESCRIPTION | D13: TOTAL | E13: $ /GSF | F13: % | G13: Prev. | H13: Delta | I13: Notes
A15: 01A | B15: Surveying | D15: ='01A Surveying'!B117 -> 0 | E15: =D15/$G$7 -> #DIV/0! | F15: =D15/$D$123 -> #DIV/0! | H15: =D15-G15 -> 0
A16: 01B | B16: Materials Testing | D16: ='01B Material Testing'!B106 -> 0 | E16: =D16/$G$7 -> #DIV/0! | F16: =D16/$D$123 -> #DIV/0! | H16: =D16-G16 -> 0
A17: 01C | B17: Final Cleaning | D17: ='01C Final Cleaning'!B106 -> 0 | E17: =D17/$G$7 -> #DIV/0! | F17: =D17/$D$123 -> #DIV/0! | H17: =D17-G17 -> 0
A18: 02A | B18: Demolition | D18: ='02A Demolition'!B93 -> 0 | E18: =D18/$G$7 -> #DIV/0! | F18: =D18/$D$123 -> #DIV/0! | H18: =D18-G18 -> 0
A19: 02B | B19: Abatement; Environmental Protection | D19: ='02B Abatement'!B93 -> 0 | E19: =D19/$G$7 -> #DIV/0! | F19: =D19/$D$123 -> #DIV/0! | H19: =D19-G19 -> 0
A20: 03A | B20: Concrete (Conventional) | D20: ='03A Concrete'!B129 -> 0 | E20: =D20/$G$7 -> #DIV/0! | F20: =D20/$D$123 -> #DIV/0! | H20: =D20-G20 -> 0
A21: 03B | B21: Precast Hollow Core | D21: ='03B Precast Hollow Core'!B82 -> 0 | E21: =D21/$G$7 -> #DIV/0! | F21: =D21/$D$123 -> #DIV/0! | H21: =D21-G21 -> 0
A22: 03C | B22: Architectural Precast | D22: ='03C Architectural Precast'!B86 -> 0 | E22: =D22/$G$7 -> #DIV/0! | F22: =D22/$D$123 -> #DIV/0! | H22: =D22-G22 -> 0
A23: 03C | B23: Concrete (Tilt-Up) | D23: ='03C Concrete Tilt Up'!B82 -> 0 | E23: =D23/$G$7 -> #DIV/0! | F23: =D23/$D$123 -> #DIV/0! | H23: =D23-G23 -> 0
A24: 03D | B24: Structural Precast | D24: ='03D Structural Precast'!B132 -> 0 | E24: =D24/$G$7 -> #DIV/0! | F24: =D24/$D$123 -> #DIV/0! | H24: =D24-G24 -> 0
A25: 03E | B25: Cranes and Hoisting | D25: ='03E Cranes and Hoisting'!B132 -> 0 | E25: =D25/$G$7 -> #DIV/0! | F25: =D25/$D$123 -> #DIV/0! | H25: =D25-G25 -> 0
A26: 03F | B26: Concrete Restoration | D26: ='03F Concrete Restoration'!B132 -> 0 | E26: =D26/$G$7 -> #DIV/0! | F26: =D26/$D$123 -> #DIV/0! | H26: =D26-G26 -> 0
A27: 04A | B27: Masonry | D27: ='04A Masonry'!B122 -> 0 | E27: =D27/$G$7 -> #DIV/0! | F27: =D27/$D$123 -> #DIV/0! | H27: =D27-G27 -> 0
A28: 04B | B28: Cast Stone, Stone Veneer | D28: ='04B Stone Veneer'!B101 -> 0 | E28: =D28/$G$7 -> #DIV/0! | F28: =D28/$D$123 -> #DIV/0! | H28: =D28-G28 -> 0
A29: 05A | B29: Structural Steel | D29: ='05A Structural Steel'!B92 -> 0 | E29: =D29/$G$7 -> #DIV/0! | F29: =D29/$D$123 -> #DIV/0! | H29: =D29-G29 -> 0
A30: 05B | B30: Metal Trusses | D30: ='05B Metal Trusses'!B88 -> 0 | E30: =D30/$G$7 -> #DIV/0! | F30: =D30/$D$123 -> #DIV/0! | H30: =D30-G30 -> 0
A31: 05C | B31: Misc. Metals | D31: ='05C Misc. Metals'!B91 -> 0 | E31: =D31/$G$7 -> #DIV/0! | F31: =D31/$D$123 -> #DIV/0! | H31: =D31-G31 -> 0
A32: 05D | B32: Handrails & Railings | D32: ='05D Handrailings & Railings'!B91 -> 0 | E32: =D32/$G$7 -> #DIV/0! | F32: =D32/$D$123 -> #DIV/0! | H32: =D32-G32 -> 0
A33: 05E | B33: Glass Railings | D33: ='05E Glass Railings'!B91 -> 0 | E33: =D33/$G$7 -> #DIV/0! | F33: =D33/$D$123 -> #DIV/0! | H33: =D33-G33 -> 0
A34: 06A | B34: Rough Carpentry | D34: ='06A Rough Carpentry'!B103 -> 0 | E34: =D34/$G$7 -> #DIV/0! | F34: =D34/$D$123 -> #DIV/0! | H34: =D34-G34 -> 0
A35: 06C | B35: Wood Trusses | D35: ='06C Wood Trusses'!B106 -> 0 | E35: =D35/$G$7 -> #DIV/0! | F35: =D35/$D$123 -> #DIV/0! | H35: =D35-G35 -> 0
A36: 06D | B36: Interior Finish Cabinetry | D36: ='06D Interior Finish Carpentry'!B100 -> 0 | E36: =D36/$G$7 -> #DIV/0! | F36: =D36/$D$123 -> #DIV/0! | H36: =D36-G36 -> 0
A37: 06E | B37: Heavy Timber Construction | D37: ='06E Heavy Timber Construction'!B88 -> 0 | E37: =D37/$G$7 -> #DIV/0! | F37: =D37/$D$123 -> #DIV/0! | H37: =D37-G37 -> 0
A38: 06F | B38: Millwork | D38: ='06F Millwork'!B90 -> 0 | E38: =D38/$G$7 -> #DIV/0! | F38: =D38/$D$123 -> #DIV/0! | H38: =D38-G38 -> 0
A39: 06G | B39: Exterior Finish Carpentry | D39: ='06G Exterior Finish Carpent'!B100 -> 0 | E39: =D39/$G$7 -> #DIV/0! | F39: =D39/$D$123 -> #DIV/0! | H39: =D39-G39 -> 0
A40: 07B | B40: Sprayed Insulation | D40: ='07B Sprayed Insulation'!B94 -> 0 | E40: =D40/$G$7 -> #DIV/0! | F40: =D40/$D$123 -> #DIV/0! | H40: =D40-G40 -> 0
A41: 07C | B41: Fireproofing & Firestopping | D41: ='07C Fireproofing&Firestopping'!B85 -> 0 | E41: =D41/$G$7 -> #DIV/0! | F41: =D41/$D$123 -> #DIV/0! | H41: =D41-G41 -> 0
A42: 07D | B42: Roofing | D42: ='07D Roofing'!B89 -> 0 | E42: =D42/$G$7 -> #DIV/0! | F42: =D42/$D$123 -> #DIV/0! | H42: =D42-G42 -> 0
A43: 07E | B43: Caulking & Waterproofing | D43: ='07E Caulking & Waterproofing'!B100 -> 0 | E43: =D43/$G$7 -> #DIV/0! | F43: =D43/$D$123 -> #DIV/0! | H43: =D43-G43 -> 0
A44: 07F | B44: Siding | D44: ='07F Siding'!B95 -> 0 | E44: =D44/$G$7 -> #DIV/0! | F44: =D44/$D$123 -> #DIV/0! | H44: =D44-G44 -> 0
A45: 07H | B45: Panelized Exterior Skin | D45: ='07H Panelized Exterior Skin'!B94 -> 0 | E45: =D45/$G$7 -> #DIV/0! | F45: =D45/$D$123 -> #DIV/0! | H45: =D45-G45 -> 0
A46: 08A | B46: Doors, Frames, & Hardware | D46: ='08A Doors, Frames, & Hardware'!B82 -> 0 | E46: =D46/$G$7 -> #DIV/0! | F46: =D46/$D$123 -> #DIV/0! | H46: =D46-G46 -> 0
A47: 08B | B47: Overhead Coiling Doors | D47: ='08B Overhead Coiling Doors'!B79 -> 0 | E47: =D47/$G$7 -> #DIV/0! | F47: =D47/$D$123 -> #DIV/0! | H47: =D47-G47 -> 0
...

Sheet IDS
G1: Hedrick Plug
F2: X | G2: Excluded
B3: BACK TO SUMMARY SHEET | F3: I | G3: Included | H3: Bidder 1 | J3: Bidder 2 | L3: Bidder 3 | N3: Bidder 4 | P3: Bidder5 | R3: Bidder6
A4: Project: | B4: ='[1]Area Calculations'!B4 -> 0 | G4: Company | H4: HB Construction
A5: Trade: | B5: IDS Services | G5: Contact | H5: Butch Carmichael
A6: CSI Code: | G6: Phone | H6: 561-225-4868
A7: Date: | G7: Email | H7: <bcarmichael@hedrickbrothers.com>
A8: Adjusted Bid | G8: Adjusted Bid | H8: =I99 -> 0 | J8: =K99 -> 0 | L8: =M99 -> 0 | N8: =O99 -> 0 | P8: =Q99 -> 0 | R8: =S99 -> 0
A9: BID DOCUMENTS: | C9: Plan/ Spec. Package | D9: QTY | E9: U/M | F9: Unit Cost | G9: Subtotal | H9: Yes/No | I9: Price | J9: Yes/No | K9: Price | L9: Yes/No | M9: Price | N9: Yes/No | O9: Price | P9: Yes/No | Q9: Price | R9: Yes/No | S9: Price
B10: Plans By Division
B11: ='[1]Area Calculations'!J54 -> 0 | C11: P
B12: ='[1]Area Calculations'!J55 -> 0 | C12: P
B13: ='[1]Area Calculations'!J56 -> 0 | C13: P
B14: ='[1]Area Calculations'!J57 -> 0 | C14: P
B15: ='[1]Area Calculations'!J58 -> 0 | C15: P
B16: ='[1]Area Calculations'!J59 -> 0 | C16: P
B17: ='[1]Area Calculations'!J60 -> 0 | C17: P
B18: ='[1]Area Calculations'!J61 -> 0 | C18: P
B19: ='[1]Area Calculations'!J62 -> 0 | C19: P
B21: Survey
B22: OCIP Insurance per exhibit
B23: GENERAL INCLUSIONS
B24: INCLUDES ALL SALES TAX
B25: ALL HOISTING & RIGGING REQUIRED TO COMPLETE THIS SCOPE
B26: PROVIDE P&P BONDS
B27: FLORIDA STATE CONTRACTORS LIC.
B28: GENERAL LIABILITY AND WORKERS COMP. INSURANCE LIMITS
B29: STATE AND LOCAL TAXES
B30: SPECIFIC TRADE SCOPE OF WORK REQUIREMENTS
B31: BASE BID | D31: 1 | E31: EA
B33: Pre-construction Modeling/BIM Execution Plan Meetings
B34: BIM Execution Plan Meeting including writing of BEP | H34: i
B35: Initial Jobsite Visit | H35: x
B36: Model Architectural | H36: i
B37: Model Structural | H37: i
B38: Model Mechanical/HVAC | H38: i
B39: Model Plumbing | H39: i
B40: Model Electrical | H40: x
B41: Model Fire Sprinkler | H41: x
B42: Model Civil | H42: x
...

Sheet 01A Surveying
G1: Hedrick Plug
F2: X | G2: Excluded
B3: BACK TO SUMMARY SHEET | F3: I | G3: Included | H3: Bidder 1 | J3: Bidder 2 | L3: Bidder 3 | N3: Bidder 4 | P3: Bidder5 | R3: Bidder6
A4: Project: | B4: ='Area Calculations'!B4 -> Project Name | G4: Company
A5: Trade: | B5: Surveying | G5: Contact
A6: CSI Code: | B6: 01A | G6: Phone
A7: Date: | G7: Email
A8: Adjusted Bid | G8: Adjusted Bid | H8: =I81 -> 0 | J8: =K81 -> 0 | L8: =M81 -> 0 | N8: =O81 -> 0 | P8: =Q81 -> 0 | R8: =S81 -> 0
A9: BID DOCUMENTS: | C9: Plan/ Spec. Package | D9: QTY | E9: U/M | F9: Unit Cost | G9: Subtotal | H9: Yes/No | I9: Price | J9: Yes/No | K9: Price | L9: Yes/No | M9: Price | N9: Yes/No | O9: Price | P9: Yes/No | Q9: Price | R9: Yes/No | S9: Price
B10: Plans By Division
B11: ='Area Calculations'!L62 -> Architectural Drawings by | C11: P
B12: ='Area Calculations'!L63 -> Structural Drawings by | C12: P
B13: ='Area Calculations'!L64 -> MEP FA FP Drawings by | C13: P
B14: ='Area Calculations'!L65 -> Civil Drawings by | C14: P
B15: ='Area Calculations'!L66 -> Land scape Drawings by | C15: P
B16: ='Area Calculations'!L67 -> Kitchen Drawings by | C16: P
B17: ='Area Calculations'!L68 -> Storefront Designer by | C17: P
B18: ='Area Calculations'!L69 -> Geotech report by | C18: P
B19: ='Area Calculations'!L70 -> Specifications | C19: P
B21: Surveying
B22: OCIP Insurance per exhibit
B23: GENERAL INCLUSIONS
B24: INCLUDES ALL SALES TAX
B25: ALL HOISTING & RIGGING REQUIRED TO COMPLETE THIS SCOPE
B26: PROVIDE P&P BONDS
B27: FLORIDA STATE CONTRACTORS LIC.
B28: GENERAL LIABILITY AND WORKERS COMP. INSURANCE LIMITS
B29: STATE AND LOCAL TAXES
B30: COMPASS
B31: SPECIFIC TRADE SCOPE OF WORK REQUIREMENTS
B32: BASE BID | D32: 1 | E32: EA
B34: Set Boundary
B35: Stake Building corners
B36: Parking Lot subgrade
B37: Parking Lot Base Rock
B38: Turn Lane subgrade
B39: Turn Lane baserock
B40: Tin tabs for curbs and tree islands | H40: i
B41: Sidewalks
B42: Curbing
...

Sheet 01B Material Testing
G1: Hedrick Plug
F2: X | G2: Excluded
B3: BACK TO SUMMARY SHEET | F3: I | G3: Included | H3: Bidder 1 | J3: Bidder 2 | L3: Bidder 3 | N3: Bidder 4 | P3: Bidder5 | R3: Bidder6
A4: Project: | B4: ='Area Calculations'!B4 -> Project Name | G4: Company
A5: Trade: | B5: Material Testing | G5: Contact
A6: CSI Code: | B6: 01B | G6: Phone
A7: Date: | G7: Email
A8: Adjusted Bid | G8: Adjusted Bid | H8: =I70 -> 0 | J8: =K70 -> 0 | L8: =M70 -> 0 | N8: =O70 -> 0 | P8: =Q70 -> 0 | R8: =S70 -> 0
A9: BID DOCUMENTS: | C9: Plan/ Spec. Package | D9: QTY | E9: U/M | F9: Unit Cost | G9: Subtotal | H9: Yes/No | I9: Price | J9: Yes/No | K9: Price | L9: Yes/No | M9: Price | N9: Yes/No | O9: Price | P9: Yes/No | Q9: Price | R9: Yes/No | S9: Price
B10: Plans By Division
B11: ='Area Calculations'!L62 -> Architectural Drawings by | C11: P
B12: ='Area Calculations'!L63 -> Structural Drawings by | C12: P
B13: ='Area Calculations'!L64 -> MEP FA FP Drawings by | C13: P
B14: ='Area Calculations'!L65 -> Civil Drawings by | C14: P
B15: ='Area Calculations'!L66 -> Land scape Drawings by | C15: P
B16: ='Area Calculations'!L67 -> Kitchen Drawings by | C16: P
B17: ='Area Calculations'!L68 -> Storefront Designer by | C17: P
B18: ='Area Calculations'!L69 -> Geotech report by | C18: P
B19: ='Area Calculations'!L70 -> Specifications | C19: P
B21: Material Testing
B22: GENERAL INCLUSIONS
B23: INCLUDES ALL SALES TAX
B24: ALL HOISTING & RIGGING REQUIRED TO COMPLETE THIS SCOPE
B25: PROVIDE P&P BONDS
B26: FLORIDA STATE CONTRACTORS LIC.
B27: GENERAL LIABILITY AND WORKERS COMP. INSURANCE LIMITS
B28: STATE AND LOCAL TAXES
B29: COMPASS
B30: SPECIFIC TRADE SCOPE OF WORK REQUIREMENTS
B31: BASE BID
H36: x
H37: i
F66: SUBTOTAL | I66: =SUM(I22:I65) -> 0 | K66: =SUM(K22:K65) -> 0 | M66: =SUM(M22:M65) -> 0 | O66: =SUM(O22:O65) -> 0 | Q66: =SUM(Q22:Q65) -> 0 | S66: =SUM(S22:S65) -> 0
F67: BOND RATE | H67: 0 | J67: 0 | L67: 0 | N67: 0 | P67: 0 | R67: 0
F68: BOND AMOUNT | I68: =H67*I66 -> 0 | K68: =J67*K66 -> 0 | M68: =L67*M66 -> 0 | O68: =N67*O66 -> 0 | Q68: =P67*Q66 -> 0 | S68: =R67*S66 -> 0
F70: ADJUSTED TOTAL | I70: =SUM(I66:I68) -> 0 | K70: =SUM(K66:K68) -> 0 | M70: =SUM(M66:M68) -> 0 | O70: =SUM(O66:O68) -> 0 | Q70: =SUM(Q66:Q68) -> 0 | S70: =SUM(S66:S68) -> 0
F71: Cost per SF | I71: =I70/'Area Calculations'!$I$4 -> #DIV/0! | K71: =K70/'Area Calculations'!$I$4 -> #DIV/0! | M71: =M70/'Area Calculations'!$I$4 -> #DIV/0! | O71: =O70/'Area Calculations'!$I$4 -> #DIV/0! | Q71: =Q70/'Area Calculations'!$I$4 -> #DIV/0! | S71: =S70/'Area Calculations'!$I$4 -> #DIV/0!
F72: Cost per Unit | I72: =I70/'Area Calculations'!#REF! -> #REF! | K72: =K70/'Area Calculations'!#REF! -> #REF! | M72: =M70/'Area Calculations'!#REF! -> #REF! | O72: =O70/'Area Calculations'!#REF! -> #REF! | Q72: =Q70/'Area Calculations'!#REF! -> #REF! | S72: =S70/'Area Calculations'!#REF! -> #REF!
A74: QUALIFICATIONS
A78: EXCLUSIONS/OWNER PROVIDED ITEMS:
...

Sheet 01C Final Cleaning
G1: Hedrick Plug
F2: X | G2: Excluded
B3: BACK TO SUMMARY SHEET | F3: I | G3: Included | H3: Bidder 1 | J3: Bidder 2 | L3: Bidder 3 | N3: Bidder 4 | P3: Bidder5 | R3: Bidder6
A4: Project: | B4: ='Area Calculations'!B4 -> Project Name | G4: Company
A5: Trade: | B5: Final Cleaning | G5: Contact
A6: CSI Code: | B6: 01C | G6: Phone
A7: Date: | G7: Email
A8: Adjusted Bid | G8: Adjusted Bid | H8: =I70 -> 0 | J8: =K70 -> 0 | L8: =M70 -> 0 | N8: =O70 -> 0 | P8: =Q70 -> 0 | R8: =S70 -> 0
A9: BID DOCUMENTS: | C9: Plan/ Spec. Package | D9: QTY | E9: U/M | F9: Unit Cost | G9: Subtotal | H9: Yes/No | I9: Price | J9: Yes/No | K9: Price | L9: Yes/No | M9: Price | N9: Yes/No | O9: Price | P9: Yes/No | Q9: Price | R9: Yes/No | S9: Price
B10: Plans By Division
B11: ='Area Calculations'!L62 -> Architectural Drawings by | C11: P
B12: ='Area Calculations'!L63 -> Structural Drawings by | C12: P
B13: ='Area Calculations'!L64 -> MEP FA FP Drawings by | C13: P
B14: ='Area Calculations'!L65 -> Civil Drawings by | C14: P
B15: ='Area Calculations'!L66 -> Land scape Drawings by | C15: P
B16: ='Area Calculations'!L67 -> Kitchen Drawings by | C16: P
B17: ='Area Calculations'!L68 -> Storefront Designer by | C17: P
B18: ='Area Calculations'!L69 -> Geotech report by | C18: P
B19: ='Area Calculations'!L70 -> Specifications | C19: P
B21: Final Cleaning
B22: GENERAL INCLUSIONS
B23: INCLUDES ALL SALES TAX
B24: ALL HOISTING & RIGGING REQUIRED TO COMPLETE THIS SCOPE
B25: PROVIDE P&P BONDS
B26: FLORIDA STATE CONTRACTORS LIC.
B27: GENERAL LIABILITY AND WORKERS COMP. INSURANCE LIMITS
B28: STATE AND LOCAL TAXES
B29: COMPASS
B30: SPECIFIC TRADE SCOPE OF WORK REQUIREMENTS
B31: BASE BID
H36: x
H37: i
F66: SUBTOTAL | I66: =SUM(I22:I65) -> 0 | K66: =SUM(K22:K65) -> 0 | M66: =SUM(M22:M65) -> 0 | O66: =SUM(O22:O65) -> 0 | Q66: =SUM(Q22:Q65) -> 0 | S66: =SUM(S22:S65) -> 0
F67: BOND RATE | H67: 0 | J67: 0 | L67: 0 | N67: 0 | P67: 0 | R67: 0
F68: BOND AMOUNT | I68: =H67*I66 -> 0 | K68: =J67*K66 -> 0 | M68: =L67*M66 -> 0 | O68: =N67*O66 -> 0 | Q68: =P67*Q66 -> 0 | S68: =R67*S66 -> 0
F70: ADJUSTED TOTAL | I70: =SUM(I66:I68) -> 0 | K70: =SUM(K66:K68) -> 0 | M70: =SUM(M66:M68) -> 0 | O70: =SUM(O66:O68) -> 0 | Q70: =SUM(Q66:Q68) -> 0 | S70: =SUM(S66:S68) -> 0
F71: Cost per SF | I71: =I70/'Area Calculations'!$I$4 -> #DIV/0! | K71: =K70/'Area Calculations'!$I$4 -> #DIV/0! | M71: =M70/'Area Calculations'!$I$4 -> #DIV/0! | O71: =O70/'Area Calculations'!$I$4 -> #DIV/0! | Q71: =Q70/'Area Calculations'!$I$4 -> #DIV/0! | S71: =S70/'Area Calculations'!$I$4 -> #DIV/0!
F72: Cost per Unit | I72: =I70/'Area Calculations'!#REF! -> #REF! | K72: =K70/'Area Calculations'!#REF! -> #REF! | M72: =M70/'Area Calculations'!#REF! -> #REF! | O72: =O70/'Area Calculations'!#REF! -> #REF! | Q72: =Q70/'Area Calculations'!#REF! -> #REF! | S72: =S70/'Area Calculations'!#REF! -> #REF!
A74: QUALIFICATIONS
A78: EXCLUSIONS/OWNER PROVIDED ITEMS:
...

Sheet 02A Demolition
G1: Hedrick Plug
F2: X | G2: Excluded
B3: BACK TO SUMMARY SHEET | F3: I | G3: Included | H3: Bidder 1 | J3: Bidder 2 | L3: Bidder 3 | N3: Bidder 4 | P3: Bidder5 | R3: Bidder6
A4: Project: | B4: ='Area Calculations'!B4 -> Project Name | G4: Company
A5: Trade: | B5: Demolition | G5: Contact
A6: CSI Code: | B6: 02A | G6: Phone
A7: Date: | G7: Email
A8: Adjusted Bid | G8: Adjusted Bid | H8: =I57 -> 0 | J8: =K57 -> 0 | L8: =M57 -> 0 | N8: =O57 -> 0 | P8: =Q57 -> 0 | R8: =S57 -> 0
A9: BID DOCUMENTS: | C9: Plan/ Spec. Package | D9: QTY | E9: U/M | F9: Unit Cost | G9: Subtotal | H9: Yes/No | I9: Price | J9: Yes/No | K9: Price | L9: Yes/No | M9: Price | N9: Yes/No | O9: Price | P9: Yes/No | Q9: Price | R9: Yes/No | S9: Price
B10: Plans By Division
B11: ='Area Calculations'!L62 -> Architectural Drawings by | C11: P
B12: ='Area Calculations'!L63 -> Structural Drawings by | C12: P
B13: ='Area Calculations'!L64 -> MEP FA FP Drawings by | C13: P
B14: ='Area Calculations'!L65 -> Civil Drawings by | C14: P
B15: ='Area Calculations'!L66 -> Land scape Drawings by | C15: P
B16: ='Area Calculations'!L67 -> Kitchen Drawings by | C16: P
B17: ='Area Calculations'!L68 -> Storefront Designer by | C17: P
B18: ='Area Calculations'!L69 -> Geotech report by | C18: P
B19: ='Area Calculations'!L70 -> Specifications | C19: P
B21: Demolition
B22: OCIP Insurance per exhibit
B23: GENERAL INCLUSIONS
B24: INCLUDES ALL SALES TAX
B25: ALL HOISTING & RIGGING REQUIRED TO COMPLETE THIS SCOPE
B26: PROVIDE P&P BONDS
B27: FLORIDA STATE CONTRACTORS LIC.
B28: GENERAL LIABILITY AND WORKERS COMP. INSURANCE LIMITS
B29: STATE AND LOCAL TAXES
B30: COMPASS
B31: SPECIFIC TRADE SCOPE OF WORK REQUIREMENTS
B32: BASE BID
H35: x
F53: SUBTOTAL | I53: =SUM(I22:I52) -> 0 | K53: =SUM(K22:K52) -> 0 | M53: =SUM(M22:M52) -> 0 | O53: =SUM(O22:O52) -> 0 | Q53: =SUM(Q22:Q52) -> 0 | S53: =SUM(S22:S52) -> 0
F54: BOND RATE | H54: 0 | J54: 0 | L54: 0 | N54: 0 | P54: 0 | R54: 0
F55: BOND AMOUNT | I55: =H54*I53 -> 0 | K55: =J54*K53 -> 0 | M55: =L54*M53 -> 0 | O55: =N54*O53 -> 0 | Q55: =P54*Q53 -> 0 | S55: =R54*S53 -> 0
F57: ADJUSTED TOTAL | I57: =SUM(I53:I55) -> 0 | K57: =SUM(K53:K55) -> 0 | M57: =SUM(M53:M55) -> 0 | O57: =SUM(O53:O55) -> 0 | Q57: =SUM(Q53:Q55) -> 0 | S57: =SUM(S53:S55) -> 0
F58: Cost per SF | I58: =I57/'Area Calculations'!$I$4 -> #DIV/0! | K58: =K57/'Area Calculations'!$I$4 -> #DIV/0! | M58: =M57/'Area Calculations'!$I$4 -> #DIV/0! | O58: =O57/'Area Calculations'!$I$4 -> #DIV/0! | Q58: =Q57/'Area Calculations'!$I$4 -> #DIV/0! | S58: =S57/'Area Calculations'!$I$4 -> #DIV/0!
F59: Cost per Unit | I59: =I57/'Area Calculations'!#REF! -> #REF! | K59: =K57/'Area Calculations'!#REF! -> #REF! | M59: =M57/'Area Calculations'!#REF! -> #REF! | O59: =O57/'Area Calculations'!#REF! -> #REF! | Q59: =Q57/'Area Calculations'!#REF! -> #REF! | S59: =S57/'Area Calculations'!#REF! -> #REF!
A61: QUALIFICATIONS
A65: EXCLUSIONS/OWNER PROVIDED ITEMS:
...

Sheet 02B Abatement
G1: Hedrick Plug
F2: X | G2: Excluded
B3: BACK TO SUMMARY SHEET | F3: I | G3: Included | H3: Bidder 1 | J3: Bidder 2 | L3: Bidder 3 | N3: Bidder 4 | P3: Bidder5 | R3: Bidder6
A4: Project: | B4: ='Area Calculations'!B4 -> Project Name | G4: Company
A5: Trade: | B5: Abatement | G5: Contact
A6: CSI Code: | B6: 02B | G6: Phone
A7: Date: | G7: Email
A8: Adjusted Bid | G8: Adjusted Bid | H8: =I57 -> 0 | J8: =K57 -> 0 | L8: =M57 -> 0 | N8: =O57 -> 0 | P8: =Q57 -> 0 | R8: =S57 -> 0
A9: BID DOCUMENTS: | C9: Plan/ Spec. Package | D9: QTY | E9: U/M | F9: Unit Cost | G9: Subtotal | H9: Yes/No | I9: Price | J9: Yes/No | K9: Price | L9: Yes/No | M9: Price | N9: Yes/No | O9: Price | P9: Yes/No | Q9: Price | R9: Yes/No | S9: Price
B10: Plans By Division
B11: ='Area Calculations'!L62 -> Architectural Drawings by | C11: P
B12: ='Area Calculations'!L63 -> Structural Drawings by | C12: P
B13: ='Area Calculations'!L64 -> MEP FA FP Drawings by | C13: P
B14: ='Area Calculations'!L65 -> Civil Drawings by | C14: P
B15: ='Area Calculations'!L66 -> Land scape Drawings by | C15: P
B16: ='Area Calculations'!L67 -> Kitchen Drawings by | C16: P
B17: ='Area Calculations'!L68 -> Storefront Designer by | C17: P
B18: ='Area Calculations'!L69 -> Geotech report by | C18: P
B19: ='Area Calculations'!L70 -> Specifications | C19: P
B21: Abatement
B22: OCIP Insurance per exhibit
B23: GENERAL INCLUSIONS
B24: INCLUDES ALL SALES TAX
B25: ALL HOISTING & RIGGING REQUIRED TO COMPLETE THIS SCOPE
B26: PROVIDE P&P BONDS
B27: FLORIDA STATE CONTRACTORS LIC.
B28: GENERAL LIABILITY AND WORKERS COMP. INSURANCE LIMITS
B29: STATE AND LOCAL TAXES
B30: COMPASS
B31: SPECIFIC TRADE SCOPE OF WORK REQUIREMENTS
B32: BASE BID
H35: x
F53: SUBTOTAL | I53: =SUM(I22:I52) -> 0 | K53: =SUM(K22:K52) -> 0 | M53: =SUM(M22:M52) -> 0 | O53: =SUM(O22:O52) -> 0 | Q53: =SUM(Q22:Q52) -> 0 | S53: =SUM(S22:S52) -> 0
F54: BOND RATE | H54: 0 | J54: 0 | L54: 0 | N54: 0 | P54: 0 | R54: 0
F55: BOND AMOUNT | I55: =H54*I53 -> 0 | K55: =J54*K53 -> 0 | M55: =L54*M53 -> 0 | O55: =N54*O53 -> 0 | Q55: =P54*Q53 -> 0 | S55: =R54*S53 -> 0
F57: ADJUSTED TOTAL | I57: =SUM(I53:I55) -> 0 | K57: =SUM(K53:K55) -> 0 | M57: =SUM(M53:M55) -> 0 | O57: =SUM(O53:O55) -> 0 | Q57: =SUM(Q53:Q55) -> 0 | S57: =SUM(S53:S55) -> 0
F58: Cost per SF | I58: =I57/'Area Calculations'!$I$4 -> #DIV/0! | K58: =K57/'Area Calculations'!$I$4 -> #DIV/0! | M58: =M57/'Area Calculations'!$I$4 -> #DIV/0! | O58: =O57/'Area Calculations'!$I$4 -> #DIV/0! | Q58: =Q57/'Area Calculations'!$I$4 -> #DIV/0! | S58: =S57/'Area Calculations'!$I$4 -> #DIV/0!
F59: Cost per Unit | I59: =I57/'Area Calculations'!#REF! -> #REF! | K59: =K57/'Area Calculations'!#REF! -> #REF! | M59: =M57/'Area Calculations'!#REF! -> #REF! | O59: =O57/'Area Calculations'!#REF! -> #REF! | Q59: =Q57/'Area Calculations'!#REF! -> #REF! | S59: =S57/'Area Calculations'!#REF! -> #REF!
A61: QUALIFICATIONS
A65: EXCLUSIONS/OWNER PROVIDED ITEMS:
...

Sheet 03A Concrete
G1: Hedrick Plug
F2: X | G2: Excluded
B3: BACK TO SUMMARY SHEET | F3: I | G3: Included | H3: Bidder 1 | J3: Bidder2 | L3: Bidder 3 | N3: Bidder 4 | P3: Bidder 5 | R3: Bidder 6
A4: Project: | B4: ='Area Calculations'!B4 -> Project Name | G4: Company
A5: Trade: | B5: Concrete | G5: Contact
A6: CSI Code: | B6: 03A | G6: Phone
A7: Date: | G7: Email
A8: Adjusted Bid | G8: Adjusted Bid | H8: =I87 -> 0 | J8: =K87 -> 0 | L8: =M87 -> 0 | N8: =O87 -> 0 | P8: =Q87 -> 0 | R8: =S87 -> 0
A9: BID DOCUMENTS: | C9: Plan/ Spec. Package | D9: QTY | E9: U/M | F9: Unit Cost | G9: Subtotal | H9: Yes/No | I9: Price | J9: Yes/No | K9: Price | L9: Yes/No | M9: Price | N9: Yes/No | O9: Price | P9: Yes/No | Q9: Price | R9: Yes/No | S9: Price
B10: Plans By Division
B11: ='Area Calculations'!L62 -> Architectural Drawings by | C11: P
B12: ='Area Calculations'!L63 -> Structural Drawings by | C12: P
B13: ='Area Calculations'!L64 -> MEP FA FP Drawings by | C13: P
B14: ='Area Calculations'!L65 -> Civil Drawings by | C14: P
B15: ='Area Calculations'!L66 -> Land scape Drawings by | C15: P
B16: ='Area Calculations'!L67 -> Kitchen Drawings by
B17: ='Area Calculations'!L68 -> Storefront Designer by
B18: ='Area Calculations'!L69 -> Geotech report by | C18: P
B19: ='Area Calculations'!L70 -> Specifications
B21: Concrete
B22: GENERAL INCLUSIONS
B23: INCLUDES ALL SALES TAX
B24: ALL HOISTING & RIGGING REQUIRED TO COMPLETE THIS SCOPE
B25: PROVIDE P&P BONDS
B26: FLORIDA STATE CONTRACTORS LIC.
B27: GENERAL LIABILITY AND WORKERS COMP. INSURANCE LIMITS
B28: STATE AND LOCAL TAXES
B29: COMPASS
B30: SPECIFIC TRADE SCOPE OF WORK REQUIREMENTS
B31: BASE BID
B33: CIP Beams , incl.:
... B53: CMU, Incl.: 8" & 12"
B54: a. Layout and formwork | C54: S0-01
B55: b. Reinf., as scheduled/detailed
B56: c. ?-psi concrete grout; 0.? w/c
B57: d. Pumping as required
B58: e. Horizontal Reinf.
B59: f. Lintels, ladder wire and accessories
B60: g. Setting of Joist Embeds & door frames
B61: h. Above scope included for: | H61: i
...

Sheet 03B Precast Hollow Core
G1: Hedrick Plug
F2: X | G2: Excluded
B3: BACK TO SUMMARY SHEET | F3: I | G3: Included | H3: Bidder1 | J3: Bidder 2 | L3: Bidder 3 | N3: Bidder 4 | P3: Bidder 5 | R3: Bidder 6
A4: Project: | B4: ='Area Calculations'!B4 -> Project Name | G4: Company
A5: Trade: | B5: Precast Hollow Core | G5: Contact
A6: CSI Code: | B6: 03B | G6: Phone
A7: Date: | G7: Email
A8: Adjusted Bid | G8: Adjusted Bid | H8: =I46 -> 0 | J8: =K46 -> 0 | L8: =M46 -> 0 | N8: =O46 -> 0 | P8: =Q46 -> 0 | R8: =S46 -> 0
A9: BID DOCUMENTS: | C9: Plan/ Spec. Package | D9: QTY | E9: U/M | F9: Unit Cost | G9: Subtotal | H9: Yes/No | I9: Price | J9: Yes/No | K9: Price | L9: Yes/No | M9: Price | N9: Yes/No | O9: Price | P9: Yes/No | Q9: Price | R9: Yes/No | S9: Price
B10: Plans By Division
B11: ='Area Calculations'!L62 -> Architectural Drawings by | C11: P
B12: ='Area Calculations'!L63 -> Structural Drawings by | C12: P
B13: ='Area Calculations'!L64 -> MEP FA FP Drawings by | C13: P
B14: ='Area Calculations'!L65 -> Civil Drawings by | C14: P
B15: ='Area Calculations'!L66 -> Land scape Drawings by | C15: P
B16: ='Area Calculations'!L67 -> Kitchen Drawings by
B17: ='Area Calculations'!L68 -> Storefront Designer by
B18: ='Area Calculations'!L69 -> Geotech report by | C18: P
B19: ='Area Calculations'!L70 -> Specifications
B21: Precast Hollow Core
B22: GENERAL INCLUSIONS
B23: INCLUDES ALL SALES TAX
B24: ALL HOISTING & RIGGING REQUIRED TO COMPLETE THIS SCOPE
B25: PROVIDE P&P BONDS
B26: FLORIDA STATE CONTRACTORS LIC.
B27: GENERAL LIABILITY AND WORKERS COMP. INSURANCE LIMITS
B28: STATE AND LOCAL TAXES
B29: COMPASS
B30: SPECIFIC TRADE SCOPE OF WORK REQUIREMENTS
B31: BASE BID
B32: Building SF
L34: i
F42: SUBTOTAL | I42: =SUM(I24:I41) -> 0 | K42: =SUM(K24:K41) -> 0 | M42: =SUM(M24:M41) -> 0 | O42: =SUM(O24:O41) -> 0 | Q42: =SUM(Q24:Q41) -> 0 | S42: =SUM(S24:S41) -> 0
F43: BOND RATE | H43: 0 | J43: 0 | L43: 0 | N43: 0 | P43: 0 | R43: 0
F44: BOND AMOUNT | I44: =H43*I42 -> 0 | K44: =J43*K42 -> 0 | M44: =L43*M42 -> 0 | O44: =N43*O42 -> 0 | Q44: =P43*Q42 -> 0 | S44: =R43*S42 -> 0
F46: ADJUSTED TOTAL | I46: =SUM(I42:I44) -> 0 | K46: =SUM(K42:K44) -> 0 | M46: =SUM(M42:M44) -> 0 | O46: =SUM(O42:O44) -> 0 | Q46: =SUM(Q42:Q44) -> 0 | S46: =SUM(S42:S44) -> 0
F47: Cost per SF | I47: =I46/'Area Calculations'!$I$4 -> #DIV/0! | K47: =K46/'Area Calculations'!$I$4 -> #DIV/0! | M47: =M46/'Area Calculations'!$I$4 -> #DIV/0! | O47: =O46/'Area Calculations'!$I$4 -> #DIV/0! | Q47: =Q46/'Area Calculations'!$I$4 -> #DIV/0! | S47: =S46/'Area Calculations'!$I$4 -> #DIV/0!
F48: Cost per Unit | I48: =I46/'Area Calculations'!#REF! -> #REF! | K48: =K46/'Area Calculations'!#REF! -> #REF! | M48: =M46/'Area Calculations'!#REF! -> #REF! | O48: =O46/'Area Calculations'!#REF! -> #REF! | Q48: =Q46/'Area Calculations'!#REF! -> #REF! | S48: =S46/'Area Calculations'!#REF! -> #REF!
A50: QUALIFICATIONS
A54: EXCLUSIONS/OWNER PROVIDED ITEMS:
...

Sheet 03C Architectural Precast
G1: Hedrick Plug
F2: X | G2: Excluded
B3: BACK TO SUMMARY SHEET | F3: I | G3: Included | H3: Bidder1 | J3: Bidder 2 | L3: Bidder 3 | N3: Bidder 4 | P3: Bidder 5 | R3: Bidder 6
A4: Project: | B4: ='Area Calculations'!B4 -> Project Name | G4: Company
A5: Trade: | B5: Architectural Precast | G5: Contact
A6: CSI Code: | B6: 03C | G6: Phone
A7: Date: | G7: Email
A8: Adjusted Bid | G8: Adjusted Bid | H8: =I50 -> 0 | J8: =K50 -> 0 | L8: =M50 -> 0 | N8: =O50 -> 0 | P8: =Q50 -> 0 | R8: =S50 -> 0
A9: BID DOCUMENTS: | C9: Plan/ Spec. Package | D9: QTY | E9: U/M | F9: Unit Cost | G9: Subtotal | H9: Yes/No | I9: Price | J9: Yes/No | K9: Price | L9: Yes/No | M9: Price | N9: Yes/No | O9: Price | P9: Yes/No | Q9: Price | R9: Yes/No | S9: Price
B10: Plans By Division
B11: ='Area Calculations'!L62 -> Architectural Drawings by | C11: P
B12: ='Area Calculations'!L63 -> Structural Drawings by | C12: P
B13: ='Area Calculations'!L64 -> MEP FA FP Drawings by | C13: P
B14: ='Area Calculations'!L65 -> Civil Drawings by | C14: P
B15: ='Area Calculations'!L66 -> Land scape Drawings by | C15: P
B16: ='Area Calculations'!L67 -> Kitchen Drawings by
B17: ='Area Calculations'!L68 -> Storefront Designer by
B18: ='Area Calculations'!L69 -> Geotech report by | C18: P
B19: ='Area Calculations'!L70 -> Specifications
B21: Architectural Precast
B22: GENERAL INCLUSIONS
B23: INCLUDES ALL SALES TAX
B24: ALL HOISTING & RIGGING REQUIRED TO COMPLETE THIS SCOPE
B25: PROVIDE P&P BONDS
B26: FLORIDA STATE CONTRACTORS LIC.
B27: GENERAL LIABILITY AND WORKERS COMP. INSURANCE LIMITS
B28: STATE AND LOCAL TAXES
B29: COMPASS
B30: SPECIFIC TRADE SCOPE OF WORK REQUIREMENTS
B31: BASE BID
B32: Building SF
H38: i
F46: SUBTOTAL | I46: =SUM(I24:I45) -> 0 | K46: =SUM(K24:K45) -> 0 | M46: =SUM(M24:M45) -> 0 | O46: =SUM(O24:O45) -> 0 | Q46: =SUM(Q24:Q45) -> 0 | S46: =SUM(S24:S45) -> 0
F47: BOND RATE | H47: 0 | J47: 0 | L47: 0 | N47: 0 | P47: 0 | R47: 0
F48: BOND AMOUNT | I48: =H47*I46 -> 0 | K48: =J47*K46 -> 0 | M48: =L47*M46 -> 0 | O48: =N47*O46 -> 0 | Q48: =P47*Q46 -> 0 | S48: =R47*S46 -> 0
F50: ADJUSTED TOTAL | I50: =SUM(I46:I48) -> 0 | K50: =SUM(K46:K48) -> 0 | M50: =SUM(M46:M48) -> 0 | O50: =SUM(O46:O48) -> 0 | Q50: =SUM(Q46:Q48) -> 0 | S50: =SUM(S46:S48) -> 0
F51: Cost per SF | I51: =I50/'Area Calculations'!$I$4 -> #DIV/0! | K51: =K50/'Area Calculations'!$I$4 -> #DIV/0! | M51: =M50/'Area Calculations'!$I$4 -> #DIV/0! | O51: =O50/'Area Calculations'!$I$4 -> #DIV/0! | Q51: =Q50/'Area Calculations'!$I$4 -> #DIV/0! | S51: =S50/'Area Calculations'!$I$4 -> #DIV/0!
F52: Cost per Unit | I52: =I50/'Area Calculations'!#REF! -> #REF! | K52: =K50/'Area Calculations'!#REF! -> #REF! | M52: =M50/'Area Calculations'!#REF! -> #REF! | O52: =O50/'Area Calculations'!#REF! -> #REF! | Q52: =Q50/'Area Calculations'!#REF! -> #REF! | S52: =S50/'Area Calculations'!#REF! -> #REF!
A54: QUALIFICATIONS
A58: EXCLUSIONS/OWNER PROVIDED ITEMS:
...

Sheet 03C Concrete Tilt Up
G1: Hedrick Plug
F2: X | G2: Excluded
B3: BACK TO SUMMARY SHEET | F3: I | G3: Included | H3: Bidder1 | J3: Bidder 2 | L3: Bidder 3 | N3: Bidder 4 | P3: Bidder 5 | R3: Bidder 6
A4: Project: | B4: ='Area Calculations'!B4 -> Project Name | G4: Company
A5: Trade: | B5: Concrete Tilt Up | G5: Contact
A6: CSI Code: | B6: 03C | G6: Phone
A7: Date: | G7: Email
A8: Adjusted Bid | G8: Adjusted Bid | H8: =I46 -> 0 | J8: =K46 -> 0 | L8: =M46 -> 0 | N8: =O46 -> 0 | P8: =Q46 -> 0 | R8: =S46 -> 0
A9: BID DOCUMENTS: | C9: Plan/ Spec. Package | D9: QTY | E9: U/M | F9: Unit Cost | G9: Subtotal | H9: Yes/No | I9: Price | J9: Yes/No | K9: Price | L9: Yes/No | M9: Price | N9: Yes/No | O9: Price | P9: Yes/No | Q9: Price | R9: Yes/No | S9: Price
B10: Plans By Division
B11: ='Area Calculations'!L62 -> Architectural Drawings by | C11: P
B12: ='Area Calculations'!L63 -> Structural Drawings by | C12: P
B13: ='Area Calculations'!L64 -> MEP FA FP Drawings by | C13: P
B14: ='Area Calculations'!L65 -> Civil Drawings by | C14: P
B15: ='Area Calculations'!L66 -> Land scape Drawings by | C15: P
B16: ='Area Calculations'!L67 -> Kitchen Drawings by
B17: ='Area Calculations'!L68 -> Storefront Designer by
B18: ='Area Calculations'!L69 -> Geotech report by | C18: P
B19: ='Area Calculations'!L70 -> Specifications
B21: Concrete Tilt Up
B22: GENERAL INCLUSIONS
B23: INCLUDES ALL SALES TAX
B24: ALL HOISTING & RIGGING REQUIRED TO COMPLETE THIS SCOPE
B25: PROVIDE P&P BONDS
B26: FLORIDA STATE CONTRACTORS LIC.
B27: GENERAL LIABILITY AND WORKERS COMP. INSURANCE LIMITS
B28: STATE AND LOCAL TAXES
B29: COMPASS
B30: SPECIFIC TRADE SCOPE OF WORK REQUIREMENTS
B31: BASE BID
B32: Building SF
L34: i
F42: SUBTOTAL | I42: =SUM(I24:I41) -> 0 | K42: =SUM(K24:K41) -> 0 | M42: =SUM(M24:M41) -> 0 | O42: =SUM(O24:O41) -> 0 | Q42: =SUM(Q24:Q41) -> 0 | S42: =SUM(S24:S41) -> 0
F43: BOND RATE | H43: 0 | J43: 0 | L43: 0 | N43: 0 | P43: 0 | R43: 0
F44: BOND AMOUNT | I44: =H43*I42 -> 0 | K44: =J43*K42 -> 0 | M44: =L43*M42 -> 0 | O44: =N43*O42 -> 0 | Q44: =P43*Q42 -> 0 | S44: =R43*S42 -> 0
F46: ADJUSTED TOTAL | I46: =SUM(I42:I44) -> 0 | K46: =SUM(K42:K44) -> 0 | M46: =SUM(M42:M44) -> 0 | O46: =SUM(O42:O44) -> 0 | Q46: =SUM(Q42:Q44) -> 0 | S46: =SUM(S42:S44) -> 0
F47: Cost per SF | I47: =I46/'Area Calculations'!$I$4 -> #DIV/0! | K47: =K46/'Area Calculations'!$I$4 -> #DIV/0! | M47: =M46/'Area Calculations'!$I$4 -> #DIV/0! | O47: =O46/'Area Calculations'!$I$4 -> #DIV/0! | Q47: =Q46/'Area Calculations'!$I$4 -> #DIV/0! | S47: =S46/'Area Calculations'!$I$4 -> #DIV/0!
F48: Cost per Unit | I48: =I46/'Area Calculations'!#REF! -> #REF! | K48: =K46/'Area Calculations'!#REF! -> #REF! | M48: =M46/'Area Calculations'!#REF! -> #REF! | O48: =O46/'Area Calculations'!#REF! -> #REF! | Q48: =Q46/'Area Calculations'!#REF! -> #REF! | S48: =S46/'Area Calculations'!#REF! -> #REF!
A50: QUALIFICATIONS
A54: EXCLUSIONS/OWNER PROVIDED ITEMS:
...

Sheet 03D Structural Precast
G1: Hedrick Plug
F2: X | G2: Excluded
B3: BACK TO SUMMARY SHEET | F3: I | G3: Included | H3: Bidder1 | J3: Bidder 2 | L3: Bidder 3 | N3: Bidder 4 | P3: Bidder 5 | R3: Bidder 6
A4: Project: | B4: ='Area Calculations'!B4 -> Project Name | G4: Company
A5: Trade: | B5: Structural Precast | G5: Contact
A6: CSI Code: | B6: 03D | G6: Phone
A7: Date: | G7: Email
A8: Adjusted Bid | G8: Adjusted Bid | H8: =I96 -> 0 | J8: =K96 -> 0 | L8: =M96 -> 0 | N8: =O96 -> 0 | P8: =Q96 -> 0 | R8: =S96 -> 0
A9: BID DOCUMENTS: | C9: Plan/ Spec. Package | D9: QTY | E9: U/M | F9: Unit Cost | G9: Subtotal | H9: Yes/No | I9: Price | J9: Yes/No | K9: Price | L9: Yes/No | M9: Price | N9: Yes/No | O9: Price | P9: Yes/No | Q9: Price | R9: Yes/No | S9: Price
B10: Plans By Division
B11: ='Area Calculations'!L62 -> Architectural Drawings by | C11: P
B12: ='Area Calculations'!L63 -> Structural Drawings by | C12: P
B13: ='Area Calculations'!L64 -> MEP FA FP Drawings by | C13: P
B14: ='Area Calculations'!L65 -> Civil Drawings by | C14: P
B15: ='Area Calculations'!L66 -> Land scape Drawings by | C15: P
B16: ='Area Calculations'!L67 -> Kitchen Drawings by
B17: ='Area Calculations'!L68 -> Storefront Designer by
B18: ='Area Calculations'!L69 -> Geotech report by | C18: P
B19: ='Area Calculations'!L70 -> Specifications
B21: Structural Precast
B22: GENERAL INCLUSIONS
B23: INCLUDES ALL SALES TAX
B24: ALL HOISTING & RIGGING REQUIRED TO COMPLETE THIS SCOPE
B25: PROVIDE P&P BONDS
B26: FLORIDA STATE CONTRACTORS LIC.
B27: GENERAL LIABILITY AND WORKERS COMP. INSURANCE LIMITS
B28: STATE AND LOCAL TAXES
B29: COMPASS
B30: SPECIFIC TRADE SCOPE OF WORK REQUIREMENTS
B31: BASE BID
B32: Building SF
... B41: Dumpster Enclosure
B42: Monument Sign - | H42: i
B44: SLAB-ON-GRADE
B45: 5" Slab w/ WWF 6x6 w.2.9xw2.9
B46: a. Soil poisoning and pre-treat
B47: b. Fine grading building pad
B48: d. F&I rebar, as per plans
B49: e. F&I wire mesh, as per plans
B50: f. 4,000 PSI
...

Sheet 03E Cranes and Hoisting
G1: Hedrick Plug
F2: X | G2: Excluded
B3: BACK TO SUMMARY SHEET | F3: I | G3: Included | H3: Bidder1 | J3: Bidder 2 | L3: Bidder 3 | N3: Bidder 4 | P3: Bidder 5 | R3: Bidder 6
A4: Project: | B4: ='Area Calculations'!B4 -> Project Name | G4: Company
A5: Trade: | B5: Cranes and Hoisting | G5: Contact
A6: CSI Code: | B6: 03E | G6: Phone
A7: Date: | G7: Email
A8: Adjusted Bid | G8: Adjusted Bid | H8: =I96 -> 0 | J8: =K96 -> 0 | L8: =M96 -> 0 | N8: =O96 -> 0 | P8: =Q96 -> 0 | R8: =S96 -> 0
A9: BID DOCUMENTS: | C9: Plan/ Spec. Package | D9: QTY | E9: U/M | F9: Unit Cost | G9: Subtotal | H9: Yes/No | I9: Price | J9: Yes/No | K9: Price | L9: Yes/No | M9: Price | N9: Yes/No | O9: Price | P9: Yes/No | Q9: Price | R9: Yes/No | S9: Price
B10: Plans By Division
B11: ='Area Calculations'!L62 -> Architectural Drawings by | C11: P
B12: ='Area Calculations'!L63 -> Structural Drawings by | C12: P
B13: ='Area Calculations'!L64 -> MEP FA FP Drawings by | C13: P
B14: ='Area Calculations'!L65 -> Civil Drawings by | C14: P
B15: ='Area Calculations'!L66 -> Land scape Drawings by | C15: P
B16: ='Area Calculations'!L67 -> Kitchen Drawings by
B17: ='Area Calculations'!L68 -> Storefront Designer by
B18: ='Area Calculations'!L69 -> Geotech report by | C18: P
B19: ='Area Calculations'!L70 -> Specifications
B21: Cranes and Hoisting
B22: GENERAL INCLUSIONS
B23: INCLUDES ALL SALES TAX
B24: ALL HOISTING & RIGGING REQUIRED TO COMPLETE THIS SCOPE
B25: PROVIDE P&P BONDS
B26: FLORIDA STATE CONTRACTORS LIC.
B27: GENERAL LIABILITY AND WORKERS COMP. INSURANCE LIMITS
B28: STATE AND LOCAL TAXES
B29: COMPASS
B30: SPECIFIC TRADE SCOPE OF WORK REQUIREMENTS
B31: BASE BID
B32: Building SF
... B41: Dumpster Enclosure
B42: Monument Sign - | H42: i
B44: SLAB-ON-GRADE
B45: 5" Slab w/ WWF 6x6 w.2.9xw2.9
B46: a. Soil poisoning and pre-treat
B47: b. Fine grading building pad
B48: d. F&I rebar, as per plans
B49: e. F&I wire mesh, as per plans
B50: f. 4,000 PSI
...

Sheet 03F Concrete Restoration
G1: Hedrick Plug
F2: X | G2: Excluded
B3: BACK TO SUMMARY SHEET | F3: I | G3: Included | H3: Bidder1 | J3: Bidder 2 | L3: Bidder 3 | N3: Bidder 4 | P3: Bidder 5 | R3: Bidder 6
A4: Project: | B4: ='Area Calculations'!B4 -> Project Name | G4: Company
A5: Trade: | B5: Concrete Restoration | G5: Contact
A6: CSI Code: | B6: 03F | G6: Phone
A7: Date: | G7: Email
A8: Adjusted Bid | G8: Adjusted Bid | H8: =I96 -> 0 | J8: =K96 -> 0 | L8: =M96 -> 0 | N8: =O96 -> 0 | P8: =Q96 -> 0 | R8: =S96 -> 0
A9: BID DOCUMENTS: | C9: Plan/ Spec. Package | D9: QTY | E9: U/M | F9: Unit Cost | G9: Subtotal | H9: Yes/No | I9: Price | J9: Yes/No | K9: Price | L9: Yes/No | M9: Price | N9: Yes/No | O9: Price | P9: Yes/No | Q9: Price | R9: Yes/No | S9: Price
B10: Plans By Division
B11: ='Area Calculations'!L62 -> Architectural Drawings by | C11: P
B12: ='Area Calculations'!L63 -> Structural Drawings by | C12: P
B13: ='Area Calculations'!L64 -> MEP FA FP Drawings by | C13: P
B14: ='Area Calculations'!L65 -> Civil Drawings by | C14: P
B15: ='Area Calculations'!L66 -> Land scape Drawings by | C15: P
B16: ='Area Calculations'!L67 -> Kitchen Drawings by
B17: ='Area Calculations'!L68 -> Storefront Designer by
B18: ='Area Calculations'!L69 -> Geotech report by | C18: P
B19: ='Area Calculations'!L70 -> Specifications
B21: Concrete Restoration
B22: GENERAL INCLUSIONS
B23: INCLUDES ALL SALES TAX
B24: ALL HOISTING & RIGGING REQUIRED TO COMPLETE THIS SCOPE
B25: PROVIDE P&P BONDS
B26: FLORIDA STATE CONTRACTORS LIC.
B27: GENERAL LIABILITY AND WORKERS COMP. INSURANCE LIMITS
B28: STATE AND LOCAL TAXES
B29: COMPASS
B30: SPECIFIC TRADE SCOPE OF WORK REQUIREMENTS
B31: BASE BID
B32: Building SF
... B41: Dumpster Enclosure
B42: Monument Sign - | H42: i
B44: SLAB-ON-GRADE
B45: 5" Slab w/ WWF 6x6 w.2.9xw2.9
B46: a. Soil poisoning and pre-treat
B47: b. Fine grading building pad
B48: d. F&I rebar, as per plans
B49: e. F&I wire mesh, as per plans
B50: f. 4,000 PSI
...

Sheet 04A Masonry
G1: Hedrick Plug
F2: X | G2: Excluded
B3: BACK TO SUMMARY SHEET | F3: I | G3: Included | H3: Bidder1 | J3: Bidder 2 | L3: Bidder 3 | N3: Bidder 4 | P3: Bidder 5 | R3: Bidder 6
A4: Project: | B4: ='Area Calculations'!B4 -> Project Name | G4: Company
A5: Trade: | B5: Masonry | G5: Contact
A6: CSI Code: | B6: 04A | G6: Phone
A7: Date: | G7: Email
A8: Adjusted Bid | G8: Adjusted Bid | H8: =I86 -> 0 | J8: =K86 -> 0 | L8: =M86 -> 0 | N8: =O86 -> 0 | P8: =Q86 -> 0 | R8: =S86 -> 0
A9: BID DOCUMENTS: | C9: Plan/ Spec. Package | D9: QTY | E9: U/M | F9: Unit Cost | G9: Subtotal | H9: Yes/No | I9: Price | J9: Yes/No | K9: Price | L9: Yes/No | M9: Price | N9: Yes/No | O9: Price | P9: Yes/No | Q9: Price | R9: Yes/No | S9: Price
B10: Plans By Division
B11: ='Area Calculations'!L62 -> Architectural Drawings by | C11: P
B12: ='Area Calculations'!L63 -> Structural Drawings by | C12: P
B13: ='Area Calculations'!L64 -> MEP FA FP Drawings by | C13: P
B14: ='Area Calculations'!L65 -> Civil Drawings by | C14: P
B15: ='Area Calculations'!L66 -> Land scape Drawings by | C15: P
B16: ='Area Calculations'!L67 -> Kitchen Drawings by
B17: ='Area Calculations'!L68 -> Storefront Designer by
B18: ='Area Calculations'!L69 -> Geotech report by | C18: P
B19: ='Area Calculations'!L70 -> Specifications
B21: Masonry
B22: GENERAL INCLUSIONS
B23: INCLUDES ALL SALES TAX
B24: ALL HOISTING & RIGGING REQUIRED TO COMPLETE THIS SCOPE
B25: PROVIDE P&P BONDS
B26: FLORIDA STATE CONTRACTORS LIC.
B27: GENERAL LIABILITY AND WORKERS COMP. INSURANCE LIMITS
B28: STATE AND LOCAL TAXES
B29: COMPASS
B30: SPECIFIC TRADE SCOPE OF WORK REQUIREMENTS
B31: BASE BID
B32: Building SF
... B39: e. Horizontal Reinf.
B40: f. Lintels, ladder wire and accessories | H40: i
B41: g. Setting of Joist Embeds & door frames
B42: h. Above scope included for:
B43: 1)
B44: 2)
B45: 3)
F82: SUBTOTAL | I82: =SUM(I24:I81) -> 0 | K82: =SUM(K24:K81) -> 0 | M82: =SUM(M24:M81) -> 0 | O82: =SUM(O24:O81) -> 0 | Q82: =SUM(Q24:Q81) -> 0 | S82: =SUM(S24:S81) -> 0
F83: BOND RATE | H83: 0 | J83: 0 | L83: 0 | N83: 0 | P83: 0 | R83: 0
...

Sheet 04B Stone Veneer
G1: Hedrick Plug
F2: X | G2: Excluded
B3: BACK TO SUMMARY SHEET | F3: I | G3: Included | H3: Bidder 1 | J3: Bidder2 | L3: Bidder 3 | N3: Bidder 4 | P3: Bidder5 | R3: Bidder6
A4: Project: | B4: ='Area Calculations'!B4 -> Project Name | G4: Company
A5: Trade: | B5: Cast Stone, Stone Veneer | G5: Contact
A6: CSI Code: | B6: 04B | G6: Phone
A7: Date: | G7: Email
A8: Adjusted Bid | G8: Adjusted Bid | H8: =I65 -> 0 | J8: =K65 -> 0 | L8: =M65 -> 0 | N8: =O65 -> 0 | P8: =Q65 -> 0 | R8: =S65 -> 0
A9: BID DOCUMENTS: | C9: Plan/ Spec. Package | D9: QTY | E9: U/M | F9: Unit Cost | G9: Subtotal | H9: Yes/No | I9: Price | J9: Yes/No | K9: Price | L9: Yes/No | M9: Price | N9: Yes/No | O9: Price | P9: Yes/No | Q9: Price | R9: Yes/No | S9: Price
B10: Plans By Division
B11: ='Area Calculations'!L62 -> Architectural Drawings by | C11: P
B12: ='Area Calculations'!L63 -> Structural Drawings by | C12: P
B13: ='Area Calculations'!L64 -> MEP FA FP Drawings by | C13: P
B14: ='Area Calculations'!L65 -> Civil Drawings by | C14: P
B15: ='Area Calculations'!L66 -> Land scape Drawings by | C15: P
B16: ='Area Calculations'!L67 -> Kitchen Drawings by | C16: P
B17: ='Area Calculations'!L68 -> Storefront Designer by | C17: P
B18: ='Area Calculations'!L69 -> Geotech report by | C18: P
B19: ='Area Calculations'!L70 -> Specifications
B21: Cast Stone, Stone Veneer
B22: GENERAL INCLUSIONS
B23: INCLUDES ALL SALES TAX
B24: ALL HOISTING & RIGGING REQUIRED TO COMPLETE THIS SCOPE
B25: PROVIDE P&P BONDS
B26: FLORIDA STATE CONTRACTORS LIC.
B27: GENERAL LIABILITY AND WORKERS COMP. INSURANCE LIMITS
B28: STATE AND LOCAL TAXES
B29: COMPASS
B30: SPECIFIC TRADE SCOPE OF WORK REQUIREMENTS
B31: BASE BID
B33: Stone Veneer, Incl.:
... B54: Self-adhering reflective rubberized asphalt membrane , 25 mils thickness minimum flashing, corner flashing to be 8"-12" and opening flashing to be 4" minimum
B55: Silicone sealant | H55: x
F61: SUBTOTAL | I61: =SUM(I16:I60) -> 0 | K61: =SUM(K16:K60) -> 0 | M61: =SUM(M16:M60) -> 0 | O61: =SUM(O16:O60) -> 0 | Q61: =SUM(Q16:Q60) -> 0 | S61: =SUM(S16:S60) -> 0
F62: BOND RATE | H62: 0 | J62: 0 | L62: 0 | N62: 0 | P62: 0 | R62: 0
F63: BOND AMOUNT | I63: =H62*I61 -> 0 | K63: =J62*K61 -> 0 | M63: =L62*M61 -> 0 | O63: =N62*O61 -> 0 | Q63: =P62*Q61 -> 0 | S63: =R62*S61 -> 0
F65: ADJUSTED TOTAL | I65: =SUM(I61:I63) -> 0 | K65: =SUM(K61:K63) -> 0 | M65: =SUM(M61:M63) -> 0 | O65: =SUM(O61:O63) -> 0 | Q65: =SUM(Q61:Q63) -> 0 | S65: =SUM(S61:S63) -> 0
F66: Cost per SF | I66: =I65/'Area Calculations'!$I$4 -> #DIV/0! | K66: =K65/'Area Calculations'!$I$4 -> #DIV/0! | M66: =M65/'Area Calculations'!$I$4 -> #DIV/0! | O66: =O65/'Area Calculations'!$I$4 -> #DIV/0! | Q66: =Q65/'Area Calculations'!$I$4 -> #DIV/0! | S66: =S65/'Area Calculations'!$I$4 -> #DIV/0!
