Workbook
Name FCP: 'Bond Calculator'!$B$7

Sheet Bond Calculator
A1: Hedrick Brothers Construction
A3: Performance / Payment Bond | E3: Performance / Payment Bond
A4: General Construction | E4: Design Build
A5: 42888 | E5: 42053
B6: =IF(B13>500000,500000,B13) -> 500000 | C6: 0.0091 | D6: =B6*C6 -> 4550 | F6: 0 | G6: 0.01875 | H6: =SUM(F6*G6) -> 0
B7: =IF(B13<2500000,(B13-B6),IF(B13>B6,2000000,0)) -> 1720594.1 | C7: 0.00725 | D7: =B7*C7 -> 12474.307 | F7: 0 | G7: 0.015 | H7: =SUM(F7*G7) -> 0
B8: =IF(B13<5000000,MAX(0,B13-2500000),IF(B13>2500000,2500000)) -> 0 | C8: 0.0063 | D8: =B8*C8 -> 0 | F8: 0 | G8: 0.01125 | H8: =SUM(F8*G8) -> 0
B9: =IF(B13<7500000,MAX(0,B13-5000000),IF(B13>7500000,2500000,0)) -> 0 | C9: 0.00555 | D9: =B9*C9 -> 0 | F9: 0 | G9: 0.009 | H9: =SUM(F9*G9) -> 0
B10: =IF(B13<7500000,MAX(0,B13-7500000),IF(B13>7500000,(B13-7500000))) -> 0 | C10: 0.0051 | D10: =B10*C10 -> 0 | F10: 0 | G10: 0.00825 | H10: =SUM(F10*G10) -> 0
D11: =B11*C11 -> 0 | F11: 0 | G11: 0.0075 | H11: =SUM(F11*G11) -> 0
A12: Contract Value | B12: ='Cost Summary'!D76 -> 33148733 | C12: Total | D12: =SUM(D6:D11) -> 17024.307 | E12: Contract Value | F12: =SUM(F6+F7+F8+F9+F10+F11) -> 0 | G12: Total | H12: =SUM(H6:H11) -> 0
A13: Cost Summary | B13: 2220594.1 | D13: =SUM(D12/B12) -> 0.00051357338 | H13: =SUM(H12/F12) -> #DIV/0!
B14: =B12-B13 -> 30928139

Sheet Allowances
A7: ='Area Calculations'!B4 -> The Club at Ibis Conceptual Estimate | C7: ='Area Calculations'!B5 -> West Palm Beach, FL
A9: Allowances
A10: =TODAY() -> 46146
A12: NO. | B12: DESCRIPTION | C12: VALUE
A13: 1 | C13: 0
A14: =A13+1 -> 2 | C14: 0
A15: =A14+1 -> 3 | C15: 0
A16: =A15+1 -> 4 | C16: 0
A17: =A16+1 -> 5 | C17: 0
A18: =A17+1 -> 6 | C18: 0
A19: =A18+1 -> 7 | C19: 0
A20: =A19+1 -> 8 | C20: 0
A21: =A20+1 -> 9 | C21: 0
A22: =A21+1 -> 10 | C22: 0
A23: =A22+1 -> 11 | C23: 0
A24: =A23+1 -> 12 | C24: 0
A25: =A24+1 -> 13 | C25: 0
... A28: =A27+1 -> 16 | C28: 0
A29: =A28+1 -> 17
A30: =A29+1 -> 18
A31: =A30+1 -> 19 | B31: Total | C31: =SUM(C13:C30) -> 0
B33: *All ALLOWANCES IN BID TABS MUST BE LISTED HERE

Sheet Alternates
A7: ='Area Calculations'!B4 -> The Club at Ibis Conceptual Estimate | C7: ='Area Calculations'!B5 -> West Palm Beach, FL
A9: Alternates
A10: =TODAY() -> 46146
A12: NO. | B12: DESCRIPTION | C12: VALUE
A13: ALT. #1 | B13: Description | C13: 0
A14: ALT. #2 | B14: Description | C14: 0
A15: ALT. #3 | B15: Description | C15: 0
A16: ALT. #4 | B16: Description | C16: 0
A17: ALT. #5 | B17: Description | C17: 0
A18: ALT. #6 | B18: Description | C18: 0
A19: ALT. #7 | B19: Description | C19: 0
A20: ALT. #8 | B20: Description | C20: 0
A21: ALT. #9 | B21: Description | C21: 0
A22: ALT. #10 | B22: Description | C22: 0
A23: ALT. #11 | B23: Description | C23: 0
A24: ALT. #12 | B24: Description | C24: 0
... A27: ALT. #15 | B27: Description | C27: 0
B28: Total | C28: =SUM(C13:C27) -> 0

Sheet Labor Rates Calculator
A5: Hedrick Brothers Construction Co., Inc.
A6: Salaries and Burden Calculations
A7: As of 8/22/24
C8: MARK-UP | F8: 0.18
E9: Burdened Rate | F9: Mark-up | G9: Total | I9: ANNUAL BURDENED AMOUNT | J9: ANNUAL BURDENED AMOUNT (W/ M/U)
B10: 1 | C10: Proj Exec | E10: 157.66656 | F10: =E10*$F$8 -> 28.379981 | G10: =SUM(E10:F10) -> 186.04654 | I10: =E10*2080 -> 327946.45 | J10: =G10*2080 -> 386976.81
B11: 2 | C11: Sr PM | E11: 130.67475 | F11: =E11*$F$8 -> 23.521455 | G11: =SUM(E11:F11) -> 154.1962 | I11: =E11*2080 -> 271803.48 | J11: =G11*2080 -> 320728.11
B12: 3 | C12: PM 3 | E12: 120.34132 | F12: =E12*$F$8 -> 21.661438 | G12: =SUM(E12:F12) -> 142.00276 | I12: =E12*2080 -> 250309.95 | J12: =G12*2080 -> 295365.75
B13: 4 | C13: PM 2 | E13: 110.14476 | F13: =E13*$F$8 -> 19.826057 | G13: =SUM(E13:F13) -> 129.97082 | I13: =E13*2080 -> 229101.1 | J13: =G13*2080 -> 270339.3
B14: 5 | C14: PM 1 | E14: 94.265604 | F14: =E14*$F$8 -> 16.967809 | G14: =SUM(E14:F14) -> 111.23341 | I14: =E14*2080 -> 196072.46 | J14: =G14*2080 -> 231365.5
B15: 6 | C15: Proj Admin | E15: 66.505247 | F15: =E15*$F$8 -> 11.970944 | G15: =SUM(E15:F15) -> 78.476192 | I15: =E15*2080 -> 138330.91 | J15: =G15*2080 -> 163230.48
B16: 7 | C16: Proj Acct | E16: 85.81004 | F16: =E16*$F$8 -> 15.445807 | G16: =SUM(E16:F16) -> 101.25585 | I16: =E16*2080 -> 178484.88 | J16: =G16*2080 -> 210612.16
B17: 8 | C17: Asst PM | E17: 82.733564 | F17: =E17*$F$8 -> 14.892041 | G17: =SUM(E17:F17) -> 97.625605 | I17: =E17*2080 -> 172085.81 | J17: =G17*2080 -> 203061.26
B18: 9 | C18: Supt 3 | E18: 131.75199 | F18: =E18*$F$8 -> 23.715358 | G18: =SUM(E18:F18) -> 155.46735 | I18: =E18*2080 -> 274044.14 | J18: =G18*2080 -> 323372.08
B19: 10 | C19: Supt 2 | E19: 110.59223 | F19: =E19*$F$8 -> 19.906601 | G19: =SUM(E19:F19) -> 130.49883 | I19: =E19*2080 -> 230031.83 | J19: =G19*2080 -> 271437.56
B20: 11 | C20: Supt 1 | E20: 90.514804 | F20: =E20*$F$8 -> 16.292665 | G20: =SUM(E20:F20) -> 106.80747 | I20: =E20*2080 -> 188270.79 | J20: =G20*2080 -> 222159.54
B21: 12 | C21: Asst Supt | E21: 59.915466 | F21: =E21*$F$8 -> 10.784784 | G21: =SUM(E21:F21) -> 70.70025 | I21: =E21*2080 -> 124624.17 | J21: =G21*2080 -> 147056.52
... B26: 17 | C26: Safety | E26: 79.733968 | F26: =E26*$F$8 -> 14.352114 | G26: =SUM(E26:F26) -> 94.086082 | I26: =E26*2080 -> 165846.65 | J26: =G26*2080 -> 195699.05
C27: Labor | E27: 32.408056 | F27: =E27*$F$8 -> 5.83345 | G27: =SUM(E27:F27) -> 38.241506 | I27: =E27*2080 -> 67408.756 | J27: =G27*2080 -> 79542.332
C28: Apprentice | E28: 32.978211 | F28: =E28*$F$8 -> 5.9360779 | G28: =SUM(E28:F28) -> 38.914289 | I28: =E28*2080 -> 68594.678 | J28: =G28*2080 -> 80941.72
C29: Carpenter | E29: 45.013251 | F29: =E29*$F$8 -> 8.1023852 | G29: =SUM(E29:F29) -> 53.115636 | I29: =E29*2080 -> 93627.563 | J29: =G29*2080 -> 110480.52
C30: Driver | E30: 35.486876 | F30: =E30*$F$8 -> 6.3876377 | G30: =SUM(E30:F30) -> 41.874514 | I30: =E30*2080 -> 73812.702 | J30: =G30*2080 -> 87098.989
C31: Leadman | E31: 46.605242 | F31: =E31*$F$8 -> 8.3889436 | G31: =SUM(E31:F31) -> 54.994186 | I31: =E31*2080 -> 96938.904 | J31: =G31*2080 -> 114387.91
C32: Supt MEP | E32: 0 | F32: =E32*$F$8 -> 0 | G32: =SUM(E32:F32) -> 0 | I32: =E32*2080 -> 0 | J32: =G32*2080 -> 0
C33: Gen Supt | E33: 130.4108 | F33: =E33*$F$8 -> 23.473945 | G33: =SUM(E33:F33) -> 153.88475 | I33: =E33*2080 -> 271254.47 | J33: =G33*2080 -> 320080.28
C34: Cons Mgr | E34: 135.45804 | F34: =E34*$F$8 -> 24.382447 | G34: =SUM(E34:F34) -> 159.84048 | I34: =E34*2080 -> 281752.72 | J34: =G34*2080 -> 332468.2
C35: Proj Coor | E35: 0 | F35: =E35*$F$8 -> 0 | G35: =SUM(E35:F35) -> 0 | I35: =E35*2080 -> 0 | J35: =G35*2080 -> 0
C36: Mktg | E36: 85.41309 | F36: =E36*$F$8 -> 15.374356 | G36: =SUM(E36:F36) -> 100.78745 | I36: =E36*2080 -> 177659.23 | J36: =G36*2080 -> 209637.89
C37: Bus Dev | E37: 121.55329 | F37: =E37*$F$8 -> 21.879592 | G37: =SUM(E37:F37) -> 143.43288 | I37: =E37*2080 -> 252830.84 | J37: =G37*2080 -> 298340.39
C38: Chief, 3 & 2 | E38: 140.9198 | F38: =E38*$F$8 -> 25.365565 | G38: =SUM(E38:F38) -> 166.28537 | I38: =E38*2080 -> 293113.19 | J38: =G38*2080 -> 345873.56
... C40: Exec Asst | E40: 69.670191 | F40: =E40*$F$8 -> 12.540634 | G40: =SUM(E40:F40) -> 82.210826 | I40: =E40*2080 -> 144914 | J40: =G40*2080 -> 170998.52
D41: TOTAL | E41: =SUM(E10:E40) -> 2612.4097 | F41: =SUM(F10:F40) -> 470.23374 | G41: =SUM(G10:G40) -> 3082.6434 | I41: =SUM(I10:I40) -> 5433812.1 | J41: =SUM(J10:J40) -> 6411898.3
G42: =E41/G41 -> 0.84745763 | I42: =I41/J41 -> 0.84745763

Sheet Area Calculations
B2: PROJECT AREA CALCULATIONS
B4: The Club at Ibis Conceptual Estimate | I4: Gross (sf) | J4: =H35 -> 0 | K4: FORMULA OFF GCS
B5: West Palm Beach, FL | I5: AC (sf) | J5: =E35 -> 0
I6: Rentable (sf) | J6: =F35 -> 0
I7: Site (acres) | J7: 1 | K7: FORMULA OFF GCS
I8: Parking Spaces | J8: 1
B9: =NOW() -> 46146.222 | I9: Build Duration (months) | J9: 1 | K9: FORMULA OFF GCS
B10: Drawings Date
A13: I. | B13: Floor | C13: Building | D13: Room | E13: ACSF | F13: RSF | G13: Acres | H13: Gross SF | I13: GROSS%
C14: Racquet | I14: =H14/$J$4 -> #DIV/0!
I15: =H15/$J$4 -> #DIV/0!
C16: Spa Building | I16: =H16/$J$4 -> #DIV/0!
I17: =H17/$J$4 -> #DIV/0!
C18: New Fitness Building | I18: =H18/$J$4 -> #DIV/0!
I19: =H19/$J$4 -> #DIV/0!
I20: =H20/$J$4 -> #DIV/0!
I21: =H21/$J$4 -> #DIV/0!
I22: =H22/$J$4 -> #DIV/0!
I23: =H23/$J$4 -> #DIV/0!
I24: =H24/$J$4 -> #DIV/0!
I25: =H25/$J$4 -> #DIV/0!
I26: =H26/$J$4 -> #DIV/0!
I27: =H27/$J$4 -> #DIV/0!
I28: =H28/$J$4 -> #DIV/0!
I29: =H29/$J$4 -> #DIV/0!
I30: =H30/$J$4 -> #DIV/0!
... I34: =H34/$J$4 -> #DIV/0!
B35: TOTAL | E35: =SUM(E14:E34) -> 0 | F35: =SUM(F14:F34) -> 0 | G35: =SUM(G14:G34) -> 0 | H35: =SUM(H14:H34) -> 0 | I35: =SUM(I14:I34) -> #DIV/0!
A37: II. | C37: Units | E37: Site SF | H37: Site(acres) | J37: %
I40: =SUM(H41:H45) -> 0
J41: =H41/$J$7 -> 0
J42: =H42/$J$7 -> 0
J43: =H43/$J$7 -> 0
J44: =H44/$J$7 -> 0
J45: =H45/$J$7 -> 0
I46: =SUM(H47:H49) -> 0
J47: =H47/$J$7 -> 0
J48: =H48/$J$7 -> 0
J49: =H49/$J$7 -> 0
B51: TOTAL | E51: =SUM(E41:E49) -> 0 | H51: =SUM(H40:H50) -> 0 | J51: =SUM(J40:J50) -> 0
...

Sheet Sub List
A5: ='Area Calculations'!$B$4 -> The Club at Ibis Conceptual Estimate
A7: Subcontractor List
A9: CSI | B9: CSI DESCRIPTION | C9: Sub 1 | D9: Sub 2 | E9: Sub 3
A10: 02A | B10: Demolition | C10: N&P | D10: Wildcat | E10: Rapid Removal
A11: 03A | B11: Concrete / CMU | C11: Victory | D11: De Celis | E11: Proshell
A12: 05A | B12: Structural Steel | C12: Suncor | D12: VMI | E12: Steel Fabricators
A13: 06F | B13: Millwork | C13: Borgzinner | D13: JC Wood | E13: Premier Architectural
A14: 07D | B14: Roofing | C14: Campany | D14: Crown | E14: Assurance
A15: 08C | B15: Glass and Glazing | C15: Performance | D15: A.Christian | E15: A.Crystal
A16: 09A | B16: Stucco | C16: Dorado | D16: Welch | E16: Lion
A17: 09B | B17: Drywall / Framing | C17: Dorado | D17: Everlast | E17: K&S
A18: 09E | B18: Tile | C18: Concolidated | D18: Jack Walsh | E18: O'Neil
A19: 09F | B19: Flooring: Carpet and Resilient Flooring | C19: Concolidated | D19: Jack Walsh | E19: O'Neil
A20: 09I | B20: Painting | C20: Dorado | D20: Phoenix | E20: Talbot
... A29: 31A | B29: Sitework | C29: American Engineering | D29: BiG D | E29: Princeland
A30: 32E | B30: Synthetic Fields | C30: Fast Dry | D30: Papico

Sheet Manpower
A1: IBIS
A2: STAFFING SCHEDULE
A3: YEAR | C3: 2026 | K3: 2027 | W3: 2028
A4: MONTHS | C4: MAY | D4: JUN | E4: JULY | F4: AUG | G4: SEPT | H4: OCT | I4: NOV | J4: DEC | K4: JAN | L4: FEB | M4: MAR | N4: APR | O4: MAY | P4: JUN | Q4: JULY | R4: AUG | S4: SEP | T4: OCT | U4: NOV | V4: DEC | W4: JAN | X4: FEB | Y4: MAR | Z4: APR | AA4: MAY | AB4: JUN | AD4: AUG | AF4: SEP
C5: 1 | D5: =C5+1 -> 2 | E5: =D5+1 -> 3 | F5: =E5+1 -> 4 | G5: =F5+1 -> 5 | H5: =G5+1 -> 6 | I5: =H5+1 -> 7 | J5: 8 | K5: 9 | L5: =K5+1 -> 10 | M5: =L5+1 -> 11 | N5: =M5+1 -> 12 | O5: =N5+1 -> 13 | P5: =O5+1 -> 14 | Q5: =P5+1 -> 15 | R5: =Q5+1 -> 16 | S5: =R5+1 -> 17 | ... V5: =U5+1 -> 20 | W5: 21 | X5: =W5+1 -> 22 | Y5: =X5+1 -> 23 | Z5: =Y5+1 -> 24 | AA5: =Z5+1 -> 25 | AB5: =AA5+1 -> 26 | AC5: 27 | AD5: 28 | AF5: =AD5+1 -> 29
A6: PHASE 1 - CLUBHOUSE PARCEL
A7: CLUBHOUSE
A8: RACQUET ADDITIONS
A9: PHASE 2 - NORTH & CLUBHOUSE PARCEL
A10: NORTH PARCEL - BOCCE, BASKETBALL, & SITE IMPROVEMENTS
A11: NORTH PARCEL - NEW 11,000SF SPA BUILDING
A12: NORTH PARCEL - EXPANSION & RENOVATION EXISTING POA
A13: CLUBHOUSE PARCEL - NEW FITNESS BUILDING/OUTDOOR TERRACE
A14: PHASE 3 - CLUBHOUSE PARCEL
A15: 19TH HOLE RESTAURANT
A16: RENOVATION OF EXISTING FITNESS BUILDING
A17: CLOSEOUT
A18: STAFFING | AE18: AVERAGE | AG18: Average
A19: PRESIDENT - LUX RESIDENTIAL | B19: N/A | AE19: =SUM(C19:AD19)/$AD$5 -> 0 | AG19: 0
A20: PROJECT EXECUTIVE | B20: Art | C20: 0.2 | D20: 0.2 | E20: 0.2 | F20: 0.2 | G20: 0.2 | H20: 0.2 | I20: 0.2 | J20: 0.2 | K20: 0.2 | L20: 0.2 | M20: 0.2 | N20: 0.2 | O20: 0.2 | P20: 0.2 | Q20: 0.2 | R20: 0.2 | S20: 0.2 | T20: 0.2 | U20: 0.2 | V20: 0.2 | W20: 0.2 | X20: 0.2 | Y20: 0.2 | Z20: 0.2 | AA20: 0.2 | AB20: 0.2 | AC20: 0.2 | AD20: 0.2 | AE20: =SUM(C20:AD20)/$AD$5 -> 0.2 | AF20: 0 | AG20: =(AF20) -> 0
A21: SENIOR PROJECT MANAGER | AE21: =SUM(C21:AD21)/$AD$5 -> 0 | AG21: =(AF21) -> 0
A22: PROJECT MANAGER | B22: Dave Rawdon | C22: 0.5 | D22: 0.5 | E22: 0.5 | F22: 0.5 | G22: 0.5 | H22: 0.5 | I22: 1 | J22: 1 | K22: 1 | L22: 1 | M22: 1 | N22: 1 | O22: 1 | P22: 1 | Q22: 1 | R22: 1 | S22: 1 | T22: 1 | U22: 1 | V22: 1 | W22: 1 | X22: 1 | Y22: 1 | Z22: 1 | AA22: 1 | AB22: 1 | AC22: 1 | AD22: 1 | AE22: =SUM(C22:AD22)/$AD$5 -> 0.89285714 | AF22: 1 | AG22: =(AF22) -> 1
A23: ASSISTANT PROJECT MANAGER | B23: TBD | AE23: =SUM(C23:AD23)/$AD$5 -> 0 | AG23: =(AF23) -> 0
A24: PROJECT ADMIN | B24: TBD | C24: 0.5 | D24: 0.5 | E24: 0.5 | F24: 0.5 | G24: 0.5 | H24: 0.5 | I24: 1 | J24: 1 | K24: 1 | L24: 1 | M24: 1 | N24: 1 | O24: 1 | P24: 1 | Q24: 1 | R24: 1 | S24: 1 | T24: 1 | U24: 1 | V24: 1 | W24: 1 | X24: 1 | Y24: 1 | Z24: 1 | AA24: 1 | AB24: 1 | AC24: 1 | AD24: 1 | AE24: =SUM(C24:AD24)/$AD$5 -> 0.89285714 | AF24: 1 | AG24: =(AF24) -> 1
A25: SUPERINTENDENT - LEVEL 2 | B25: Brad | C25: 1 | D25: 1 | E25: 1 | F25: 1 | G25: 1 | H25: 1 | I25: 1 | J25: 1 | K25: 1 | L25: 1 | M25: 1 | N25: 1 | O25: 1 | P25: 1 | Q25: 1 | R25: 1 | S25: 1 | T25: 1 | U25: 1 | V25: 1 | W25: 1 | X25: 1 | Y25: 1 | Z25: 1 | AA25: 1 | AB25: 1 | AC25: 1 | AD25: 1 | AE25: =SUM(C25:AD25)/$AD$5 -> 1 | AF25: 1 | AG25: =(AF25) -> 1
A26: SUPERINTENDENT - LEVEL 1 | B26: TBD | K26: 1 | L26: 1 | M26: 1 | N26: 1 | O26: 1 | P26: 1 | Q26: 1 | R26: 1 | S26: 1 | T26: 1 | U26: 1 | V26: 1 | W26: 1 | X26: 1 | AE26: =SUM(C26:AD26)/$AD$5 -> 0.5 | AG26: =(AF26) -> 0
A27: ASSISTANT SUPERINTENDENT | B27: TBD | C27: 1 | D27: 1 | E27: 1 | F27: 1 | G27: 1 | H27: 1 | I27: 1 | J27: 1 | K27: 1 | L27: 1 | M27: 1 | N27: 1 | O27: 1 | P27: 1 | Q27: 1 | R27: 1 | S27: 1 | T27: 1 | U27: 1 | V27: 1 | W27: 1 | X27: 1 | Y27: 1 | Z27: 1 | AA27: 1 | AB27: 1 | AC27: 1 | AD27: 1 | AE27: =SUM(C27:AD27)/$AD$5 -> 1 | AF27: 1 | AG27: =(AF27) -> 1
A28: ASSISTANT SUPERINTENDENT | B28: TBD | K28: 1 | L28: 1 | M28: 1 | N28: 1 | O28: 1 | P28: 1 | Q28: 1 | R28: 1 | S28: 1 | T28: 1 | U28: 1 | V28: 1 | W28: 1 | X28: 1 | AE28: =SUM(C28:AD28)/$AD$5 -> 0.5 | AG28: =(AF28) -> 0
A29: Quality Control | B29: TBD | C29: 0.2 | D29: 0.2 | E29: 0.2 | F29: 0.2 | G29: 0.2 | H29: 0.2 | I29: 0.2 | J29: 0.2 | K29: 0.2 | L29: 0.2 | M29: 0.2 | N29: 0.2 | O29: 0.2 | P29: 0.2 | Q29: 0.2 | R29: 0.2 | S29: 0.2 | T29: 0.2 | U29: 0.2 | V29: 0.2 | W29: 0.2 | X29: 0.2 | Y29: 0.2 | Z29: 0.2 | AA29: 0.2 | AB29: 0.2 | AC29: 0.2 | AD29: 0.2 | AE29: =SUM(C29:AD29)/$AD$5 -> 0.2 | AF29: 0 | AG29: =(AF29) -> 0
A30: General Super | B30: TBD | AE30: =SUM(C30:AD30)/$AD$5 -> 0 | AG30: =(AF30) -> 0
A31: Safety | B31: TBD | C31: 0.2 | D31: 0.2 | E31: 0.2 | F31: 0.2 | G31: 0.2 | H31: 0.2 | I31: 0.2 | J31: 0.2 | K31: 0.2 | L31: 0.2 | M31: 0.2 | N31: 0.2 | O31: 0.2 | P31: 0.2 | Q31: 0.2 | R31: 0.2 | S31: 0.2 | T31: 0.2 | U31: 0.2 | V31: 0.2 | W31: 0.2 | X31: 0.2 | Y31: 0.2 | Z31: 0.2 | AA31: 0.2 | AB31: 0.2 | AC31: 0.2 | AD31: 0.2 | AE31: =SUM(C31:AD31)/$AD$5 -> 0.2 | AF31: 0 | AG31: =(AF31) -> 0
A32: ACCOUNTING | B32: TBD | C32: 0.2 | D32: 0.2 | E32: 0.2 | F32: 0.2 | G32: 0.2 | H32: 0.2 | I32: 0.2 | J32: 0.2 | K32: 0.2 | L32: 0.2 | M32: 0.2 | N32: 0.2 | O32: 0.2 | P32: 0.2 | Q32: 0.2 | R32: 0.2 | S32: 0.2 | T32: 0.2 | U32: 0.2 | V32: 0.2 | W32: 0.2 | X32: 0.2 | Y32: 0.2 | Z32: 0.2 | AA32: 0.2 | AB32: 0.2 | AC32: 0.2 | AD32: 0.2 | AE32: =SUM(C32:AD32)/$AD$5 -> 0.2 | AF32: 0.2 | AG32: =(AF32) -> 0.2
A33: Scheduling Consultant w/ weekly updates | B33: TBD | AE33: =SUM(C33:AD33)/$AD$5 -> 0 | AG33: =(AF33) -> 0
A34: FOREMAN | B34: Job Cost | AE34: =SUM(C34:AD34)/$AD$5 -> 0 | AG34: =(AF34) -> 0
A35: CARPENTER | B35: Job Cost | AE35: =SUM(C35:AD35)/$AD$5 -> 0 | AG35: =(AF35) -> 0
A36: LABORER | B36: Job Cost | AE36: =SUM(C36:AD36)/$AD$5 -> 0 | AG36: =(AF36) -> 0
AE37: =SUM(C37:AD37)/$AD$5 -> 0 | AG37: =(AF37) -> 0

Sheet GCs & GRs
A1: Contract Reference | B1: General Condition Ref. | C1: ='Area Calculations'!B4 -> The Club at Ibis Conceptual Estimate
C3: Construction | F3: Activity | H3: Start | I3: Finish | J3: Days | K3: Weeks | L3: Months | M3: % Time | N3: Remarks | Q3: Demo to building pad
F4: Construction | H4: 46143 | I4: 46996 | J4: =SUM(I4-H4) -> 853 | K4: =SUM(J4/7) -> 121.85714 | L4: =SUM(J4/30) -> 28.433333 | Q4: Activity | S4: Start | T4: Finish | U4: Days | V4: Weeks | W4: Months | Z4: Per RFP Schedule
F5: Close Out | H5: 46997 | I5: 47026 | J5: =SUM(I5-H5) -> 29 | K5: =SUM(J5/7) -> 4.1428571 | L5: =SUM(J5/30) -> 0.96666667 | Q5: Construction | S5: 0 | T5: 0 | U5: =SUM(T5-S5) -> 0 | V5: =SUM(U5/7) -> 0 | W5: =SUM(U5/30) -> 0
F6: General Conditions | H6: General Req. - Field Office | J6: General Req. | L6: Total | Q6: Building
C7: Description | D7: Qty. | E7: U | F7: Unit | G7: Const. | H7: Unit | I7: General | J7: Unit | K7: General | O7: LABOR RATE FY 2025 *Updated 09.26.24 | P7: LABOR RATE (MIAMI/FT. LAUDERDALE) | Q7: Activity | S7: Start | T7: Finish | U7: Days | V7: Weeks | W7: Months | X7: LABOR RATE (MF CENTRAL FLORIDA)
F8: Cost | G8: Cond. | H8: Cost | I8: Req. | J8: Cost | K8: Req. | Q8: Construction | S8: 0 | T8: 0 | U8: =SUM(T8-S8) -> 0 | V8: =SUM(U8/7) -> 0 | W8: =SUM(U8/30) -> 0
C9: Field Labor - Construction | L9: =SUM(L10:L27) -> 2897709.5
C10: Project Executive | D10: =$K$4 -> 121.85714 | E10: wks | F10: =(O10*40)*M10 -> 1488.3724 | G10: =SUM(D10*F10) -> 181368.8 | L10: =SUM(G10+I10+K10) -> 181368.8 | M10: =Manpower!$AE$20 -> 0.2 | N10: Art | O10: ='Labor Rates Calculator'!G10 -> 186.04654 | P10: 253 | X10: 216
C11: Senior Project Manager | D11: =$K$4 -> 121.85714 | E11: wks | F11: =(O11*40)*M11 -> 0 | G11: =SUM(D11*F11) -> 0 | L11: =SUM(G11+I11+K11) -> 0 | M11: =Manpower!$AE$21 -> 0 | O11: ='Labor Rates Calculator'!G11 -> 154.1962 | P11: 195 | X11: 175
C12: Project Manager - Level 3 | D12: =$K$4 -> 121.85714 | E12: wks | F12: =(O12*40)*M12 -> 5071.5272 | G12: =SUM(D12*F12) -> 618001.82 | L12: =SUM(G12+I12+K12) -> 618001.82 | M12: =Manpower!AE22 -> 0.89285714 | N12: =N13 -> 0 | O12: ='Labor Rates Calculator'!G12 -> 142.00276
C13: Project Manager - Level 2 | D13: =$K$4 -> 121.85714 | E13: wks | F13: =(O13*40)*M13 -> 0 | G13: =SUM(D13*F13) -> 0 | L13: =SUM(G13+I13+K13) -> 0 | M13: 0 | O13: ='Labor Rates Calculator'!G13 -> 129.97082 | P13: 185 | X13: 155
C14: Project Manager - Level 1 | D14: =$K$4 -> 121.85714 | E14: wks | F14: =(O14*40)*M14 -> 0 | G14: =SUM(D14*F14) -> 0 | L14: =SUM(G14+I14+K14) -> 0 | M14: 0 | O14: ='Labor Rates Calculator'!G14 -> 111.23341 | P14: 163 | X14: 130
C15: Project Administator | D15: =$K$4 -> 121.85714 | E15: wks | F15: =(O15*40)*M15 -> 2802.7211 | G15: =SUM(D15*F15) -> 341531.59 | L15: =SUM(G15+I15+K15) -> 341531.59 | M15: =Manpower!$AE$24 -> 0.89285714 | N15: TBD | O15: ='Labor Rates Calculator'!G15 -> 78.476192 | P15: 95 | X15: 65
C16: Project Accountant | D16: =$K$4 -> 121.85714 | E16: wks | F16: =(O16*40)*M16 -> 0 | G16: =SUM(D16*F16) -> 0 | L16: =SUM(G16+I16+K16) -> 0 | M16: 0 | O16: ='Labor Rates Calculator'!G16 -> 101.25585 | P16: 81 | X16: 60
C17: Assistant Project Manager | D17: =$K$4 -> 121.85714 | E17: wks | F17: =(O17*40)*M17 -> 0 | G17: =SUM(D17*F17) -> 0 | L17: =SUM(G17+I17+K17) -> 0 | M17: 0 | O17: ='Labor Rates Calculator'!G17 -> 97.625605 | P17: 118 | X17: 95
C18: Superintendent - Level 3 | D18: =$K$4 -> 121.85714 | E18: wks | F18: =(O18*40)*M18 -> 0 | G18: =SUM(D18*F18) -> 0 | L18: =SUM(G18+I18+K18) -> 0 | M18: 0 | O18: ='Labor Rates Calculator'!G18 -> 155.46735 | P18: 183 | X18: 194
C19: Superintendent - Level 2 | D19: =$K$4 -> 121.85714 | E19: wks | F19: =(O19*40)*M19 -> 5219.9531 | G19: =SUM(D19*F19) -> 636088.57 | L19: =SUM(G19+I19+K19) -> 636088.57 | M19: =Manpower!$AE$25 -> 1 | N19: Brad Harrison | O19: ='Labor Rates Calculator'!G19 -> 130.49883 | P19: 161 | X19: 173
C20: Superintendent - Level 1 | D20: =$K$4 -> 121.85714 | E20: wks | F20: =(O20*40)*M20 -> 2136.1494 | G20: =SUM(D20*F20) -> 260305.06 | L20: =SUM(G20+I20+K20) -> 260305.06 | M20: =Manpower!$AE$26 -> 0.5 | N20: TBD for phase 2 only | O20: ='Labor Rates Calculator'!G20 -> 106.80747 | P20: 161 | X20: 173
C21: Superintendent - Level 1 | D21: =$K$4 -> 121.85714 | E21: wks | F21: =(O21*40)*M21 -> 0 | G21: =SUM(D21*F21) -> 0 | L21: =SUM(G21+I21+K21) -> 0 | M21: 0 | O21: ='Labor Rates Calculator'!G20 -> 106.80747 | P21: 121 | X21: 155
C22: Assistant Superintendent | D22: =$K$4 -> 121.85714 | E22: wks | F22: =(O22*40)*M22 -> 2828.01 | G22: =SUM(D22*F22) -> 344613.22 | L22: =SUM(G22+I22+K22) -> 344613.22 | M22: =Manpower!$AE$27 -> 1 | N22: TBD | O22: ='Labor Rates Calculator'!G21 -> 70.70025 | P22: 84 | X22: 95
C23: Assistant Superintendent | D23: =$K$4 -> 121.85714 | E23: wks | F23: =(O23*40)*M23 -> 1414.005 | G23: =SUM(D23*F23) -> 172306.61 | L23: =SUM(G23+I23+K23) -> 172306.61 | M23: =Manpower!$AE$28 -> 0.5 | N23: TBD for phase 2 only | O23: ='Labor Rates Calculator'!G21 -> 70.70025 | P23: 84 | X23: 95
C24: Quality Control Manager | D24: =$K$4 -> 121.85714 | E24: wks | F24: =(O24*40)*M24 -> 971.68174 | G24: =SUM(D24*F24) -> 118406.36 | L24: =SUM(G24+I24+K24) -> 118406.36 | M24: =Manpower!$AE$29 -> 0.2 | O24: ='Labor Rates Calculator'!G22 -> 121.46022
C25: Foreman | D25: =$K$4 -> 121.85714 | E25: wks | F25: =(O25*40)*M25 -> 0 | G25: =SUM(D25*F25) -> 0 | L25: =SUM(G25+I25+K25) -> 0 | M25: =Manpower!$AE$34 -> 0 | O25: ='Labor Rates Calculator'!G23 -> 49.003574 | P25: 65 | X25: 65
C26: Accounting | D26: =$K$4 -> 121.85714 | E26: wks | F26: =(O26*40)*M26 -> 1094.4532 | G26: =SUM(D26*F26) -> 133366.95 | L26: =SUM(G26+I26+K26) -> 133366.95 | M26: =Manpower!$AE$32 -> 0.2 | O26: ='Labor Rates Calculator'!G24 -> 136.80666 | P26: 80 | X26: 90
C27: Safety Supervisor/Inspector | D27: =K4 -> 121.85714 | E27: wks | F27: =(O27*40)*M27 -> 752.68866 | G27: =SUM(D27*F27) -> 91720.489 | L27: =SUM(G27+I27+K27) -> 91720.489 | M27: =Manpower!$AE$31 -> 0.2 | O27: ='Labor Rates Calculator'!G26 -> 94.086082 | P27: 96 | X27: 96
C28: Field Labor - Close Out | L28: =SUM(L29:L43) -> 93428.985
C29: Project Executive | D29: =$K$5 -> 4.1428571 | E29: wks | F29: =(40*O29)*M29 -> 0 | G29: =SUM(D29*F29) -> 0 | L29: =SUM(G29+I29+K29) -> 0 | M29: =Manpower!$AG$20 -> 0 | O29: =+O10 -> 186.04654 | P29: =+P10 -> 253 | X29: =+X10 -> 216
C30: Senior Project Manager | D30: =$K$5 -> 4.1428571 | E30: wks | F30: =(40*O30)*M30 -> 0 | G30: =SUM(D30*F30) -> 0 | L30: =SUM(G30+I30+K30) -> 0 | M30: =+M11 -> 0 | O30: =+O11 -> 154.1962 | P30: =+P11 -> 195 | X30: =+X11 -> 175
C31: Project Manager - Level 3 | D31: =$K$5 -> 4.1428571 | E31: wks | F31: =(40*O31)*M31 -> 5071.5272 | G31: =SUM(D31*F31) -> 21010.613 | L31: =SUM(G31+I31+K31) -> 21010.613 | M31: =+M12 -> 0.89285714 | O31: =O12 -> 142.00276
C32: Project Manager - Level 2 | D32: =$K$5 -> 4.1428571 | E32: wks | F32: =(40*O32)*M32 -> 5198.8326 | G32: =SUM(D32*F32) -> 21538.021 | L32: =SUM(G32+I32+K32) -> 21538.021 | M32: =Manpower!$AG$22 -> 1 | O32: =+O13 -> 129.97082 | P32: =+P13 -> 185 | X32: =+X13 -> 155
C33: Project Manager - Level 1 | D33: =$K$5 -> 4.1428571 | E33: wks | F33: =(40*O33)*M33 -> 0 | G33: =SUM(D33*F33) -> 0 | L33: =SUM(G33+I33+K33) -> 0 | M33: =+M14 -> 0 | O33: =+O14 -> 111.23341 | P33: =+P14 -> 163 | X33: =+X14 -> 130
C34: Project Administator | D34: =$K$5 -> 4.1428571 | E34: wks | F34: =(40*O34)*M34 -> 3139.0477 | G34: =SUM(D34*F34) -> 13004.626 | L34: =SUM(G34+I34+K34) -> 13004.626 | M34: =Manpower!$AG$24 -> 1 | O34: =+O15 -> 78.476192 | P34: =+P15 -> 95 | X34: =+X15 -> 65
C35: Project Coordinator | D35: =$K$5 -> 4.1428571 | E35: wks | F35: =(40*O35)*M35 -> 0 | G35: =SUM(D35*F35) -> 0 | L35: =SUM(G35+I35+K35) -> 0 | M35: =+M16 -> 0 | O35: =+O16 -> 101.25585 | P35: =+P16 -> 81 | X35: =+X16 -> 60
C36: Assistant Project Manager | D36: =$K$5 -> 4.1428571 | E36: wks | F36: =(40*O36)*M36 -> 0 | G36: =SUM(D36*F36) -> 0 | L36: =SUM(G36+I36+K36) -> 0 | M36: =+M17 -> 0 | O36: =+O17 -> 97.625605 | P36: =+P17 -> 118 | X36: =+X17 -> 95
C37: Superintendent - Level 3 | D37: =$K$5 -> 4.1428571 | E37: wks | F37: =(40*O37)*M37 -> 0 | G37: =SUM(D37*F37) -> 0 | L37: =SUM(G37+I37+K37) -> 0 | M37: =+M18 -> 0 | O37: =+O18 -> 155.46735 | P37: =+P18 -> 183 | X37: =+X18 -> 194
C38: Superintendent - Level 2 | D38: =$K$5 -> 4.1428571 | E38: wks | F38: =(40*O38)*M38 -> 5219.9531 | G38: =SUM(D38*F38) -> 21625.52 | L38: =SUM(G38+I38+K38) -> 21625.52 | M38: =Manpower!$AF$25 -> 1 | O38: =+O19 -> 130.49883 | P38: =+P19 -> 161 | X38: =+X19 -> 173
C39: Superintendent - Level 1 | D39: =$K$5 -> 4.1428571 | E39: wks | F39: =(40*O39)*M39 -> 0 | G39: =SUM(D39*F39) -> 0 | L39: =SUM(G39+I39+K39) -> 0 | M39: =+M21 -> 0 | O39: =+O21 -> 106.80747 | P39: =+P21 -> 121 | X39: =+X21 -> 155
C40: Assistant Superinterndent | D40: =$K$5 -> 4.1428571 | E40: wks | F40: =(40*O40)*M40 -> 2828.01 | G40: =SUM(D40*F40) -> 11716.041 | L40: =SUM(G40+I40+K40) -> 11716.041 | M40: =Manpower!$AF$27 -> 1 | O40: =+O22 -> 70.70025 | P40: =+P22 -> 84 | X40: =+X22 -> 95
C41: Foreman | D41: =$K$5 -> 4.1428571 | E41: wks | F41: =(40*O41)*M41 -> 0 | G41: =SUM(D41*F41) -> 0 | L41: =SUM(G41+I41+K41) -> 0 | M41: =+M25 -> 0 | O41: =+O25 -> 49.003574 | P41: =+P25 -> 65 | X41: =+X25 -> 65
...

Sheet IDS
G1: Hedrick Plug
F2: X | G2: Excluded
B3: BACK TO SUMMARY SHEET | F3: I | G3: Included | H3: Bidder 1 | J3: Bidder 2 | L3: Bidder 3 | N3: Bidder 4 | P3: Bidder5 | R3: Bidder6
A4: Project: | B4: ='Area Calculations'!B4 -> The Club at Ibis Conceptual Estimate | G4: Company | H4: HB Construction
A5: Trade: | B5: IDS Services | G5: Contact | H5: Butch Carmichael
A6: CSI Code: | G6: Phone | H6: 561-225-4868
A7: Date: | G7: Email | H7: <bcarmichael@hedrickbrothers.com>
A8: Adjusted Bid | G8: Adjusted Bid | H8: =I99 -> 50969 | J8: =K99 -> 0 | L8: =M99 -> 0 | N8: =O99 -> 0 | P8: =Q99 -> 0 | R8: =S99 -> 0
A9: BID DOCUMENTS: | C9: Plan/ Spec. Package | D9: QTY | E9: U/M | F9: Unit Cost | G9: Subtotal | H9: Yes/No | I9: Price | J9: Yes/No | K9: Price | L9: Yes/No | M9: Price | N9: Yes/No | O9: Price | P9: Yes/No | Q9: Price | R9: Yes/No | S9: Price
B10: Plans By Division
B11: ='[1]Area Calculations'!J54 -> #VALUE! | C11: P
B12: ='[1]Area Calculations'!J55 -> #VALUE! | C12: P
B13: ='[1]Area Calculations'!J56 -> #VALUE! | C13: P
B14: ='[1]Area Calculations'!J57 -> #VALUE! | C14: P
B15: ='[1]Area Calculations'!J58 -> #VALUE! | C15: P
B16: ='[1]Area Calculations'!J59 -> #VALUE! | C16: P
B17: ='[1]Area Calculations'!J60 -> #VALUE! | C17: P
B18: ='[1]Area Calculations'!J61 -> #VALUE! | C18: P
B19: ='[1]Area Calculations'!J62 -> #VALUE! | C19: P
B21: Survey
B22: OCIP Insurance per exhibit
B23: GENERAL INCLUSIONS
B24: INCLUDES ALL SALES TAX
B25: ALL HOISTING & RIGGING REQUIRED TO COMPLETE THIS SCOPE
B26: PROVIDE P&P BONDS
B27: FLORIDA STATE CONTRACTORS LIC.
B28: GENERAL LIABILITY AND WORKERS COMP. INSURANCE LIMITS
B29: STATE AND LOCAL TAXES
B30: SPECIFIC TRADE SCOPE OF WORK REQUIREMENTS
B31: BASE BID | I31: 50969
B33: Pre-construction Modeling/BIM Execution Plan Meetings
B34: BIM Execution Plan Meeting including writing of BEP
B35: Initial Jobsite Visit
B36: Model Architectural
B37: Model Structural
B38: Model Mechanical/HVAC
B39: Model Plumbing
B40: Model Electrical
B41: Model Fire Sprinkler
B42: Model Civil
...

Sheet Cost Summary (2)
A1: COST ESTIMATE (ROM)
A6: ='Area Calculations'!B4 -> The Club at Ibis Conceptual Estimate
A7: ='Area Calculations'!B5 -> West Palm Beach, FL | E7: Gross (sf) | F7: =J7+N7+R7+W7+Y7+AA7+AE7+AC7 -> 149933 | I7: Gross (sf) | J7: 663 | M7: Gross (sf) | N7: 11678 | Q7: Gross (sf) | R7: =5262+1663+4300 -> 11225 | W7: 91377 | Y7: 8946 | AA7: =5824+223 -> 6047 | AC7: =3436+1206 -> 4642 | AE7: =8101+7254 -> 15355
E8: Build Duration (months) | F8: ='GCs & GRs'!$L$4+'GCs & GRs'!$L$5 -> 29.4 | I8: Build Duration (months) | J8: 10 | M8: Build Duration (months) | N8: 14 | Q8: Build Duration (months) | R8: 12 | W8: 7 | Y8: 5 | AA8: 5 | AC8: 7 | AE8: 7
A9: =NOW() -> 46146.222 | E9: Acres | F9: =J9+N9+R9+W9+Y9+AA9+AE9+AC9 -> 9.77 | I9: Acres | J9: 3.49 | M9: Acres | N9: 2.14 | Q9: Acres | R9: 0.96 | W9: 1.57 | Y9: 0.25 | AA9: 0.17 | AC9: 0.88 | AE9: 0.31
A11: CSI | B11: CSI DESCRIPTION | D11: GRAND TOTAL | E11: $ /GSF | F11: % | H11: Phase 1B Racquet Courts | I11: $ /GSF | J11: % | L11: Phase 2 New Spa Building | M11: $ /GSF | N11: % | P11: Phase 2A New Fitness Build. + Pav. | Q11: $ /GSF | R11: % | T11: Verif | U11: Delta | W11: Phase 1A Interior Club House Renos | Y11: Phase 2 Bocce& Basketball | AA11: Phase 2 POA building | AC11: Phase 3 19th Hole Restaurant | AE11: Phase 3 Reno Existing Fitness Building | AG11: Prev. | AI11: Delta | AK11: Notes
A13: 01A | B13: Surveying | D13: ='Cost Summary'!D13*($D$85+1) -> 61417.558 | H13: ='Cost Summary'!H13*(1+$H$85) -> 16136.035 | L13: ='Cost Summary'!L13*(1+$L$85) -> 32960.02 | M13: =L13/$N$7 -> 2.8224028 | N13: =L13/$L$76 -> 0.0034984029 | P13: ='Cost Summary'!P13*(1+$P$85) -> 12321.503 | Q13: =P13/$R$7 -> 1.097684 | R13: =P13/$P$76 -> 0.001875447 | T13: =H13+L13+P13+W13+Y13+AA13+AC13+AE13 -> 61417.558 | U13: =D13-T13 -> 0 | AI13: =D13-AG13 -> 61417.558
A14: 01B | B14: Materials Testing | C14: By Owner
A15: 02A | B15: Demolition | D15: ='Cost Summary'!D15*($D$85+1) -> 40301.583 | H15: ='Cost Summary'!H15*(1+$H$85) -> 10267.919 | L15: ='Cost Summary'!L15*(1+$L$85) -> 0 | M15: =L15/$N$7 -> 0 | N15: =L15/$L$76 -> 0 | P15: ='Cost Summary'!P15*(1+$P$85) -> 30033.663 | Q15: =P15/$R$7 -> 2.6756048 | R15: =P15/$P$76 -> 0.004571402 | T15: =H15+L15+P15+W15+Y15+AA15+AC15+AE15 -> 40301.583 | U15: =D15-T15 -> 0 | AI15: =D15-AG15 -> 40301.583
A16: 03A | B16: Concrete / CMU | D16: ='Cost Summary'!D16*($D$85+1) -> 1796291.3 | H16: ='Cost Summary'!H16*(1+$H$85) -> 153115.21 | L16: ='Cost Summary'!L16*(1+$L$85) -> 803388.69 | M16: =L16/$N$7 -> 68.795058 | N16: =L16/$L$76 -> 0.085272317 | P16: ='Cost Summary'!P16*(1+$P$85) -> 839787.43 | Q16: =P16/$R$7 -> 74.814025 | R16: =P16/$P$76 -> 0.12782343 | T16: =H16+L16+P16+W16+Y16+AA16+AC16+AE16 -> 1796291.3 | U16: =D16-T16 -> 0 | AI16: =D16-AG16 -> 1796291.3
A17: 05A | B17: Structural Steel | D17: ='Cost Summary'!D17*($D$85+1) -> 640995.28 | H17: ='Cost Summary'!H17*(1+$H$85) -> 304649.16 | L17: ='Cost Summary'!L17*(1+$L$85) -> 296006.04 | M17: =L17/$N$7 -> 25.347323 | N17: =L17/$L$76 -> 0.031418317 | P17: ='Cost Summary'!P17*(1+$P$85) -> 40340.087 | Q17: =P17/$R$7 -> 3.5937717 | R17: =P17/$P$76 -> 0.0061401353 | T17: =H17+L17+P17+W17+Y17+AA17+AC17+AE17 -> 640995.28 | U17: =D17-T17 -> 0 | AI17: =D17-AG17 -> 640995.28
A18: 05C | B18: Misc. Metals | D18: ='Cost Summary'!D18*($D$85+1) -> 108734.7 | H18: ='Cost Summary'!H18*(1+$H$85) -> 1361.5261 | L18: ='Cost Summary'!L18*(1+$L$85) -> 93478.109 | M18: =L18/$N$7 -> 8.0046334 | N18: =L18/$L$76 -> 0.0099218411 | P18: ='Cost Summary'!P18*(1+$P$85) -> 13895.062 | Q18: =P18/$R$7 -> 1.2378674 | R18: =P18/$P$76 -> 0.0021149572 | T18: =H18+L18+P18+W18+Y18+AA18+AC18+AE18 -> 108734.7 | U18: =D18-T18 -> 0 | AI18: =D18-AG18 -> 108734.7
A19: 06A | B19: Rough Carpentry | D19: ='Cost Summary'!D19*($D$85+1) -> 357903.73 | H19: ='Cost Summary'!H19*(1+$H$85) -> 7413.3809 | L19: ='Cost Summary'!L19*(1+$L$85) -> 179577.92 | M19: =L19/$N$7 -> 15.377455 | N19: =L19/$L$76 -> 0.019060544 | P19: ='Cost Summary'!P19*(1+$P$85) -> 170912.43 | Q19: =P19/$R$7 -> 15.226051 | R19: =P19/$P$76 -> 0.026014456 | T19: =H19+L19+P19+W19+Y19+AA19+AC19+AE19 -> 357903.73 | U19: =D19-T19 -> 0 | AI19: =D19-AG19 -> 357903.73
A20: 06C | B20: Wood Trusses | D20: ='Cost Summary'!D20*($D$85+1) -> 42694.008 | H20: ='Cost Summary'!H20*(1+$H$85) -> 7360.0444 | L20: ='Cost Summary'!L20*(1+$L$85) -> 0 | M20: =L20/$N$7 -> 0 | N20: =L20/$L$76 -> 0 | P20: ='Cost Summary'!P20*(1+$P$85) -> 35333.963 | Q20: =P20/$R$7 -> 3.1477918 | R20: =P20/$P$76 -> 0.0053781568 | T20: =H20+L20+P20+W20+Y20+AA20+AC20+AE20 -> 42694.008 | U20: =D20-T20 -> 0 | AI20: =D20-AG20 -> 42694.008
A21: 06F | B21: Millwork | D21: ='Cost Summary'!D21*($D$85+1) -> 518139.73 | H21: ='Cost Summary'!H21*(1+$H$85) -> 15044.555 | L21: ='Cost Summary'!L21*(1+$L$85) -> 437483.18 | M21: =L21/$N$7 -> 37.462166 | N21: =L21/$L$76 -> 0.046434814 | P21: ='Cost Summary'!P21*(1+$P$85) -> 65612.003 | Q21: =P21/$R$7 -> 5.8451673 | R21: =P21/$P$76 -> 0.0099867552 | T21: =H21+L21+P21+W21+Y21+AA21+AC21+AE21 -> 518139.73 | U21: =D21-T21 -> 0 | AI21: =D21-AG21 -> 518139.73
A22: 07D | B22: Roofing | D22: ='Cost Summary'!D22*($D$85+1) -> 527810.06 | H22: ='Cost Summary'!H22*(1+$H$85) -> 23131.568 | L22: ='Cost Summary'!L22*(1+$L$85) -> 357364.66 | M22: =L22/$N$7 -> 30.601529 | N22: =L22/$L$76 -> 0.03793097 | P22: ='Cost Summary'!P22*(1+$P$85) -> 147313.84 | Q22: =P22/$R$7 -> 13.123727 | R22: =P22/$P$76 -> 0.022422532 | T22: =H22+L22+P22+W22+Y22+AA22+AC22+AE22 -> 527810.06 | U22: =D22-T22 -> 0 | AI22: =D22-AG22 -> 527810.06
A23: 07E | B23: Caulking & Waterproofing | D23: ='Cost Summary'!D23*($D$85+1) -> 91072.032 | H23: ='Cost Summary'!H23*(1+$H$85) -> 1701.9076 | L23: ='Cost Summary'!L23*(1+$L$85) -> 49030.038 | M23: =L23/$N$7 -> 4.1984961 | N23: =L23/$L$76 -> 0.0052040874 | P23: ='Cost Summary'!P23*(1+$P$85) -> 40340.087 | Q23: =P23/$R$7 -> 3.5937717 | R23: =P23/$P$76 -> 0.0061401353 | T23: =H23+L23+P23+W23+Y23+AA23+AC23+AE23 -> 91072.032 | U23: =D23-T23 -> 0 | AI23: =D23-AG23 -> 91072.032
A24: 07H | B24: Panelized Exterior Skin | D24: ='Cost Summary'!D24*($D$85+1) -> 232868.14 | H24: ='Cost Summary'!H24*(1+$H$85) -> 0 | L24: ='Cost Summary'!L24*(1+$L$85) -> 232868.14 | M24: =L24/$N$7 -> 19.940755 | N24: =L24/$L$76 -> 0.02471681 | P24: ='Cost Summary'!P24*(1+$P$85) -> 0 | Q24: =P24/$R$7 -> 0 | R24: =P24/$P$76 -> 0 | T24: =H24+L24+P24+W24+Y24+AA24+AC24+AE24 -> 232868.14 | U24: =D24-T24 -> 0 | AI24: =D24-AG24 -> 232868.14
A25: 08A | B25: Doors, Frames, & Hardware | D25: ='Cost Summary'!D25*($D$85+1) -> 170190.76 | H25: ='Cost Summary'!H25*(1+$H$85) -> 3593.7717 | L25: ='Cost Summary'!L25*(1+$L$85) -> 125268.61 | M25: =L25/$N$7 -> 10.726889 | N25: =L25/$L$76 -> 0.013296111 | P25: ='Cost Summary'!P25*(1+$P$85) -> 41328.374 | Q25: =P25/$R$7 -> 3.6818151 | R25: =P25/$P$76 -> 0.0062905618 | T25: =H25+L25+P25+W25+Y25+AA25+AC25+AE25 -> 170190.76 | U25: =D25-T25 -> 0 | AI25: =D25-AG25 -> 170190.76
A26: 08C | B26: Glass and Glazing | D26: ='Cost Summary'!D26*($D$85+1) -> 522770.57 | H26: ='Cost Summary'!H26*(1+$H$85) -> 0 | L26: ='Cost Summary'!L26*(1+$L$85) -> 147488.39 | M26: =L26/$N$7 -> 12.629593 | N26: =L26/$L$76 -> 0.015654536 | P26: ='Cost Summary'!P26*(1+$P$85) -> 375282.18 | Q26: =P26/$R$7 -> 33.432711 | R26: =P26/$P$76 -> 0.057121427 | T26: =H26+L26+P26+W26+Y26+AA26+AC26+AE26 -> 522770.57 | U26: =D26-T26 -> 0 | AI26: =D26-AG26 -> 522770.57
... A41: 13B | B41: Swimming Pools | D41: ='Cost Summary'!D41*($D$85+1) -> 452969.25 | H41: ='Cost Summary'!H41*(1+$H$85) -> 0 | L41: ='Cost Summary'!L41*(1+$L$85) -> 452969.25 | M41: =L41/$N$7 -> 38.788256 | N41: =L41/$L$76 -> 0.048078518 | P41: ='Cost Summary'!P41*(1+$P$85) -> 0 | Q41: =P41/$R$7 -> 0 | R41: =P41/$P$76 -> 0 | T41: =H41+L41+P41+W41+Y41+AA41+AC41+AE41 -> 452969.25 | U41: =D41-T41 -> 0 | AI41: =D41-AG41 -> 452969.25
A42: 13C | B42: Covered Structures | D42: ='Cost Summary'!D42*($D$85+1) -> 303073.03 | H42: ='Cost Summary'!H42*(1+$H$85) -> 303073.03 | L42: ='Cost Summary'!L42*(1+$L$85) -> 0 | M42: =L42/$N$7 -> 0 | N42: =L42/$L$76 -> 0 | P42: ='Cost Summary'!P42*(1+$P$85) -> 0 | T42: =H42+L42+P42+W42+Y42+AA42+AC42+AE42 -> 303073.03 | U42: =D42-T42 -> 0
A43: 14A | B43: Elevators | D43: ='Cost Summary'!D43*($D$85+1) -> 133482.95 | H43: ='Cost Summary'!H43*(1+$H$85) -> 0 | L43: ='Cost Summary'!L43*(1+$L$85) -> 0 | M43: =L43/$N$7 -> 0 | N43: =L43/$L$76 -> 0 | P43: ='Cost Summary'!P43*(1+$P$85) -> 133482.95 | Q43: =P43/$R$7 -> 11.891577 | R43: =P43/$P$76 -> 0.020317342 | T43: =H43+L43+P43+W43+Y43+AA43+AC43+AE43 -> 133482.95 | U43: =D43-T43 -> 0 | AI43: =D43-AG43 -> 133482.95
A44: 21A | B44: Fire Sprinkler | D44: ='Cost Summary'!D44*($D$85+1) -> 85711.968 | H44: ='Cost Summary'!H44*(1+$H$85) -> 3403.8152 | L44: ='Cost Summary'!L44*(1+$L$85) -> 41968.066 | M44: =L44/$N$7 -> 3.5937717 | N44: =L44/$L$76 -> 0.004454524 | P44: ='Cost Summary'!P44*(1+$P$85) -> 40340.087 | Q44: =P44/$R$7 -> 3.5937717 | R44: =P44/$P$76 -> 0.0061401353 | T44: =H44+L44+P44+W44+Y44+AA44+AC44+AE44 -> 85711.968 | U44: =D44-T44 -> 0 | AI44: =D44-AG44 -> 85711.968
A45: 22A | B45: Plumbing | D45: ='Cost Summary'!D45*($D$85+1) -> 545226.51 | H45: ='Cost Summary'!H45*(1+$H$85) -> 35937.717 | L45: ='Cost Summary'!L45*(1+$L$85) -> 338841.33 | M45: =L45/$N$7 -> 29.015356 | N45: =L45/$L$76 -> 0.03596489 | P45: ='Cost Summary'!P45*(1+$P$85) -> 170447.46 | Q45: =P45/$R$7 -> 15.184629 | R45: =P45/$P$76 -> 0.025943683 | T45: =H45+L45+P45+W45+Y45+AA45+AC45+AE45 -> 545226.51 | U45: =D45-T45 -> 0 | AI45: =D45-AG45 -> 545226.51
A46: 23A | B46: HVAC | D46: ='Cost Summary'!D46*($D$85+1) -> 1600768.6 | H46: ='Cost Summary'!H46*(1+$H$85) -> 43125.26 | L46: ='Cost Summary'!L46*(1+$L$85) -> 1117149.6 | M46: =L46/$N$7 -> 95.66275 | N46: =L46/$L$76 -> 0.11857515 | P46: ='Cost Summary'!P46*(1+$P$85) -> 440493.73 | Q46: =P46/$R$7 -> 39.242203 | R46: =P46/$P$76 -> 0.06704723 | T46: =H46+L46+P46+W46+Y46+AA46+AC46+AE46 -> 1600768.6 | U46: =D46-T46 -> 0 | AI46: =D46-AG46 -> 1600768.6
A47: 26A | B47: Electrical & Fire Alarm | D47: ='Cost Summary'!D47*($D$85+1) -> 1730944.9 | H47: ='Cost Summary'!H47*(1+$H$85) -> 285054.76 | L47: ='Cost Summary'!L47*(1+$L$85) -> 743018.2 | M47: =L47/$N$7 -> 63.625467 | N47: =L47/$L$76 -> 0.078864545 | P47: ='Cost Summary'!P47*(1+$P$85) -> 702871.92 | Q47: =P47/$R$7 -> 62.616652 | R47: =P47/$P$76 -> 0.10698362 | T47: =H47+L47+P47+W47+Y47+AA47+AC47+AE47 -> 1730944.9 | U47: =D47-T47 -> 0 | AI47: =D47-AG47 -> 1730944.9
A48: 28A | B48: Low Voltage - Conduits included in Electrical | D48: ='Cost Summary'!D48*($D$85+1) -> 245784.72 | H48: ='Cost Summary'!H48*(1+$H$85) -> 19189.714 | L48: ='Cost Summary'!L48*(1+$L$85) -> 98772.248 | M48: =L48/$N$7 -> 8.4579764 | N48: =L48/$L$76 -> 0.010483765 | P48: ='Cost Summary'!P48*(1+$P$85) -> 127822.76 | Q48: =P48/$R$7 -> 11.387328 | R48: =P48/$P$76 -> 0.019455809 | T48: =H48+L48+P48+W48+Y48+AA48+AC48+AE48 -> 245784.72 | U48: =D48-T48 -> 0 | AI48: =D48-AG48 -> 245784.72
A49: 31A | B49: Sitework | D49: ='Cost Summary'!D49*($D$85+1) -> 2138400.9 | H49: ='Cost Summary'!H49*(1+$H$85) -> 1168780.8 | L49: ='Cost Summary'!L49*(1+$L$85) -> 564735.55 | M49: =L49/$N$7 -> 48.358927 | N49: =L49/$L$76 -> 0.059941483 | P49: ='Cost Summary'!P49*(1+$P$85) -> 404884.59 | Q49: =P49/$R$7 -> 36.069896 | R49: =P49/$P$76 -> 0.061627188 | T49: =H49+L49+P49+W49+Y49+AA49+AC49+AE49 -> 2138400.9 | U49: =D49-T49 -> 0 | AI49: =D49-AG49 -> 2138400.9
A50: 32A | B50: Pavers | D50: ='Cost Summary'!D50*($D$85+1) -> 289576.88 | H50: ='Cost Summary'!H50*(1+$H$85) -> 173204.39 | L50: ='Cost Summary'!L50*(1+$L$85) -> 67702.551 | M50: =L50/$N$7 -> 5.797444 | N50: =L50/$L$76 -> 0.0071860029 | P50: ='Cost Summary'!P50*(1+$P$85) -> 48669.937 | Q50: =P50/$R$7 -> 4.3358518 | R50: =P50/$P$76 -> 0.0074080156 | T50: =H50+L50+P50+W50+Y50+AA50+AC50+AE50 -> 289576.88 | U50: =D50-T50 -> 0 | AI50: =D50-AG50 -> 289576.88
A51: 32B | B51: Site Furnishings | C51: By Owner | AI51: =D51-AG51 -> 0
A52: 32C | B52: Landscape and Irrigation | D52: ='Cost Summary'!D52*($D$85+1) -> 502614.64 | H52: ='Cost Summary'!H52*(1+$H$85) -> 189443.11 | L52: ='Cost Summary'!L52*(1+$L$85) -> 164800.1 | M52: =L52/$N$7 -> 14.112014 | N52: =L52/$L$76 -> 0.017492014 | P52: ='Cost Summary'!P52*(1+$P$85) -> 148371.43 | Q52: =P52/$R$7 -> 13.217945 | R52: =P52/$P$76 -> 0.022583508 | T52: =H52+L52+P52+W52+Y52+AA52+AC52+AE52 -> 502614.64 | U52: =D52-T52 -> 0 | AI52: =D52-AG52 -> 502614.64
A53: 32D | B53: Fencing | D53: ='Cost Summary'!D53*($D$85+1) -> 74006.027 | H53: ='Cost Summary'!H53*(1+$H$85) -> 74006.027 | L53: ='Cost Summary'!L53*(1+$L$85) -> 0 | M53: =L53/$N$7 -> 0 | N53: =L53/$L$76 -> 0 | P53: ='Cost Summary'!P53*(1+$P$85) -> 0 | Q53: =P53/$R$7 -> 0 | R53: =P53/$P$76 -> 0 | T53: =H53+L53+P53+W53+Y53+AA53+AC53+AE53 -> 74006.027 | U53: =D53-T53 -> 0 | AI53: =D53-AG53 -> 74006.027
A54: 32E | B54: Synthetic Fields | D54: ='Cost Summary'!D54*($D$85+1) -> 3029036.1 | H54: ='Cost Summary'!H54*(1+$H$85) -> 3029036.1 | L54: ='Cost Summary'!L54*(1+$L$85) -> 0 | M54: =L54/$N$7 -> 0 | N54: =L54/$L$76 -> 0 | P54: ='Cost Summary'!P54*(1+$P$85) -> 0 | Q54: =P54/$R$7 -> 0 | R54: =P54/$P$76 -> 0 | T54: =H54+L54+P54+W54+Y54+AA54+AC54+AE54 -> 3029036.1 | U54: =D54-T54 -> 0 | AI54: =D54-AG54 -> 3029036.1
B55: Phase 1 Interior Clubhouse Renovations | D55: ='Cost Summary'!D55*($D$85+1) -> 157481.43 | T55: =H55+L55+P55+W55+Y55+AA55+AC55+AE55 -> 157481.43 | U55: =D55-T55 -> 0 | W55: ='Cost Summary'!W55*(1+$W$85) -> 157481.43
B56: Phase 2 Bocce & Basketball | D56: ='Cost Summary'!D56*($D$85+1) -> 1653555 | T56: =H56+L56+P56+W56+Y56+AA56+AC56+AE56 -> 1653555 | U56: =D56-T56 -> 0 | X56: 14901.05 | Y56: ='Cost Summary'!Y56*(1+$Y$85) -> 1653555
B57: Phase 2 POA | D57: ='Cost Summary'!D57*($D$85+1) -> 1968517.9 | T57: =H57+L57+P57+W57+Y57+AA57+AC57+AE57 -> 1968517.9 | U57: =D57-T57 -> 0 | AA57: ='Cost Summary'!AA57*(1+$AA$85) -> 1968517.9
B58: Phase 3 19th Hole | D58: ='Cost Summary'!D58*($D$85+1) -> 1968517.9 | T58: =H58+L58+P58+W58+Y58+AA58+AC58+AE58 -> 1968517.9 | U58: =D58-T58 -> 0 | AC58: ='Cost Summary'!AC58*(1+$AC$85) -> 1968517.9
B59: Phase 3 Existing Fitness Building | D59: ='Cost Summary'!D59*($D$85+1) -> 1811036.4 | T59: =H59+L59+P59+W59+Y59+AA59+AC59+AE59 -> 1811036.4 | U59: =D59-T59 -> 0 | AE59: ='Cost Summary'!AE59*(1+$AE$85) -> 1811036.4
B60: SUB-TOTAL 1 (Cost of Work)Building | D60: =SUM(D13:D59) -> 26101552 | E60: =D60/F7 -> 174.0881 | F60: =D60/$D$76 -> 0.78740721 | H60: =SUM(H13:H54) -> 5950738.8 | L60: =SUM(L13:L54) -> 7418516 | M60: =SUM(M13:M59) -> 635.25569 | N60: =SUM(N13:N54) -> 0.78740721 | P60: =SUM(P13:P54) -> 5173188.2 | Q60: =SUM(Q13:Q54) -> 460.86309 | R60: =SUM(R13:R54) -> 0.78740721 | T60: =H60+L60+P60+W60+Y60+AA60+AC60+AE60 -> 26101552 | U60: =D60-T60 -> 0 | W60: =SUM(W13:W59) -> 157481.43 | Y60: =SUM(Y13:Y59) -> 1653555 | AA60: =SUM(AA13:AA59) -> 1968517.9 | AC60: =SUM(AC13:AC59) -> 1968517.9 | AE60: =SUM(AE13:AE59) -> 1811036.4 | AG60: =SUM(AG13:AG54) -> 0 | AI60: =D60-AG60 -> 26101552
...

Sheet Cost Summary
A1: COST ESTIMATE (ROM)
A6: ='Area Calculations'!B4 -> The Club at Ibis Conceptual Estimate
A7: ='Area Calculations'!B5 -> West Palm Beach, FL | E7: Gross (sf) | F7: =J7+N7+R7+W7+Y7+AA7+AE7+AC7 -> 141141 | I7: Gross (sf) | J7: 663 | M7: Gross (sf) | N7: 11678 | Q7: Gross (sf) | R7: =5262+1663+4300 -> 11225 | W7: 91377 | Y7: 0 | AA7: 6201 | AC7: =3436+1206 -> 4642 | AE7: =8101+7254 -> 15355
E8: Build Duration (months) | F8: ='GCs & GRs'!$L$4+'GCs & GRs'!$L$5 -> 29.4 | I8: Build Duration (months) | J8: 10 | M8: Build Duration (months) | N8: 14 | Q8: Build Duration (months) | R8: 12 | W8: 7 | Y8: 5 | AA8: 5 | AC8: 7 | AE8: 7
A9: =NOW() -> 46146.222 | E9: Acres | F9: =J9+N9+R9+W9+Y9+AA9+AE9+AC9 -> 9.77 | I9: Acres | J9: 3.49 | M9: Acres | N9: 2.14 | Q9: Acres | R9: 0.96 | W9: 1.57 | Y9: 0.25 | AA9: 0.17 | AC9: 0.88 | AE9: 0.31
A11: CSI | B11: CSI DESCRIPTION | D11: GRAND TOTAL | E11: $ /GSF | F11: % | H11: Phase 1B Racquet Courts | I11: $ /GSF | J11: % | L11: Phase 2 New Spa Building | M11: $ /GSF | N11: % | P11: Phase 2A New Fitness Build. + Pav. | Q11: $ /GSF | R11: % | T11: Verif | U11: Delta | W11: Phase 1A Interior Club House Renos | Y11: Phase 2 Bocce& Basketball | AA11: Phase 2 POA building | AC11: Phase 3 19th Hole Restaurant | AE11: Phase 3 Reno Existing Fitness Building | AG11: Prev. | AI11: Delta | AK11: Notes
A13: 01A | B13: Surveying | D13: ='01A Surveying'!B98 -> 59815 | H13: =SUM('01A Surveying'!$I$36:$I$39) -> 15715 | L13: =SUM('01A Surveying'!$I$42:$I$44) -> 32100 | M13: =L13/$N$7 -> 2.7487583 | N13: =L13/$L$76 -> 0.0034071196 | P13: =SUM('01A Surveying'!$I$47:$I$49) -> 12000 | Q13: =P13/$R$7 -> 1.0690423 | R13: =P13/$P$76 -> 0.0018265113 | T13: =H13+L13+P13+W13+Y13+AA13+AC13+AE13 -> 59815 | U13: =D13-T13 -> 0 | AI13: =D13-AG13 -> 59815
A14: 01B | B14: Materials Testing | C14: By Owner
A15: 02A | B15: Demolition | D15: ='02A Demolition'!B100 -> 39250 | H15: =SUM('02A Demolition'!$I$36:$I$41) -> 10000 | L15: =SUM('02A Demolition'!$I$44:$I$45) -> 0 | M15: =L15/$N$7 -> 0 | N15: =L15/$L$76 -> 0 | P15: =SUM('02A Demolition'!$I$48:$I$52) -> 29250 | Q15: =P15/$R$7 -> 2.6057906 | R15: =P15/$P$76 -> 0.0044521212 | T15: =H15+L15+P15+W15+Y15+AA15+AC15+AE15 -> 39250 | U15: =D15-T15 -> 0 | AI15: =D15-AG15 -> 39250
A16: 03A | B16: Concrete / CMU | D16: ='03A Concrete'!B110 -> 1749421 | H16: =SUM('03A Concrete'!$I$36:$I$45) -> 149120 | L16: =SUM('03A Concrete'!$I$48:$I$50) -> 782426 | M16: =L16/$N$7 -> 67 | N16: =L16/$L$76 -> 0.08304732 | P16: =SUM('03A Concrete'!$I$53:$I$57) -> 817875 | Q16: =P16/$R$7 -> 72.861915 | R16: =P16/$P$76 -> 0.12448816 | T16: =H16+L16+P16+W16+Y16+AA16+AC16+AE16 -> 1749421 | U16: =D16-T16 -> 0 | AI16: =D16-AG16 -> 1749421
A17: 05A | B17: Structural Steel | D17: ='05A Structural Steel'!$B$96 -> 624269.9 | H17: =SUM('05A Structural Steel'!$I$36:$I$37) -> 296700 | L17: =SUM('05A Structural Steel'!$I$41:$I$44) -> 288282.4 | M17: =L17/$N$7 -> 24.685939 | N17: =L17/$L$76 -> 0.030598524 | P17: =SUM('05A Structural Steel'!$I$47:$I$48) -> 39287.5 | Q17: =P17/$R$7 -> 3.5 | R17: =P17/$P$76 -> 0.0059799218 | T17: =H17+L17+P17+W17+Y17+AA17+AC17+AE17 -> 624269.9 | U17: =D17-T17 -> 0 | AI17: =D17-AG17 -> 624269.9
A18: 05C | B18: Misc. Metals | D18: ='05C Misc. Metals'!B99 -> 105897.5 | H18: =SUM('05C Misc. Metals'!$I$36:$I$37) -> 1326 | L18: =SUM('05C Misc. Metals'!$I$41:$I$44) -> 91039 | M18: =L18/$N$7 -> 7.7957698 | N18: =L18/$L$76 -> 0.0096629522 | P18: =SUM('05C Misc. Metals'!$I$47:$I$51) -> 13532.5 | Q18: =P18/$R$7 -> 1.2055679 | R18: =P18/$P$76 -> 0.002059772 | T18: =H18+L18+P18+W18+Y18+AA18+AC18+AE18 -> 105897.5 | U18: =D18-T18 -> 0 | AI18: =D18-AG18 -> 105897.5
A19: 06A | B19: Rough Carpentry | D19: ='06A Rough Carpentry'!B103 -> 348565.01 | H19: =SUM('06A Rough Carpentry'!$I$36:$I$40) -> 7219.9447 | L19: =SUM('06A Rough Carpentry'!$I$43:$I$47) -> 174892.23 | M19: =L19/$N$7 -> 14.976214 | N19: =L19/$L$76 -> 0.018563201 | P19: =SUM('06A Rough Carpentry'!$I$50:$I$55) -> 166452.84 | Q19: =P19/$R$7 -> 14.828761 | R19: =P19/$P$76 -> 0.025335665 | T19: =H19+L19+P19+W19+Y19+AA19+AC19+AE19 -> 348565.01 | U19: =D19-T19 -> 0 | AI19: =D19-AG19 -> 348565.01
A20: 06C | B20: Wood Trusses | D20: ='06C Wood Trusses'!$B$94 -> 41580 | H20: =SUM('06C Wood Trusses'!$I$36:$I$38) -> 7168 | L20: =SUM('06C Wood Trusses'!$I$41:$I$42) -> 0 | M20: =L20/$N$7 -> 0 | N20: =L20/$L$76 -> 0 | P20: =SUM('06C Wood Trusses'!$I$45:$I$47) -> 34412 | Q20: =P20/$R$7 -> 3.065657 | R20: =P20/$P$76 -> 0.0052378255 | T20: =H20+L20+P20+W20+Y20+AA20+AC20+AE20 -> 41580 | U20: =D20-T20 -> 0 | AI20: =D20-AG20 -> 41580
A21: 06F | B21: Millwork | D21: ='06F Millwork'!B118 -> 504620 | H21: =SUM('06F Millwork'!$I$36:$I$39) -> 14652 | L21: =SUM('06F Millwork'!$I$42:$I$63) -> 426068 | M21: =L21/$N$7 -> 36.484672 | N21: =L21/$L$76 -> 0.045223198 | P21: =SUM('06F Millwork'!$I$66:$I$71) -> 63900 | Q21: =P21/$R$7 -> 5.6926503 | R21: =P21/$P$76 -> 0.0097261725 | T21: =H21+L21+P21+W21+Y21+AA21+AC21+AE21 -> 504620 | U21: =D21-T21 -> 0 | AI21: =D21-AG21 -> 504620
A22: 07D | B22: Roofing | D22: ='07D Roofing'!B98 -> 514038 | H22: =SUM('07D Roofing'!$I$36:$I$38) -> 22528 | L22: =SUM('07D Roofing'!$I$41:$I$44) -> 348040 | M22: =L22/$N$7 -> 29.803048 | N22: =L22/$L$76 -> 0.036941244 | P22: =SUM('07D Roofing'!$I$47:$I$51) -> 143470 | Q22: =P22/$R$7 -> 12.781292 | R22: =P22/$P$76 -> 0.021837464 | T22: =H22+L22+P22+W22+Y22+AA22+AC22+AE22 -> 514038 | U22: =D22-T22 -> 0 | AI22: =D22-AG22 -> 514038
A23: 07E | B23: Caulking & Waterproofing | D23: ='07E Caulking & Waterproofing'!B118 -> 88695.705 | H23: =SUM('07E Caulking & Waterproofing'!$I$36:$I$38) -> 1657.5 | L23: =SUM('07E Caulking & Waterproofing'!$I$41:$I$44) -> 47750.705 | M23: =L23/$N$7 -> 4.0889455 | N23: =L23/$L$76 -> 0.005068298 | P23: =SUM('07E Caulking & Waterproofing'!$I$47:$I$49) -> 39287.5 | Q23: =P23/$R$7 -> 3.5 | R23: =P23/$P$76 -> 0.0059799218 | T23: =H23+L23+P23+W23+Y23+AA23+AC23+AE23 -> 88695.705 | U23: =D23-T23 -> 0 | AI23: =D23-AG23 -> 88695.705
A24: 07H | B24: Panelized Exterior Skin | D24: ='07H Panelized Exterior Skin'!$B$93 -> 226791.95 | H24: =SUM('07H Panelized Exterior Skin'!$I$36:$I$37) -> 0 | L24: =SUM('07H Panelized Exterior Skin'!$I$40:$I$42) -> 226791.95 | M24: =L24/$N$7 -> 19.420444 | N24: =L24/$L$76 -> 0.024071879 | P24: =SUM('07H Panelized Exterior Skin'!$I$45:$I$46) -> 0 | Q24: =P24/$R$7 -> 0 | R24: =P24/$P$76 -> 0 | T24: =H24+L24+P24+W24+Y24+AA24+AC24+AE24 -> 226791.95 | U24: =D24-T24 -> 0 | AI24: =D24-AG24 -> 226791.95
A25: 08A | B25: Doors, Frames, & Hardware | D25: ='08A Doors, Frames, & Hardware'!B95 -> 165750 | H25: =SUM('08A Doors, Frames, & Hardware'!$I$36:$I$38) -> 3500 | L25: =SUM('08A Doors, Frames, & Hardware'!$I$41:$I$43) -> 122000 | M25: =L25/$N$7 -> 10.446994 | N25: =L25/$L$76 -> 0.012949177 | P25: =SUM('08A Doors, Frames, & Hardware'!$I$46:$I$48) -> 40250 | Q25: =P25/$R$7 -> 3.5857461 | R25: =P25/$P$76 -> 0.0061264232 | T25: =H25+L25+P25+W25+Y25+AA25+AC25+AE25 -> 165750 | U25: =D25-T25 -> 0 | AI25: =D25-AG25 -> 165750
A26: 08C | B26: Glass and Glazing | D26: ='08C Glass and Glazing'!B95 -> 509130 | H26: =SUM('08C Glass and Glazing'!$I$36:$I$37) -> 0 | L26: =SUM('08C Glass and Glazing'!$I$40:$I$42) -> 143640 | M26: =L26/$N$7 -> 12.300051 | N26: =L26/$L$76 -> 0.015246064 | P26: =SUM('08C Glass and Glazing'!$I$45:$I$48) -> 365490 | Q26: =P26/$R$7 -> 32.560356 | R26: =P26/$P$76 -> 0.055630967 | T26: =H26+L26+P26+W26+Y26+AA26+AC26+AE26 -> 509130 | U26: =D26-T26 -> 0 | AI26: =D26-AG26 -> 509130
A27: 09A | B27: Stucco | D27: ='09A Stucco'!B97 -> 123408 | H27: =SUM('09A Stucco'!$I$36:$I$38) -> 9570 | L27: =SUM('09A Stucco'!$I$41:$I$43) -> 55848 | M27: =L27/$N$7 -> 4.7823257 | N27: =L27/$L$76 -> 0.0059277513 | P27: =SUM('09A Stucco'!$I$46:$I$50) -> 57990 | Q27: =P27/$R$7 -> 5.166147 | R27: =P27/$P$76 -> 0.0088266157 | T27: =H27+L27+P27+W27+Y27+AA27+AC27+AE27 -> 123408 | U27: =D27-T27 -> 0 | AI27: =D27-AG27 -> 123408
A28: 09B | B28: Drywall / Framing | D28: ='09B Drywall&Framing'!B95 -> 819230 | H28: =SUM('09B Drywall&Framing'!$I$36:$I$38) -> 19890 | L28: =SUM('09B Drywall&Framing'!$I$41:$I$43) -> 350340 | M28: =L28/$N$7 -> 30 | N28: =L28/$L$76 -> 0.037185367 | P28: =SUM('09B Drywall&Framing'!$I$46:$I$48) -> 449000 | Q28: =P28/$R$7 -> 40 | R28: =P28/$P$76 -> 0.068341963 | T28: =H28+L28+P28+W28+Y28+AA28+AC28+AE28 -> 819230 | U28: =D28-T28 -> 0 | AI28: =D28-AG28 -> 819230
A29: 09C | B29: Acoustical Ceilings | D29: ='09C Acoustical Ceilings'!B100 -> 32632 | H29: =SUM('09C Acoustical Ceilings'!$I$36:$I$37) -> 0 | L29: =SUM('09C Acoustical Ceilings'!$I$40:$I$48) -> 6376 | M29: =L29/$N$7 -> 0.5459839 | N29: =L29/$L$76 -> 0.00067675373 | P29: =SUM('09C Acoustical Ceilings'!$I$51:$I$53) -> 26256 | Q29: =P29/$R$7 -> 2.3390646 | R29: =P29/$P$76 -> 0.0039964066 | T29: =H29+L29+P29+W29+Y29+AA29+AC29+AE29 -> 32632 | U29: =D29-T29 -> 0 | AI29: =D29-AG29 -> 32632
A30: 09D | B30: Acoustical Treatment | D30: ='09D Acoustical Treatment'!$B$93 -> 25350 | H30: =SUM('09D Acoustical Treatment'!$I$35:$I$36) -> 0 | L30: =SUM('09D Acoustical Treatment'!$I$39:$I$40) -> 0 | M30: =L30/$N$7 -> 0 | N30: =L30/$L$76 -> 0 | P30: =SUM('09D Acoustical Treatment'!$I$43:$I$46) -> 25350 | Q30: =P30/$R$7 -> 2.2583519 | R30: =P30/$P$76 -> 0.003858505 | T30: =H30+L30+P30+W30+Y30+AA30+AC30+AE30 -> 25350 | U30: =D30-T30 -> 0 | AI30: =D30-AG30 -> 25350
A31: 09E | B31: Tile | D31: ='09E Tile & Stone'!B171 -> 449937.24 | H31: =SUM('09E Tile & Stone'!$I$41:$I$45) -> 34990.34 | L31: =SUM('09E Tile & Stone'!$I$48:$I$97) -> 316959.88 | M31: =L31/$N$7 -> 27.141624 | N31: =L31/$L$76 -> 0.033642375 | P31: =SUM('09E Tile & Stone'!$I$100:$I$124) -> 97987.02 | Q31: =P31/$R$7 -> 8.7293559 | R31: =P31/$P$76 -> 0.014914533 | T31: =H31+L31+P31+W31+Y31+AA31+AC31+AE31 -> 449937.24 | U31: =D31-T31 -> 0 | AI31: =D31-AG31 -> 449937.24
A32: 09F | B32: Flooring: Carpet and Resilient Flooring | D32: ='09F Carpet & Resilient'!B154 -> 53846.2 | H32: =SUM('09F Carpet & Resilient'!$I$40:$I$41) -> 0 | L32: =SUM('09F Carpet & Resilient'!$I$44:$I$65) -> 47876.58 | M32: =L32/$N$7 -> 4.0997243 | N32: =L32/$L$76 -> 0.0050816584 | P32: =SUM('09F Carpet & Resilient'!$I$68:$I$78) -> 5969.62 | Q32: =P32/$R$7 -> 0.5318147 | R32: =P32/$P$76 -> 0.00090863151 | T32: =H32+L32+P32+W32+Y32+AA32+AC32+AE32 -> 53846.2 | U32: =D32-T32 -> 0 | AI32: =D32-AG32 -> 53846.2
A33: 09G | B33: Sports Flooring | D33: ='09G Sports Flooring'!$B$103 -> 121912.25 | H33: =SUM('09G Sports Flooring'!$I$35:$I$36) -> 0 | L33: =SUM('09G Sports Flooring'!$I$39:$I$40) -> 0 | M33: =L33/$N$7 -> 0 | N33: =L33/$L$76 -> 0 | P33: =SUM('09G Sports Flooring'!$I$43:$I$47) -> 121912.25 | Q33: =P33/$R$7 -> 10.86078 | R33: =P33/$P$76 -> 0.018556175 | T33: =H33+L33+P33+W33+Y33+AA33+AC33+AE33 -> 121912.25 | U33: =D33-T33 -> 0 | AI33: =D33-AG33 -> 121912.25
A34: 09I | B34: Painting | D34: ='09I Painting'!B126 -> 227808.6 | H34: =SUM('09I Painting'!$I$41:$I$44) -> 2270.5 | L34: =SUM('09I Painting'!$I$47:$I$69) -> 121879.77 | M34: =L34/$N$7 -> 10.436699 | N34: =L34/$L$76 -> 0.012936416 | P34: =SUM('09I Painting'!$I$72:$I$78) -> 103658.33 | Q34: =P34/$R$7 -> 9.2345954 | R34: =P34/$P$76 -> 0.015777759 | T34: =H34+L34+P34+W34+Y34+AA34+AC34+AE34 -> 227808.6 | U34: =D34-T34 -> 0 | AI34: =D34-AG34 -> 227808.6
A35: 10A | B35: Signage | D35: ='10A Signage'!B95 -> 23403 | H35: =SUM('10A Signage'!$I$36:$I$38) -> 500 | L35: =SUM('10A Signage'!$I$41:$I$43) -> 11678 | M35: =L35/$N$7 -> 1 | N35: =L35/$L$76 -> 0.0012395122 | P35: =SUM('10A Signage'!$I$46:$I$48) -> 11225 | Q35: =P35/$R$7 -> 1 | R35: =P35/$P$76 -> 0.0017085491 | T35: =H35+L35+P35+W35+Y35+AA35+AC35+AE35 -> 23403 | U35: =D35-T35 -> 0 | AI35: =D35-AG35 -> 23403
A36: 10B | B36: Operable Partitions | D36: ='10B Operable Partitions'!$B$94 -> 190000 | H36: =SUM('10B Operable Partitions'!$I$36:$I$37) -> 0 | L36: =SUM('10B Operable Partitions'!$I$40:$I$41) -> 0 | M36: =L36/$N$7 -> 0 | N36: =L36/$L$76 -> 0 | P36: =SUM('10B Operable Partitions'!$I$44:$I$47) -> 190000 | Q36: =P36/$R$7 -> 16.926503 | R36: =P36/$P$76 -> 0.028919762 | T36: =H36+L36+P36+W36+Y36+AA36+AC36+AE36 -> 190000 | U36: =D36-T36 -> 0 | AI36: =D36-AG36 -> 190000
A37: 10C | B37: Toilet Partitions & Bathroom Accessories | D37: ='10C Toilet Partitions & Bath'!B102 -> 28590 | H37: =SUM('10C Toilet Partitions & Bath'!$I$36:$I$41) -> 12730 | L37: =SUM('10C Toilet Partitions & Bath'!$I$44:$I$48) -> 10820 | M37: =L37/$N$7 -> 0.92652852 | N37: =L37/$L$76 -> 0.0011484434 | P37: =SUM('10C Toilet Partitions & Bath'!$I$51:$I$55) -> 5040 | Q37: =P37/$R$7 -> 0.44899777 | R37: =P37/$P$76 -> 0.00076713473 | T37: =H37+L37+P37+W37+Y37+AA37+AC37+AE37 -> 28590 | U37: =D37-T37 -> 0 | AI37: =D37-AG37 -> 28590
A38: 10F | B38: Lockers | D38: ='10F Lockers'!B95 -> 104000 | H38: =SUM('10F Lockers'!$I$36:$I$37) -> 0 | L38: =SUM('10F Lockers'!$I$40:$I$43) -> 104000 | M38: =L38/$N$7 -> 8.9056345 | N38: =L38/$L$76 -> 0.011038643 | P38: =SUM('10F Lockers'!$I$46:$I$47) -> 0 | Q38: =P38/$R$7 -> 0 | R38: =P38/$P$76 -> 0 | T38: =H38+L38+P38+W38+Y38+AA38+AC38+AE38 -> 104000 | U38: =D38-T38 -> 0 | AI38: =D38-AG38 -> 104000
A39: 10I | B39: Fire Extinguishers& Cabinets | D39: ='10I Fire Extinguishers&Cabinet'!B95 -> 5180.6 | H39: =SUM('10I Fire Extinguishers&Cabinet'!$I$36:$I$38) -> 600 | L39: =SUM('10I Fire Extinguishers&Cabinet'!$I$41:$I$43) -> 2335.6 | M39: =L39/$N$7 -> 0.2 | N39: =L39/$L$76 -> 0.00024790245 | P39: =SUM('10I Fire Extinguishers&Cabinet'!$I$46:$I$48) -> 2245 | Q39: =P39/$R$7 -> 0.2 | R39: =P39/$P$76 -> 0.00034170981 | T39: =H39+L39+P39+W39+Y39+AA39+AC39+AE39 -> 5180.6 | U39: =D39-T39 -> 0 | AI39: =D39-AG39 -> 5180.6
A40: 12A | B40: Window Treatment | D40: ='12A Window Treatment'!B94 -> 34354.5 | H40: =SUM('12A Window Treatment'!$I$36:$I$37) -> 0 | L40: =SUM('12A Window Treatment'!$I$40:$I$42) -> 17517 | M40: =L40/$N$7 -> 1.5 | N40: =L40/$L$76 -> 0.0018592684 | P40: =SUM('12A Window Treatment'!$I$45:$I$47) -> 16837.5 | Q40: =P40/$R$7 -> 1.5 | R40: =P40/$P$76 -> 0.0025628236 | T40: =H40+L40+P40+W40+Y40+AA40+AC40+AE40 -> 34354.5 | U40: =D40-T40 -> 0 | AI40: =D40-AG40 -> 34354.5
A41: 13B | B41: Swimming Pools | D41: ='13B Swimming Pools'!$B$112 -> 441150 | H41: 0 | L41: =SUM('13B Swimming Pools'!$I$37:$I$42) -> 441150 | M41: =L41/$N$7 -> 37.77616 | N41: =L41/$L$76 -> 0.046824013 | P41: =SUM('13B Swimming Pools'!$I$45:$I$46) -> 0 | Q41: =P41/$R$7 -> 0 | R41: =P41/$P$76 -> 0 | T41: =H41+L41+P41+W41+Y41+AA41+AC41+AE41 -> 441150 | U41: =D41-T41 -> 0 | AI41: =D41-AG41 -> 441150
A42: 13C | B42: Covered Structures | C42: By Owner | D42: ='13C Awnings,Canopies,Shutters'!$B$97 -> 295165 | H42: =SUM('13C Awnings,Canopies,Shutters'!$I$36:$I$42) -> 295165 | L42: =SUM('13C Awnings,Canopies,Shutters'!$I$45:$I$46) -> 0 | M42: =L42/$N$7 -> 0 | N42: =L42/$L$76 -> 0 | P42: =SUM('13C Awnings,Canopies,Shutters'!$I$49:$I$50) -> 0 | T42: =H42+L42+P42+W42+Y42+AA42+AC42+AE42 -> 295165 | U42: =D42-T42 -> 0
A43: 14A | B43: Elevators | D43: ='14A Elevators'!$B$92 -> 130000 | H43: =SUM('14A Elevators'!$I$35:$I$36) -> 0 | L43: =SUM('14A Elevators'!$I$39:$I$40) -> 0 | M43: =L43/$N$7 -> 0 | N43: =L43/$L$76 -> 0 | P43: =SUM('14A Elevators'!$I$43:$I$45) -> 130000 | Q43: =P43/$R$7 -> 11.581292 | R43: =P43/$P$76 -> 0.019787205 | T43: =H43+L43+P43+W43+Y43+AA43+AC43+AE43 -> 130000 | U43: =D43-T43 -> 0 | AI43: =D43-AG43 -> 130000
A44: 21A | B44: Fire Sprinkler | D44: ='21A Fire Sprinkler'!B95 -> 83475.5 | H44: =SUM('21A Fire Sprinkler'!$I$36:$I$38) -> 3315 | L44: =SUM('21A Fire Sprinkler'!$I$41:$I$43) -> 40873 | M44: =L44/$N$7 -> 3.5 | N44: =L44/$L$76 -> 0.0043382929 | P44: =SUM('21A Fire Sprinkler'!$I$46:$I$48) -> 39287.5 | Q44: =P44/$R$7 -> 3.5 | R44: =P44/$P$76 -> 0.0059799218 | T44: =H44+L44+P44+W44+Y44+AA44+AC44+AE44 -> 83475.5 | U44: =D44-T44 -> 0 | AI44: =D44-AG44 -> 83475.5
A45: 22A | B45: Plumbing | D45: ='22A Plumbing '!B109 -> 531000 | H45: =SUM('22A Plumbing '!$I$46:$I$50) -> 35000 | L45: =SUM('22A Plumbing '!$I$53:$I$55) -> 330000 | M45: =L45/$N$7 -> 28.258263 | N45: =L45/$L$76 -> 0.035026464 | P45: =SUM('22A Plumbing '!$I$58:$I$61) -> 166000 | Q45: =P45/$R$7 -> 14.788419 | R45: =P45/$P$76 -> 0.025266739 | T45: =H45+L45+P45+W45+Y45+AA45+AC45+AE45 -> 531000 | U45: =D45-T45 -> 0 | AI45: =D45-AG45 -> 531000
A46: 23A | B46: HVAC | D46: ='23A HVAC'!B114 -> 1559000 | H46: =SUM('23A HVAC'!$I$45:$I$47) -> 42000 | L46: =SUM('23A HVAC'!$I$50:$I$57) -> 1088000 | M46: =L46/$N$7 -> 93.166638 | N46: =L46/$L$76 -> 0.11548119 | P46: =SUM('23A HVAC'!$I$60:$I$67) -> 429000 | Q46: =P46/$R$7 -> 38.218263 | R46: =P46/$P$76 -> 0.065297778 | T46: =H46+L46+P46+W46+Y46+AA46+AC46+AE46 -> 1559000 | U46: =D46-T46 -> 0 | AI46: =D46-AG46 -> 1559000
...

Sheet 01A Surveying
G1: Hedrick Plug
F2: X | G2: Excluded
B3: BACK TO SUMMARY SHEET | F3: I | G3: Included | H3: Bidder 1 | J3: Bidder 2 | L3: Bidder 3 | N3: Bidder 4 | P3: Bidder5 | R3: Bidder6
A4: Project: | B4: ='Area Calculations'!B4 -> The Club at Ibis Conceptual Estimate | G4: Company
A5: Trade: | B5: Surveying | G5: Contact
A6: CSI Code: | B6: 01A | G6: Phone
A7: Date: | G7: Email
A8: Adjusted Bid | G8: Adjusted Bid | H8: =I62 -> 59815 | J8: =K62 -> 0 | L8: =M62 -> 0 | N8: =O62 -> 0 | P8: =Q62 -> 0 | R8: =S62 -> 0
A9: BID DOCUMENTS: | C9: Plan/ Spec. Package | D9: QTY | E9: U/M | F9: Unit Cost | G9: Subtotal | H9: Yes/No | I9: Price | J9: Yes/No | K9: Price | L9: Yes/No | M9: Price | N9: Yes/No | O9: Price | P9: Yes/No | Q9: Price | R9: Yes/No | S9: Price
B10: Plans By Division
B11: ='Area Calculations'!M62 -> Architectural Drawings by | C11: P
B12: ='Area Calculations'!M63 -> Structural Drawings by | C12: P
B13: ='Area Calculations'!M64 -> MEP FA FP Drawings by | C13: P
B14: ='Area Calculations'!M65 -> Civil Drawings by | C14: P
B15: ='Area Calculations'!M66 -> Land scape Drawings by | C15: P
B16: ='Area Calculations'!M67 -> Kitchen Drawings by | C16: P
B17: ='Area Calculations'!M68 -> Storefront Designer by | C17: P
