Workbook
Name FCP: 'Bond Calculator'!$B$7

Sheet AREA CALC's
B2: PROJECT AREA CALCULATIONS
E3: BU1 | F3: =E5/E4 -> 0.81350556 | G3: BU2 | H3: =G5/G4 -> 0.80223005 | I3: BU3 | J3: =I5/I4 -> 0.7880291 | K3: BU4 | L3: =K5/K4 -> #VALUE! | M3: Total
B4: Alton Hilltop Gardens | D4: Gross (sf) | E4: =M33 -> 236436 | F4: Gross (sf) | G4: =M56 -> 193538 | H4: Gross (sf) | I4: =M79 -> 84190.8 | J4: Gross (sf) | K4: Gross R (sf) | L4: =E4+G4+I4 -> 514164.8 | M4: Gross T (sf) | N4: =E4+G4+I4+N9+T4 -> 538483.8 | O4: FORMULA OFF GCS | Q4: EFF. | R4: =N5/N4 -> 0.76873028 | S4: Garage (sf) | T4: =M107 -> 9669 | V4: =N4-T4-N9 -> 514164.8
B5: Construction Design | D5: RSF | E5: =F33 -> 192342 | F5: RSF | G5: =F56 -> 155262 | H5: RSF | I5: =F79 -> 66344.8 | J5: RSF | K5: =F99+K99 -> 0 | M5: RSF | N5: =E5+G5+I5 -> 413948.8
D6: Units | E6: =D33 -> 177 | F6: Units | G6: =D56 -> 176 | H6: Units | I6: =D79 -> 79 | J6: Units | K6: =D99 -> 0 | M6: Units | N6: =E6+G6+I6 -> 432
D7: Bedrooms | E7: =H33 -> 348 | F7: Bedrooms | G7: =H56 -> 224 | H7: Bedrooms | I7: =H79 -> 84 | J7: Bedrooms | K7: =H99 -> 0 | M7: Site (acres) | N7: 17.64 | O7: FORMULA OFF GCS
D8: Bathrooms | E8: =G33 -> 318 | F8: Bathrooms | G8: =G56 -> 224 | H8: Bathrooms | I8: =G79 -> 84 | J8: Bathrooms | K8: =G99 -> 0 | M8: Parking Spaces
B9: =NOW() -> 46143.711 | M9: CH | N9: =M115 -> 14650 | O9: FORMULA OFF GCS
C10: 01 Bid set | M10: Duration (months) | N10: 20 | O10: FORMULA OFF GCS
B11: BU Type l | C11: Stories | D11: QTY.
C12: 5 | D12: 3
A13: l. | B13: Levels | C13: Units | D13: QTY. | E13: SF | F13: RSF | G13: Bathrooms | H13: Bedrooms | I13: BOH | J13: Corridors | K13: Balconies | L13: Stairs | M13: Gross SF | N13: %
C14: Building Type l | R14: St1 | T14: =D15+D38+D61 -> 28
B15: =$C$12 -> 5 | C15: St1 | D15: 0 | E15: 598 | F15: =D15*E15 -> 0 | G15: =D15*1 -> 0 | H15: =D15*1 -> 0 | M15: =F15 -> 0 | N15: =M15/$E$4 -> 0 | R15: A1 - 1 bed/1 bath | T15: =D16+D39+D62 -> 128
B16: =$C$12 -> 5 | C16: A1 - 1 bed/1 bath | D16: =12*$D$12 -> 36 | E16: 757 | F16: =D16*E16 -> 27252 | G16: =D16*1 -> 36 | H16: =D16*1 -> 36 | M16: =F16 -> 27252 | N16: =M16/$E$4 -> 0.11526164 | R16: A2 - 1 bed/1 bath | T16: =D17+D40+D63 -> 30
B17: =$C$12 -> 5 | C17: A2 - 1 bed/1 bath | D17: =0*$D$12 -> 0 | E17: 796 | F17: =D17*E17 -> 0 | G17: =D17*1 -> 0 | H17: =D17*1 -> 0 | M17: =F17 -> 0 | N17: =M17/$E$4 -> 0 | R17: B1- M - 1 bed/1 bath | T17: =D18+D41+D64 -> 12
B18: =$C$12 -> 5 | C18: B1- M - 1 bed/1 bath | D18: =0*$D$12 -> 0 | E18: 840 | F18: =D18*E18 -> 0 | G18: =D18*1 -> 0 | H18: =D18*1 -> 0 | M18: =F18 -> 0 | N18: =M18/$E$4 -> 0 | R18: B2- M - 1 bed/1 bath | T18: =D19+D42+D65 -> 5
B19: =$C$12 -> 5 | C19: B2- M - 1 bed/1 bath | D19: =0*$D$12 -> 0 | E19: 844 | F19: =D19*E19 -> 0 | G19: =D19*1 -> 0 | H19: =D19*1 -> 0 | M19: =F19 -> 0 | N19: =M19/$E$4 -> 0 | R19: A3(C2 MOD) - 1 bed/1 bath | T19: =D20+D43+D66 -> 2
B20: =$C$12 -> 5 | C20: A3(C2 MOD) - 1 bed/1 bath | D20: =0*$D$12 -> 0 | E20: 779 | F20: =D20*E20 -> 0 | G20: =D20*1 -> 0 | H20: =D20*1 -> 0 | M20: =F20 -> 0 | N20: =M20/$E$4 -> 0 | R20: B1 | T20: =D21+D44+D67 -> 18
B21: =$C$12 -> 5 | C21: B1 | D21: =0*$D$12 -> 0 | E21: 986 | F21: =D21*E21 -> 0 | G21: =D21*1 -> 0 | H21: =D21*1 -> 0 | M21: =F21 -> 0 | N21: =M21/$E$4 -> 0 | R21: B2 | T21: =D22+D45+D68 -> 9
B22: =$C$12 -> 5 | C22: B2 | D22: =0*$D$12 -> 0 | E22: 993 | F22: =D22*E22 -> 0 | G22: =D22*1 -> 0 | H22: =D22*1 -> 0 | M22: =F22 -> 0 | N22: =M22/$E$4 -> 0 | R22: B2.1 | T22: =D23+D46+D69 -> 6
B23: =$C$12 -> 5 | C23: B2.1 | D23: =0*$D$12 -> 0 | E23: 1014 | F23: =D23*E23 -> 0 | G23: =D23*1 -> 0 | H23: =D23*1 -> 0 | M23: =F23 -> 0 | N23: =M23/$E$4 -> 0 | R23: C1 - 2 bed/2 bath | T23: =D24+D47+D70 -> 44
B24: =$C$12 -> 5 | C24: C1 - 2 bed/2 bath | D24: =13*$D$12 -> 39 | E24: 1148 | F24: =D24*E24 -> 44772 | G24: =D24*2 -> 78 | H24: =D24*2 -> 78 | M24: =F24 -> 44772 | N24: =M24/$E$4 -> 0.18936203 | R24: C2 - 2 bed/2 bath | T24: =D25+D48+D71 -> 50
B25: =$C$12 -> 5 | C25: C2 - 2 bed/2 bath | D25: =14*$D$12 -> 42 | E25: 1054 | F25: =D25*E25 -> 44268 | G25: =D25*2 -> 84 | H25: =D25*2 -> 84 | M25: =F25 -> 44268 | N25: =M25/$E$4 -> 0.18723037 | R25: C3 2 bd /2 bath | T25: =D26+D49+D72 -> 70
B26: =$C$12 -> 5 | C26: C3 2 bd /2 bath | D26: =10*$D$12 -> 30 | E26: 1214 | F26: =D26*E26 -> 36420 | G26: =D26*2 -> 60 | H26: =D26*2 -> 60 | M26: =F26 -> 36420 | N26: =M26/$E$4 -> 0.15403746 | R26: D1 - 3 bed/2 bath | T26: =D27+D50+D73 -> 30
B27: =$C$12 -> 5 | C27: D1 - 3 bed/2 bath | D27: 30 | E27: 1321 | F27: =D27*E27 -> 39630 | G27: =D27*2 -> 60 | H27: =D27*3 -> 90 | M27: =F27 -> 39630 | N27: =M27/$E$4 -> 0.16761407 | T27: =SUM(T14:T26) -> 432
B28: =$C$12 -> 5 | C28: Corridors | J28: =7151*3 -> 21453 | M28: =J28 -> 21453 | N28: =M28/$E$4 -> 0.090734913
B29: =$C$12 -> 5 | C29: Balconies | K29: =3866*3 -> 11598 | M29: =K29 -> 11598 | N29: =M29/$E$4 -> 0.049053444
B30: =$C$12 -> 5 | C30: Amenity/ Maintenance | I30: =1682*3 -> 5046 | L30: 0 | M30: =I30 -> 5046 | N30: =M30/$E$4 -> 0.021341928
B31: =$C$12 -> 5 | C31: Stair Towers | L31: =1999*3 -> 5997 | M31: =L31 -> 5997 | N31: =M31/$E$4 -> 0.025364158
B33: TOTALs | D33: =SUM(D15:D27) -> 177 | F33: =SUM(F15:F27) -> 192342 | G33: =SUM(G15:G27) -> 318 | H33: =SUM(H15:H27) -> 348 | I33: =SUM(I30:I32) -> 5046 | J33: =SUM(J28:J32) -> 21453 | K33: =SUM(K14:K31) -> 11598 | L33: =SUM(L30:L32) -> 5997 | M33: =SUM(M15:M32) -> 236436 | N33: =SUM(N15:N31) -> 1 | O33: Av | P33: =F33/D33 -> 1086.678 | Q33: AV ALL | R33: =N5/432 -> 958.21481
B34: BU Type ll | C34: Stories | D34: QTY.
C35: 5 | D35: 2
A36: ll. | B36: Levels | C36: Units | D36: QTY. | E36: SF | F36: RSF | G36: Bathrooms | H36: Bedrooms | I36: BOH | J36: Corridors | K36: Balconies | L36: Stairs | M36: Gross SF | N36: %
C37: Building type ll
B38: =$C$35 -> 5 | C38: St1 | D38: =9*$D$35 -> 18 | E38: 598 | F38: =D38*E38 -> 10764 | G38: =D38*1 -> 18 | H38: =D38*1 -> 18 | M38: =F38 -> 10764 | N38: =M38/$G$4 -> 0.055616985
B39: =$C$35 -> 5 | C39: A1 - 1 bed/1 bath | D39: =34*$D$35 -> 68 | E39: 757 | F39: =D39*E39 -> 51476 | G39: =D39*1 -> 68 | H39: =D39*1 -> 68 | M39: =F39 -> 51476 | N39: =M39/$G$4 -> 0.26597361
B40: =$C$35 -> 5 | C40: A2 - 1 bed/1 bath | D40: =10*$D$35 -> 20 | E40: 796 | F40: =D40*E40 -> 15920 | G40: =D40*1 -> 20 | H40: =D40*1 -> 20 | M40: =F40 -> 15920 | N40: =M40/$G$4 -> 0.082257748
B41: =$C$35 -> 5 | C41: B1 M - 1 bed/1 bath | D41: =4*$D$35 -> 8 | E41: 840 | F41: =D41*E41 -> 6720 | G41: =D41*1 -> 8 | H41: =D41*1 -> 8 | M41: =F41 -> 6720 | N41: =M41/$G$4 -> 0.034721863
B42: =$C$35 -> 5 | C42: B2 M - 1 bed/1 bath | D42: =0*$D$35 -> 0 | E42: 844 | F42: =D42*E42 -> 0 | G42: =D42*1 -> 0 | H42: =D42*1 -> 0 | M42: =F42 -> 0 | N42: =M42/$G$4 -> 0
...

Sheet Project Difference
B5: Item | C5: Multi Family | D5: Hilltop | E5: Dofference | F5: Notes
B6: Eartwork Import Fill to the required elevation | C6: 1600000 | D6: 2850000 | E6: =D6-C6 -> 1250000 | F6: Increase of 24,000 CY for import for pads and increase of 45,000 CY to balance the whole site
B7: LiFt station | C7: 275000 | D7: 875000 | E7: =D7-C7 -> 600000 | F7: Usr Muncibility lift Stataion ILO private one
B8: Landscaping (17.5 Acres) | C8: =17.5*75000 -> 1312500 | D8: 2700000 | E8: =D8-C8 -> 1387500 | F8: Usualy the price /Acre is around 65k-75k/ Acre Hilltop is 155k/Acre
B9: Facades decorative items | C9: 150000 | D9: 600000 | E9: =D9-C9 -> 450000 | F9: Adde decorative columns, brakets and Rafter tails
E10: =SUM(E6:E9) -> 3687500

Sheet Bond Calculator
A1: Hedrick Brothers Construction
A3: Performance / Payment Bond | E3: Performance / Payment Bond
A4: General Construction | E4: Design Build
A5: 42888 | E5: 42053
B6: =IF(B13>500000,500000,B13) -> 500000 | C6: 0.0091 | D6: =B6*C6 -> 4550 | F6: 0 | G6: 0.01875 | H6: =SUM(F6*G6) -> 0
B7: =IF(B13<2500000,(B13-B6),IF(B13>B6,2000000,0)) -> 1720594.1 | C7: 0.00725 | D7: =B7*C7 -> 12474.307 | F7: 0 | G7: 0.015 | H7: =SUM(F7*G7) -> 0
B8: =IF(B13<5000000,MAX(0,B13-2500000),IF(B13>2500000,2500000)) -> 0 | C8: 0.0063 | D8: =B8*C8 -> 0 | F8: 0 | G8: 0.01125 | H8: =SUM(F8*G8) -> 0
B9: =IF(B13<7500000,MAX(0,B13-5000000),IF(B13>7500000,2500000,0)) -> 0 | C9: 0.00555 | D9: =B9*C9 -> 0 | F9: 0 | G9: 0.009 | H9: =SUM(F9*G9) -> 0
B10: =IF(B13<7500000,MAX(0,B13-7500000),IF(B13>7500000,(B13-7500000))) -> 0 | C10: 0.0051 | D10: =B10*C10 -> 0 | F10: 0 | G10: 0.00825 | H10: =SUM(F10*G10) -> 0
D11: =B11*C11 -> 0 | F11: 0 | G11: 0.0075 | H11: =SUM(F11*G11) -> 0
A12: Contract Value | B12: ='Cost Summary'!#REF! -> #REF! | C12: Total | D12: =SUM(D6:D11) -> 17024.307 | E12: Contract Value | F12: =SUM(F6+F7+F8+F9+F10+F11) -> 0 | G12: Total | H12: =SUM(H6:H11) -> 0
A13: Cost Summary | B13: 2220594.1 | D13: =SUM(D12/B12) -> #REF! | H13: =SUM(H12/F12) -> #DIV/0!
B14: =B12-B13 -> #REF!

Sheet Allowances
A7: ='AREA CALC''s'!B4 -> Alton Hilltop Gardens | C7: ='AREA CALC''s'!B4 -> Alton Hilltop Gardens
A9: Allowances
A10: =TODAY() -> 46143
A12: NO. | B12: DESCRIPTION | C12: VALUE
A13: 1 | B13: Allowance for Luxer System | C13: 50000
A14: =A13+1 -> 2 | B14: Allowance for Elevator cab finishes | C14: 10000
A15: =A14+1 -> 3 | B15: Allowance for Clubhouse glass railing (MTL-1 and GL-1 as per ID) | C15: 46000
A16: =A15+1 -> 4 | B16: Allowance for Plumbing Fixtures
A17: =A16+1 -> 5 | B17: Allowance Electrical Fixtures | C17: ='32C Landscape and Irrigation'!I52 -> 0
A18: =A17+1 -> 6 | B18: Allowance for Electrical and Water Consumptions (Allowance) | C18: 25000
A19: =A18+1 -> 7 | B19: Allowance for unit entry wall tile | C19: ='09E Flooring'!S61 -> 93268
A20: =A19+1 -> 8 | B20: Allowance for 30 steel bollards | C20: 0
A21: =A20+1 -> 9 | B21: Allowance for clubhouse roller shades | C21: ='12A Window Treatment'!I47 -> 12000
A22: =A21+1 -> 10 | C22: 0
A23: =A22+1 -> 11 | B23: Total | C23: =SUM(C13:C22) -> 236268
B25: *All ALLOWANCES IN BID TABS MUST BE LISTED HERE

Sheet Alternates
A7: ='AREA CALC''s'!B4 -> Alton Hilltop Gardens
A9: Alternates | D9: Markup | E9: 1.125
A10: =TODAY() -> 46143
A12: NO. | B12: DESCRIPTION | C12: VALUE
A13: ALT. #1
A14: ALT. #2 | B14: Add for aluminum abrasive stair nosings | C14: ='05C Misc. Metals'!#REF!*E9 -> #REF!
A15: ALT. #3 | B15: Add Corrosion -Resistance Coating for the HVAC equipment | C15: =-'23A HVAC'!Q103*E9 -> 327375
A16: ALT. #4 | B16: Add for intumescent paint at steel columns ilo drywall wrap | C16: =(-'09B Drywall&Framing'!I57+'07C Fireproofing&Firestopping'!I63)*E9 -> 153664.88
A17: ALT. #5 | B17: Add Vibro replacement | C17: =380000*E9 -> 427500
A18: ALT. #6 | B18: Add for Solarban | C18: ='08C Glass and Glazing'!K140*E9 -> 279000
A19: ALT. #7 | B19: Add for original Caesarstone Calacatta Nuvo 3151 | C19: =E9*340315.37 -> 382854.79
B20: Total | C20: =SUM(C13:C19) -> #REF!

Sheet GCS&GRS HB
A1: Contract Reference | B1: General Condition Ref. | C1: Miami Vertice Riverside
C3: Construction | F3: Activity | H3: Start | I3: Finish | J3: Days | K3: Weeks | L3: Months | M3: % Time | N3: Remarks | Q3: Demo to building pad
F4: Construction | H4: 46049 | I4: 46671 | J4: =SUM(I4-H4) -> 622 | K4: =SUM(J4/7) -> 88.857143 | L4: =SUM(J4/30) -> 20.733333 | Q4: Activity | S4: Start | T4: Finish | U4: Days | V4: Weeks | W4: Months
F5: Close Out | H5: 46675 | I5: 46736 | J5: =SUM(I5-H5) -> 61 | K5: =SUM(J5/7) -> 8.7142857 | L5: =SUM(J5/30) -> 2.0333333 | Q5: Construction | S5: 0 | T5: 0 | U5: =SUM(T5-S5) -> 0 | V5: =SUM(U5/7) -> 0 | W5: =SUM(U5/30) -> 0
F6: General Conditions | H6: General Req. - Field Office | J6: General Req. | L6: Total | Q6: Building
C7: Description | D7: Qty. | E7: U | F7: Unit | G7: Const. | H7: Unit | I7: General | J7: Unit | K7: General | O7: LABOR RATE FY 2025 *Updated 09.26.24 | P7: LABOR RATE (MIAMI/FT. LAUDERDALE) | Q7: Activity | S7: Start | T7: Finish | U7: Days | V7: Weeks | W7: Months | X7: LABOR RATE (MF CENTRAL FLORIDA)
F8: Cost | G8: Cond. | H8: Cost | I8: Req. | J8: Cost | K8: Req. | Q8: Construction | S8: 0 | T8: 0 | U8: =SUM(T8-S8) -> 0 | V8: =SUM(U8/7) -> 0 | W8: =SUM(U8/30) -> 0
C9: Field Labor - Construction | L9: =SUM(L10:L27) -> 3833360.5
C10: Project Executive | D10: =$K$4 -> 88.857143 | E10: wks | F10: =(O10*40)*M10 -> 2809.6181 | G10: =SUM(D10*F10) -> 249654.64 | L10: =SUM(G10+I10+K10) -> 249654.64 | M10: 0.33 | O10: 212.84986 | P10: 253 | X10: 216
C11: Senior Project Manager | D11: =$K$4 -> 88.857143 | E11: wks | F11: =(O11*40)*M11 -> 0 | G11: =SUM(D11*F11) -> 0 | L11: =SUM(G11+I11+K11) -> 0 | M11: 0 | O11: 176.41091 | P11: 195 | X11: 175
C12: Project Manager - Level 3 | D12: =$K$4 -> 88.857143 | E12: wks | F12: =(O12*40)*M12 -> 6520 | G12: =SUM(D12*F12) -> 579348.57 | L12: =SUM(G12+I12+K12) -> 579348.57 | M12: 1 | O12: 163 | P12: 185 | X12: 155
C13: Project Manager - Level 2 | D13: =$K$4 -> 88.857143 | E13: wks | F13: =(O13*40)*M13 -> 0 | G13: =SUM(D13*F13) -> 0 | L13: =SUM(G13+I13+K13) -> 0 | M13: 0 | O13: 148.69542 | P13: 185 | X13: 155
C14: Project Manager - Level 1 | D14: =$K$4 -> 88.857143 | E14: wks | F14: =(O14*40)*M14 -> 2545.1713 | G14: =SUM(D14*F14) -> 226156.65 | L14: =SUM(G14+I14+K14) -> 226156.65 | M14: 0.5 | O14: 127.25857 | P14: 163 | X14: 130
C15: Project Administator | D15: =$K$4 -> 88.857143 | E15: wks | F15: =(O15*40)*M15 -> 3591.2833 | G15: =SUM(D15*F15) -> 319111.18 | L15: =SUM(G15+I15+K15) -> 319111.18 | M15: 1 | O15: 89.782084 | P15: 95 | X15: 65
C16: Project Accountant | D16: =$K$4 -> 88.857143 | E16: wks | F16: =(O16*40)*M16 -> 0 | G16: =SUM(D16*F16) -> 0 | L16: =SUM(G16+I16+K16) -> 0 | M16: 0 | O16: 115.84355 | P16: 81 | X16: 60
C17: Assistant Project Manager | D17: =$K$4 -> 88.857143 | E17: wks | F17: =(O17*40)*M17 -> 4467.6124 | G17: =SUM(D17*F17) -> 396979.28 | L17: =SUM(G17+I17+K17) -> 396979.28 | M17: 1 | O17: 111.69031 | P17: 118 | X17: 95
C18: General Superintendent | D18: =$K$4 -> 88.857143 | E18: wks | F18: =(O18*40)*M18 -> 563.37467 | G18: =SUM(D18*F18) -> 50059.864 | L18: =SUM(G18+I18+K18) -> 50059.864 | M18: 0.08 | O18: 176.05459
C19: Superintendent - Level 3 | D19: =$K$4 -> 88.857143 | E19: wks | F19: =(O19*40)*M19 -> 5335.9555 | G19: =SUM(D19*F19) -> 474137.76 | L19: =SUM(G19+I19+K19) -> 474137.76 | M19: 0.75 | O19: 177.86518 | P19: 183 | X19: 194
C20: Superintendent - Level 2 | D20: =$K$4 -> 88.857143 | E20: wks | F20: =(O20*40)*M20 -> 5971.9803 | G20: =SUM(D20*F20) -> 530653.1 | L20: =SUM(G20+I20+K20) -> 530653.1 | M20: 1 | O20: 149.29951 | P20: 161 | X20: 173
C21: Superintendent - Level 1 | D21: =$K$4 -> 88.857143 | E21: wks | F21: =(O21*40)*M21 -> 4887.7994 | G21: =SUM(D21*F21) -> 434315.89 | L21: =SUM(G21+I21+K21) -> 434315.89 | M21: 1 | O21: 122.19499 | P21: 121 | X21: 155
C22: Assistant Superinterndent | D22: =$K$4 -> 88.857143 | E22: wks | F22: =(O22*40)*M22 -> 2426.5764 | G22: =SUM(D22*F22) -> 215618.64 | L22: =SUM(G22+I22+K22) -> 215618.64 | M22: 0.75 | O22: 80.885879 | P22: 84 | X22: 95
C23: Quality Control Manager | D23: =$K$4 -> 88.857143 | E23: wks | F23: =(O23*40)*M23 -> 1111.6698 | G23: =SUM(D23*F23) -> 98779.801 | L23: =SUM(G23+I23+K23) -> 98779.801 | M23: 0.2 | O23: 138.95872
C24: Foreman | D24: =$K$4 -> 88.857143 | E24: wks | F24: =(O24*40)*M24 -> 0 | G24: =SUM(D24*F24) -> 0 | L24: =SUM(G24+I24+K24) -> 0 | M24: 0 | O24: 56.06341 | P24: 65 | X24: 65
C25: Accounting | D25: =$K$4 -> 88.857143 | E25: wks | F25: =(O25*40)*M25 -> 939.09653 | G25: =SUM(D25*F25) -> 83445.435 | L25: =SUM(G25+I25+K25) -> 83445.435 | M25: 0.15 | O25: 156.51609 | P25: 80 | X25: 90
C26: VDC Manager | D26: =$K$4 -> 88.857143 | E26: wks | F26: =(O26*40)*M26 -> 1109.4485 | G26: =SUM(D26*F26) -> 98582.425 | L26: =SUM(G26+I26+K26) -> 98582.425 | M26: 0.2 | O26: 138.68106 | P26: 101 | X26: 101
C27: Safety Supervisor/Inspector | D27: =K4 -> 88.857143 | E27: wks | F27: =(O27*40)*M27 -> 861.12686 | G27: =SUM(D27*F27) -> 76517.272 | L27: =SUM(G27+I27+K27) -> 76517.272 | M27: 0.2 | O27: 107.64086 | P27: 96 | X27: 96
C28: Field Labor - Close Out | L28: =SUM(L29:L43) -> 312545.3
C29: Project Executive | D29: =$K$5 -> 8.7142857 | E29: wks | F29: =(40*O29)*M29 -> 2128.4986 | G29: =SUM(D29*F29) -> 18548.345 | L29: =SUM(G29+I29+K29) -> 18548.345 | M29: 0.25 | O29: =+O10 -> 212.84986 | P29: =+P10 -> 253 | X29: =+X10 -> 216
C30: Senior Project Manager | D30: =$K$5 -> 8.7142857 | E30: wks | F30: =(40*O30)*M30 -> 7056.4365 | G30: =SUM(D30*F30) -> 61491.804 | L30: =SUM(G30+I30+K30) -> 61491.804 | M30: 1 | O30: =+O11 -> 176.41091 | P30: =+P11 -> 195 | X30: =+X11 -> 175
C31: Project Manager - Level 2 | D31: =$K$5 -> 8.7142857 | E31: wks | F31: =(40*O31)*M31 -> 0 | G31: =SUM(D31*F31) -> 0 | L31: =SUM(G31+I31+K31) -> 0 | M31: 0 | O31: =+O13 -> 148.69542 | P31: =+P13 -> 185 | X31: =+X13 -> 155
C32: Project Manager - Level 1 | D32: =$K$5 -> 8.7142857 | E32: wks | F32: =(40*O32)*M32 -> 0 | G32: =SUM(D32*F32) -> 0 | L32: =SUM(G32+I32+K32) -> 0 | M32: 0 | O32: =+O14 -> 127.25857 | P32: =+P14 -> 163 | X32: =+X14 -> 130
C33: Project Administator | D33: =$K$5 -> 8.7142857 | E33: wks | F33: =(40*O33)*M33 -> 3591.2833 | G33: =SUM(D33*F33) -> 31295.469 | L33: =SUM(G33+I33+K33) -> 31295.469 | M33: 1 | O33: =+O15 -> 89.782084 | P33: =+P15 -> 95 | X33: =+X15 -> 65
C34: Project Coordinator | D34: =$K$5 -> 8.7142857 | E34: wks | F34: =(40*O34)*M34 -> 0 | G34: =SUM(D34*F34) -> 0 | L34: =SUM(G34+I34+K34) -> 0 | M34: 0 | O34: =+O16 -> 115.84355 | P34: =+P16 -> 81 | X34: =+X16 -> 60
C35: Assistant Project Manager | D35: =$K$5 -> 8.7142857 | E35: wks | F35: =(40*O35)*M35 -> 4467.6124 | G35: =SUM(D35*F35) -> 38932.051 | L35: =SUM(G35+I35+K35) -> 38932.051 | M35: 1 | O35: =+O17 -> 111.69031 | P35: =+P17 -> 118 | X35: =+X17 -> 95
C36: Superintendent - Level 3 | D36: =$K$5 -> 8.7142857 | E36: wks | F36: =(40*O36)*M36 -> 5335.9555 | G36: =SUM(D36*F36) -> 46499.041 | L36: =SUM(G36+I36+K36) -> 46499.041 | M36: 0.75 | O36: =+O19 -> 177.86518 | P36: =+P19 -> 183 | X36: =+X19 -> 194
C37: Superintendent - Level 2 | D37: =$K$5 -> 8.7142857 | E37: wks | F37: =(40*O37)*M37 -> 5971.9803 | G37: =SUM(D37*F37) -> 52041.542 | L37: =SUM(G37+I37+K37) -> 52041.542 | M37: 1 | O37: =+O20 -> 149.29951 | P37: =+P20 -> 161 | X37: =+X20 -> 173
C38: Superintendent - Level 1 | D38: =$K$5 -> 8.7142857 | E38: wks | F38: =(40*O38)*M38 -> 4887.7994 | G38: =SUM(D38*F38) -> 42593.681 | L38: =SUM(G38+I38+K38) -> 42593.681 | M38: 1 | O38: =+O21 -> 122.19499 | P38: =+P21 -> 121 | X38: =+X21 -> 155
C39: Assistant Superinterndent | D39: =$K$5 -> 8.7142857 | E39: wks | F39: =(40*O39)*M39 -> 0 | G39: =SUM(D39*F39) -> 0 | L39: =SUM(G39+I39+K39) -> 0 | M39: 0 | O39: =+O22 -> 80.885879 | P39: =+P22 -> 84 | X39: =+X22 -> 95
C40: Foreman | D40: =$K$5 -> 8.7142857 | E40: wks | F40: =(40*O40)*M40 -> 0 | G40: =SUM(D40*F40) -> 0 | L40: =SUM(G40+I40+K40) -> 0 | M40: 0 | O40: =+O24 -> 56.06341 | P40: =+P24 -> 65 | X40: =+X24 -> 65
C41: Accounting | D41: =$K$5 -> 8.7142857 | E41: wks | F41: =(40*O41)*M41 -> 1565.1609 | G41: =SUM(D41*F41) -> 13639.259 | L41: =SUM(G41+I41+K41) -> 13639.259 | M41: 0.25 | O41: =+O25 -> 156.51609 | P41: =+P25 -> 80 | X41: =+X25 -> 90
...

Sheet GCs&GRs-1
A1: Contract Reference | B1: General Condition Ref. | C1: Miami Vertice Riverside
C3: Construction | F3: Activity | H3: Start | I3: Finish | J3: Days | K3: Weeks | L3: Months | M3: % Time | N3: Remarks | Q3: Demo to building pad
F4: Construction | H4: 46049 | I4: 46671 | J4: =SUM(I4-H4) -> 622 | K4: =SUM(J4/7) -> 88.857143 | L4: =SUM(J4/30) -> 20.733333 | Q4: Activity | S4: Start | T4: Finish | U4: Days | V4: Weeks | W4: Months
F5: Close Out | H5: 46675 | I5: 46736 | J5: =SUM(I5-H5) -> 61 | K5: =SUM(J5/7) -> 8.7142857 | L5: =SUM(J5/30) -> 2.0333333 | Q5: Construction | S5: 0 | T5: 0 | U5: =SUM(T5-S5) -> 0 | V5: =SUM(U5/7) -> 0 | W5: =SUM(U5/30) -> 0
F6: General Conditions | H6: General Req. - Field Office | J6: General Req. | L6: Total | Q6: Building
C7: Description | D7: Qty. | E7: U | F7: Unit | G7: Const. | H7: Unit | I7: General | J7: Unit | K7: General | O7: LABOR RATE FY 2025 *Updated 09.26.24 | P7: LABOR RATE (MIAMI/FT. LAUDERDALE) | Q7: Activity | S7: Start | T7: Finish | U7: Days | V7: Weeks | W7: Months | X7: LABOR RATE (MF CENTRAL FLORIDA)
F8: Cost | G8: Cond. | H8: Cost | I8: Req. | J8: Cost | K8: Req. | Q8: Construction | S8: 0 | T8: 0 | U8: =SUM(T8-S8) -> 0 | V8: =SUM(U8/7) -> 0 | W8: =SUM(U8/30) -> 0
C9: Field Labor - Construction | L9: =SUM(L10:L26) -> 3567861.4
C10: Project Executive | D10: =$K$4 -> 88.857143 | E10: wks | F10: =(O10*40)*M10 -> 4256.9972 | G10: =SUM(D10*F10) -> 378264.61 | L10: =SUM(G10+I10+K10) -> 378264.61 | M10: 0.5 | O10: 212.84986 | P10: 253 | X10: 216
C11: Senior Project Manager | D11: =$K$4 -> 88.857143 | E11: wks | F11: =(O11*40)*M11 -> 7056.4365 | G11: =SUM(D11*F11) -> 627014.78 | L11: =SUM(G11+I11+K11) -> 627014.78 | M11: 1 | O11: 176.41091 | P11: 195 | X11: 175
C12: Project Manager - Level 2 | D12: =$K$4 -> 88.857143 | E12: wks | F12: =(O12*40)*M12 -> 0 | G12: =SUM(D12*F12) -> 0 | L12: =SUM(G12+I12+K12) -> 0 | M12: 0 | O12: 148.69542 | P12: 185 | X12: 155
C13: Project Manager - Level 1 | D13: =$K$4 -> 88.857143 | E13: wks | F13: =(O13*40)*M13 -> 0 | G13: =SUM(D13*F13) -> 0 | L13: =SUM(G13+I13+K13) -> 0 | M13: 0 | O13: 127.25857 | P13: 163 | X13: 130
C14: Project Administator | D14: =$K$4 -> 88.857143 | E14: wks | F14: =(O14*40)*M14 -> 3591.2833 | G14: =SUM(D14*F14) -> 319111.18 | L14: =SUM(G14+I14+K14) -> 319111.18 | M14: 1 | O14: 89.782084 | P14: 95 | X14: 65
C15: Project Accountant | D15: =$K$4 -> 88.857143 | E15: wks | F15: =(O15*40)*M15 -> 0 | G15: =SUM(D15*F15) -> 0 | L15: =SUM(G15+I15+K15) -> 0 | M15: 0 | O15: 115.84355 | P15: 81 | X15: 60
C16: Assistant Project Manager | D16: =$K$4 -> 88.857143 | E16: wks | F16: =(O16*40)*M16 -> 4467.6124 | G16: =SUM(D16*F16) -> 396979.28 | L16: =SUM(G16+I16+K16) -> 396979.28 | M16: 1 | O16: 111.69031 | P16: 118 | X16: 95
C17: General Superintendent | D17: =$K$4 -> 88.857143 | E17: wks | F17: =(O17*40)*M17 -> 563.37467 | G17: =SUM(D17*F17) -> 50059.864 | L17: =SUM(G17+I17+K17) -> 50059.864 | M17: 0.08 | O17: 176.05459
C18: Superintendent - Level 3 | D18: =$K$4 -> 88.857143 | E18: wks | F18: =(O18*40)*M18 -> 5335.9555 | G18: =SUM(D18*F18) -> 474137.76 | L18: =SUM(G18+I18+K18) -> 474137.76 | M18: 0.75 | O18: 177.86518 | P18: 183 | X18: 194
C19: Superintendent - Level 2 | D19: =$K$4 -> 88.857143 | E19: wks | F19: =(O19*40)*M19 -> 5971.9803 | G19: =SUM(D19*F19) -> 530653.1 | L19: =SUM(G19+I19+K19) -> 530653.1 | M19: 1 | O19: 149.29951 | P19: 161 | X19: 173
C20: Superintendent - Level 1 | D20: =$K$4 -> 88.857143 | E20: wks | F20: =(O20*40)*M20 -> 4887.7994 | G20: =SUM(D20*F20) -> 434315.89 | L20: =SUM(G20+I20+K20) -> 434315.89 | M20: 1 | O20: 122.19499 | P20: 121 | X20: 155
C21: Assistant Superinterndent | D21: =$K$4 -> 88.857143 | E21: wks | F21: =(O21*40)*M21 -> 0 | G21: =SUM(D21*F21) -> 0 | L21: =SUM(G21+I21+K21) -> 0 | M21: 0 | O21: 80.885879 | P21: 84 | X21: 95
C22: Quality Control Manager | D22: =$K$4 -> 88.857143 | E22: wks | F22: =(O22*40)*M22 -> 1111.6698 | G22: =SUM(D22*F22) -> 98779.801 | L22: =SUM(G22+I22+K22) -> 98779.801 | M22: 0.2 | O22: 138.95872
C23: Foreman | D23: =$K$4 -> 88.857143 | E23: wks | F23: =(O23*40)*M23 -> 0 | G23: =SUM(D23*F23) -> 0 | L23: =SUM(G23+I23+K23) -> 0 | M23: 0 | O23: 56.06341 | P23: 65 | X23: 65
C24: Accounting | D24: =$K$4 -> 88.857143 | E24: wks | F24: =(O24*40)*M24 -> 939.09653 | G24: =SUM(D24*F24) -> 83445.435 | L24: =SUM(G24+I24+K24) -> 83445.435 | M24: 0.15 | O24: 156.51609 | P24: 80 | X24: 90
C25: VDC Manager | D25: =$K$4 -> 88.857143 | E25: wks | F25: =(O25*40)*M25 -> 1109.4485 | G25: =SUM(D25*F25) -> 98582.425 | L25: =SUM(G25+I25+K25) -> 98582.425 | M25: 0.2 | O25: 138.68106 | P25: 101 | X25: 101
C26: Safety Supervisor/Inspector | D26: =K4 -> 88.857143 | E26: wks | F26: =(O26*40)*M26 -> 861.12686 | G26: =SUM(D26*F26) -> 76517.272 | L26: =SUM(G26+I26+K26) -> 76517.272 | M26: 0.2 | O26: 107.64086 | P26: 96 | X26: 96
C27: Field Labor - Close Out | L27: =SUM(L28:L42) -> 312545.3
C28: Project Executive | D28: =$K$5 -> 8.7142857 | E28: wks | F28: =(40*O28)*M28 -> 2128.4986 | G28: =SUM(D28*F28) -> 18548.345 | L28: =SUM(G28+I28+K28) -> 18548.345 | M28: 0.25 | O28: =+O10 -> 212.84986 | P28: =+P10 -> 253 | X28: =+X10 -> 216
C29: Senior Project Manager | D29: =$K$5 -> 8.7142857 | E29: wks | F29: =(40*O29)*M29 -> 7056.4365 | G29: =SUM(D29*F29) -> 61491.804 | L29: =SUM(G29+I29+K29) -> 61491.804 | M29: 1 | O29: =+O11 -> 176.41091 | P29: =+P11 -> 195 | X29: =+X11 -> 175
C30: Project Manager - Level 2 | D30: =$K$5 -> 8.7142857 | E30: wks | F30: =(40*O30)*M30 -> 0 | G30: =SUM(D30*F30) -> 0 | L30: =SUM(G30+I30+K30) -> 0 | M30: 0 | O30: =+O12 -> 148.69542 | P30: =+P12 -> 185 | X30: =+X12 -> 155
C31: Project Manager - Level 1 | D31: =$K$5 -> 8.7142857 | E31: wks | F31: =(40*O31)*M31 -> 0 | G31: =SUM(D31*F31) -> 0 | L31: =SUM(G31+I31+K31) -> 0 | M31: 0 | O31: =+O13 -> 127.25857 | P31: =+P13 -> 163 | X31: =+X13 -> 130
C32: Project Administator | D32: =$K$5 -> 8.7142857 | E32: wks | F32: =(40*O32)*M32 -> 3591.2833 | G32: =SUM(D32*F32) -> 31295.469 | L32: =SUM(G32+I32+K32) -> 31295.469 | M32: 1 | O32: =+O14 -> 89.782084 | P32: =+P14 -> 95 | X32: =+X14 -> 65
C33: Project Coordinator | D33: =$K$5 -> 8.7142857 | E33: wks | F33: =(40*O33)*M33 -> 0 | G33: =SUM(D33*F33) -> 0 | L33: =SUM(G33+I33+K33) -> 0 | M33: 0 | O33: =+O15 -> 115.84355 | P33: =+P15 -> 81 | X33: =+X15 -> 60
C34: Assistant Project Manager | D34: =$K$5 -> 8.7142857 | E34: wks | F34: =(40*O34)*M34 -> 4467.6124 | G34: =SUM(D34*F34) -> 38932.051 | L34: =SUM(G34+I34+K34) -> 38932.051 | M34: 1 | O34: =+O16 -> 111.69031 | P34: =+P16 -> 118 | X34: =+X16 -> 95
C35: Superintendent - Level 3 | D35: =$K$5 -> 8.7142857 | E35: wks | F35: =(40*O35)*M35 -> 5335.9555 | G35: =SUM(D35*F35) -> 46499.041 | L35: =SUM(G35+I35+K35) -> 46499.041 | M35: 0.75 | O35: =+O18 -> 177.86518 | P35: =+P18 -> 183 | X35: =+X18 -> 194
C36: Superintendent - Level 2 | D36: =$K$5 -> 8.7142857 | E36: wks | F36: =(40*O36)*M36 -> 5971.9803 | G36: =SUM(D36*F36) -> 52041.542 | L36: =SUM(G36+I36+K36) -> 52041.542 | M36: 1 | O36: =+O19 -> 149.29951 | P36: =+P19 -> 161 | X36: =+X19 -> 173
C37: Superintendent - Level 1 | D37: =$K$5 -> 8.7142857 | E37: wks | F37: =(40*O37)*M37 -> 4887.7994 | G37: =SUM(D37*F37) -> 42593.681 | L37: =SUM(G37+I37+K37) -> 42593.681 | M37: 1 | O37: =+O20 -> 122.19499 | P37: =+P20 -> 121 | X37: =+X20 -> 155
C38: Assistant Superinterndent | D38: =$K$5 -> 8.7142857 | E38: wks | F38: =(40*O38)*M38 -> 0 | G38: =SUM(D38*F38) -> 0 | L38: =SUM(G38+I38+K38) -> 0 | M38: 0 | O38: =+O21 -> 80.885879 | P38: =+P21 -> 84 | X38: =+X21 -> 95
C39: Foreman | D39: =$K$5 -> 8.7142857 | E39: wks | F39: =(40*O39)*M39 -> 0 | G39: =SUM(D39*F39) -> 0 | L39: =SUM(G39+I39+K39) -> 0 | M39: 0 | O39: =+O23 -> 56.06341 | P39: =+P23 -> 65 | X39: =+X23 -> 65
C40: Accounting | D40: =$K$5 -> 8.7142857 | E40: wks | F40: =(40*O40)*M40 -> 1565.1609 | G40: =SUM(D40*F40) -> 13639.259 | L40: =SUM(G40+I40+K40) -> 13639.259 | M40: 0.25 | O40: =+O24 -> 156.51609 | P40: =+P24 -> 80 | X40: =+X24 -> 90
C41: VDC Manager | D41: =$K$5 -> 8.7142857 | E41: wks | F41: =(40*O41)*M41 -> 0 | G41: =SUM(D41*F41) -> 0 | L41: =SUM(G41+I41+K41) -> 0 | M41: 0 | O41: =+O25 -> 138.68106 | P41: =+P25 -> 101 | X41: =+X25 -> 101
...

Sheet GCs & GRs
A1: Contract Reference | B1: General Condition Ref. | C1: Alton Hilltop Gardens - Permit Set - General Conditions/Requirements Summary
C3: Construction | F3: Activity | H3: Start | I3: Finish | J3: Days | K3: Weeks | L3: Months | M3: % Time | N3: Remarks
F4: Construction | H4: 46049 | I4: 46674 | J4: =SUM(I4-H4) -> 625 | K4: =SUM(J4/7) -> 89.285714 | L4: =SUM(J4/30) -> 20.833333 | AA4: 46008 | AB4: 46630 | AC4: 622 | AD4: 88.86 | AE4: 20.73
F5: Close Out | H5: 46675 | I5: 46737 | J5: =SUM(I5-H5) -> 62 | K5: =SUM(J5/7) -> 8.8571429 | L5: =SUM(J5/30) -> 2.0666667 | AA5: 46566 | AB5: 46627 | AC5: 61 | AD5: 8.71 | AE5: 2.03
F6: General Conditions | H6: General Req. - Field Office | J6: General Req. | L6: Total
C7: Description | D7: Qty. | E7: U | F7: Unit | G7: Const. | H7: Unit | I7: General | J7: Unit | K7: General | O7: LABOR RATE FY 2025 *Updated 09.26.24
F8: Cost | G8: Cond. | H8: Cost | I8: Req. | J8: Cost | K8: Req.
C9: Field Labor - Construction | L9: 3567861
C10: Project Executive | D10: 88.9 | E10: wks | F10: =(O10*40)*M10 -> 4257 | G10: =SUM(D10*F10) -> 378447.3 | L10: 378265 | M10: 0.5 | O10: ='Labor Rates Calculator'!G10 -> 212.85
C11: Senior Project Manager | D11: 88.9 | E11: wks | F11: =(O11*40)*M11 -> 7056.4 | G11: =SUM(D11*F11) -> 627313.96 | L11: 627015 | M11: 1 | O11: ='Labor Rates Calculator'!G11 -> 176.41
C12: Project Manager - Level 2 | D12: 88.9 | E12: wks | F12: =(O12*40)*M12 -> 0 | G12: =SUM(D12*F12) -> 0 | L12: $ - | M12: 0 | O12: ='Labor Rates Calculator'!G12 -> 148.7
C13: Project Manager - Level 1 | D13: 88.9 | E13: wks | F13: =(O13*40)*M13 -> 0 | G13: =SUM(D13*F13) -> 0 | L13: $ - | M13: 0 | O13: ='Labor Rates Calculator'!G13 -> 127.26
C14: Project Administator | D14: 88.9 | E14: wks | F14: =(O14*40)*M14 -> 3591.2 | G14: =SUM(D14*F14) -> 319257.68 | L14: 319111 | M14: 1 | O14: ='Labor Rates Calculator'!G14 -> 89.78
C15: Project Accountant | D15: 88.9 | E15: wks | F15: =(O15*40)*M15 -> 0 | G15: =SUM(D15*F15) -> 0 | L15: $ - | M15: 0 | O15: ='Labor Rates Calculator'!G15 -> 115.84
C16: Assistant Project Manager | D16: 88.9 | E16: wks | F16: =(O16*40)*M16 -> 4467.6 | G16: =SUM(D16*F16) -> 397169.64 | L16: 396979 | M16: 1 | O16: ='Labor Rates Calculator'!G16 -> 111.69
C17: General Superintendent | D17: 88.9 | E17: wks | F17: =(O17*40)*M17 -> 563.36 | G17: =SUM(D17*F17) -> 50082.704 | L17: 50060 | M17: 0.08 | O17: ='Labor Rates Calculator'!G17 -> 176.05
C18: Superintendent - Level 3 | D18: 88.9 | E18: wks | F18: =(O18*40)*M18 -> 5336.1 | G18: =SUM(D18*F18) -> 474379.29 | L18: 474138 | M18: 0.75 | O18: ='Labor Rates Calculator'!G18 -> 177.87
C19: Superintendent - Level 2 | D19: 88.9 | E19: wks | F19: =(O19*40)*M19 -> 5972 | G19: =SUM(D19*F19) -> 530910.8 | L19: 530653 | M19: 1 | O19: ='Labor Rates Calculator'!G19 -> 149.3
C20: Superintendent - Level 1 | D20: 88.9 | E20: wks | F20: =(O20*40)*M20 -> 4887.6 | G20: =SUM(D20*F20) -> 434507.64 | L20: 434316 | M20: 1 | O20: ='Labor Rates Calculator'!G20 -> 122.19
C21: Assistant Superinterndent | D21: 88.9 | E21: wks | F21: =(O21*40)*M21 -> 0 | G21: =SUM(D21*F21) -> 0 | L21: $ - | M21: 0 | O21: ='Labor Rates Calculator'!G21 -> 80.89
C22: Quality Control Manager | D22: 88.9 | E22: wks | F22: =(O22*40)*M22 -> 1111.68 | G22: =SUM(D22*F22) -> 98828.352 | L22: 98780 | M22: 0.2 | O22: ='Labor Rates Calculator'!G22 -> 138.96
C23: Foreman | D23: 88.9 | E23: wks | F23: =(O23*40)*M23 -> 0 | G23: =SUM(D23*F23) -> 0 | L23: $ - | M23: 0 | O23: ='Labor Rates Calculator'!G23 -> 56.06
C24: Accounting | D24: 88.9 | E24: wks | F24: =(O24*40)*M24 -> 939.12 | G24: =SUM(D24*F24) -> 83487.768 | L24: 83445 | M24: 0.15 | O24: ='Labor Rates Calculator'!G24 -> 156.52
C25: VDC Manager | D25: 88.9 | E25: wks | F25: =(O25*40)*M25 -> 1109.44 | G25: =SUM(D25*F25) -> 98629.216 | L25: 98582 | M25: 0.2 | O25: ='Labor Rates Calculator'!G25 -> 138.68
C26: Safety Supervisor/Inspector | D26: 88.9 | E26: wks | F26: =(O26*40)*M26 -> 861.12 | G26: =SUM(D26*F26) -> 76553.568 | L26: 76517 | M26: 0.2 | O26: ='Labor Rates Calculator'!G26 -> 107.64
C27: Field Labor - Close Out | L27: 312545
C28: Project Executive | D28: 8.7 | E28: wks | F28: 1109 | G28: 18548 | L28: 18548 | M28: 0.25 | O28: 212.85
C29: Senior Project Manager | D29: 8.7 | E29: wks | F29: 7056 | G29: 61492 | L29: 61492 | M29: 1 | O29: 176.41
C30: Project Manager - Level 2 | D30: 8.7 | E30: wks | F30: $ - | G30: $ - | L30: $ - | M30: 0 | O30: 148.7
C31: Project Manager - Level 1 | D31: 8.7 | E31: wks | F31: $ - | G31: $ - | L31: $ - | M31: 0 | O31: 127.26
C32: Project Administator | D32: 8.7 | E32: wks | F32: 3591 | G32: 31295 | L32: 31295 | M32: 1 | O32: 89.78
C33: Project Coordinator | D33: 8.7 | E33: wks | F33: $ - | G33: $ - | L33: $ - | M33: 0 | O33: 115.84
C34: Assistant Project Manager | D34: 8.7 | E34: wks | F34: 4468 | G34: 38932 | L34: 38932 | M34: 1 | O34: 111.69
C35: Superintendent - Level 3 | D35: 8.7 | E35: wks | F35: 5336 | G35: 46499 | L35: 46499 | M35: 0.75 | O35: 177.87
C36: Superintendent - Level 2 | D36: 8.7 | E36: wks | F36: 5972 | G36: 52042 | L36: 52042 | M36: 1 | O36: 149.3
C37: Superintendent - Level 1 | D37: 8.7 | E37: wks | F37: 4888 | G37: 42594 | L37: 42594 | M37: 1 | O37: 122.19
C38: Assistant Superinterndent | D38: 8.7 | E38: wks | F38: $ - | G38: $ - | L38: $ - | M38: 0 | O38: 80.89
C39: Foreman | D39: 8.7 | E39: wks | F39: $ - | G39: $ - | L39: $ - | M39: 0 | O39: 56.06
C40: Accounting | D40: 8.7 | E40: wks | F40: 1565 | G40: 13639 | L40: 13639 | M40: 0.25 | O40: 156.52
C41: VDC Manager | D41: 8.7 | E41: wks | F41: $ - | G41: $ - | L41: $ - | M41: 0 | O41: 138.68
...

Sheet Labor Rates Calculator
A5: Hedrick Brothers Construction Co., Inc.
A6: Salaries and Burden Calculations
A7: As of 8/22/24
C8: MARK-UP | F8: 0.35
E9: Burdened Rate | F9: Mark-up | G9: Total
C10: Proj Exec | E10: 157.67 | F10: 55.18 | G10: 212.85
C11: Sr PM | E11: 130.67 | F11: 45.74 | G11: 176.41
C12: PM 2 | E12: 110.14 | F12: 38.55 | G12: 148.7
C13: PM 1 | E13: 94.27 | F13: 32.99 | G13: 127.26
C14: Proj Admin | E14: 66.51 | F14: 23.28 | G14: 89.78
C15: Proj Acct | E15: 85.81 | F15: 30.03 | G15: 115.84
C16: Asst PM | E16: 82.73 | F16: 28.96 | G16: 111.69
C17: Gen Supt | E17: 130.41 | F17: 45.64 | G17: 176.05
C18: Supt 3 | E18: 131.75 | F18: 46.11 | G18: 177.87
C19: Supt 2 | E19: 110.59 | F19: 38.71 | G19: 149.3
C20: Supt 1 | E20: 90.51 | F20: 31.68 | G20: 122.19
C21: Asst Supt | E21: 59.92 | F21: 20.97 | G21: 80.89
... C31: Leadman | E31: 46.61 | F31: 16.31 | G31: 62.92
C32: Supt MEP | E32: $ - | F32: $ - | G32: $ -
C33: PM 3 | E33: 120.34 | F33: 42.12 | G33: 162.46
C34: Cons Mgr | E34: 135.46 | F34: 47.41 | G34: 182.87
C35: Proj Coor | E35: $ - | F35: $ - | G35: $ -
C36: Mktg | E36: 85.41 | F36: 29.89 | G36: 115.31
C37: Bus Dev | E37: 121.55 | F37: 42.54 | G37: 164.1
C38: Chief, 3 & 2 | E38: 140.92 | F38: 49.32 | G38: 190.24
C39: Coord & Jrs | E39: 52.72 | F39: 18.45 | G39: 71.17
C40: Exec Asst | E40: 69.67 | F40: 24.38 | G40: 94.05
C42: Total | E42: =SUM(E10:E41) -> 2612.41 | F42: =SUM(F10:F41) -> 914.31 | G42: =SUM(G10:G41) -> 3526.76
G43: =E42/G42 -> 0.74073938

Sheet Cost Summary
A1: 26 | B1: COST ESTIMATE (ROM)
R3: Rev. 3 dated 03/19/26
B6: ='AREA CALC''s'!B4 -> Alton Hilltop Gardens | F6: Gross (sf) | G6: ='AREA CALC''s'!L4 -> 514164.8 | Q6: Gross (sf) | R6: ='AREA CALC''s'!N4 -> 538483.8 | S6: Site (acres) | T6: ='AREA CALC''s'!N7 -> 17.64
B7: GMP Estimate | F7: RSF | G7: ='AREA CALC''s'!N5 -> 413948.8 | Q7: RSF | R7: ='AREA CALC''s'!N5 -> 413948.8 | S7: CH | T7: ='AREA CALC''s'!N9 -> 14650
F8: Units | G8: ='AREA CALC''s'!N6 -> 432 | Q8: Units | R8: ='AREA CALC''s'!N6 -> 432 | S8: Duration | T8: 20
F10: Total Apartment Buildings | K10: Site | M10: Clubhouse | O10: Garage | Z10: B | AA10: (A-B)
B11: CSI | C11: CSI DESCRIPTION | F11: TOTAL | G11: $ /GSF | H11: $ /RSF | I11: $ /UNIT | K11: TOTAL | M11: TOTAL | O11: TOTAL | Q11: GRAND TOTAL | R11: $ /GSF | S11: $ /RSF | T11: $ /UNIT | U11: % | V11: No. of Proposals | W11: BO Price | X11: Savings | Y11: SUB | Z11: GMP R2 | AA11: Variance | AB11: Notes | AC11: No. of Proposals
B13: 00A | C13: Electrical and Water Consumptions (Allowance) | F13: 21000 | G13: =F13/$G$6 -> 0.040842936 | H13: =F13/$G$7 -> 0.050730912 | I13: =F13/$G$8 -> 48.611111 | M13: 4000 | Q13: =F13+K13+M13+O13 -> 25000 | R13: =Q13/$R$6 -> 0.046426652 | S13: =Q13/$G$7 -> 0.060393942 | T13: =Q13/$G$8 -> 57.87037 | U13: =Q13/$Q$89 -> 0.0002394545 | W13: =Q13 -> 25000 | X13: =W13-Q13 -> 0 | Z13: 25000 | AA13: =Q13-Z13 -> 0
B14: 01A | C14: Surveying | F14: ='01A Surveying'!C84 -> 66000 | G14: =F14/$G$6 -> 0.12836351 | H14: =F14/$G$7 -> 0.15944001 | I14: =F14/$G$8 -> 152.77778 | K14: ='01A Surveying'!F84 -> 30000 | M14: ='01A Surveying'!D84 -> 8000 | O14: ='01A Surveying'!E84 -> 6000 | Q14: =F14+K14+M14+O14 -> 110000 | R14: =Q14/$R$6 -> 0.20427727 | S14: =Q14/$G$7 -> 0.26573335 | T14: =Q14/$G$8 -> 254.62963 | U14: =Q14/$Q$89 -> 0.0010535998 | V14: 4 | W14: =Q14 -> 110000 | X14: =W14-Q14 -> 0 | Z14: 110000 | AA14: =Q14-Z14 -> 0 | AC14: 4
B15: 01B | C15: Materials Testing | F15: Excluded | Q15: Excluded | Z15: Excluded
B16: 01C | C16: Site Maintenance / Dumpster / Cleaning | F16: ='01C Final Cleaning'!B106 -> 898690 | G16: =F16/$G$6 -> 1.7478637 | H16: =F16/$G$7 -> 2.1710173 | I16: =F16/$G$8 -> 2080.3009 | Q16: =F16+K16+M16+O16 -> 898690 | R16: =Q16/$G$6 -> 1.7478637 | S16: =Q16/$G$7 -> 2.1710173 | T16: =Q16/$G$8 -> 2080.3009 | U16: =Q16/$Q$89 -> 0.0086078145 | W16: =Q16 -> 898690 | X16: =W16-Q16 -> 0 | Z16: 898690 | AA16: =Q16-Z16 -> 0
B17: 02A | C17: Demolition | F17: Excluded | Q17: Excluded | Z17: Excluded
B18: 03A | C18: Concrete (Tunnel Form) | F18: ='03A Concrete'!B175 -> 18970000 | G18: =F18/$G$6 -> 36.894785 | H18: =F18/$G$7 -> 45.826924 | I18: =F18/$G$8 -> 43912.037 | K18: ='03A Concrete'!F175 -> 120000 | M18: ='03A Concrete'!D175 -> 1040000 | O18: ='03A Concrete'!E175 -> 340000 | Q18: =F18+K18+M18+O18 -> 20470000 | R18: =Q18/$G$6 -> 39.812138 | S18: =Q18/$G$7 -> 49.45056 | T18: =Q18/$G$8 -> 47384.259 | U18: =Q18/$Q$89 -> 0.19606534 | V18: 3 | W18: 19780000 | X18: =W18-Q18 -> -690000 | Z18: 20470000 | AA18: =Q18-Z18 -> 0 | AC18: 3
B19: 03C | C19: Architectural Precast | F19: ='03A Concrete'!C176 -> 0 | G19: =F19/$G$6 -> 0 | H19: =F19/$G$7 -> 0 | I19: =F19/$G$8 -> 0 | K19: ='03C Architectural Precast'!B88 -> 368772 | M19: ='03A Concrete'!D176 -> 0 | O19: ='03A Concrete'!E176 -> 0 | Q19: =F19+K19+M19+O19 -> 368772 | R19: =Q19/$G$6 -> 0.71722529 | S19: =Q19/$G$7 -> 0.8908638 | T19: =Q19/$G$8 -> 853.63889 | U19: =Q19/$Q$89 -> 0.0035321645 | V19: 3 | Z19: 368772 | AA19: =Q19-Z19 -> 0 | AC19: 3
B20: 04A | C20: Masonry | F20: in Concrete | G20: in Concrete | H20: in Concrete | I20: in Concrete | K20: in Concrete | M20: in Concrete | O20: in Concrete | Q20: in Concrete | R20: in Concrete | S20: in Concrete | T20: in Concrete | Z20: in Concrete
B21: 04B | C21: Stone Veneer | F21: ='04B Stone Veneer'!B113 -> 101719 | K21: ='04B Stone Veneer'!E113 -> 9350 | M21: ='04B Stone Veneer'!C113 -> 13513 | Q21: =F21+K21+M21+O21 -> 124582 | R21: =Q21/$G$6 -> 0.24229975 | S21: =Q21/$G$7 -> 0.30095993 | T21: =Q21/$G$8 -> 288.38426 | U21: =Q21/$Q$89 -> 0.0011932688 | V21: 4 | Z21: 67260 | AA21: =Q21-Z21 -> 57322 | AB21: RFI CD #23, added precast trims | AC21: 4
B22: 05A | C22: Structural Steel | F22: in Concrete | G22: in Concrete | H22: in Concrete | I22: in Concrete | K22: in Concrete | M22: in Concrete | O22: in Concrete | Q22: in Concrete | R22: in Concrete | S22: in Concrete | T22: in Concrete | Z22: in Concrete
B23: 05C | C23: Misc. Metals | F23: ='05C Misc. Metals'!B113 -> 879361.55 | G23: =F23/$G$6 -> 1.7102718 | H23: =F23/$G$7 -> 2.1243244 | I23: =F23/$G$8 -> 2035.5591 | Q23: =F23+K23+M23+O23 -> 879361.55 | R23: =Q23/$G$6 -> 1.7102718 | S23: =Q23/$G$7 -> 2.1243244 | T23: =Q23/$G$8 -> 2035.5591 | U23: =Q23/$Q$89 -> 0.0084226831 | V23: 5 | Z23: 879361.55 | AA23: =Q23-Z23 -> 0 | AC23: 5
B24: 05E | C24: Glass Railings | G24: =F24/$G$6 -> 0 | H24: =F24/$G$7 -> 0 | I24: =F24/$G$8 -> 0 | M24: ='05E Glass Railings'!B91 -> 46000 | Q24: =F24+K24+M24+O24 -> 46000 | R24: =Q24/$G$6 -> 0.089465479 | S24: =Q24/$G$7 -> 0.11112485 | T24: =Q24/$G$8 -> 106.48148 | U24: =Q24/$Q$89 -> 0.00044059627 | V24: 4 | Z24: 46000 | AA24: =Q24-Z24 -> 0 | AC24: 4
B25: 05F | C25: Brackets & Rafter Tails | F25: ='05F Brackets & Rafter Tails'!B148 -> 493453 | Q25: =F25+K25+M25+O25 -> 493453 | R25: =Q25/$G$6 -> 0.95971758 | S25: =Q25/$G$7 -> 1.1920629 | T25: =Q25/$G$8 -> 1142.2523 | U25: =Q25/$Q$89 -> 0.0047263816 | V25: 4 | Z25: 493453 | AA25: =Q25-Z25 -> 0 | AC25: 4
B26: 05G | C26: Balcony Columns | F26: ='05G Balcony Columns'!B81 -> 0 | G26: =F26/$G$6 -> 0 | H26: =F26/$G$7 -> 0 | I26: =F26/$G$8 -> 0 | M26: 0 | Q26: =F26+K26+M26+O26 -> 0 | R26: =Q26/$G$6 -> 0 | S26: =Q26/$G$7 -> 0 | T26: =Q26/$G$8 -> 0 | U26: =Q26/$Q$89 -> 0 | Z26: 353486 | AA26: =Q26-Z26 -> -353486 | AB26: Moved to Drywall & Stucco
B27: 06A | C27: Rough Carpentry | F27: ='06A Rough Carpentry'!B115 -> 587134.4 | G27: =F27/$G$6 -> 1.1419187 | H27: =F27/$G$7 -> 1.4183744 | I27: =F27/$G$8 -> 1359.1074 | Q27: =F27+K27+M27+O27 -> 587134.4 | R27: =Q27/$G$6 -> 1.1419187 | S27: =Q27/$G$7 -> 1.4183744 | T27: =Q27/$G$8 -> 1359.1074 | U27: =Q27/$Q$89 -> 0.0056236789 | Z27: 462134.4 | AA27: =Q27-Z27 -> 125000 | AB27: Added grout for HMF
B28: 06C | C28: Wood Trusses | F28: ='06C Wood Trusses'!B107 -> 252757.98 | G28: =F28/$G$6 -> 0.49158943 | H28: =F28/$G$7 -> 0.61060204 | I28: =F28/$G$8 -> 585.08792 | Q28: =F28+K28+M28+O28 -> 252757.98 | R28: =Q28/$G$6 -> 0.49158943 | S28: =Q28/$G$7 -> 0.61060204 | T28: =Q28/$G$8 -> 585.08792 | U28: =Q28/$Q$89 -> 0.0024209614 | V28: 5 | Z28: 287972.58 | AA28: =Q28-Z28 -> -35214.6 | AB28: more competitive proposal | AC28: 5
B29: 06D | C29: Interior Finish Cabinetry | F29: ='06D Interior Finish Carpentry'!B98 -> 243815 | G29: =F29/$G$6 -> 0.47419621 | H29: =F29/$G$7 -> 0.58899796 | I29: =F29/$G$8 -> 564.38657 | Q29: =F29+K29+M29+O29 -> 243815 | R29: =Q29/$G$6 -> 0.47419621 | S29: =Q29/$G$7 -> 0.58899796 | T29: =Q29/$G$8 -> 564.38657 | U29: =Q29/$Q$89 -> 0.0023353039 | V29: 3 | Z29: 243815 | AA29: =Q29-Z29 -> 0 | AC29: 3
B30: 06F | C30: Millwork | F30: ='06F Millwork'!C190 -> 0 | G30: =F30/$G$6 -> 0 | H30: =F30/$G$7 -> 0 | I30: =F30/$G$8 -> 0 | M30: ='06F Millwork'!D190 -> 697916.55 | Q30: =F30+K30+M30+O30 -> 697916.55 | R30: =Q30/$G$6 -> 1.3573791 | S30: =Q30/$G$7 -> 1.6859973 | T30: =Q30/$G$8 -> 1615.5476 | U30: =Q30/$Q$89 -> 0.0066847702 | V30: 4 | Z30: 695928.88 | AA30: =Q30-Z30 -> 1987.6673 | AC30: 4
B31: 07B | C31: Building Insulation | F31: ='07B Building Insulation'!B123 -> 325845 | G31: =F31/$G$6 -> 0.6337365 | H31: =F31/$G$7 -> 0.78716257 | I31: =F31/$G$8 -> 754.27083 | M31: ='07B Building Insulation'!D123 -> 0 | Q31: =F31+K31+M31+O31 -> 325845 | R31: =Q31/$G$6 -> 0.6337365 | S31: =Q31/$G$7 -> 0.78716257 | T31: =Q31/$G$8 -> 754.27083 | U31: =Q31/$Q$89 -> 0.003121002 | V31: 6 | Z31: 325845 | AA31: =Q31-Z31 -> 0 | AC31: 6
B32: 07C | C32: Fireproofing & Firestopping | F32: ='07C Fireproofing&Firestopping'!B86 -> 227000 | G32: =F32/$G$6 -> 0.44149269 | H32: =F32/$G$7 -> 0.548377 | I32: =F32/$G$8 -> 525.46296 | Q32: =F32+K32+M32+O32 -> 227000 | R32: =Q32/$G$6 -> 0.44149269 | S32: =Q32/$G$7 -> 0.548377 | T32: =Q32/$G$8 -> 525.46296 | U32: =Q32/$Q$89 -> 0.0021742468 | V32: 4 | Z32: 227000 | AA32: =Q32-Z32 -> 0 | AC32: 4
B33: 07D | C33: Roofing | F33: ='07D Roofing'!B116 -> 2020840 | G33: =F33/$G$6 -> 3.9303352 | H33: =F33/$G$7 -> 4.8818598 | I33: =F33/$G$8 -> 4677.8704 | K33: ='07D Roofing'!E116 -> 0 | M33: ='07D Roofing'!C116 -> 96760 | O33: ='07D Roofing'!D116 -> 114310 | Q33: =F33+K33+M33+O33 -> 2231910 | R33: =Q33/$G$6 -> 4.3408456 | S33: =Q33/$G$7 -> 5.3917538 | T33: =Q33/$G$8 -> 5166.4583 | U33: =Q33/$Q$89 -> 0.021377635 | V33: 7 | Z33: 2231910 | AA33: =Q33-Z33 -> 0 | AC33: 7
B34: 07E | C34: Caulking & Waterproofing | F34: ='07E Caulking & Waterproofing'!B131 -> 893620.86 | G34: =F34/$G$6 -> 1.7380047 | H34: =F34/$G$7 -> 2.1587715 | I34: =F34/$G$8 -> 2068.5668 | Q34: =F34+K34+M34+O34 -> 893620.86 | R34: =Q34/$G$6 -> 1.7380047 | S34: =Q34/$G$7 -> 2.1587715 | T34: =Q34/$G$8 -> 2068.5668 | U34: =Q34/$Q$89 -> 0.0085592613 | V34: 4 | Z34: 800871.79 | AA34: =Q34-Z34 -> 92749.07 | AC34: 4
B35: 08A | C35: Doors, Frames, & Hardware | F35: ='08A Doors, Frames, & Hardware'!B150 -> 2337225 | G35: =F35/$G$6 -> 4.5456729 | H35: =F35/$G$7 -> 5.6461693 | I35: =F35/$G$8 -> 5410.2431 | Q35: =F35+K35+M35+O35 -> 2337225 | R35: =Q35/$G$6 -> 4.5456729 | S35: =Q35/$G$7 -> 5.6461693 | T35: =Q35/$G$8 -> 5410.2431 | U35: =Q35/$Q$89 -> 0.022386361 | V35: 3 | Z35: 2262225 | AA35: =Q35-Z35 -> 75000 | AB35: Panel entry door as per RFI | AC35: 3
B36: 08B | C36: Overhead Coiling Doors | F36: ='08B Overhead Coiling Doors'!B85 -> 66970 | G36: =F36/$G$6 -> 0.13025007 | H36: =F36/$G$7 -> 0.16178329 | I36: =F36/$G$8 -> 155.02315 | Q36: =F36+K36+M36+O36 -> 66970 | R36: =Q36/$G$6 -> 0.13025007 | S36: =Q36/$G$7 -> 0.16178329 | T36: =Q36/$G$8 -> 155.02315 | U36: =Q36/$Q$89 -> 0.00064145071 | V36: 7 | Z36: 66970 | AA36: =Q36-Z36 -> 0 | AC36: 7
B37: 08C | C37: Glass and Glazing | F37: ='08C Glass and Glazing'!B164 -> 3029956.3 | G37: =F37/$G$6 -> 5.8929671 | H37: =F37/$G$7 -> 7.3196402 | I37: =F37/$G$8 -> 7013.7877 | Q37: =F37+K37+M37+O37 -> 3029956.3 | R37: =Q37/$G$6 -> 5.8929671 | S37: =Q37/$G$7 -> 7.3196402 | T37: =Q37/$G$8 -> 7013.7877 | U37: =Q37/$Q$89 -> 0.029021466 | V37: 11 | Z37: 3029956.3 | AA37: =Q37-Z37 -> 0 | AC37: 11
B38: 08E | C38: Mirrors | F38: ='08E Mirrors'!B93 -> 229579.02 | G38: =F38/$G$6 -> 0.44650863 | H38: =F38/$G$7 -> 0.55460728 | I38: =F38/$G$8 -> 531.43291 | Q38: =F38+K38+M38+O38 -> 229579.02 | R38: =Q38/$G$6 -> 0.44650863 | S38: =Q38/$G$7 -> 0.55460728 | T38: =Q38/$G$8 -> 531.43291 | U38: =Q38/$Q$89 -> 0.0021989491 | V38: 3 | Z38: 230109.02 | AA38: =Q38-Z38 -> -530 | AC38: 3
B39: 09A | C39: Stucco | F39: ='09A Stucco'!B128 -> 3017500 | G39: =F39/$G$6 -> 5.8687409 | H39: =F39/$G$7 -> 7.2895489 | I39: =F39/$G$8 -> 6984.9537 | K39: ='09A Stucco'!E128 -> 17000 | M39: ='09A Stucco'!C128 -> 84500 | O39: ='09A Stucco'!D128 -> 25000 | Q39: =F39+K39+M39+O39 -> 3144000 | R39: =Q39/$G$6 -> 6.114771 | S39: =Q39/$G$7 -> 7.5951422 | T39: =Q39/$G$8 -> 7277.7778 | U39: =Q39/$Q$89 -> 0.030113797 | V39: 8 | Z39: 3000000 | AA39: =Q39-Z39 -> 144000 | AB39: Balcony columns, no net increase | AC39: 8
B40: 09B | C40: Drywall / Framing | F40: ='09B Drywall&Framing'!B113 -> 4941119 | G40: =F40/$G$6 -> 9.6099908 | H40: =F40/$G$7 -> 11.936546 | I40: =F40/$G$8 -> 11437.775 | K40: ='09B Drywall&Framing'!D113 -> 8756 | M40: ='09B Drywall&Framing'!C113 -> 150736 | O40: ='09B Drywall&Framing'!E113 -> 65340 | Q40: =F40+K40+M40+O40 -> 5165951 | R40: =Q40/$G$6 -> 10.047267 | S40: =Q40/$G$7 -> 12.479686 | T40: =Q40/$G$8 -> 11958.22 | U40: =Q40/$Q$89 -> 0.049480408 | V40: 5 | Z40: 4952465 | AA40: =Q40-Z40 -> 213486 | AB40: Balcony columns, no net increase | AC40: 5
B41: 09E | C41: Flooring | F41: ='09E Flooring'!B161 -> 2821318 | G41: =F41/$G$6 -> 5.4871862 | H41: =F41/$G$7 -> 6.8156207 | I41: =F41/$G$8 -> 6530.8287 | M41: ='09E Flooring'!C161 -> 334620 | Q41: =F41+K41+M41+O41 -> 3155938 | R41: =Q41/$G$6 -> 6.1379892 | S41: =Q41/$G$7 -> 7.6239815 | T41: =Q41/$G$8 -> 7305.412 | U41: =Q41/$Q$89 -> 0.030228142 | V41: 4 | Z41: 2582940 | AA41: =Q41-Z41 -> 572998 | AB41: Kast RFI for shower surround and kitchen backsplash material | AC41: 4
B42: 09I | C42: Painting | F42: ='09I Painting'!B117 -> 1553114.8 | G42: =F42/$G$6 -> 3.0206556 | H42: =F42/$G$7 -> 3.751949 | I42: =F42/$G$8 -> 3595.1732 | K42: ='09I Painting'!E117 -> 5742 | M42: ='09I Painting'!C117 -> 150834 | O42: ='09I Painting'!D117 -> 19952 | Q42: =F42+K42+M42+O42 -> 1729642.8 | R42: =Q42/$G$6 -> 3.3639853 | S42: =Q42/$G$7 -> 4.1783979 | T42: =Q42/$G$8 -> 4003.8028 | U42: =Q42/$Q$89 -> 0.01656683 | V42: 7 | W42: 1550000 | Y42: Talbot/CF | Z42: 1729642.8 | AA42: =Q42-Z42 -> 0 | AC42: 7
B43: 10A | C43: Signage | F43: ='10A Signage'!B92 -> 88080.3 | G43: =F43/$G$6 -> 0.17130753 | H43: =F43/$G$7 -> 0.21278066 | I43: =F43/$G$8 -> 203.88958 | M43: ='10C Toilet Partitions & Bath'!C94 -> 0 | Q43: =F43+K43+M43+O43 -> 88080.3 | R43: =Q43/$G$6 -> 0.17130753 | S43: =Q43/$G$7 -> 0.21278066 | T43: =Q43/$G$8 -> 203.88958 | U43: =Q43/$Q$89 -> 0.00084364896 | V43: 1 | Z43: 88080.3 | AA43: =Q43-Z43 -> 0 | AC43: 1
B44: 10C | C44: Bath Accessories / Signs / Fire Extinguishers | F44: ='10C Toilet Partitions & Bath'!B95 -> 352460 | G44: =F44/$G$6 -> 0.68550006 | H44: =F44/$G$7 -> 0.85145796 | I44: =F44/$G$8 -> 815.87963 | M44: ='10C Toilet Partitions & Bath'!C95 -> 0 | Q44: =F44+K44+M44+O44 -> 352460 | R44: =Q44/$G$6 -> 0.68550006 | S44: =Q44/$G$7 -> 0.85145796 | T44: =Q44/$G$8 -> 815.87963 | U44: =Q44/$Q$89 -> 0.0033759253 | V44: 3 | Z44: 307905 | AA44: =Q44-Z44 -> 44555 | AC44: 3
B45: 10D | C45: Shower enclosures | F45: ='10D Shower Enclosures'!B88 -> 254000 | G45: =F45/$G$6 -> 0.49400503 | H45: =F45/$G$7 -> 0.61360246 | I45: =F45/$G$8 -> 587.96296 | Q45: =F45+K45+M45+O45 -> 254000 | R45: =Q45/$G$6 -> 0.49400503 | S45: =Q45/$G$7 -> 0.61360246 | T45: =Q45/$G$8 -> 587.96296 | U45: =Q45/$Q$89 -> 0.0024328577 | V45: 4 | Z45: 282370 | AA45: =Q45-Z45 -> -28370 | AB45: more competitive proposal | AC45: 4
...

Sheet IDS
G1: Hedrick Plug
F2: X | G2: Excluded
B3: BACK TO SUMMARY SHEET | F3: I | G3: Included | H3: Bidder 1 | J3: Bidder 2 | L3: Bidder 3 | N3: Bidder 4 | P3: Bidder5 | R3: Bidder6
A4: Project: | B4: 0 | G4: Company | H4: HB Construction
A5: Trade: | B5: IDS Services | G5: Contact | H5: Butch Carmichael
A6: CSI Code: | G6: Phone | H6: 561-225-4868
A7: Date: | G7: Email | H7: <bcarmichael@hedrickbrothers.com>
A8: Adjusted Bid | G8: Adjusted Bid | H8: =I99 -> 0 | J8: =K99 -> 0 | L8: =M99 -> 0 | N8: =O99 -> 0 | P8: =Q99 -> 0 | R8: =S99 -> 0
A9: BID DOCUMENTS: | C9: Plan/ Spec. Package | D9: QTY | E9: U/M | F9: Unit Cost | G9: Subtotal | H9: Yes/No | I9: Price | J9: Yes/No | K9: Price | L9: Yes/No | M9: Price | N9: Yes/No | O9: Price | P9: Yes/No | Q9: Price | R9: Yes/No | S9: Price
B10: Plans By Division
B11: 0 | C11: P
B12: 0 | C12: P
B13: 0 | C13: P
B14: 0 | C14: P
B15: 0 | C15: P
B16: 0 | C16: P
B17: 0 | C17: P
B18: 0 | C18: P
B19: 0 | C19: P
B21: Survey
B22: OCIP Insurance per exhibit
B23: GENERAL INCLUSIONS
B24: INCLUDES ALL SALES TAX
B25: ALL HOISTING & RIGGING REQUIRED TO COMPLETE THIS SCOPE
B26: PROVIDE P&P BONDS
B27: FLORIDA STATE CONTRACTORS LIC.
B28: GENERAL LIABILITY AND WORKERS COMP. INSURANCE LIMITS
B29: STATE AND LOCAL TAXES
B30: SPECIFIC TRADE SCOPE OF WORK REQUIREMENTS
B31: BASE BID | D31: 1 | E31: EA
B33: Pre-construction Modeling/BIM Execution Plan Meetings
B34: BIM Execution Plan Meeting including writing of BEP | H34: i
B35: Initial Jobsite Visit | H35: x
B36: Model Architectural | H36: i
B37: Model Structural | H37: i
B38: Model Mechanical/HVAC | H38: i
B39: Model Plumbing | H39: i
B40: Model Electrical | H40: x
B41: Model Fire Sprinkler | H41: x
B42: Model Civil | H42: x
...

Sheet 01A Surveying
G1: Hedrick Plug
F2: X | G2: Excluded
B3: BACK TO SUMMARY SHEET | F3: I | G3: Included | H3: Bidder 1 | J3: Bidder 2 | L3: Bidder 3 | N3: Bidder 4 | P3: Bidder5 | R3: Bidder6
A4: Project: | B4: ='AREA CALC''s'!B4 -> Alton Hilltop Gardens | G4: Company | H4: HB | J4: Caulffield & Wheeler
A5: Trade: | B5: Surveying | G5: Contact | J5: Renee Watson
A6: CSI Code: | B6: 01A | G6: Phone | J6: 5613921991
A7: Date: | G7: Email | J7: estimates@cwiassoc.com
A8: Adjusted Bid | G8: Adjusted Bid | H8: =I48 -> 110000 | J8: =K48 -> 167700 | L8: =M48 -> 0 | N8: =O48 -> 0 | P8: =Q48 -> 0 | R8: =S48 -> 0
A9: BID DOCUMENTS: | C9: Plan/ Spec. Package | D9: QTY | E9: U/M | F9: Unit Cost | G9: Subtotal | H9: Yes/No | I9: Price | J9: Yes/No | K9: Price | L9: Yes/No | M9: Price | N9: Yes/No | O9: Price | P9: Yes/No | Q9: Price | R9: Yes/No | S9: Price
B10: Plans By Division
B11: =#REF! -> #REF! | C11: P
B12: =#REF! -> #REF! | C12: P
B13: =#REF! -> #REF! | C13: P
B14: =#REF! -> #REF! | C14: P
B15: =#REF! -> #REF! | C15: P
B16: =#REF! -> #REF! | C16: P
B17: =#REF! -> #REF! | C17: P
B18: =#REF! -> #REF! | C18: P
B19: =#REF! -> #REF! | C19: P
B21: Surveying
B22: OCIP Insurance per exhibit
B23: GENERAL INCLUSIONS
B24: INCLUDES ALL SALES TAX
B25: ALL HOISTING & RIGGING REQUIRED TO COMPLETE THIS SCOPE
B26: PROVIDE P&P BONDS
B27: FLORIDA STATE CONTRACTORS LIC.
B28: GENERAL LIABILITY AND WORKERS COMP. INSURANCE LIMITS
B29: STATE AND LOCAL TAXES
B30: COMPASS
B31: SPECIFIC TRADE SCOPE OF WORK REQUIREMENTS
B32: BASE BID | D32: 1 | E32: EA | K32: =27950*6 -> 167700
B35: Residential Building 1 | D35: 3 | E35: EA | F35: 10000 | G35: =D35*F35 -> 30000 | H35: i | I35: =G35 -> 30000
B36: Residential Building 2 | D36: 2 | E36: EA | F36: 12000 | G36: =D36*F36 -> 24000 | H36: i | I36: =G36 -> 24000
B37: Residential Building 3 | D37: 1 | E37: EA | F37: 12000 | G37: =D37*F37 -> 12000 | H37: i | I37: =G37 -> 12000
B39: Site | D39: 1 | E39: EA | F39: 30000 | G39: =D39*F39 -> 30000 | H39: i | I39: =G39 -> 30000
B40: Garage | D40: 3 | E40: EA | F40: 2000 | G40: =D40*F40 -> 6000 | H40: i | I40: =G40 -> 6000
B41: Clubhouse | D41: 1 | E41: EA | F41: 8000 | G41: =D41*F41 -> 8000 | H41: i | I41: =G41 -> 8000
F44: SUBTOTAL | G44: =SUM(G35:G43) -> 110000 | I44: =SUM(I32:I43) -> 110000 | K44: =SUM(K32:K43) -> 167700 | M44: =SUM(M32:M43) -> 0 | O44: =SUM(O32:O43) -> 0 | Q44: =SUM(Q32:Q43) -> 0 | S44: =SUM(S32:S43) -> 0
F45: BOND RATE | H45: 0 | J45: 0 | L45: 0 | N45: 0 | P45: 0 | R45: 0
F46: BOND AMOUNT | I46: =H45*I44 -> 0 | K46: =J45*K44 -> 0 | M46: =L45*M44 -> 0 | O46: =N45*O44 -> 0 | Q46: =P45*Q44 -> 0 | S46: =R45*S44 -> 0
...

Sheet 01B Material Testing
G1: Hedrick Plug
F2: X | G2: Excluded
B3: BACK TO SUMMARY SHEET | F3: I | G3: Included | H3: Bidder 1 | J3: Bidder 2 | L3: Bidder 3 | N3: Bidder 4 | P3: Bidder5 | R3: Bidder6
A4: Project: | B4: ='AREA CALC''s'!B4 -> Alton Hilltop Gardens | G4: Company
A5: Trade: | B5: Material Testing | G5: Contact
A6: CSI Code: | B6: 01B | G6: Phone
A7: Date: | G7: Email
A8: Adjusted Bid | G8: Adjusted Bid | H8: =I70 -> 0 | J8: =K70 -> 0 | L8: =M70 -> 0 | N8: =O70 -> 0 | P8: =Q70 -> 0 | R8: =S70 -> 0
A9: BID DOCUMENTS: | C9: Plan/ Spec. Package | D9: QTY | E9: U/M | F9: Unit Cost | G9: Subtotal | H9: Yes/No | I9: Price | J9: Yes/No | K9: Price | L9: Yes/No | M9: Price | N9: Yes/No | O9: Price | P9: Yes/No | Q9: Price | R9: Yes/No | S9: Price
B10: Plans By Division
B11: =#REF! -> #REF! | C11: P
B12: =#REF! -> #REF! | C12: P
B13: =#REF! -> #REF! | C13: P
B14: =#REF! -> #REF! | C14: P
B15: =#REF! -> #REF! | C15: P
B16: =#REF! -> #REF! | C16: P
B17: =#REF! -> #REF! | C17: P
B18: =#REF! -> #REF! | C18: P
B19: =#REF! -> #REF! | C19: P
B21: Material Testing
B22: GENERAL INCLUSIONS
B23: INCLUDES ALL SALES TAX
B24: ALL HOISTING & RIGGING REQUIRED TO COMPLETE THIS SCOPE
B25: PROVIDE P&P BONDS
B26: FLORIDA STATE CONTRACTORS LIC.
B27: GENERAL LIABILITY AND WORKERS COMP. INSURANCE LIMITS
B28: STATE AND LOCAL TAXES
B29: COMPASS
B30: SPECIFIC TRADE SCOPE OF WORK REQUIREMENTS
B31: BASE BID
H36: x
H37: i
F66: SUBTOTAL | I66: =SUM(I22:I65) -> 0 | K66: =SUM(K22:K65) -> 0 | M66: =SUM(M22:M65) -> 0 | O66: =SUM(O22:O65) -> 0 | Q66: =SUM(Q22:Q65) -> 0 | S66: =SUM(S22:S65) -> 0
F67: BOND RATE | H67: 0 | J67: 0 | L67: 0 | N67: 0 | P67: 0 | R67: 0
F68: BOND AMOUNT | I68: =H67*I66 -> 0 | K68: =J67*K66 -> 0 | M68: =L67*M66 -> 0 | O68: =N67*O66 -> 0 | Q68: =P67*Q66 -> 0 | S68: =R67*S66 -> 0
F70: ADJUSTED TOTAL | I70: =SUM(I66:I68) -> 0 | K70: =SUM(K66:K68) -> 0 | M70: =SUM(M66:M68) -> 0 | O70: =SUM(O66:O68) -> 0 | Q70: =SUM(Q66:Q68) -> 0 | S70: =SUM(S66:S68) -> 0
F71: Cost per SF | I71: =I70/#REF! -> #REF! | K71: =K70/#REF! -> #REF! | M71: =M70/#REF! -> #REF! | O71: =O70/#REF! -> #REF! | Q71: =Q70/#REF! -> #REF! | S71: =S70/#REF! -> #REF!
F72: Cost per Unit | I72: =I70/#REF! -> #REF! | K72: =K70/#REF! -> #REF! | M72: =M70/#REF! -> #REF! | O72: =O70/#REF! -> #REF! | Q72: =Q70/#REF! -> #REF! | S72: =S70/#REF! -> #REF!
A74: QUALIFICATIONS
A78: EXCLUSIONS/OWNER PROVIDED ITEMS:
...

Sheet 01C Final Cleaning
G1: Hedrick Plug
F2: X | G2: Excluded
B3: BACK TO SUMMARY SHEET | F3: I | G3: Included | H3: Bidder 1 | J3: Bidder 2 | L3: Bidder 3 | N3: Bidder 4 | P3: Bidder5 | R3: Bidder6
A4: Project: | B4: =#REF! -> #REF! | G4: Company
A5: Trade: | B5: Site Maintenance | G5: Contact
A6: CSI Code: | B6: 01C | G6: Phone
A7: Date: | G7: Email
A8: Adjusted Bid | G8: Adjusted Bid | H8: =I70 -> 0 | J8: =K70 -> 0 | L8: =M70 -> 0 | N8: =O70 -> 0 | P8: =Q70 -> 0 | R8: =S70 -> 0
A9: BID DOCUMENTS: | C9: Plan/ Spec. Package | D9: QTY | E9: U/M | F9: Unit Cost | G9: Subtotal | H9: Yes/No | I9: Price | J9: Yes/No | K9: Price | L9: Yes/No | M9: Price | N9: Yes/No | O9: Price | P9: Yes/No | Q9: Price | R9: Yes/No | S9: Price
B10: Plans By Division
B11: =#REF! -> #REF! | C11: P
B12: =#REF! -> #REF! | C12: P
B13: =#REF! -> #REF! | C13: P
B14: =#REF! -> #REF! | C14: P
B15: =#REF! -> #REF! | C15: P
B16: =#REF! -> #REF! | C16: P
B17: =#REF! -> #REF! | C17: P
B18: =#REF! -> #REF! | C18: P
B19: =#REF! -> #REF! | C19: P
B21: Final Cleaning
B22: GENERAL INCLUSIONS
B23: INCLUDES ALL SALES TAX
B24: ALL HOISTING & RIGGING REQUIRED TO COMPLETE THIS SCOPE
B25: PROVIDE P&P BONDS
B26: FLORIDA STATE CONTRACTORS LIC.
B27: GENERAL LIABILITY AND WORKERS COMP. INSURANCE LIMITS
B28: STATE AND LOCAL TAXES
B29: COMPASS
B30: SPECIFIC TRADE SCOPE OF WORK REQUIREMENTS
B31: BASE BID | G31: =SUM(G33:G47) -> 898690
B33: Construction fence | D33: 3600 | E33: LF | F33: 12 | G33: =D33*F33 -> 43200
B34: Construction gates | D34: 2 | E34: EA | F34: 6000 | G34: =D34*F34 -> 12000
B35: Maintenance during construction | D35: 1 | E35: LS | F35: 10000 | G35: =D35*F35 -> 10000
B36: Street Maintenance & Cleaning | D36: 1 | E36: LS | F36: 8000 | G36: =D36*F36 -> 8000 | H36: x
B37: Final Cleaning | D37: 412250 | E37: SF | F37: 0.5 | G37: =D37*F37 -> 206125 | H37: i
B38: Misc. Street Sweeping | D38: 1 | E38: LS | F38: 8000 | G38: =D38*F38 -> 8000
B39: Concrete Wash-out | D39: 1 | E39: LS | F39: 15000 | G39: =D39*F39 -> 15000
B40: Construction waste removal / recycle | D40: 1 | E40: LS | F40: 10000 | G40: =D40*F40 -> 10000
B41: Temp Fire Protection - Temp Holding Tanks (5) ea | D41: 16 | E41: Month | F41: 2500 | G41: =D41*F41 -> 40000
B42: Temp Fire Protection - Fill | D42: 5 | E42: ea | F42: 2000 | G42: =D42*F42 -> 10000
...

Sheet 02A Demolition
G1: Hedrick Plug
F2: X | G2: Excluded
B3: BACK TO SUMMARY SHEET | F3: I | G3: Included | H3: Bidder 1 | J3: Bidder 2 | L3: Bidder 3 | N3: Bidder 4 | P3: Bidder5 | R3: Bidder6
A4: Project: | B4: =#REF! -> #REF! | G4: Company
A5: Trade: | B5: Demolition | G5: Contact
A6: CSI Code: | B6: 02A | G6: Phone
A7: Date: | G7: Email
A8: Adjusted Bid | G8: Adjusted Bid | H8: =I57 -> 0 | J8: =K57 -> 0 | L8: =M57 -> 0 | N8: =O57 -> 0 | P8: =Q57 -> 0 | R8: =S57 -> 0
A9: BID DOCUMENTS: | C9: Plan/ Spec. Package | D9: QTY | E9: U/M | F9: Unit Cost | G9: Subtotal | H9: Yes/No | I9: Price | J9: Yes/No | K9: Price | L9: Yes/No | M9: Price | N9: Yes/No | O9: Price | P9: Yes/No | Q9: Price | R9: Yes/No | S9: Price
B10: Plans By Division
B11: =#REF! -> #REF! | C11: P
B12: =#REF! -> #REF! | C12: P
B13: =#REF! -> #REF! | C13: P
B14: =#REF! -> #REF! | C14: P
B15: =#REF! -> #REF! | C15: P
B16: =#REF! -> #REF! | C16: P
B17: =#REF! -> #REF! | C17: P
B18: =#REF! -> #REF! | C18: P
B19: =#REF! -> #REF! | C19: P
B21: Demolition
B22: OCIP Insurance per exhibit
B23: GENERAL INCLUSIONS
B24: INCLUDES ALL SALES TAX
B25: ALL HOISTING & RIGGING REQUIRED TO COMPLETE THIS SCOPE
B26: PROVIDE P&P BONDS
B27: FLORIDA STATE CONTRACTORS LIC.
B28: GENERAL LIABILITY AND WORKERS COMP. INSURANCE LIMITS
B29: STATE AND LOCAL TAXES
B30: COMPASS
B31: SPECIFIC TRADE SCOPE OF WORK REQUIREMENTS
B32: BASE BID
H35: x
F53: SUBTOTAL | I53: =SUM(I22:I52) -> 0 | K53: =SUM(K22:K52) -> 0 | M53: =SUM(M22:M52) -> 0 | O53: =SUM(O22:O52) -> 0 | Q53: =SUM(Q22:Q52) -> 0 | S53: =SUM(S22:S52) -> 0
F54: BOND RATE | H54: 0 | J54: 0 | L54: 0 | N54: 0 | P54: 0 | R54: 0
F55: BOND AMOUNT | I55: =H54*I53 -> 0 | K55: =J54*K53 -> 0 | M55: =L54*M53 -> 0 | O55: =N54*O53 -> 0 | Q55: =P54*Q53 -> 0 | S55: =R54*S53 -> 0
F57: ADJUSTED TOTAL | I57: =SUM(I53:I55) -> 0 | K57: =SUM(K53:K55) -> 0 | M57: =SUM(M53:M55) -> 0 | O57: =SUM(O53:O55) -> 0 | Q57: =SUM(Q53:Q55) -> 0 | S57: =SUM(S53:S55) -> 0
F58: Cost per SF | I58: =I57/#REF! -> #REF! | K58: =K57/#REF! -> #REF! | M58: =M57/#REF! -> #REF! | O58: =O57/#REF! -> #REF! | Q58: =Q57/#REF! -> #REF! | S58: =S57/#REF! -> #REF!
F59: Cost per Unit | I59: =I57/#REF! -> #REF! | K59: =K57/#REF! -> #REF! | M59: =M57/#REF! -> #REF! | O59: =O57/#REF! -> #REF! | Q59: =Q57/#REF! -> #REF! | S59: =S57/#REF! -> #REF!
A61: QUALIFICATIONS
A65: EXCLUSIONS/OWNER PROVIDED ITEMS:
...

Sheet 02B Abatement
G1: Hedrick Plug
F2: X | G2: Excluded
