Workbook
Name FCP: 'Bond Calculator'!$B$7

Sheet Area Calculations
B2: PROJECT AREA CALCULATIONS
B4: ERAU Residential Hall & Garage Building | F4: Gross (sf) | G4: 578663
B5: Daytona Beach | F5: AC (sf)
F6: Site (acres) | G6: =H6/43560 -> 6.5699725 | H6: 286188
F7: Parking Spaces Surface | G7: 131
F8: Parking Spaces Garage | G8: 925
F9: No. of Units: | G9: =C30 -> 107
F10: No. of Beds: | G10: 423
F11: Build Duration (months)
B14: Floors | C14: Units | D14: AC SF | E14: Gross SF | F14: LSF | G14: GROSS%
G16: =E16/$G$4 -> 0
B17: 2nd | C17: 21 | G17: =E17/$G$4 -> 0
B18: 3rd | C18: 21 | G18: =E18/$G$4 -> 0
B19: 4th | C19: 21 | G19: =E19/$G$4 -> 0
B20: 5th | C20: 20 | G20: =E20/$G$4 -> 0
B21: 5th staff | C21: 1 | G21: =E21/$G$4 -> 0
B22: 5th guest | C22: 1 | G22: =E22/$G$4 -> 0
B23: 6th | C23: 20 | G23: =E23/$G$4 -> 0
B24: 6th staff | C24: 1 | G24: =E24/$G$4 -> 0
B25: 6th guest | C25: 1 | G25: =E25/$G$4 -> 0
G26: =E26/$G$4 -> 0
G27: =E27/$G$4 -> 0
B30: TOTAL | C30: =SUM(C16:C29) -> 107 | D30: =SUM(D16:D29) -> 0 | E30: =SUM(E16:E29) -> 0 | F30: =SUM(F16:F29) -> 0 | G30: =SUM(G16:G29) -> 0
A46: IV. | B46: SITE AREAS | F46: $ /UNIT | G46: %
B49: Site Perimeter | F49: LF
B50: Walk Gates
B51: Drive Gates
B52: Tire Grates / Truck Wash
A53: III. | B53: SITE AREAS | F53: $ /UNIT | G53: %
B54: Sidewalks
B55: Drives
B56: Asphalt Parking
B57: Fill CY
A58: III. | B58: Barking Spaces | C58: FLOOR BREAKDOWN | E58: QTY. | G58: %
G60: =E60/$G$7 -> 0
G61: =E61/$G$7 -> 0
B63: TOTAL Units | E63: =SUM(E60:E62) -> 0 | G63: =SUM(G60:G62) -> 0

Sheet Bond Calculator
A1: Hedrick Brothers Construction
A3: Performance / Payment Bond | E3: Performance / Payment Bond
A4: General Construction | E4: Design Build
B6: =IF(B13>500000,500000,B13) -> 500000 | C6: 0.0091 | D6: =B6*C6 -> 4550 | F6: 0 | G6: 0.01875 | H6: =SUM(F6*G6) -> 0
B7: =IF(B13<2500000,(B13-B6),IF(B13>B6,2000000,0)) -> 2000000 | C7: 0.00725 | D7: =B7*C7 -> 14500 | F7: 0 | G7: 0.015 | H7: =SUM(F7*G7) -> 0
B8: =IF(B13<5000000,MAX(0,B13-2500000),IF(B13>2500000,2500000)) -> 2500000 | C8: 0.0063 | D8: =B8*C8 -> 15750 | F8: 0 | G8: 0.01125 | H8: =SUM(F8*G8) -> 0
B9: =IF(B13<7500000,MAX(0,B13-5000000),IF(B13>7500000,2500000,0)) -> 2500000 | C9: 0.00555 | D9: =B9*C9 -> 13875 | F9: 0 | G9: 0.009 | H9: =SUM(F9*G9) -> 0
B10: =IF(B13<7500000,MAX(0,B13-7500000),IF(B13>7500000,(B13-7500000))) -> 92779112 | C10: 0.0051 | D10: =B10*C10 -> 473173.47 | F10: 0 | G10: 0.00825 | H10: =SUM(F10*G10) -> 0
D11: =B11*C11 -> 0 | F11: 0 | G11: 0.0075 | H11: =SUM(F11*G11) -> 0
A12: Contract Value | B12: ='Cost Summary'!C84 -> 1.0027911e+08 | C12: Total | D12: =SUM(D6:D11) -> 521848.47 | E12: Contract Value | F12: =SUM(F6+F7+F8+F9+F10+F11) -> 0 | G12: Total | H12: =SUM(H6:H11) -> 0
A13: Cost Summary | B13: ='Cost Summary'!C84 -> 1.0027911e+08 | D13: =SUM(D12/B12) -> 0.0052039598 | H13: =SUM(H12/F12) -> #DIV/0!
B14: =B12-B13 -> 0

Sheet Allowances
A3: ='Area Calculations'!B4 -> ERAU Residential Hall & Garage Building
A5: Allowances
A6: =TODAY() -> 46085
A8: NO. | B8: DESCRIPTION | C8: VALUE
A9: 1
A10: =A9+1 -> 2
A11: =A10+1 -> 3
A12: =A11+1 -> 4
A13: =A12+1 -> 5
A14: =A13+1 -> 6
A15: =A14+1 -> 7
A16: =A15+1 -> 8
A17: =A16+1 -> 9
A18: =A17+1 -> 10
A19: =A18+1 -> 11
A20: =A19+1 -> 12
A21: =A20+1 -> 13
... A26: =A25+1 -> 18
A27: =A26+1 -> 19 | B27: Total | C27: =SUM(C9:C26) -> 0

Sheet Alternate & VE
A3: ='Area Calculations'!B4 -> ERAU Residential Hall & Garage Building
A5: Alternate & Value Engineering Pricing
A6: =TODAY() -> 46085 | E6: Add markup | F6: 1.12
D7: 0.11067508
A8: NO. | B8: DESCRIPTION | C8: VALUE | D8: VALUE W/ MARK-UP
A9: 1 | B9: Provide a cost to ADD a performance and payment bond for the entirety of the project. | C9: ='Cost Summary'!C87 -> 1002791.1 | D9: =C9*(1+$D$7) -> 1113775.1
A10: =A9+1 -> 2 | B10: Provide cost to ADD epoxy paint in all student corridors from floor to five feet above, in lieu of base paint system | C10: ='09 90 Painting'!M67 -> 38975 | D10: =C10*(1+$D$7) -> 43288.561
A11: =A10+1 -> 3 | B11: Provide cost to DELETE the solid surface countertop from the residential unit kitchens, then provide plastic laminate countertops in lieu of. | C11: ='12 36 Solid Surface'!I70 -> -96475 | D11: =C11*(1+$D$7) -> -107152.38
A12: =A11+1 -> 4 | B12: Provide cost to delete the concealed anchors at the wall mounted railings, then provide costs exposed anchors in lieu of. | C12: ='05 52 Misc. Metals'!K76 -> -36060 | D12: =C12*(1+$D$7) -> -40050.943
A13: =A12+1 -> 5 | B13: Provide cost to delete the ESP coatings as noted on the drawings on the metal railings, then provide costs for primed and painted railings as noted in the specifications. | C13: ='09 90 Painting'!K66 -> -42400 | D13: =C13*(1+$D$7) -> -47092.623
A14: =A13+1 -> 6 | B14: Provide ADD costs for graphics on the precast panels at the exterior. | C14: =500000 -> 500000 | D14: =C14*(1+$D$7) -> 555337.54
A15: =A14+1 -> 7 | B15: Provide ADD costs for the exterior wing shaped sun screen (canopies) | C15: ='05 10 Steel'!I79 -> 403683.72 | D15: =C15*(1+$D$7) -> 448361.45
A16: =A15+1 -> 8 | B16: Provide ADD/DEDUCT costs per the allowance. (Base Bid per Interior Plans). | C16: =294000+4563708.31 -> 4857708.3 | D16: =C16*(1+$D$7) -> 5395335.6
A17: =A16+1 -> 9 | B17: Provide DEDUCT costs for under cabinetry lights in Units. | C17: -10550 | D17: =C17*(1+$D$7) -> -11717.622
A18: =A17+1 -> 10 | B18: ='ERUA Cost Summary'!B114 -> Assigned wallcoverings | C18: 175000 | D18: =C18*(1+$D$7) -> 194368.14
A19: =A18+1 -> 11 | B19: ='ERUA Cost Summary'!B115 -> Full Tile Kitchen Backsplashes | C19: 18500 | D19: =C19*(1+$D$7) -> 20547.489
A20: =A19+1 -> 12 | B20: ='ERUA Cost Summary'!B116 -> 30-Inch Trash Chutes | C20: 7608.87 | D20: =C20*(1+$D$7) -> 8450.9823
A21: =A20+1 -> 13 | B21: ='ERUA Cost Summary'!B117 -> Wallcoverings identified in Addendum 1 | C21: 303578 | D21: =C21*(1+$D$7) -> 337176.52
A22: =A21+1 -> 14 | B22: ='ERUA Cost Summary'!B118 -> Vinyl Flooring System with integral sound attenuation layer | C22: ='09 60 Flooring'!I59 -> -124910 | D22: =C22*(1+$D$7) -> -138734.42
A23: =A22+1 -> 15 | B23: ='ERUA Cost Summary'!B119 -> CPVC Piping in lieu of Copper up to 1 1/2" Deduct | C23: 0 | D23: =C23*(1+$D$7) -> 0 | E23: Base Bid
B24: ='ERUA Cost Summary'!B120 -> Copper Piping in lieu of CPVC up to 1 1/2" Add | C24: 300000 | D24: =C24*(1+$D$7) -> 333202.52 | F24: shades | G24: elec
A25: =A23+1 -> 16 | B25: ='ERUA Cost Summary'!B121 -> Motorized window shades for all public areas and lounges. | C25: =H25 -> 182132.36 | D25: =C25*(1+$D$7) -> 202289.87 | F25: 131382.36 | G25: =203*250 -> 50750 | H25: =F25+G25 -> 182132.36
A26: =A25+1 -> 17 | B26: ='ERUA Cost Summary'!B122 -> Automatic door operators - 24 Single doors / 4 Double doors | C26: =P32 -> 127000 | D26: =C26*(1+$D$7) -> 141055.74
A27: =A26+1 -> 18 | B27: Please provide a cost for only providing Rod & Shelves ( 2 each, stack) for the individual bedrooms, instead of the original closet millwork system as specified. | C27: ='12 34 Residential Casework'!AH39 -> -188100 | D27: =C27*(1+$D$7) -> -208917.98
B28: Total | C28: =SUM(C9:C27) -> 7418482.4 | D28: =SUM(D9:D27) -> 8239523.5 | M28: operator | N28: power | O28: pedistal
M29: installed
F30: 24 single door operators - HM door & frame | K30: +power | L30: 24 | M30: 3500 | N30: 500 | O30: 0 | P30: =L30*(M30+N30+O30) -> 96000
F31: 4 double door operators - storefront | K31: +power | L31: 4 | M31: 6000 | N31: 250 | O31: 1500 | P31: =L31*(M31+N31+O31) -> 31000
P32: =SUM(P30:P31) -> 127000
B35: Geopier - rammed aggregate | C35: ='31 32 Soil Stabilization'!N9-'31 32 Soil Stabilization'!H9 -> -682500 | D35: =C35*(1+$D$7) -> -758035.74
B36: Lighting fixture VE package | C36: -400000 | D36: =C36*(1+$D$7) -> -444270.03
B37: Light Fixture VE alternate to Sesco package - subject to architect and engineer approval | C37: -1000000 | D37: =C37*(1+$D$7) -> -1110675.1
B38: Aluminum feeders and secondaries 100amp and larger - subject to architect and engineer approval | C38: =-2137000 -> -2137000 | D38: =C38*(1+$D$7) -> -2373512.6

Sheet ERUA Cost Summary
A1: GC BID PROPOSAL SUMMARY
B3: EMBRY RIDDLE PHASE IV - RESIDENCE HALL AND GARAGE DAYTONA BEACH CAMPUS ADDENDUM NO 5 dated August 7, 2025 | C3: sq. ft. of project | E3: 578663
A5: Division | C5: PSF value | E5: Total
A6: 1 | B6: General Conditions, staffing and temp Facilities | C6: =+E6/$E$3 -> 7.6708747 | E6: ='Cost Summary'!E11+'Cost Summary'!E12 -> 4438851.4
A7: 1 | B7: Surveying | C7: =+E7/$E$3 -> 0.10350238 | E7: ='Cost Summary'!E13 -> 59893
A8: 1 | B8: Site Maintenance | C8: =+E8/$E$3 -> 3.0789029 | E8: ='Cost Summary'!E15 -> 1781647.2
A9: 1 | B9: Addition Building Width Allowance | C9: =+E9/$E$3 -> 0.86406077 | E9: 500000 | G9: 0 | H9: =E9-G9 -> 500000
A10: 2 | B10: Deep Foundations / Soils Improvements | C10: =+E10/$E$3 -> 2.2806724 | E10: ='Cost Summary'!E63 -> 1319740.7 | G10: 0 | H10: =E10-G10 -> 1319740.7 | J10: =SUM(E10:E13) -> 4699395.8 | K10: ='Cost Summary'!E62+'Cost Summary'!E63+'Cost Summary'!E64+'Cost Summary'!E65+'Cost Summary'!E66 -> 4699395.8 | L10: =J10-K10 -> 0
A11: 2 | B11: Site Work / Improvements | C11: =+E11/$E$3 -> 3.4730844 | E11: ='Cost Summary'!E62+'Cost Summary'!E63+'Cost Summary'!E64+'Cost Summary'!E65-N11-E10 -> 2009745.4 | G11: 3329486.1 | H11: =E11-G11 -> -1319740.7 | N11: =O11*1.1 -> 903601.79 | O11: =SUM(P11:U11) -> 821456.17 | P11: =P12 -> 149328 | Q11: =Q12 -> 86403.333 | R11: =R12 -> 1512 | S11: =S12 -> 22090.53 | T11: =T12 -> 183470 | U11: =P13 -> 378652.31
A12: 2 | B12: Parking Lot Pavement / Striping | C12: =+E12/$E$3 -> 0.84174079 | E12: =N12 -> 487084.25 | N12: =O12*1.1 -> 487084.25 | O12: =SUM(P12:U12) -> 442803.86 | P12: ='31 30 Site Work'!I68 -> 149328 | Q12: ='31 30 Site Work'!I74 -> 86403.333 | R12: ='31 30 Site Work'!I75 -> 1512 | S12: ='31 30 Site Work'!I132 -> 22090.53 | T12: =SUM('31 30 Site Work'!I142:I145) -> 183470
A13: 2 | B13: Landscaping (including sidewalk and curbs) | C13: =+E13/$E$3 -> 1.5256296 | E13: ='Cost Summary'!E66+N13 -> 882825.42 | N13: =O13*1.1 -> 416517.54 | O13: =SUM(P13:U13) -> 378652.31 | P13: =SUM('31 30 Site Work'!I78:I83) -> 378652.31
A14: 3 | B14: Concrete, Foundation/Slab on Grade | C14: =+E14/$E$3 -> 9.8222244 | E14: ='Cost Summary'!E16-E16 -> 5683757.8 | G14: 5757857.8 | H14: =E14-G14 -> -74100
A15: 3 | B15: Precast Concrete - Metromont | C15: =+E15/$E$3 -> 36.753267 | E15: ='Cost Summary'!E17-E9 -> 21267756 | G15: 21767756 | H15: =E15-G15 -> -500000
A16: 4 | B16: Masonry | C16: =+E16/$E$3 -> 0.12805381 | E16: ='03 30 CIP Concrete'!K76+'03 30 CIP Concrete'!K77 -> 74100 | H16: =E16-G16 -> 74100
A17: 5 | B17: Structural Steel | C17: =+E17/$E$3 -> 0.61037392 | E17: ='Cost Summary'!E19 -> 353200.8
A18: 5 | B18: Canopies and Shading Louvers | C18: =+E18/$E$3 -> 0 | E18: 0 | G18: 25450.99 | H18: =E18-G18 -> -25450.99
A19: 5 | B19: Decorative Metals | C19: =+E19/$E$3 -> 0 | E19: 0
A20: 5 | B20: Stairs, Railing Systems, Misc | C20: =+E20/$E$3 -> 0.58399691 | E20: ='Cost Summary'!E20 -> 337937.4
A21: 6 | B21: Interior Carpentry | C21: =+E21/$E$3 -> 0.57857915 | E21: ='Cost Summary'!E22 -> 334802.35 | G21: 1323589.8 | H21: =E21-G21 -> -988787.49 | J21: =E21 -> 334802.35 | K21: ='Cost Summary'!E22+'Cost Summary'!E47+'Cost Summary'!E48 -> 1684491.2 | L21: =J21-K21 -> -1349688.8 | O21: =SUM(P21:U21) -> 1684491.2 | P21: ='Cost Summary'!E22 -> 334802.35 | Q21: ='Cost Summary'!E47 -> 793220.85 | R21: ='Cost Summary'!E48 -> 556467.99
A22: 6 | B22: Rough Carpentry | C22: =+E22/$E$3 -> 0.85350368 | E22: ='Cost Summary'!C21 -> 493891
A23: 7 | B23: Thermal and Moisture Protection | C23: =+E23/$E$3 -> 1.5646229 | E23: ='Cost Summary'!E23+'Cost Summary'!E28+'Cost Summary'!E29 -> 905389.36 | J23: =E23 -> 905389.36 | K23: ='Cost Summary'!E23+'Cost Summary'!E29+'Cost Summary'!E28 -> 905389.36 | L23: =J23-K23 -> 0 | O23: =SUM(P23:U23) -> 905389.36 | P23: ='Cost Summary'!E23 -> 714322.61 | Q23: ='Cost Summary'!E28 -> 19366.75 | R23: ='Cost Summary'!E29 -> 171700
A24: 7 | B24: Exterior Metal Panels | C24: =+E24/$E$3 -> 2.2571616 | E24: ='Cost Summary'!E25 -> 1306135.9
A25: 7 | B25: Roofing and Trim | C25: =+E25/$E$3 -> 2.2803687 | E25: ='Cost Summary'!E26 -> 1319565
A26: 7 | B26: Fireproofing | C26: =+E26/$E$3 -> 0.15219912 | E26: ='Cost Summary'!E27 -> 88072
A27: 8 | B27: Doors / Frames | C27: =+E27/$E$3 -> 2.970493 | E27: ='Cost Summary'!E30-N27 -> 1718914.4 | J27: =E27+E28 -> 2093315.9 | K27: ='Cost Summary'!E30 -> 2093315.9 | L27: =J27-K27 -> 0 | N27: =O27*1.1 -> 374401.5 | O27: =SUM(P27:U27) -> 340365 | P27: ='08 10 DFH'!I155+'08 10 DFH'!I159 -> 340365
A28: 8 | B28: Door & Hardware Installation | C28: =+E28/$E$3 -> 0.6470113 | E28: =N27 -> 374401.5
A29: 8 | B29: Windows / Glazing | C29: =+E29/$E$3 -> 7.3420435 | E29: ='Cost Summary'!E33-N33 -> 4248568.9 | J29: =E29+E33 -> 5059090 | K29: ='Cost Summary'!E33 -> 5059090 | L29: =J29-K29 -> 0
A30: 8 | B30: Hangar Doors - OH Doors Trash Rooms | C30: =+E30/$E$3 -> 0.051454474 | E30: ='Cost Summary'!E32 -> 29774.8
A31: 8 | B31: Bi-parting Doors (5th Floor) | C31: =+E31/$E$3 -> 0.13567439 | E31: =S31 -> 78509.748 | J31: =E31+E32 -> 563645.85 | K31: ='Cost Summary'!E31 -> 563645.85 | L31: =J31-K31 -> 0 | N31: =O31*1.1 -> 0 | P31: ='08 32 Hangar Doors'!G40 -> 77732.424 | Q31: 0.01 | R31: =P31*Q31 -> 777.32424 | S31: =P31+R31 -> 78509.748
A32: 8 | B32: Overhead Hydraulic Doors (1st Floor) | C32: =+E32/$E$3 -> 0.83837414 | E32: =S32 -> 485136.1 | N32: =O32*1.1 -> 0 | P32: ='08 32 Hangar Doors'!G39 -> 480332.77 | Q32: 0.01 | R32: =P32*Q32 -> 4803.3277 | S32: =P32+R32 -> 485136.1
A33: 8 | B33: Curtainwall systems | C33: =+E33/$E$3 -> 1.4006789 | E33: =N33 -> 810521.05 | N33: =O33*1.1 -> 810521.05 | O33: =SUM(P33:U33) -> 736837.32 | P33: =SUM('08 50 Storefront & Windows'!G44:G47) -> 736837.32
A34: 9 | B34: Interior Framing and Gypsum Board | C34: =+E34/$E$3 -> 7.9741863 | E34: ='Cost Summary'!E34 -> 4614366.5
A35: 9 | B35: Acoustical Ceilings | C35: =+E35/$E$3 -> 0.53606206 | E35: ='Cost Summary'!E37 -> 310199.28
A36: 9 | B36: Painting | C36: =+E36/$E$3 -> 1.4731074 | E36: ='Cost Summary'!E41 -> 852432.73
A37: 9 | B37: Carpet, Vinyl Flooring, Tile - Labor | C37: =+E37/$E$3 -> 0.96635455 | E37: ='Cost Summary'!E35+'Cost Summary'!E38 -> 559193.62
A38: 9 | B38: Carpet Vinyl Floor Tile - Material | C38: =+E38/$E$3 -> 1.6956277 | E38: =SUM('ERUA Cost Summary'!E81:E84) -> 981197
A39: 9 | B39: Resinuous Flooring | C39: =+E39/$E$3 -> 0.19667664 | E39: ='Cost Summary'!E40 -> 113809.5
A40: 10 | B40: Specialties | C40: =+E40/$E$3 -> 0.10536298 | E40: ='Cost Summary'!E44 -> 60969.66
A41: 10 | B41: Toilet, Bath Accessories | C41: =+E41/$E$3 -> 0.52880766 | E41: ='Cost Summary'!E43 -> 306001.43
A42: 10 | B42: Interior Signage | C42: =+E42/$E$3 -> 0 | E42: 0
...

Sheet Cost Summary
A3: ='Area Calculations'!B4 -> ERAU Residential Hall & Garage Building
A4: ='Area Calculations'!B5 -> Daytona Beach | C4: Gross (sf) | F4: ='Area Calculations'!G4 -> 578663 | G4: Site (acres) | H4: ='Area Calculations'!G6 -> 6.5699725 | M4: Hank
A5: Hard Bid | C5: AC (sf) | F5: ='Area Calculations'!G5 -> 0 | G5: Parking Spcs | H5: ='Area Calculations'!G7 -> 131 | L5: surface | M5: Claudia
A6: =NOW() -> 46085.544 | C6: No. of Units: | F6: ='Area Calculations'!G9 -> 107 | G6: Parking Spcs | H6: ='Area Calculations'!G8 -> 925 | L6: garage | M6: Sam
C7: No. of Beds: | F7: ='Area Calculations'!G10 -> 423 | G7: Build Dur (mo) | H7: ='Area Calculations'!G11 -> 0 | M7: Hunter
E8: 0.01
A9: CSI | B9: CSI DESCRIPTION | C9: TOTAL | E9: =+ 1% -> 0.01 | F9: $ /SF | G9: $ /UNIT | H9: % | I9: Prev. | J9: Delta | K9: Notes
B11: General Conditions | C11: ='GCs & GRs'!L164 -> 3961757.1 | E11: =C11 -> 3961757.1 | F11: =C11/$F$4 -> 6.8463978 | G11: =C11/$F$6 -> 37025.767 | H11: =C11/$C$84 -> 0.039507301 | J11: =C11-I11 -> 3961757.1 | L11: =C11 -> 3961757.1 | M11: =C11/C84 -> 0.039507301 | P11: =E11-C11 -> 0
B12: General Requirements | C12: ='GCs & GRs'!L165 -> 477094.3 | E12: =C12 -> 477094.3 | F12: =C12/$F$4 -> 0.82447694 | G12: =C12/$F$6 -> 4458.8252 | H12: =C12/$C$84 -> 0.0047576638 | J12: =C12-I12 -> 477094.3 | L12: =C12 -> 477094.3 | M12: =C12/C84 -> 0.0047576638 | P12: =E12-C12 -> 0
A13: 02 21 00 | B13: Surveying | C13: ='02 21 Survey '!B94 -> 59300 | D13: =C13 -> 59300 | E13: =C13*(1+$E$8) -> 59893 | F13: =C13/$F$4 -> 0.10247761 | G13: =C13/$F$6 -> 554.20561 | H13: =C13/$C$84 -> 0.00059134947 | J13: =C13-I13 -> 59300 | L13: =C13 -> 59300 | P13: =E13-C13 -> 593
A14: 02 41 00 | B14: Demolition | C14: ='02 41 Demolition'!B91 -> 0 | F14: =C14/$F$4 -> 0 | G14: =C14/$F$6 -> 0 | H14: =C14/$C$84 -> 0 | L14: =C14 -> 0 | P14: =E14-C14 -> 0
A15: 02 50 10 | B15: Site Maintenance / Dumpster / Cleaning | C15: ='02 50 Site Maint'!B97 -> 1781647.2 | E15: =C15 -> 1781647.2 | F15: =C15/$F$4 -> 3.0789029 | G15: =C15/$F$6 -> 16650.909 | H15: =C15/$C$84 -> 0.017766883 | J15: =C15-I15 -> 1781647.2 | L15: =C15 -> 1781647.2 | P15: =E15-C15 -> 0
A16: 03 30 00 | B16: Concrete | C16: ='03 30 CIP Concrete'!$B$132 -> 5700849.3 | D16: =C16 -> 5700849.3 | E16: =C16*(1+$E$8) -> 5757857.8 | F16: =C16/$F$4 -> 9.8517606 | G16: =C16/$F$6 -> 53278.966 | H16: =C16/$C$84 -> 0.056849819 | J16: =C16-I16 -> 5700849.3 | L16: =C16 -> 5700849.3 | P16: =E16-C16 -> 57008.493
A17: 03 41 00 | B17: Precast Hollow Core | C17: ='03 41 Precast Hollow Core'!B124 -> 21767756 | E17: =C17 -> 21767756 | F17: =C17/$F$4 -> 37.617328 | G17: =C17/$F$6 -> 203436.97 | H17: =C17/$C$84 -> 0.21707169 | J17: =C17-I17 -> 21767756 | L17: =C17 -> 21767756 | P17: =E17-C17 -> 0
A18: 04 22 00 | B18: Concrete Unit Masonry | C18: ='04 22 Concrete Unit Masonry'!B92 -> 0 | F18: =C18/$F$4 -> 0 | G18: =C18/$F$6 -> 0 | H18: =C18/$C$84 -> 0 | J18: =C18-I18 -> 0 | L18: =C18 -> 0 | P18: =E18-C18 -> 0
A19: 05 10 00 | B19: Structural Steel | C19: ='05 10 Steel'!B102 -> 349703.77 | D19: =C19 -> 349703.77 | E19: =C19*(1+$E$8) -> 353200.8 | F19: =C19/$F$4 -> 0.60433061 | G19: =C19/$F$6 -> 3268.2595 | H19: =C19/$C$84 -> 0.0034873042 | J19: =C19-I19 -> 349703.77 | L19: =C19 -> 349703.77 | P19: =E19-C19 -> 3497.0377
A20: 05 52 00 | B20: Misc. Metals | C20: ='05 52 Misc. Metals'!B99 -> 334591.49 | D20: =C20 -> 334591.49 | E20: =C20*(1+$E$8) -> 337937.4 | F20: =C20/$F$4 -> 0.57821476 | G20: =C20/$F$6 -> 3127.0233 | H20: =C20/$C$84 -> 0.0033366021 | J20: =C20-I20 -> 334591.49 | L20: =C20 -> 334591.49 | P20: =E20-C20 -> 3345.9149
A21: 06 10 00 | B21: Rough Carpentry | C21: ='06 10 Rough Carpentry'!B91 -> 493891 | E21: =C21 -> 493891 | F21: =C21/$F$4 -> 0.85350368 | G21: =C21/$F$6 -> 4615.8037 | H21: =C21/$C$84 -> 0.0049251633 | J21: =C21-I21 -> 493891 | L21: =C21 -> 493891 | P21: =E21-C21 -> 0
A22: 06 21 00 | B22: Millwork | C22: ='06 21 Millwork'!B96 -> 331487.47 | D22: =C22 -> 331487.47 | E22: =C22*(1+$E$8) -> 334802.35 | F22: =C22/$F$4 -> 0.57285064 | G22: =C22/$F$6 -> 3098.0138 | H22: =C22/$C$84 -> 0.0033056483 | J22: =C22-I22 -> 331487.47 | L22: =C22 -> 331487.47 | P22: =E22-C22 -> 3314.8747
A23: 07 10 00 | B23: Waterproofing | C23: ='07 10 Waterproofing'!B96 -> 707250.11 | D23: =C23 -> 707250.11 | E23: =C23*(1+$E$8) -> 714322.61 | F23: =C23/$F$4 -> 1.2222142 | G23: =C23/$F$6 -> 6609.8141 | H23: =C23/$C$84 -> 0.0070528159 | J23: =C23-I23 -> 707250.11 | L23: =C23 -> 707250.11 | P23: =E23-C23 -> 7072.5011
A24: 07 21 00 | B24: Insulation - INC 09 29 50 | C24: ='07 21 Insulation'!B91 -> 0 | D24: =C24 -> 0 | E24: =C24*(1+$E$8) -> 0 | F24: =C24/$F$4 -> 0 | G24: =C24/$F$6 -> 0 | H24: =C24/$C$84 -> 0 | J24: =C24-I24 -> 0 | L24: =C24 -> 0 | P24: =E24-C24 -> 0
A25: 07 42 00 | B25: Metal Wall Panels | C25: ='07 42 Metal Panel'!B91 -> 1293203.9 | D25: =C25 -> 1293203.9 | E25: =C25*(1+$E$8) -> 1306135.9 | F25: =C25/$F$4 -> 2.2348134 | G25: =C25/$F$6 -> 12086.017 | H25: =C25/$C$84 -> 0.012896044 | J25: =C25-I25 -> 1293203.9 | L25: =C25 -> 1293203.9 | P25: =E25-C25 -> 12932.039
A26: 07 50 00 | B26: Roofing | C26: ='07 50 Roofing'!B94 -> 1306500 | D26: =C26 -> 1306500 | E26: =C26*(1+$E$8) -> 1319565 | F26: =C26/$F$4 -> 2.2577908 | G26: =C26/$F$6 -> 12210.28 | H26: =C26/$C$84 -> 0.013028636 | J26: =C26-I26 -> 1306500 | L26: =C26 -> 1306500 | P26: =E26-C26 -> 13065
A27: 07 81 00 | B27: Spray Fireproofing | C27: ='07 81 Spray Fireproofing'!B91 -> 87200 | D27: =C27 -> 87200 | E27: =C27*(1+$E$8) -> 88072 | F27: =C27/$F$4 -> 0.1506922 | G27: =C27/$F$6 -> 814.95327 | H27: =C27/$C$84 -> 0.00086957292 | J27: =C27-I27 -> 87200 | L27: =C27 -> 87200 | P27: =E27-C27 -> 872
A28: 07 84 00 | B28: Firestopping | C28: ='07 84 Firestopping'!B91 -> 19175 | D28: =C28 -> 19175 | E28: =C28*(1+$E$8) -> 19366.75 | F28: =C28/$F$4 -> 0.033136731 | G28: =C28/$F$6 -> 179.20561 | H28: =C28/$C$84 -> 0.00019121629 | J28: =C28-I28 -> 19175 | L28: =C28 -> 19175 | P28: =E28-C28 -> 191.75
A29: 07 92 00 | B29: Expansion Joints | C29: ='07 92 Exp Joint'!B91 -> 170000 | D29: =C29 -> 170000 | E29: =C29*(1+$E$8) -> 171700 | F29: =C29/$F$4 -> 0.29378066 | G29: =C29/$F$6 -> 1588.785 | H29: =C29/$C$84 -> 0.0016952683 | J29: =C29-I29 -> 170000 | L29: =C29 -> 170000 | P29: =E29-C29 -> 1700
A30: 08 10 70 | B30: Doors, Frames, & Hardware | C30: ='08 10 DFH'!B207 -> 2072590 | D30: =C30 -> 2072590 | E30: =C30*(1+$E$8) -> 2093315.9 | F30: =C30/$F$4 -> 3.5816874 | G30: =C30/$F$6 -> 19370 | H30: =C30/$C$84 -> 0.020668213 | J30: =C30-I30 -> 2072590 | L30: =C30 -> 2072590 | P30: =E30-C30 -> 20725.9
A31: 08 32 00 | B31: Hangar Doors | C31: ='08 32 Hangar Doors'!$B$92 -> 558065.19 | D31: =C31 -> 558065.19 | E31: =C31*(1+$E$8) -> 563645.85 | F31: =C31/$F$4 -> 0.96440449 | G31: =C31/$F$6 -> 5215.5626 | H31: =C31/$C$84 -> 0.005565119 | J31: =C31-I31 -> 558065.19 | L31: =C31 -> 558065.19 | M31: 0.01 | N31: =L31*M31 -> 5580.6519 | O31: =L31+N31 -> 563645.85 | P31: =E31-C31 -> 5580.6519 | Q31: =P31/L31 -> 0.01
A32: 08 33 00 | B32: Overhead Doors | C32: ='08 33 Overhead doors'!B94 -> 29480 | D32: =C32 -> 29480 | E32: =C32*(1+$E$8) -> 29774.8 | F32: =C32/$F$4 -> 0.050945023 | G32: =C32/$F$6 -> 275.51402 | H32: =C32/$C$84 -> 0.00029397947 | J32: =C32-I32 -> 29480 | L32: =C32 -> 29480 | P32: =E32-C32 -> 294.8
A33: 08 50 00 | B33: Storefront & Windows | C33: ='08 50 Storefront & Windows'!B161 -> 5009000 | D33: =C33 -> 5009000 | E33: =C33*(1+$E$8) -> 5059090 | F33: =C33/$F$4 -> 8.6561608 | G33: =C33/$F$6 -> 46813.084 | H33: =C33/$C$84 -> 0.049950582 | J33: =C33-I33 -> 5009000 | L33: =C33 -> 5009000 | P33: =E33-C33 -> 50090
A34: 09 29 50 | B34: Drywall & Framing | C34: ='09 29 Drywall & Frame'!B94 -> 4568679.8 | D34: =C34 -> 4568679.8 | E34: =C34*(1+$E$8) -> 4614366.5 | F34: =C34/$F$4 -> 7.8952339 | G34: =C34/$F$6 -> 42697.942 | H34: =C34/$C$84 -> 0.045559635 | J34: =C34-I34 -> 4568679.8 | L34: =C34 -> 4568679.8 | P34: =E34-C34 -> 45686.798
A35: 09 30 00 | B35: Tile | C35: ='09 30 Tile'!B78-C36 -> 219979.27 | D35: =C35 -> 219979.27 | E35: =C35*(1+$E$8) -> 222179.07 | F35: =C35/$F$4 -> 0.38015092 | G35: =C35/$F$6 -> 2055.8811 | H35: =C35/$C$84 -> 0.00219367 | J35: =C35-I35 -> 219979.27 | L35: =C35 -> 219979.27 | P35: =E35-C35 -> 2199.7927
B36: Tile mat allowance | C36: ='ERUA Cost Summary'!E84 -> 240000 | E36: =C36 -> 240000 | P36: =E36-C36 -> 0
A37: 09 51 00 | B37: Acoustical Ceilings | C37: ='09 51 ACT'!B77 -> 307128 | D37: =C37 -> 307128 | E37: =C37*(1+$E$8) -> 310199.28 | F37: =C37/$F$4 -> 0.53075452 | G37: =C37/$F$6 -> 2870.3551 | H37: =C37/$C$84 -> 0.0030627316 | J37: =C37-I37 -> 307128 | L37: =C37 -> 307128 | P37: =E37-C37 -> 3071.28
A38: 09 60 00 | B38: Flooring | C38: ='09 60 Flooring'!B81-C39 -> 333677.78 | D38: =C38 -> 333677.78 | E38: =C38*(1+$E$8) -> 337014.55 | F38: =C38/$F$4 -> 0.57663575 | G38: =C38/$F$6 -> 3118.4839 | H38: =C38/$C$84 -> 0.0033274903 | J38: =C38-I38 -> 333677.78 | L38: =C38 -> 333677.78 | P38: =E38-C38 -> 3336.7778
B39: Flooring Mat Allowance | C39: ='ERUA Cost Summary'!E81+'ERUA Cost Summary'!E82+'ERUA Cost Summary'!E83 -> 741197 | E39: =C39 -> 741197 | P39: =E39-C39 -> 0
A40: 09 96 00 | B40: Fluid-Applied Flooring | C40: ='09 96 Fluid Applied Flooring'!B74 -> 112682.67 | D40: =C40 -> 112682.67 | E40: =C40*(1+$E$8) -> 113809.5 | F40: =C40/$F$4 -> 0.19472935 | G40: =C40/$F$6 -> 1053.1091 | H40: =C40/$C$84 -> 0.0011236903 | J40: =C40-I40 -> 112682.67 | L40: =C40 -> 112682.67 | P40: =E40-C40 -> 1126.8267
A41: 09 90 00 | B41: Painting | C41: ='09 90 Painting'!B90 -> 843992.8 | D41: =C41 -> 843992.8 | E41: =C41*(1+$E$8) -> 852432.73 | F41: =C41/$F$4 -> 1.4585221 | G41: =C41/$F$6 -> 7887.7832 | H41: =C41/$C$84 -> 0.0084164367 | J41: =C41-I41 -> 843992.8 | L41: =C41 -> 843992.8 | P41: =E41-C41 -> 8439.928
A42: 10 14 00 | B42: Signage (Allowance) | C42: ='10 14 Signage'!B68 -> 20000 | E42: =C42 -> 20000 | F42: =C42/$F$4 -> 0.034562431 | G42: =C42/$F$6 -> 186.91589 | H42: =C42/$C$84 -> 0.00019944333 | J42: =C42-I42 -> 20000 | L42: =C42 -> 20000 | P42: =E42-C42 -> 0
A43: 10 20 00 | B43: Bath Accessories | C43: ='10 20 Toilet Partitions & Bath'!B88 -> 302971.71 | D43: =C43 -> 302971.71 | E43: =C43*(1+$E$8) -> 306001.43 | F43: =C43/$F$4 -> 0.52357194 | G43: =C43/$F$6 -> 2831.5113 | H43: =C43/$C$84 -> 0.0030212843 | J43: =C43-I43 -> 302971.71 | L43: =C43 -> 302971.71 | P43: =E43-C43 -> 3029.7171
...

Sheet GCs & GRs
A1: Contract Reference | B1: General Condition Ref. | C1: TEST
C3: Construction | F3: Activity | H3: Start | I3: Finish | J3: Days | K3: Weeks | L3: Months | M3: % Time | N3: Remarks | Q3: 45915 | R3: 45932 | S3: 46629 | T3: 46628
F4: Construction | H4: 45931 | I4: =H4+J4 -> 46630 | J4: 699 | K4: =SUM(J4/7) -> 99.857143 | L4: =SUM(J4/30) -> 23.3 | Q4: 46612 | R4: =R3+Q5 -> 46629 | S4: 46588 | T4: =T3-S5 -> 46587
F5: Close Out | J5: =L5*30.42 -> 60.84 | K5: =L5*4.33 -> 8.66 | L5: 2 | Q5: =Q4-Q3 -> 697 | S5: =S3-S4 -> 41
F6: General Conditions | H6: General Req. - Field Office | J6: General Req. | L6: Total
C7: Description | D7: Qty. | E7: U | F7: Unit | G7: Const. | H7: Unit | I7: General | J7: Unit | K7: General | O7: CUSTOMIZED LABOR RATES
F8: Cost | G8: Cond. | H8: Cost | I8: Req. | J8: Cost | K8: Req.
C9: Field Labor - Construction | L9: =SUM(L10:L27) -> 3717618.1
A10: 1 | C10: Project Executive | D10: ='Staffing Schedule '!AE27 -> 56.29 | E10: wks | F10: =(O10*40)*M10 -> 6306.6625 | G10: =SUM(D10*F10) -> 355002.03 | L10: =SUM(G10+I10+K10) -> 355002.03 | M10: 1 | O10: ='Labor Rates'!G8 -> 157.66656
A11: =A10+1 -> 2 | C11: Senior Project Manager | D11: ='Staffing Schedule '!AE28 -> 99.59 | E11: wks | F11: =(O11*40)*M11 -> 5226.99 | G11: =SUM(D11*F11) -> 520555.93 | L11: =SUM(G11+I11+K11) -> 520555.93 | M11: 1 | O11: ='Labor Rates'!G9 -> 130.67475
A12: =A11+1 -> 3 | C12: Project Manager - Level 3 | D12: ='Staffing Schedule '!AE28 -> 99.59 | E12: wks | F12: =(O12*40)*M12 -> 0 | G12: =SUM(D12*F12) -> 0 | L12: =SUM(G12+I12+K12) -> 0 | M12: 0 | O12: ='Labor Rates'!G10 -> 120.34132
A13: =A12+1 -> 4 | C13: Project Manager - Level 2 | D13: =$K$4 -> 99.857143 | E13: wks | F13: =(O13*40)*M13 -> 0 | G13: =SUM(D13*F13) -> 0 | L13: =SUM(G13+I13+K13) -> 0 | M13: 0 | O13: ='Labor Rates'!G11 -> 110.14476
A14: =A13+1 -> 5 | C14: Project Manager - Level 1 | D14: =$K$4 -> 99.857143 | E14: wks | F14: =(O14*40)*M14 -> 3770.6242 | G14: =SUM(D14*F14) -> 376523.76 | L14: =SUM(G14+I14+K14) -> 376523.76 | M14: 1 | O14: ='Labor Rates'!G12 -> 94.265604
A15: =A14+1 -> 6 | C15: Project Administator | D15: ='Staffing Schedule '!AE31 -> 103.92 | E15: wks | F15: =(O15*40)*M15 -> 2660.2099 | G15: =SUM(D15*F15) -> 276449.01 | L15: =SUM(G15+I15+K15) -> 276449.01 | M15: 1 | O15: ='Labor Rates'!G13 -> 66.505247
A16: =A15+1 -> 7 | C16: Project Accountant | D16: ='Staffing Schedule '!AE30 -> 56.29 | E16: wks | F16: =(O16*40)*M16 -> 3432.4016 | G16: =SUM(D16*F16) -> 193209.89 | L16: =SUM(G16+I16+K16) -> 193209.89 | M16: 1 | O16: ='Labor Rates'!G14 -> 85.81004
A17: =A16+1 -> 8 | C17: Assistant Project Manager | D17: ='Staffing Schedule '!AE29 -> 103.92 | E17: wks | F17: =(O17*40)*M17 -> 3309.3425 | G17: =SUM(D17*F17) -> 343906.88 | L17: =SUM(G17+I17+K17) -> 343906.88 | M17: 1 | O17: ='Labor Rates'!G15 -> 82.733564
A18: =A17+1 -> 9 | C18: Superintendent - Level 3 | D18: ='Staffing Schedule '!AE23 -> 99.59 | E18: wks | F18: =(O18*40)*M18 -> 5270.0795 | G18: =SUM(D18*F18) -> 524847.22 | L18: =SUM(G18+I18+K18) -> 524847.22 | M18: 1 | O18: ='Labor Rates'!G16 -> 131.75199
A19: =A18+1 -> 10 | C19: Superintendent - Level 2 | D19: ='Staffing Schedule '!AE25 -> 82.27 | E19: wks | F19: =(O19*40)*M19 -> 4423.6891 | G19: =SUM(D19*F19) -> 363936.9 | L19: =SUM(G19+I19+K19) -> 363936.9 | M19: 1 | O19: ='Labor Rates'!G17 -> 110.59223
A20: =A19+1 -> 11 | C20: Superintendent - Level 1 | D20: 0 | E20: wks | F20: =(O20*40)*M20 -> 0 | G20: =SUM(D20*F20) -> 0 | L20: =SUM(G20+I20+K20) -> 0 | M20: 0 | O20: ='Labor Rates'!G18 -> 90.514804
A21: =A20+1 -> 12 | C21: Assistant Superinterndent #1 | D21: ='Staffing Schedule '!AE24 -> 103.92 | E21: wks | F21: =(O21*40)*M21 -> 2396.6186 | G21: =SUM(D21*F21) -> 249056.61 | L21: =SUM(G21+I21+K21) -> 249056.61 | M21: 1 | O21: ='Labor Rates'!G19 -> 59.915466
A22: =A21+1 -> 13 | C22: Assistant Superinterndent #2 | D22: ='Staffing Schedule '!AE26 -> 86.6 | E22: wks | F22: =(O22*40)*M22 -> 2396.6186 | G22: =SUM(D22*F22) -> 207547.17 | L22: =SUM(G22+I22+K22) -> 207547.17 | M22: 1 | O22: =O21 -> 59.915466
A23: =A22+1 -> 14 | C23: Quality Control Manager | D23: =$K$4 -> 99.857143 | E23: wks | F23: =(O23*40)*M23 -> 823.4591 | G23: =SUM(D23*F23) -> 82228.273 | L23: =SUM(G23+I23+K23) -> 82228.273 | M23: 0.2 | O23: ='Labor Rates'!G20 -> 102.93239
A24: =A23+1 -> 15 | C24: Foreman | D24: =$K$4 -> 99.857143 | E24: wks | F24: =(O24*40)*M24 -> 0 | G24: =SUM(D24*F24) -> 0 | L24: =SUM(G24+I24+K24) -> 0 | M24: 0 | O24: ='Labor Rates'!G21 -> 41.528452
A25: =A24+1 -> 16 | C25: Accounting | D25: =$K$4 -> 99.857143 | E25: wks | F25: =(O25*40)*M25 -> 695.62706 | G25: =SUM(D25*F25) -> 69463.331 | L25: =SUM(G25+I25+K25) -> 69463.331 | M25: 0.15 | O25: ='Labor Rates'!G22 -> 115.93784
A26: =A25+1 -> 17 | C26: VDC Manager | D26: 1 | E26: ls | F26: 91195 | G26: =SUM(D26*F26) -> 91195 | L26: =SUM(G26+I26+K26) -> 91195 | O26: ='Labor Rates'!G23 -> 102.72671
A27: =A26+1 -> 18 | C27: Safety Supervisor/Inspector | D27: =K4 -> 99.857143 | E27: wks | F27: =(O27*40)*M27 -> 637.87174 | G27: =SUM(D27*F27) -> 63696.05 | L27: =SUM(G27+I27+K27) -> 63696.05 | M27: 0.2 | O27: ='Labor Rates'!G24 -> 79.733968
C28: Field Labor - Close Out | L28: =SUM(L29:L45) -> 244139.02
A29: 1 | C29: Project Executive | D29: =$K$5 -> 8.66 | E29: wks | F29: =(40*O29)*M29 -> 315.33313 | G29: =SUM(D29*F29) -> 2730.7849 | L29: =SUM(G29+I29+K29) -> 2730.7849 | M29: 0.05 | O29: =O10 -> 157.66656
A30: =A29+1 -> 2 | C30: Senior Project Manager | D30: =$K$5 -> 8.66 | E30: wks | F30: =(40*O30)*M30 -> 5226.99 | G30: =SUM(D30*F30) -> 45265.733 | L30: =SUM(G30+I30+K30) -> 45265.733 | M30: =+M11 -> 1 | O30: =O11 -> 130.67475
A31: =A30+1 -> 3 | C31: Project Manager - Level 3 | D31: =$K$5 -> 8.66 | E31: wks | F31: =(40*O31)*M31 -> 0 | G31: =SUM(D31*F31) -> 0 | L31: =SUM(G31+I31+K31) -> 0 | M31: =+M12 -> 0 | O31: =O12 -> 120.34132
A32: =A31+1 -> 4 | C32: Project Manager - Level 2 | D32: =$K$5 -> 8.66 | E32: wks | F32: =(40*O32)*M32 -> 0 | G32: =SUM(D32*F32) -> 0 | L32: =SUM(G32+I32+K32) -> 0 | M32: =+M13 -> 0 | O32: =O13 -> 110.14476
A33: =A32+1 -> 5 | C33: Project Manager - Level 1 | D33: =$K$5 -> 8.66 | E33: wks | F33: =(40*O33)*M33 -> 3770.6242 | G33: =SUM(D33*F33) -> 32653.605 | L33: =SUM(G33+I33+K33) -> 32653.605 | M33: =+M14 -> 1 | O33: =O14 -> 94.265604
A34: =A33+1 -> 6 | C34: Project Administator | D34: =$K$5 -> 8.66 | E34: wks | F34: =(40*O34)*M34 -> 2660.2099 | G34: =SUM(D34*F34) -> 23037.418 | L34: =SUM(G34+I34+K34) -> 23037.418 | M34: =+M15 -> 1 | O34: =O15 -> 66.505247
A35: =A34+1 -> 7 | C35: Project Accountant | D35: =$K$5 -> 8.66 | E35: wks | F35: =(40*O35)*M35 -> 3432.4016 | G35: =SUM(D35*F35) -> 29724.598 | L35: =SUM(G35+I35+K35) -> 29724.598 | M35: =+M16 -> 1 | O35: =O16 -> 85.81004
A36: =A35+1 -> 8 | C36: Assistant Project Manager | D36: =$K$5 -> 8.66 | E36: wks | F36: =(40*O36)*M36 -> 0 | G36: =SUM(D36*F36) -> 0 | L36: =SUM(G36+I36+K36) -> 0 | M36: 0 | O36: =O17 -> 82.733564
A37: =A36+1 -> 9 | C37: Superintendent - Level 3 | D37: =$K$5 -> 8.66 | E37: wks | F37: =(40*O37)*M37 -> 5270.0795 | G37: =SUM(D37*F37) -> 45638.889 | L37: =SUM(G37+I37+K37) -> 45638.889 | M37: =+M18 -> 1 | O37: =O18 -> 131.75199
A38: =A37+1 -> 10 | C38: Superintendent - Level 2 | D38: =$K$5 -> 8.66 | E38: wks | F38: =(40*O38)*M38 -> 4423.6891 | G38: =SUM(D38*F38) -> 38309.148 | L38: =SUM(G38+I38+K38) -> 38309.148 | M38: =+M19 -> 1 | O38: =O19 -> 110.59223
A39: =A38+1 -> 11 | C39: Superintendent - Level 1 | D39: =$K$5 -> 8.66 | E39: wks | F39: =(40*O39)*M39 -> 0 | G39: =SUM(D39*F39) -> 0 | L39: =SUM(G39+I39+K39) -> 0 | M39: 0 | O39: =O20 -> 90.514804
A40: =A39+1 -> 12 | C40: Assistant Superinterndent | D40: =$K$5 -> 8.66 | E40: wks | F40: =(40*O40)*M40 -> 2396.6186 | G40: =SUM(D40*F40) -> 20754.717 | L40: =SUM(G40+I40+K40) -> 20754.717 | M40: 1 | O40: =O21 -> 59.915466
A41: =A40+1 -> 13 | C41: Quality Control Manager | D41: =$K$5 -> 8.66 | E41: wks | F41: =(40*O41)*M41 -> 0 | G41: =SUM(D41*F41) -> 0 | L41: =SUM(G41+I41+K41) -> 0 | M41: =+M24 -> 0 | O41: =O23 -> 102.93239
...

Sheet Labor Rates
A1: ='Area Calculations'!B4 -> ERAU Residential Hall & Garage Building
A3: Hedrick Brothers Construction Co., Inc.
A4: Salaries and Burden Calculations
C6: MARK-UP | F6: 0
E7: Burdened Rate | F7: Mark-up | G7: Total
B8: 1 | C8: Proj Exec | E8: 157.66656 | F8: =E8*$F$6 -> 0 | G8: =SUM(E8:F8) -> 157.66656
B9: 2 | C9: Sr PM | E9: 130.67475 | F9: =E9*$F$6 -> 0 | G9: =SUM(E9:F9) -> 130.67475
B10: 3 | C10: PM 3 | E10: 120.34132 | F10: =E10*$F$6 -> 0 | G10: =SUM(E10:F10) -> 120.34132
B11: 4 | C11: PM 2 | E11: 110.14476 | F11: =E11*$F$6 -> 0 | G11: =SUM(E11:F11) -> 110.14476
B12: 5 | C12: PM 1 | E12: 94.265604 | F12: =E12*$F$6 -> 0 | G12: =SUM(E12:F12) -> 94.265604
B13: 6 | C13: Proj Admin | E13: 66.505247 | F13: =E13*$F$6 -> 0 | G13: =SUM(E13:F13) -> 66.505247
B14: 7 | C14: Proj Acct | E14: 85.81004 | F14: =E14*$F$6 -> 0 | G14: =SUM(E14:F14) -> 85.81004
B15: 8 | C15: Asst PM | E15: 82.733564 | F15: =E15*$F$6 -> 0 | G15: =SUM(E15:F15) -> 82.733564
B16: 9 | C16: Supt 3 | E16: 131.75199 | F16: =E16*$F$6 -> 0 | G16: =SUM(E16:F16) -> 131.75199
B17: 10 | C17: Supt 2 | E17: 110.59223 | F17: =E17*$F$6 -> 0 | G17: =SUM(E17:F17) -> 110.59223
B18: 11 | C18: Supt 1 | E18: 90.514804 | F18: =E18*$F$6 -> 0 | G18: =SUM(E18:F18) -> 90.514804
B19: 12 | C19: Asst Supt | E19: 59.915466 | F19: =E19*$F$6 -> 0 | G19: =SUM(E19:F19) -> 59.915466
... B24: 17 | C24: Safety | E24: 79.733968 | F24: =E24*$F$6 -> 0 | G24: =SUM(E24:F24) -> 79.733968
C25: Labor | E25: 32.408056 | F25: =E25*$F$6 -> 0 | G25: =SUM(E25:F25) -> 32.408056
C26: Apprentice | E26: 32.978211 | F26: =E26*$F$6 -> 0 | G26: =SUM(E26:F26) -> 32.978211
C27: Carpenter | E27: 45.013251 | F27: =E27*$F$6 -> 0 | G27: =SUM(E27:F27) -> 45.013251
C28: Driver | E28: 35.486876 | F28: =E28*$F$6 -> 0 | G28: =SUM(E28:F28) -> 35.486876
C29: Leadman | E29: 46.605242 | F29: =E29*$F$6 -> 0 | G29: =SUM(E29:F29) -> 46.605242
C30: Supt MEP | E30: 0 | F30: =E30*$F$6 -> 0 | G30: =SUM(E30:F30) -> 0
C31: Gen Supt | E31: 130.4108 | F31: =E31*$F$6 -> 0 | G31: =SUM(E31:F31) -> 130.4108
C32: Cons Mgr | E32: 135.45804 | F32: =E32*$F$6 -> 0 | G32: =SUM(E32:F32) -> 135.45804
C33: Proj Coor | E33: 0 | F33: =E33*$F$6 -> 0 | G33: =SUM(E33:F33) -> 0
C34: Mktg | E34: 85.41309 | F34: =E34*$F$6 -> 0 | G34: =SUM(E34:F34) -> 85.41309
C35: Bus Dev | E35: 121.55329 | F35: =E35*$F$6 -> 0 | G35: =SUM(E35:F35) -> 121.55329
C36: Chief, 3 & 2 | E36: 140.9198 | F36: =E36*$F$6 -> 0 | G36: =SUM(E36:F36) -> 140.9198
... C38: Exec Asst | E38: 69.670191 | F38: =E38*$F$6 -> 0 | G38: =SUM(E38:F38) -> 69.670191

Sheet Staffing Schedule 
A1: Embry Riddle Aeronautical University
A2: STAFFING SCHEDULE
B3: PROJECT DURATION 24 Months
A4: YEAR | B4: 2025 | C4: thru | D4: 2027
A5: MONTHS | B5: Sept | C5: Oct | D5: Nov | E5: Dec | F5: Jan | G5: Feb | H5: Mar | I5: April | J5: May | K5: Jun | L5: July | M5: Aug | N5: Sept | O5: Oct | P5: Nov | Q5: Dec | R5: Jan | S5: Feb | T5: Mar | U5: April | V5: May | W5: Jun | X5: July | Y5: Aug
A6: 4 Story | B6: 1 | C6: 2 | D6: 3 | E6: 4 | F6: 5 | G6: 6 | H6: 7 | I6: 8 | J6: 9 | K6: 10 | L6: 11 | M6: 12 | N6: 13 | O6: 14 | P6: 15 | Q6: 16 | R6: 17 | S6: 18 | T6: 19 | U6: 20 | V6: 21 | W6: 22 | X6: 23 | Y6: 24 | AD6: Close Out Nov/ Dec | AE6: 45896
A7: INITIAL SITEWORK
A8: Infrastrure
A9: Foundation
A10: Erect Phase South A
A11: Erect Phase South B
A12: Erect Phase North A
A13: Erect Phase North B
A14: INTERIORS South A
A15: Building South Side A Envelope
A16: Interiors Phase South B
A17: Building Envelope Building South B
A18: INTERIORS North Side A
... A22: TCO/ Punch list
A23: LEAD SUPERINTENDENT | B23: 1 | C23: 1 | D23: 1 | E23: 1 | F23: 1 | G23: 1 | H23: 1 | I23: 1 | J23: 1 | K23: 1 | L23: 1 | M23: 1 | N23: 1 | O23: 1 | P23: 1 | Q23: 1 | R23: 1 | S23: 1 | T23: 1 | U23: 1 | V23: 1 | W23: 1 | X23: 1 | AD23: =SUM(B23:AC23) -> 23 | AE23: =AD23*4.33 -> 99.59
A24: ASSISTANT SUPERINTENDENT | B24: 1 | C24: 1 | D24: 1 | E24: 1 | F24: 1 | G24: 1 | H24: 1 | I24: 1 | J24: 1 | K24: 1 | L24: 1 | M24: 1 | N24: 1 | O24: 1 | P24: 1 | Q24: 1 | R24: 1 | S24: 1 | T24: 1 | U24: 1 | V24: 1 | W24: 1 | X24: 1 | Y24: 1 | AD24: =SUM(B24:AC24) -> 24 | AE24: =AD24*4.33 -> 103.92
A25: PROJECT SUPERINTENDENT | G25: 1 | H25: 1 | I25: 1 | J25: 1 | K25: 1 | L25: 1 | M25: 1 | N25: 1 | O25: 1 | P25: 1 | Q25: 1 | R25: 1 | S25: 1 | T25: 1 | U25: 1 | V25: 1 | W25: 1 | X25: 1 | Y25: 1 | AD25: =SUM(B25:AC25) -> 19 | AE25: =AD25*4.33 -> 82.27
A26: ASSISTANT SUPERINTENDENT | E26: 1 | F26: 1 | G26: 1 | H26: 1 | I26: 1 | J26: 1 | K26: 1 | L26: 1 | M26: 1 | N26: 1 | O26: 1 | P26: 1 | Q26: 1 | R26: 1 | S26: 1 | T26: 1 | U26: 1 | V26: 1 | W26: 1 | X26: 1 | AD26: =SUM(B26:AC26) -> 20 | AE26: =AD26*4.33 -> 86.6
A27: PROJECT EXECUTIVE | B27: 1 | C27: 1 | D27: 1 | E27: 1 | F27: 1 | G27: 1 | H27: 1 | I27: 1 | J27: 1 | K27: 1 | L27: 1 | M27: 1 | N27: 1 | AD27: =SUM(B27:AC27) -> 13 | AE27: =AD27*4.33 -> 56.29
A28: SENIOR PROJECT MANAGER | B28: 1 | C28: 1 | D28: 1 | E28: 1 | F28: 1 | G28: 1 | H28: 1 | I28: 1 | J28: 1 | K28: 1 | L28: 1 | M28: 1 | N28: 1 | O28: 1 | P28: 1 | Q28: 1 | R28: 1 | S28: 1 | T28: 1 | U28: 1 | V28: 1 | W28: 1 | X28: 1 | AD28: =SUM(B28:AC28) -> 23 | AE28: =AD28*4.33 -> 99.59
A29: APM | B29: 1 | C29: 1 | D29: 1 | E29: 1 | F29: 1 | G29: 1 | H29: 1 | I29: 1 | J29: 1 | K29: 1 | L29: 1 | M29: 1 | N29: 1 | O29: 1 | P29: 1 | Q29: 1 | R29: 1 | S29: 1 | T29: 1 | U29: 1 | V29: 1 | W29: 1 | X29: 1 | Y29: 1 | AD29: =SUM(B29:AC29) -> 24 | AE29: =AD29*4.33 -> 103.92
A30: PROJECT ACCOUNTANT | B30: 1 | C30: 1 | D30: 1 | E30: 1 | F30: 1 | G30: 1 | H30: 1 | I30: 1 | J30: 1 | K30: 1 | L30: 1 | M30: 1 | N30: 1 | AD30: =SUM(B30:AC30) -> 13 | AE30: =AD30*4.33 -> 56.29
A31: PA | B31: 1 | C31: 1 | D31: 1 | E31: 1 | F31: 1 | G31: 1 | H31: 1 | I31: 1 | J31: 1 | K31: 1 | L31: 1 | M31: 1 | N31: 1 | O31: 1 | P31: 1 | Q31: 1 | R31: 1 | S31: 1 | T31: 1 | U31: 1 | V31: 1 | W31: 1 | X31: 1 | Y31: 1 | AD31: =SUM(B31:AC31) -> 24 | AE31: =AD31*4.33 -> 103.92
A32: FOREMAN | B32: 1 | C32: 1 | D32: 1 | E32: 1 | F32: 1 | G32: 1 | H32: 1 | I32: 1 | J32: 1 | K32: 1 | L32: 1 | M32: 1 | N32: 1 | O32: 1 | P32: 1 | Q32: 1 | R32: 1 | S32: 1 | T32: 1 | U32: 1 | V32: 1 | W32: 1 | X32: 1 | Y32: 1 | AD32: =SUM(B32:AC32) -> 24 | AE32: =AD32*4.33 -> 103.92
A33: FOREMAN | AD33: =SUM(B33:AC33) -> 0 | AE33: =AD33*4.33 -> 0
A34: CARPENTER | B34: 1 | C34: 1 | D34: 1 | E34: 1 | F34: 1 | G34: 1 | H34: 1 | I34: 1 | J34: 1 | K34: 1 | L34: 1 | M34: 1 | N34: 1 | O34: 1 | P34: 1 | Q34: 1 | R34: 1 | S34: 1 | T34: 1 | U34: 1 | V34: 1 | W34: 1 | X34: 1 | Y34: 1 | AD34: =SUM(B34:AC34) -> 24 | AE34: =AD34*4.33 -> 103.92
A35: CARPETNER | E35: 1 | F35: 1 | G35: 1 | H35: 1 | I35: 1 | J35: 1 | K35: 1 | L35: 1 | M35: 1 | N35: 1 | O35: 1 | P35: 1 | Q35: 1 | R35: 1 | S35: 1 | T35: 1 | U35: 1 | V35: 1 | W35: 1 | AD35: =SUM(B35:AC35) -> 19 | AE35: =AD35*4.33 -> 82.27

Sheet 02 21 Survey 
G1: Hedrick Plug
F2: X | G2: Excluded
F3: I | G3: Included
B4: BACK TO SUMMARY SHEET | G4: Sub Add/Deduct | H4: Bidder 1 | J4: Bidder 2 | L4: Bidder 3 | N4: Bidder 4 | P4: Bidder 5 | R4: Bidder 6
A5: Project: | B5: ='Area Calculations'!B4 -> ERAU Residential Hall & Garage Building | G5: Company | H5: American Layout & Land Surveying | J5: Leading Edge Land Serv | L5: MacGillivray & Co | N5: Carnahan Proctor & Cross | P5: Pacifica Engineering Services | R5: RYANIK
A6: Trade: | B6: Survey | G6: Contact | H6: Lisa Rizzi | J6: Karol J. Hofius | L6: Arlene Wroblewski
A7: CSI Code: | B7: 02 21 00 | G7: Phone | H7: (732) 807-6250 | J7: (407) 351-6730 | L7: (631) 291-8886
A8: Date: | G8: Email | H8: estimating@americansurveyors.us | J8: khofius@leadingedgels.com | L8: bids@macgillivraysurveying.com
G9: Adjusted Bid | H9: =I58 -> 59300 | J9: =K58 -> 72365 | L9: =M58 -> 105919.77 | N9: =O58 -> 0 | P9: =Q58 -> 0 | R9: =S58 -> 0
C10: Plan/ Spec. Package | D10: QTY | E10: U/M | F10: Unit Cost | G10: Subtotal | H10: Yes/No | I10: Price | J10: Yes/No | K10: Price | L10: Yes/No | M10: Price | N10: Yes/No | O10: Price | P10: Yes/No | Q10: Price | R10: Yes/No | S10: Price
B11: GENERAL INCLUSIONS
B12: INCLUDES ALL SALES TAX | H12: i | J12: i | L12: i
B13: ALL HOISTING & RIGGING REQUIRED TO COMPLETE THIS SCOPE | H13: i | J13: i | L13: i
B14: PROVIDE P&P BONDS | H14: x | J14: x | L14: x
B15: FLORIDA STATE CONTRACTORS LIC. | H15: i | J15: i | L15: i
B16: GENERAL LIABILITY AND WORKERS COMP. INSURANCE LIMITS | H16: i | J16: i | L16: i
B17: STATE AND LOCAL TAXES | H17: i | J17: i | L17: i
B18: COMPASS | H18: x | J18: x | K18: {5.0} | L18: x
B19: SPECIFIC TRADE SCOPE OF WORK REQUIREMENTS
B20: BASE BID
B22: Verify and Set Horizontal & Vertical Control | H22: I | I22: 2100 | J22: I | K22: 1820 | L22: I | M22: 7416.75
B23: Builidng Layout | H23: I | I23: =750+2800+500 -> 4050 | J23: I | K23: 7270 | L23: I | M23: 45311.75
B24: Parking Garage Layout | H24: I | I24: 0 | J24: I | K24: 9190 | L24: I | M24: 0
B25: Foundations Surveys | H25: I | I25: 1500 | J25: I | K25: 5345 | L25: I | M25: 0
B27: Sitework | M27: 33039.1
B28: Site boundary | H28: I | I28: 845 | K28: 845 | L28: I
B29: Detention Basins | H29: I | I29: 2000 | K29: 2000 | L29: I
B30: Utilities | H30: I | I30: =10950+1050+2150+150 -> 14300 | K30: 14300 | L30: I
B31: Curb Layout | H31: I | I31: 3675 | K31: 3675 | L31: I
B32: Sidewalks | H32: I | I32: 4785 | K32: 4785 | L32: I
B33: Trash Enclosure | H33: I | I33: 350 | J33: I | K33: 910 | L33: I
B34: Transformer Pad | H34: I | I34: 600 | J34: I | L34: I
B35: Generator Enclosure | H35: I | I35: 350 | L35: I
B36: Site Lighting | H36: I | I36: 1350 | J36: I | K36: 2225 | L36: I
B38: Site As-builts | H38: I | I38: =3895+19500 -> 23395 | K38: 20000 | M38: 20152.17
F54: SUBTOTAL | I54: =SUM(I20:I53) -> 59300 | K54: =SUM(K20:K53) -> 72365 | M54: =SUM(M20:M53) -> 105919.77 | O54: =SUM(O20:O53) -> 0 | Q54: =SUM(Q20:Q53) -> 0 | S54: =SUM(S20:S53) -> 0
F55: BOND RATE | H55: 0 | J55: 0 | L55: 0 | N55: 0 | P55: 0 | R55: 0
F56: BOND AMOUNT | I56: =H55*I54 -> 0 | K56: =J55*K54 -> 0 | M56: =L55*M54 -> 0 | O56: =N55*O54 -> 0 | Q56: =P55*Q54 -> 0 | S56: =R55*S54 -> 0
F58: ADJUSTED TOTAL | I58: =SUM(I54:I56) -> 59300 | K58: =SUM(K54:K56) -> 72365 | M58: =SUM(M54:M56) -> 105919.77 | O58: =SUM(O54:O56) -> 0 | Q58: =SUM(Q54:Q56) -> 0 | S58: =SUM(S54:S56) -> 0
F59: Cost per SF | I59: =I58/'Area Calculations'!$G$4 -> 0.10247761 | K59: =K58/'Area Calculations'!$G$4 -> 0.12505552 | M59: =M58/'Area Calculations'!$G$4 -> 0.18304224 | O59: =O58/'Area Calculations'!$G$4 -> 0 | Q59: =Q58/'Area Calculations'!$G$4 -> 0 | R59: =R58/'Area Calculations'!$G$4 -> 0 | S59: =S58/'Cost Summary'!#REF! -> #REF!
...

Sheet 02 41 Demolition
G1: Hedrick Plug
F2: X | G2: Excluded
F3: I | G3: Included
B4: BACK TO SUMMARY SHEET | G4: Sub Add/Deduct | H4: Bidder 1 | J4: Bidder 2 | L4: Bidder 3 | N4: Bidder 4 | P4: Bidder5 | R4: Bidder6
A5: Project: | B5: ='Area Calculations'!B4 -> ERAU Residential Hall & Garage Building | G5: Company
A6: Trade: | B6: Demolition | G6: Contact
A7: CSI Code: | B7: 02 41 00 | G7: Phone
A8: Date: | G8: Email
G9: Adjusted Bid | H9: =I55 -> 0 | J9: =K55 -> 0 | L9: =M55 -> 0 | N9: =O55 -> 0 | P9: =Q55 -> 0 | R9: =S55 -> 0
C10: Plan/ Spec. Package | D10: QTY | E10: U/M | F10: Unit Cost | G10: Subtotal | H10: Yes/No | I10: Price | J10: Yes/No | K10: Price | L10: Yes/No | M10: Price | N10: Yes/No | O10: Price | P10: Yes/No | Q10: Price | R10: Yes/No | S10: Price
B11: GENERAL INCLUSIONS
B12: INCLUDES ALL SALES TAX
B13: ALL HOISTING & RIGGING REQUIRED TO COMPLETE THIS SCOPE
B14: PROVIDE P&P BONDS
B15: FLORIDA STATE CONTRACTORS LIC.
B16: GENERAL LIABILITY AND WORKERS COMP. INSURANCE LIMITS
B17: STATE AND LOCAL TAXES
B18: SPECIFIC TRADE SCOPE OF WORK REQUIREMENTS
B19: BASE BID
F51: SUBTOTAL | I51: =SUM(I11:I50) -> 0 | K51: =SUM(K11:K50) -> 0 | M51: =SUM(M11:M50) -> 0 | O51: =SUM(O11:O50) -> 0 | Q51: =SUM(Q11:Q50) -> 0 | S51: =SUM(S11:S50) -> 0
F52: BOND RATE | H52: 0 | J52: 0 | L52: 0 | N52: 0 | P52: 0 | R52: 0
F53: BOND AMOUNT | I53: =H52*I51 -> 0 | K53: =J52*K51 -> 0 | M53: =L52*M51 -> 0 | O53: =N52*O51 -> 0 | Q53: =P52*Q51 -> 0 | S53: =R52*S51 -> 0
F55: ADJUSTED TOTAL | I55: =SUM(I51:I53) -> 0 | K55: =SUM(K51:K53) -> 0 | M55: =SUM(M51:M53) -> 0 | O55: =SUM(O51:O53) -> 0 | Q55: =SUM(Q51:Q53) -> 0 | S55: =SUM(S51:S53) -> 0
F56: Cost per SF | I56: =I55/'Area Calculations'!$G$4 -> 0 | K56: =K55/'Area Calculations'!$G$4 -> 0 | M56: =M55/'Area Calculations'!$G$4 -> 0 | O56: =O55/'Area Calculations'!$G$4 -> 0 | Q56: =Q55/'Area Calculations'!$G$4 -> 0 | S56: =S55/'Area Calculations'!$G$4 -> 0
F57: Cost per Unit | I57: =I55/'Area Calculations'!$G$9 -> 0 | K57: =K55/'Area Calculations'!$G$9 -> 0 | M57: =M55/'Area Calculations'!$G$9 -> 0 | O57: =O55/'Area Calculations'!$G$9 -> 0 | Q57: =Q55/'Area Calculations'!$G$9 -> 0 | S57: =S55/'Area Calculations'!$G$9 -> 0
A59: QUALIFICATIONS
A63: EXCLUSIONS/OWNER PROVIDED ITEMS:
A67: ALTERNATES:
A71: PROPOSED VE (Provide Clear Description):
A75: FULLY LOADED LABOR RATES
B76: Laborer
B77: Mechanic
B78: Superintendent
B79: Project Manager
A81: SCHEDULE
B82: Prepared shop drawings/submittals
B83: Mobilization
B84: Total duration to complete scope of work
A86: Winner
A87: Company
...

Sheet 02 50 Site Maint
G1: Hedrick Plug
F2: X | G2: Excluded
F3: I | G3: Included
B4: BACK TO SUMMARY SHEET | G4: Sub Add/Deduct | H4: Bidder 1 | J4: Bidder 2 | L4: Bidder 3 | N4: Bidder 4 | P4: Bidder5 | R4: Bidder6
A5: Project: | B5: ='Area Calculations'!B4 -> ERAU Residential Hall & Garage Building | G5: Company | J5: Oneliance | L5: Milclean USA
A6: Trade: | B6: Site Maintenance | G6: Contact | J6: Justin Dossie | L6: Karina Correa
A7: CSI Code: | B7: 02 10 | G7: Phone | J7: (757) 812-5650 | L7: (954) 681-3641
A8: Date: | G8: Email | J8: jdossie@oneliance.com | L8: karina@milcleanusa.com
A9: Base Bid | G9: Base Bid | H9: =I61 -> 1781647.2 | J9: =K61 -> 199490 | L9: =M61 -> 155983.11 | N9: =O61 -> 0 | P9: =Q61 -> 0 | R9: =S61 -> 0
C10: Plan/ Spec. Package | D10: QTY | E10: U/M | F10: Unit Cost | G10: Subtotal | H10: Yes/No | I10: Price | J10: Yes/No | K10: Price | L10: Yes/No | M10: Price | N10: Yes/No | O10: Price | P10: Yes/No | Q10: Price | R10: Yes/No | S10: Price
B11: GENERAL INCLUSIONS
B12: INCLUDES ALL SALES TAX
B13: ALL HOISTING & RIGGING REQUIRED TO COMPLETE THIS SCOPE
B14: PROVIDE P&P BONDS
B15: FLORIDA STATE CONTRACTORS LIC.
B16: GENERAL LIABILITY AND WORKERS COMP. INSURANCE LIMITS
B17: STATE AND LOCAL TAXES
B18: SPECIFIC TRADE SCOPE OF WORK REQUIREMENTS
B19: BASE BID
B22: Construction fence | D22: 2274 | E22: lf | F22: 12 | G22: =D22*F22 -> 27288 | I22: =G22 -> 27288
B23: Construction gates | D23: 2 | E23: ea | F23: 10000 | G23: =D23*F23 -> 20000 | I23: =G23 -> 20000
B24: Maintenance during construction | D24: 1 | E24: ls | F24: 3000 | G24: =D24*F24 -> 3000 | I24: =G24 -> 3000
B25: Street Maintenance & Cleaning | D25: 1 | E25: ls | F25: 50000 | G25: =D25*F25 -> 50000 | I25: =G25 -> 50000
B26: Final Cleaning - garage - pressure wash | D26: =54077+(51436*5) -> 311257 | E26: sf | F26: 0.15 | G26: =D26*F26 -> 46688.55 | I26: =G26 -> 46688.55 | K26: 46710 | M26: 9337.71
B27: Final Cleaning - building | D27: =578663-D26 -> 267406 | E27: sf | F27: 0.5 | G27: =D27*F27 -> 133703 | I27: =G27 -> 133703 | K27: 108780 | M27: =78673+10500+24396.81-M26 -> 104232.1
B28: Final Cleaning - building windows exterior | D28: ='08 50 Storefront & Windows'!AC66 -> 33930.643 | E28: sf | F28: 1.25 | G28: =D28*F28 -> 42413.304 | I28: =G28 -> 42413.304 | K28: 44000 | M28: =$G28 -> 42413.304
B29: Concrete Wash-out | E29: ls | F29: 10000 | G29: =D29*F29 -> 0 | I29: =G29 -> 0
B30: Construction waste removal / recycle | E30: ls | F30: 8000 | G30: =D30*F30 -> 0 | I30: =G30 -> 0
B31: Temp Parking | G31: =D31*F31 -> 0 | I31: =G31 -> 0
B32: Bus - buy 2 | D32: 2 | E32: ea | F32: 35000 | G32: =D32*F32 -> 70000 | I32: =G32 -> 70000
B33: Bus - drivers - 2 | D33: ='GCs & GRs'!K4 -> 99.857143 | E33: wks | F33: =2*8*5*35 -> 2800 | G33: =D33*F33 -> 279600 | I33: =G33 -> 279600
B34: Bus - fuel & maint | D34: ='GCs & GRs'!K4 -> 99.857143 | E34: wks | F34: =20/5*5*5*2 -> 200 | G34: =D34*F34 -> 19971.429 | I34: =G34 -> 19971.429
B35: Parking control | D35: ='GCs & GRs'!K4 -> 99.857143 | E35: wks | F35: =2*8*5*35 -> 2800 | G35: =D35*F35 -> 279600 | I35: =G35 -> 279600
B36: Dumpster | D36: ='GCs & GRs'!K4 -> 99.857143 | E36: wks | F36: =4*600 -> 2400 | G36: =D36*F36 -> 239657.14 | I36: =G36 -> 239657.14
B37: Trash Chute | D37: 8 | E37: mo | F37: =40000/8 -> 5000 | G37: =D37*F37 -> 40000
B38: Labor | D38: ='GCs & GRs'!K4 -> 99.857143 | E38: wks | F38: =2*8*55 -> 880 | G38: =D38*F38 -> 87874.286 | I38: =G38 -> 87874.286
B39: Floor Protection | D39: =D27 -> 267406 | E39: sf | F39: 0.25 | G39: =D39*F39 -> 66851.5 | I39: =G39 -> 66851.5
B40: MOT | D40: 1 | E40: ls | F40: 50000 | G40: =D40*F40 -> 50000 | I40: =G40 -> 50000
B41: Safety rails, Penetration Covers & Maintenance of rails | E41: ls | F41: 5000 | G41: =D41*F41 -> 0 | I41: =G41 -> 0
B42: Polution Coverage | D42: 1 | E42: ls | F42: 15000 | G42: =D42*F42 -> 15000 | I42: =G42 -> 15000
...

Sheet 03 30 CIP Concrete
G1: Hedrick Plug
F2: X | G2: Excluded
F3: I | G3: Included
B4: BACK TO SUMMARY SHEET | G4: Sub Add/Deduct | H4: Bidder 1 | J4: Bidder 7 | L4: Bidder2 | N4: Bidder 3 | P4: Bidder 5 | R4: Bidder 4 | T4: Bidder 6 | V4: Bidder 8 | X4: Bidder 9
A5: Project: | B5: ='Area Calculations'!B4 -> ERAU Residential Hall & Garage Building | G5: Company | H5: DeWitt Custom Concrete | J5: Don Kings Concrete | L5: 2000 Concrete | N5: Starlite | P5: Baker Concrete | R5: Legomatic Construction | T5: Core Concrete | V5: Genesis Concrete Struct | X5: Leo's Concrete Specilaties
A6: Trade: | B6: Concrete | G6: Contact | H6: Tim Streeter | J6: Dan Belanger | L6: Sebastian Lopez | N6: Sean Williams | P6: Allison Mickley | R6: Casey Isaac
A7: CSI Code: | B7: 03 30 00 | G7: Phone | H7: (786) 208.8458 | J7: (407) 977-9001 | L7: (239) 687.8581 | N7: (561) 719-7607 | P7: (407) 205-3776 | R7: (386) 216-6335
A8: Date: | G8: Email | H8: tim@dewittcc.com | J8: DBelanger@dkcfl.com | L8: slopez@2000concrete.com | N8: SeWilliams@starlitebuild.com | P8: MickleyA@BakerConcrete.com | R8: caseyisaac@legomaticconstruction.com
G9: Adjusted Bid | H9: =I96 -> 6808725.6 | J9: =K96 -> 5700849.3 | L9: =M96 -> 5882569.3 | N9: =O96 -> 6755331.3 | P9: =Q96 -> 6892046.3 | R9: =S96 -> 8202620.9 | T9: =U96 -> 0 | V9: =W96 -> 0 | X9: =Y96 -> 0
C10: Plan/ Spec. Package | D10: QTY | E10: U/M | F10: Unit Cost | G10: Subtotal | H10: Yes/No | I10: Price | J10: Yes/No | K10: Price | L10: Yes/No | M10: Price | N10: Yes/No | O10: Price | P10: Yes/No | Q10: Price | R10: Yes/No | S10: Price | T10: Yes/No | U10: Price | V10: Yes/No | W10: Price | X10: Yes/No | Y10: Price
B11: GENERAL INCLUSIONS
B12: INCLUDES ALL SALES TAX | H12: i
B13: ALL HOISTING & RIGGING REQUIRED TO COMPLETE THIS SCOPE | H13: i
B14: PROVIDE P&P BONDS | H14: x | I14: {2.0%}
B15: FLORIDA STATE CONTRACTORS LIC. | H15: i
B16: GENERAL LIABILITY AND WORKERS COMP. INSURANCE LIMITS | H16: i
B17: STATE AND LOCAL TAXES | H17: i
B18: COMPASS | H18: x | I18: {6.0}
B19: SPECIFIC TRADE SCOPE OF WORK REQUIREMENTS
B20: BASE BID | I20: =4845635 -> 4845635 | K20: =5459900-K66-K67 -> 3654100 | M20: =5448000-M66-M67 -> 4053489 | O20: =6133682-O66 -> 4514629 | Q20: 4828019 | S20: =8426760.93-S76-S79 -> 8335834.9
AG21: + 20" spoils
B22: Foundations | H22: I | J22: I | L22: I | N22: I | P22: I | R22: I | AG22: =20/12 -> 1.6666667
A23: =D23 -> 1504 | B23: Mat 36" | D23: 1504 | E23: cy | F23: 650 | G23: =D23*F23 -> 977600 | AC23: 13537 | AD23: SF | AG23: =$AG$22*AC23/27 -> 835.61728
A24: =D24 -> 1268 | B24: Mat 48" | D24: 1268 | E24: cy | F24: 650 | G24: =D24*F24 -> 824200 | AC24: 8558 | AD24: SF | AG24: =$AG$22*AC24/27 -> 528.2716
A25: =D25 -> 287 | B25: Mat 60" | D25: 287 | E25: cy | F25: 650 | G25: =D25*F25 -> 186550 | AC25: 1550 | AD25: SF | AG25: =$AG$22*AC25/27 -> 95.679012
A26: =D26 -> 48 | B26: Footing - F14.0 | D26: 48 | E26: cy | F26: 650 | G26: =D26*F26 -> 31200 | AA26: 7 | AB26: Footing - F14.0 | AC26: 2 | AD26: EA | AE26: 48 | AF26: CY | AG26: =14*14*AG22/27*2 -> 24.197531
A27: =D27 -> 49 | B27: Footing - F20.0 | D27: 49 | E27: cy | F27: 650 | G27: =D27*F27 -> 31850 | AA27: 8 | AB27: Footing - F20.0 | AC27: 2 | AD27: EA | AE27: 0 | AG27: =20*11*AG22/27*2 -> 27.160494
A28: =D28 -> 158 | B28: Footing - F43.0 | D28: 158 | E28: cy | F28: 650 | G28: =D28*F28 -> 102700 | AA28: 9 | AB28: Footing - F43.0 | AC28: 2 | AD28: EA | AE28: 0 | AG28: =43*11*AG22/27*2 -> 58.395062
A29: =D29 -> 31 | B29: Footing - CF2.5 | D29: 31 | E29: cy | F29: 650 | G29: =D29*F29 -> 20150 | AA29: 10 | AB29: Footing - CF2.5 | AC29: 133 | AD29: LF | AE29: 31 | AF29: CY | AG29: =2.5*133*2/27 -> 24.62963
A30: =D30 -> 17 | B30: Footing - CF4.0 | D30: 17 | E30: cy | F30: 650 | G30: =D30*F30 -> 11050 | AA30: 11 | AB30: Footing - CF4.0 | AC30: 46 | AD30: LF | AE30: 17 | AF30: CY | AG30: =4*46*AG22/27 -> 11.358025
A31: =D31 -> 580 | B31: Footing - CF7.0 | D31: 580 | E31: cy | F31: 650 | G31: =D31*F31 -> 377000 | AA31: 12 | AB31: Footing - CF7.0 | AC31: 895 | AD31: LF | AE31: 580 | AF31: CY | AG31: =7*895*AG22/27 -> 386.7284
A32: =D32 -> 316 | B32: Footing - CF10.0 | D32: 316 | E32: cy | F32: 650 | G32: =D32*F32 -> 205400 | AA32: 13 | AB32: Footing - CF10.0 | AC32: 342 | AD32: LF | AE32: 316 | AF32: CY | AG32: =10*242*AG22/27 -> 149.38272
A33: =D33 -> 651 | B33: Footing - CF16.0 | D33: 651 | E33: cy | F33: 650 | G33: =D33*F33 -> 423150 | AA33: 14 | AB33: Footing - CF16.0 | AC33: 366 | AD33: LF | AE33: 651 | AF33: CY | AG33: =16*366*AG22/27 -> 361.48148
A34: =D34 -> 8 | B34: Footing - CMU walls | D34: 8 | E34: cy | F34: 650 | G34: =D34*F34 -> 5200 | AF34: to top of footing | AG34: =SUM(AG23:AG33) -> 2502.9012 | AH34: cy
G35: =D35*F35 -> 0 | AF35: footings | AG35: =SUM(D23:D34) -> 4917 | AH35: cy
B36: Slabs on grade | G36: =D36*F36 -> 0 | H36: I | J36: I | L36: I | N36: I | P36: I | R36: I | AG36: =SUM(AG34:AG35) -> 7419.9012 | AH36: cy
A37: =D37*0.33/27 -> 506.59889 | B37: SOG - 4" | D37: 41449 | E37: sf | F37: 8 | G37: =D37*F37 -> 331592
A38: =D38*0.42/27 -> 928.07556 | B38: SOG - 5" | D38: 59662 | E38: sf | F38: 10 | G38: =D38*F38 -> 596620
G39: =D39*F39 -> 0
B40: CIP Walls | G40: =D40*F40 -> 0 | H40: I | J40: I | L40: I | N40: I | P40: I | R40: I
...

Sheet 03 41 Precast Hollow Core
G1: Hedrick Plug
F2: X | G2: Excluded
F3: I | G3: Included
B4: BACK TO SUMMARY SHEET | G4: Sub Add/Deduct | H4: Bidder1 | J4: Bidder 2 | L4: Bidder 3 | N4: Bidder 4 | P4: Bidder 5 | R4: Bidder 6
A5: Project: | B5: ='Area Calculations'!B4 -> ERAU Residential Hall & Garage Building | G5: Company | H5: Metromont
A6: Trade: | B6: Precast Hollow Core | G6: Contact | H6: Eric Scherden
A7: CSI Code: | B7: 03 41 00 | G7: Phone | H7: 813-417-8796
A8: Date: | G8: Email | H8: escherden@metromont.com
G9: Adjusted Bid | H9: =I88 -> 21767756 | J9: =K88 -> 0 | L9: =M88 -> 0 | N9: =O88 -> 0 | P9: =Q88 -> 0 | R9: =S88 -> 0
C10: Plan/ Spec. Package | D10: QTY | E10: U/M | F10: Unit Cost | G10: Subtotal | H10: Yes/No | I10: Price | J10: Yes/No | K10: Price | L10: Yes/No | M10: Price | N10: Yes/No | O10: Price | P10: Yes/No | Q10: Price | R10: Yes/No | S10: Price
B11: GENERAL INCLUSIONS
B12: INCLUDES ALL SALES TAX | H12: i
B13: ALL HOISTING & RIGGING REQUIRED TO COMPLETE THIS SCOPE | H13: i
B14: PROVIDE P&P BONDS | H14: x | I14: {0.525%}
B15: FLORIDA STATE CONTRACTORS LIC. | H15: i
B16: GENERAL LIABILITY AND WORKERS COMP. INSURANCE LIMITS | H16: i
B17: STATE AND LOCAL TAXES | H17: i
B18: COMPASS | H18: x | I18: {4.0}
B19: SPECIFIC TRADE SCOPE OF WORK REQUIREMENTS
B20: BASE BID | I20: 20274020
B21: Residence Hall Dorms
B22: All precast columns CLA 24x24 | C22: E0.05, E1.01 | D22: 16 | H22: i
B23: Field topped double Tee FTA | C23: E0.05 | H23: i
B24: L Girders LGA 18x48 | C24: E0.05 | H24: i
B25: Factory topped Metrodeck 9" MDK for the roof | C25: E0.06, E2.06 | H25: i
B26: Factory topped Metrodeck 10" MDK Skimcoat for all floors | C26: E0.06, E2.01 | H26: i
B27: Horizontzl insulated wall panels WPB 11" and 12" with return | C27: E0.07 | H27: i
B28: Horizontzl soild wall panels WPB 8" | H28: i
B29: Vertical insulated wall panels WPB 11" with return | C29: E0.07 | H29: i
B30: Vertical insulated wall panels Non-Thermal WPB 11" | C30: E0.07 | H30: i
B31: Vertical solid wall panels Non-Insulated WPB 8" | C31: E0.07 | H31: i
B33: Parking Garage
B34: All precast columns CLA 96x16 | C34: E1.01 | D34: 4 | H34: i
B35: All precast columns CLA 24x33 | C35: E1.01 | D35: 4 | H35: i
B36: Facyory topped double Tee FTA DT | C36: E0.05, E2.02 | D36: 242000 | E36: SF | H36: i
B37: Flat slabs FS 8" | C37: E0.05 | H37: i
B38: Litewall vertical MWV 8" | C38: E0.05 | H38: i
B39: R beams RBA 8x30 | C39: E0.05 | H39: i
B40: Vertical shear walls SWA 12" | C40: E0.05 S113 | H40: i
B41: Spandrel SPA 8x43 | C41: E0.05 | H41: i
...

Sheet 03 45 Architectural Precast
G1: Hedrick Plug
F2: X | G2: Excluded
F3: I | G3: Included
B4: BACK TO SUMMARY SHEET | G4: Sub Add/Deduct | H4: Bidder1 | J4: Bidder 2 | L4: Bidder 3 | N4: Bidder 4 | P4: Bidder 5 | R4: Bidder 6
A5: Project: | B5: ='Area Calculations'!B4 -> ERAU Residential Hall & Garage Building | G5: Company
A6: Trade: | B6: Architectural Precast | G6: Contact
A7: CSI Code: | B7: 03 45 00 | G7: Phone
A8: Date: | G8: Email
G9: Adjusted Bid | H9: =I56 -> 0 | J9: =K56 -> 0 | L9: =M56 -> 0 | N9: =O56 -> 0 | P9: =Q56 -> 0 | R9: =S56 -> 0
C10: Plan/ Spec. Package | D10: QTY | E10: U/M | F10: Unit Cost | G10: Subtotal | H10: Yes/No | I10: Price | J10: Yes/No | K10: Price | L10: Yes/No | M10: Price | N10: Yes/No | O10: Price | P10: Yes/No | Q10: Price | R10: Yes/No | S10: Price
B11: GENERAL INCLUSIONS
B12: INCLUDES ALL SALES TAX
B13: ALL HOISTING & RIGGING REQUIRED TO COMPLETE THIS SCOPE
B14: PROVIDE P&P BONDS
B15: FLORIDA STATE CONTRACTORS LIC.
B16: GENERAL LIABILITY AND WORKERS COMP. INSURANCE LIMITS
B17: STATE AND LOCAL TAXES
B18: SPECIFIC TRADE SCOPE OF WORK REQUIREMENTS
B19: BASE BID
F52: SUBTOTAL | I52: =SUM(I13:I51) -> 0 | K52: =SUM(K13:K51) -> 0 | M52: =SUM(M13:M51) -> 0 | O52: =SUM(O13:O51) -> 0 | Q52: =SUM(Q13:Q51) -> 0 | S52: =SUM(S13:S51) -> 0
F53: BOND RATE | H53: 0 | J53: 0 | L53: 0 | N53: 0 | P53: 0 | R53: 0
F54: BOND AMOUNT | I54: =H53*I52 -> 0 | K54: =J53*K52 -> 0 | M54: =L53*M52 -> 0 | O54: =N53*O52 -> 0 | Q54: =P53*Q52 -> 0 | S54: =R53*S52 -> 0
F56: ADJUSTED TOTAL | I56: =SUM(I52:I54) -> 0 | K56: =SUM(K52:K54) -> 0 | M56: =SUM(M52:M54) -> 0 | O56: =SUM(O52:O54) -> 0 | Q56: =SUM(Q52:Q54) -> 0 | S56: =SUM(S52:S54) -> 0
F57: Cost per SF | I57: =I56/'Area Calculations'!$G$4 -> 0 | K57: =K56/'Area Calculations'!$G$4 -> 0 | M57: =M56/'Area Calculations'!$G$4 -> 0 | O57: =O56/'Area Calculations'!$G$4 -> 0 | Q57: =Q56/'Area Calculations'!$G$4 -> 0 | S57: =S56/'Area Calculations'!$G$4 -> 0
