Workbook

Sheet Area Calculations
B2: PROJECT AREA CALCULATIONS
B4: Atlantic Fields Club Core / Dock Bar / Spa Pods / Water Features
B5: Hobe Sound | E5: Gross (sf) | F5: =D45 -> 88672
E6: AC (sf) | F6: =C45 -> 72629
E7: Leasable (sf) | F7: =E45 -> 0
E8: Site (acres) | F8: 1
E9: Parking Spaces
E10: No. of Units:
E11: Build Duration (months)
A14: I. | B14: Floors | C14: AC SF | D14: Gross SF | E14: LSF
B15: LEVEL 00
B16: DINING - LOWER LEVEL | C16: =D16 -> 7078 | D16: 7078
B17: DINING - LOWER LEVEL - COVERED PATIO | D17: 511
B18: DINING - LOWER LEVEL - COVERED SERVICE | D18: 1078
B19: FITNESS - LOWER LEVEL | C19: =D19 -> 4746 | D19: 4746
B20: POOL EQUIPMENT 01 | D20: 889
B21: POOL EQUIPMENT 02 | D21: 1413
B22: POOL EQUIPMENT 03 | D22: 562
B23: POOL EQUIPMENT 04 | D23: 1521
B24: WELLNESS - LOWER LEVEL | C24: =D24 -> 12861 | D24: 12861
B25: LEVEL 01
B26: DINING - LEVEL 01 | C26: =D26 -> 10905 | D26: 10905
B27: DINING - LEVEL 01 -COVERED PATIO | D27: 3621
B28: FITNESS - LEVEL 01 | C28: =D28 -> 7857 | D28: 7857
B29: FITNESS - LEVEL 01 - COVERED PATIO | D29: 2615
B30: WELLNESS - LEVEL 01 | C30: =D30 -> 14954 | D30: 14954
B31: WELLNESS - LEVEL 01 - COVERED PATIO | D31: 1522
B32: LEVEL 02
B33: DINING - LEVEL 02 | C33: =D33 -> 3386 | D33: 3386
B34: DINING - LEVEL 02 - COVERED PATIO | D34: 2032
B35: WELLNESS - LEVEL 02 | C35: =D35 -> 8314 | D35: 8314
B36: WELLNESS - LEVEL 02 - COVERED PATIO | D36: 279
B38: DoCK BAR | C38: =D38 -> 2528 | D38: 2528
B45: TOTAL | C45: =SUM(C15:C44) -> 72629 | D45: =SUM(D15:D44) -> 88672 | E45: =SUM(E15:E44) -> 0
A47: II. | C47: Site SF | D47: Site(acres)
B61: TOTAL | C61: =SUM(C51:C59) -> 0 | D61: =SUM(D50:D60) -> 0
A78: IV. | B78: SITE AREAS | E78: $ /UNIT | F78: %
B81: Site Perimeter | E81: LF
B82: Walk Gates
B83: Drive Gates
...

Sheet Word C&A
B2: Note 4 - S-121 - W8x10 centered under all CMU
B4: Pool - standard tile, std glass tile - std coping
B23: Finishes
A24: 1 | B24: We have included 5/8" stucco with sand/float finish and bonding agent only at the wellness exterior site wall. All stucco accessories are included as PVC.
A25: 2 | B25: We have included 5/8" scratch coat under stone cladding as specified in A0.32 . The material is assumed to be compatible with the specified mortar bed for the stone cladding
A26: 3 | B26: We include UR-1 (Dur-a-Flex., style: quartz blends, color: hybr-flex EQ) at the tunnels connecting Dining, Fitness and Wellnes ground levels
A27: 4 | B27: We included concrete sealer SC-1 at BOH stair treads
A28: 5 | B28: We have exlcuded all finishes for D-107 Rhoze area as not shown in plans
A29: 6 | B29: We have included 3/4" plywood subfloor and Proflex SIM-90 sound membrane for all wood floors
A30: 7 | B30: We have included BOH ceilings as exposed non painted ceilings.
A31: 8 | B31: We have included high performance painting all decorative C channel fascia
A32: 9 | B32: We have included painting all exposed steel at occupied spaces
A33: 10 | B33: We have included painting exposed pipes at Golf Cart Barn
A34: 11 | B34: We have included Schluter waterproofing at all showers and Laticrete Hydroban waterproofing at Steam Rooms and Hammam room
B38: Framing and Drywall
A39: 1 | B39: We include G60 metal framing as specified. See VA log for deduct
A40: 2 | B40: We include 5/8" CDX fire treated plywood under all ceilings to receive wood cladding
A41: 3 | B41: We include 5/8" CDX plywood backing behind all walls to receive wood cladding
A42: 4 | B42: We have included level 5 finish for all front of house areas and level 4 finish for all BOH areas
A43: 5 | B43: We have included 2" rigid insulation for exterior block walls as specified. See VA log for VR Plus Fi Foil option
A44: 6 | B44: We have included R-11 Fiberglass Batt Insulation at interior walls and partitions
A45: 7 | B45: We have included 2" rigid insulation at unconditioned space below conditioned space. Areas to be included are W-001 Cart Barn and D-000A Service Area. See VA log
A46: 8 | B46: We have included 3 5/8" 18 Gga metal studs with 5/8" CDX plywood for all exterior ceilings and soffits
A47: 9 | B47: We have included 3 5/8" 18 Gga metal studs with 5/8" densglass for all exterior framed parapets to receive metal plates

Sheet RFI
A5: Atlantic Fields Club Core
A6: Hobe Sound
A7: Master RFI Log - Pending
A8: =TODAY() -> 46146
A9: No. | B9: Subject | C9: Reference | D9: Question | E9: Date Created | F9: Answer | G9: Date Answered
A10: 1 | B10: Bid Bond | C10: DOCUMENT 001116 - INVITATION TO BID 1.3 BID SECURITY | D10: Please confirm that a bid bond will be required to be submitted with our bid proposal. | E10: 45670 | F10: No bid bond to be required. | G10: 45688
A11: =1+A10 -> 2 | B11: Liquidated damages | C11: DOCUMENT 001116 - INVITATION TO BID 1.5 TIME OF COMPLETION AND LIQUIDATED DAMAGES | D11: This section states that the Work is subject to liquidated damages. Please confirm and if stipulated, provide amounts for damages and how they are to be applied. | E11: 45670 | F11: liquidated damages will be negotiated with the selected contractor. | G11: 45688
A12: =1+A11 -> 3 | B12: AIA Document A701 | C12: DOCUMENT 002113 - INSTRUCTIONS TO BIDDERS 1.2 SUMMARY: | D12: This section refers to an attached sample AIA Document A701 for reference. Please provide a copy of AIA Document A701. | E12: 45670
A13: =1+A15 -> 6 | B13: Existing site conditions | C13: DOCUMENT 003119 - EXISTING CONDITION INFORMATION 1.1 EXISTING CONDITION INFORMATION | D13: Paragraph B. of this section references a site survey of existing conditions. Please provide a copy of the site survey. Please confirm that this survey is representative of the site conditions that will exist when the general contractor is to start work on site. | E13: 45670 | F13: The rough grading is still in progress, so there is no site survey available at this time. However, a survey will be provided Owner will provide a building pad including geotechnical certification to elevation 42 NAVD. A topo survey of all buildings is still being developed but will be provided to the awarded General Contractor during the execution of the construction contract. | G13: 45688
A14: =1+A12 -> 4 | B14: Geotechnical investigation report. | C14: DOCUMENT 003132 - GEOTECHNICAL DATA 1.1 GEOTECHNICAL DATA | D14: Please provide a copy of the referenced geotechnical investigation report. | E14: 45670 | F14: The rough grading is still in progress, so the Geotech report provided is preliminary at this time. However, a final report will be provided prior to mobilization to the site. | G14: 45688
A15: =1+A14 -> 5 | B15: Additional borings | C15: DOCUMENT 003132 - GEOTECHNICAL DATA 1.1 GEOTECHNICAL DATA | D15: Paragraph C.2. states: Any party using information described in the geotechnical report shall make additional test borings and conduct other exploratory operations that may be required to determine the character of subsurface materials that may be encountered. Are we to include the costs for additional test borings and other exploratory operations in our bid proposal? Are we to allow time in our proposed schedule for this work? | E15: 45670 | F15: No. Owner will assume all costs for geotechnical reports and borings. | G15: 45688
A16: =1+A15 -> 6 | B16: Allowances | C16: DOCUMENT 004321 - ALLOWANCE FORM | D16: Paragraph 1.2 B. references Section 012100 "Allowances." Sections 012100 was not provided. Please provide a copy of Section 012100 "Allowances." | E16: 45670 | F16: Only one allowance has been determined at this time. $350,000 for Dining roof retractable awning. Otherwise, bid should be based on the documents provided. Final version of allowances will be added to Section 012100 document during Contract negotiations. | G16: 45688
A17: =1+A16 -> 7 | B17: Form of Agreement | C17: DOCUMENT 006000 - PROJECT FORMS 1.1 FORM OF AGREEMENT AND GENERAL CONDITIONS | D17: This section states that the contract for the Project is to be AIA Document A102, "Standard Form of Agreement between Owner and Contractor, Cost Plus Fee, Guaranteed Maximum Price." The Request for Proposal dated 12/23 references a Stipulate Sum contract. Please confirm the form of contract that will be used for the Project. | E17: 45670 | F17: The contract will be Cost Plus Fee, Guaranteed Maximum Price. Refer to sample copy of AIA A102. | G17: 45688
A18: =1+A17 -> 8 | B18: Special and Supplementary Conditions | C18: SECTION 010000 - GENERAL REQUIREMENTS | D18: Section 1.1 A. references Special and Supplementary Conditions. Please provide a copy of the Special and Supplementary Conditions. | E18: 45670 | F18: There are no special and supplementary conditions at this time. | G18: 45688
A19: =1+A18 -> 9 | B19: Kitchen Equipment | C19: SECTION 011000 - SUMMARY | D19: Section 1.7 B. states that the kitchen equipment installation will be under a separate contract with the owner. Sections 1.8 A. and B. indicate that the owner's contract for the kitchen equipment will be assigned to the Contractor. Please confirm that this contract will be assigned to the Contractor and if so, please provided a copy of the contract. Are we to include the value of this contract in our bid proposal? | E19: 45670 | F19: Section 1.8.B-a is incorrect and will be removed from the specifications. | G19: 45688
A20: =1+A19 -> 10 | B20: Owner Furnished Products | C20: SECTION 011000 - SUMMARY Section 1.9 OWNER-FURNISHED PRODUCTS | D20: Please confirm that the items listed in this section will be furnished and installed by the owner. See #8 above regarding the kitchen equipment. | E20: 45670 | F20: Section 1.9 contains owner furnished, contractor installed list of items. | G20: 45688
A21: =1+A20 -> 11 | B21: Owner Furnished Products | C21: SECTION 011000 - SUMMARY Section 1.9 OWNER-FURNISHED PRODUCTS | D21: Assuming that the items in this section are to be furnished and installed by the owner, please confirm that the owner will furnish and install all Division 27 and Division 28 "Low Voltage" scopes of work. | E21: 45670 | F21: Section 1.9 contains owner furnished, contractor installed list of items. Refer to KCL LV drawings for schedule of OFCI vs. | G21: 45688
A22: =1+A21 -> 12 | B22: Early turn over of areas of the project | C22: SECTION 011000 - SUMMARY Section 1.11 COORDINATION WITH OCCUPANTS | D22: This section indicates that the Contractor will be required to turn over areas of the project prior to overall completion of the project and that these areas are to receive a Certificate of Occupancy. Please provide a list of these areas and a schedule indicating when these area are required to be turned over. | E22: 45670 | F22: Main kitchen at Dining Level 01 to receive Temporary Certificate of Occupancy 30 days prior to scheduled construction completion. | G22: 45688
A23: =1+A22 -> 13 | B23: Alternates | C23: SECTION 012300 - ALTERNATES | D23: Section 3.1 references a SCHEDULE OF ALTERNATES. Please provide a copy of the SCHEDULE OF ALTERNATES. | E23: 45670 | F23: There are no additional alternates at this time. | G23: 45688
A24: =1+A23 -> 14 | B24: Site Access Prior to Bid Due Date | D24: Please provide instructions for site access prior to the bid due date. | E24: 45670 | F24: The project site requires security access. Access will be granted on a reserved. Please contact Director of Architecture Peter Oliver to schedule any site visits. | G24: 45688
A25: =1+A24 -> 15 | B25: Site Conditions at Construction Commencement | D25: Please clarify the anticipated site conditions at the commencement of construction, specifically regarding grading and utility installations. What grading will be competed? What utilities will be in place and up to what connection point? | E25: 45670 | F25: Rough grading will be completed to a pad elevation, provided by the Owner, of 42’-0” and utilities will be provided, by Owner, to within 20 feet of the building envelopes. Contractor shall be responsible for site work within the proposed area including parking installation. | G25: 45688
A26: =1+A25 -> 16 | B26: Utility Points of Connection | D26: Regarding the new utilities shown on the civil drawings to be installed by the Contractor, please provide the location of connection points to utilities being brought to the site by others. This includes, but is not limited to, storm drainage, sewer, water, fiber optic, and electrical connections. | E26: 45670 | F26: Owner is providing a pad ready site at all building locations. Owner will provide utilities (water, fireline, sanitary sewer, storm drainage) at 20’ outside of the building footprint. | G26: 45688
A27: =1+A26 -> 17 | B27: Interior Windows | C27: Window Elevation Notes | D27: Window Elevation Notes state that all interior window frame systems are to be Haworth Enclosed Frameless Glass Systems. Please provide a specification for the Haworth Glass system. | E27: 45670 | F27: All Interior window systems are to be Haworth single frame glass fronts systems. Haworth product "4SPACE will be highlighted with specific spec and locations on the revised Window schedule in next submittal | G27: 45688
A28: =1+A27 -> 18 | B28: Door Hardware | C28: Specifications | D28: Two separate Door Hardware Specifications 087100 have been provided. One was included with the architectural plans for the Club Core. The other was included with the overall group of specifications provided most recently. Please confirm which Specification 087100 we should use. | E28: 45670 | F28: Current door Hardware schedule has been revised and updated based on corresponding hardware types to specific doors. | G28: 45688
A29: =1+A28 -> 19 | B29: Dock Bar bar interior floor finish | D29: Please provided a specification for the Dock Bar bar interior floor finish. | E29: 45670 | F29: Interior Floor Finish will be Ipe. Please refer to A0.60. | G29: 45688
A30: =1+A29 -> 20 | B30: Intumescent Fire Coating | C30: A4.13 | D30: Please provide a specification for the Intumescent Fire Coating called for on the Cart Barn structural steel.. | E30: 45670 | F30: Exposed steel columns at Cart Barn intumescent fire coating is specified to be Isolatek CAFCO Spray film or equal. | G30: 45688
A31: =1+A30 -> 21 | B31: Fire Proofing | C31: 1/A4.01 | D31: Detail 1/A4.01 appears to show fire proofing on some of the steel members. Please confirm if this is required and if so, please provide a specification. | E31: 45670 | F31: See revised drawing A4.01 for updated information. Drawing 1/4.01 illustrates a close cell foam insultation (not fireproofing) to underside slab of interior space over an external space for thermal bridging. | G31: 45688
A32: =1+A31 -> 22 | B32: Dock construction | C32: Dock Bar - A8.01 | D32: The details on Drawing A8.01 for the Dock Bar show 2x framing members for the framing of the pier portion of the dock platform. These details refer to the structural drawings. The structural drawings do not include any information regarding this farming. Please provide structural details for the dock (pier) platform framing. | E32: 45673 | F32: Below FF Structural platform slab, piers and beams will all be provided by Ownership prior to Club Core Construction. All sub-flooring elements, columns, walls and roofing will all be coordinated as part of the Club Core scope of work. | G32: 45688
A33: =1+A32 -> 23 | B33: Existing site conditions | C33: DOCUMENT 003119 - EXISTING CONDITION INFORMATION 1.1 EXISTING CONDITION INFORMATION | D33: Paragraph C. 2. of this section references Document 003126 "Existing Hazardous Material Information". Please provide a copy of any hazardous materials reports. | E33: 45673 | F33: No Hazardous Materials are present. | G33: 45688
A34: =1+A33 -> 24 | B34: Storm Drainage Pipe Material | C34: Civil Sheet 24 | D34: Martin County Public Works - Standard Detail R-70 on Civil Sheet 24 states "ALL PIPE LOCATED UNDER ROADWAYS AND/OR RESIDENTIAL PARKING AREAS SHALL BE REINFORCED CONCRETE PIPE (RCP)." Please clarify storm drainage pipe material specification for installations in green areas or otherwise not governed by this detail. | E34: 45673 | F34: Pursuant to the Discovery PUD agreement, ADS may be used in lieu of RCP under all pavement areas. | G34: 45688
A35: =1+A34 -> 25 | B35: Civil Permit Responsibility | C35: Civil sheet 23 | D35: General Construction Note #6 on Civil sheet 23 states "CONTRACTOR SHALL OBTAIN ALL REQUIRED PERMITS / LICENSES PRIOR TO COMMENCING WORK." Please clarify which permits the Contractor shall be responsible for obtaining. | E35: 45673 | F35: Contractor shall be responsible for the building permit. All other permits shall be owners supplied. | G35: 45688
A36: =1+A35 -> 26 | B36: Spa Pod Water Supply | D36: The civil plans do not show a source for the domestic water for Spa Pod buildings. Please clarify. Please provide a plumbing site plan if available. | E36: 45673 | F36: Civil plans are currently being updated per comments from Martin County. Updated plans will be provided by February 14, 2025. Contractor should assume services will be provided to within 20 feet of all buildings. | G36: 45688
A37: =1+A36 -> 27 | B37: Fiber optic site conduits | C37: Telecom drawings TT3.02, TT3.02 | D37: Will the general contractor's electrical subcontractor be responsible for the telecom site conduits shown on the Telecon drawings? | E37: 45673 | F37: Yes, the general contractor's electrical subcontractor be responsible for the telecom site conduits shown on the Telecon drawings. | G37: 45688
A38: =1+A37 -> 28 | B38: Pool Technical Specifications. | D38: The General Notes on pool drawing W0.001 reference a set of "Technical Specifications". Please provide a copy of the following: 13 1105 AQUATIC SPECIFICATIONS TABLE OF CONTENTS 13 1110 AQUATICS GENERAL 13 1113 BELOW-GRADE SWIMMING POOLS (CONCRETE) 13 1114 BELOW-GRADE SWIMMING POOLS (SST/LINER-BASED BASINS) 13 1125 POOL BONDING AND GROUNDING 13 1126 POOL ELECTRICAL 13 1133 ELEVATED SWIMMING POOLS (CONCRETE) 13 1134 ELEVATED SWIMMING POOLS (SST/ LINER-BASED BASINS) 13 1146 SWIMMING POOL ACCESSORIES 22 5100 SWIMMING POOL PLUMBING SYSTEMS | E38: 45673 | F38: Specifications were provided with the doucuments included with the 02/19/25 RFI responses. | G38: 45707
A39: =1+A38 -> 29 | B39: Retractable Awning Canopy | C39: A6.30 | D39: Drawing A6.30 shows a retractable awning canopy in the roof adjacent to the Sky Bar. No information has been provided for this canopy. Should we include an allowance for this? | E39: 45673 | F39: Retractable roof system (Enfold) is still being coordinated, and design has not yet been solidified. Please include an allowance of $350,000.00 so suffice this item. | G39: 45688
A40: =1+A39 -> 30 | B40: Concrete Pier DCP-1 | C40: S-101 | D40: Concrete pier DCP-1 appears to sit on footing at 24'-10" which means pier would be taller than 24". Please confirm pier DCP-1 height | E40: 45673 | F40: DCP-1 extends from foundation at elevation 24'- 10" to first floor framing plan. | G40: 45688
A41: =1+A40 -> 31 | B41: Roofing assembly | D41: The architectural plans show the roofing membrane on ridged insulation on metal deck. Some structural drawing sections show the roofing membrane on ridged insulation on concrete (assume LWIC) on metal deck. Please confirm roofing insulation requirements. | E41: 45673 | F41: Projects roofing conditions are distinguished between two main systems. (i) 1-1/2" Metal Decking with Insulation and roofing application above. (ii) 3" Concrete Slab over 2" Metal Decking. Depending on location (Covered Exterior Space vs. Covered Interior space) Insulation application is as follows: Layer 1 (3.5" Iso board). Layer 2 ( 1/4" Tapered 1-1/2" start point insulation board) Layer 3 (1/8" spot fastened Asphaltic cover board. Please refer to sheet A2.50-A2.54 for all application areas and conditions. | G41: 45688
A42: =1+A41 -> 32 | B42: PVC Roofing Specification | C42: SECTION 07 54 19 POLYVINYL-CHLORIDE (PVC) ROOFING | D42: Roofing specification 07 54 19 was issued with the other Division 7 specifications. Please provide direction as to where this roofing type will apply. | E42: 45673 | F42: Roofing specification 07 54 19 will not be part of the building envelop and should be omitted from bid. | G42: 45688
A43: =1+A42 -> 33 | B43: Pit Slab - Wellness | C43: S-113 | D43: Please provide a section thru the 14" CONC PIT SLAB at column lines U & 21 of does Section 11/S-403.1 also apply here? | E43: 45673 | F43: Section 11/S-403.1 is a similar section at U/21. | G43: 45688
A44: =1+A43 -> 34 | B44: Pit Slab - Wellness | C44: Section 11/S-403.1 | D44: Is the 8" CONC PIT WALL on all 3 sides? | E44: 45673 | F44: yes | G44: 45688
...

Sheet Documents
A3: ='Area Calculations'!B4 -> Atlantic Fields Club Core / Dock Bar / Spa Pods / Water Features
A4: ='Area Calculations'!B5 -> Hobe Sound
A5: List of Drawings
A6: =TODAY() -> 46146
A7: SHEET NO. | B7: DESCRIPTION | C7: DATE | D7: DATE REC'D | E7: Add #1
B8: CLUB CORE
B9: PEACOCK + LEWIS
A10: CVR | B10: COVER SHEET | C10: 45681 | D10: 45708
A11: A0.00 | B11: SHEET INDEX | C11: 45681 | D11: 45708
A12: A0.01 | B12: SHEET INDEX | C12: 45681 | D12: 45708
A13: S0.02 | B13: GENERAL NOTES AND PROJECT INFORMATION | C13: 45681 | D13: 45708
A14: A0.08 | B14: AREA PLANS | C14: 45681 | D14: 45708
A15: A0.09 | B15: ROOM SCHEDULE | C15: 45681 | D15: 45708
A16: A0.10 | B16: LIEF SAFETY & CODE STUDY | C16: 45681 | D16: 45708
A17: A0.10A | B17: PLUMBING CALCULATIONS | C17: 45681 | D17: 45708
A18: A0.11 | B18: ADA STANDARDS | C18: 45681 | D18: 45708
A19: A0.12 | B19: ADA STANDARDS | C19: 45681 | D19: 45708
A20: A0.13 | B20: LEVEL 00 - LIFE SAFETY OVERALL | C20: 45681 | D20: 45708
A21: A0.14 | B21: LEVEL 01 - LIFE SAFETY OVERALL | C21: 45681 | D21: 45708
... A32: A0.30 | B32: ASSEMBLIES - ROOFS, CEILINGS, FLOORS | C32: 45681 | D32: 45708
A33: A0.31 | B33: ASSEMBLIES - INTERIOR PARTITIONS | C33: 45681 | D33: 45708 | E33: 45723
A34: A0.32 | B34: ASSEMBLIES - EXTERIOR PARTITIONS | C34: 45681 | D34: 45708 | E34: 45723
A35: A0.34 | B35: PARTITION FRAMING DETAILS | C35: 45681 | D35: 45708 | E35: 45723
A36: A0.36 | B36: EXTERIOR DOOR AND WINDOW ELEVATIONS - DINING | C36: 45681 | D36: 45708 | E36: 45723
A37: A0.37 | B37: EXTERIOR DOOR AND WINDOW ELEVATIONS - DINING | C37: 45681 | D37: 45708 | E37: 45723
A38: A0.38 | B38: EXTERIOR DOOR AND WINDOW ELEVATIONS - FITNESS | C38: 45681 | D38: 45708 | E38: 45723
A39: A0.39 | B39: EXTERIOR DOOR AND WINDOW ELEVATIONS - WELLNESS | C39: 45681 | D39: 45708 | E39: 45723
A40: A0.40 | B40: EXTERIOR DOOR AND WINDOW ELEVATIONS - WELLNESS | C40: 45681 | D40: 45708 | E40: 45723
A41: A0.50 | B41: DOOR SCHEDULES | C41: 45681 | D41: 45708 | E41: 45723
A42: A0.51 | B42: DOOR SCHEDULES | C42: 45681 | D42: 45708 | E42: 45723
A43: A0.52 | B43: DOOR ELEVATIONS | C43: 45681 | D43: 45708 | E43: 45723
A44: A0.53 | B44: EXTERIOR DOOR DETAILS | C44: 45681 | D44: 45708
A45: A0.54 | B45: INTERIOR DOOR DETAILS | C45: 45681 | D45: 45708 | E45: 45723
A46: A0.54 A | B46: INTERIOR DOOR DETAILS | E46: 45723
A47: A0.54 B | B47: INTERIOR DOOR DETAILS | E47: 45723
A48: A0.55 | B48: SLIDING GLASS DOOR DETAILS | C48: 45681 | D48: 45708
A49: A0.55.2 | B49: SLIDING GLASS DOOR DETAILS | C49: 45681 | D49: 45708
A50: S0.55.3 | B50: SLIDING GLASS DOOR DETAILS | C50: 45681 | D50: 45708
A51: A0.56 | B51: OVERHEAD COILING DOOR DETAILS | C51: 45681 | D51: 45708
A52: A0.57 | B52: WINDOW + LOUVER DETAILS | C52: 45681 | D52: 45708
...

Sheet Sub List
A3: ='Area Calculations'!B4 -> Atlantic Fields Club Core / Dock Bar / Spa Pods / Water Features
A4: ='Area Calculations'!B5 -> Hobe Sound
A5: List of Subcontractors
A6: =TODAY() -> 46146
A7: NO. | B7: CSI DIV | C7: NAME
A8: 1 | B8: ='Cost Summary'!A8 -> 02 21 00 | C8: ='02 21 Survey '!H5 -> Velcon Engineering and Surveying
A9: =A8+1 -> 2 | B9: ='Cost Summary'!A9 -> 03 30 00 | C9: ='03 30 CIP Concrete'!H6 -> Victory Concrete
A10: =A9+1 -> 3 | B10: ='Cost Summary'!A10 -> 04 40 00 | C10: ='04 40 Stone Veneer'!H5 -> Titan Stone
A11: =A10+1 -> 4 | B11: ='Cost Summary'!A11 -> 05 10 00 | C11: ='05 10 Structural Steel'!J5 -> VM Iron Works
A12: =A11+1 -> 5 | B12: ='Cost Summary'!A12 -> 05 52 00 | C12: ='05 52 Railings'!H5 -> JC Iron Ornamental
A13: =A12+1 -> 6 | B13: ='Cost Summary'!A13 -> 05 70 00 | C13: ='05 70 Arch Metals'!H5 -> VM Iron Works
A14: =A13+1 -> 7 | B14: ='Cost Summary'!A14 -> 06 10 00 | C14: Hedrick / A-1 Industries
A15: =A14+1 -> 8 | B15: ='Cost Summary'!A15 -> 06 40 00 | C15: ='06 40 Exterior Finish Carpentry'!H5 -> Lotspeich Co.
A16: =A15+1 -> 9 | B16: ='Cost Summary'!A16 -> 06 50 00 | C16: ='06 50 Millwork'!H5 -> Beaubois
A17: =A16+1 -> 10 | B17: ='Cost Summary'!A17 -> 07 17 00 | C17: ='07 17 Waterproofing & Caulk'!H5 -> Triton
A18: =A17+1 -> 11 | B18: ='Cost Summary'!A18 -> 07 21 00 | C18: ='07 21 Insulation'!H5 -> Gale Insulation
A19: =A18+1 -> 12 | B19: ='Cost Summary'!A19 -> 07 50 00 | C19: ='07 50 Roofing'!H5 -> Vero Beach Roofing
A20: =A19+1 -> 13 | B20: ='Cost Summary'!A20 -> 07 81 00 | C20: ='07 81 Fireproofing'!H5 -> Fire Stop Systems
A21: =A20+1 -> 14 | B21: ='Cost Summary'!A21 -> 08 10 70 | C21: ='08 10 DFH'!H5 -> Atlantic Doors & Hard
A22: =A21+1 -> 15 | B22: ='Cost Summary'!A22 -> 08 11 00 | C22: ='08 11 Insect Screens'!H5 -> Shades by Design
A23: =A22+1 -> 16 | B23: ='Cost Summary'!A23 -> 08 33 00 | C23: ='08 33 OH Coiling Doors'!H5 -> D&D Garage Door
A24: =A23+1 -> 17 | B24: ='Cost Summary'!A24 -> 08 50 00 | C24: ='08 50 Storefront'!H5 -> Ready Window
A25: =A24+1 -> 18 | B25: ='Cost Summary'!A25 -> 08 60 00 | C25: ='08 60 Skylights'!H5 -> Skylight Concepts
A26: =A25+1 -> 19 | B26: ='Cost Summary'!A26 -> 09 24 00 | C26: ='09 24 Stucco'!H5 -> Welch Plastering, Inc.
A27: =A26+1 -> 20 | B27: ='Cost Summary'!A27 -> 09 26 00 | C27: ='09 26 Plaster'!L5 -> Foster Reeve & Associates
A28: =A27+1 -> 21 | B28: ='Cost Summary'!A28 -> 09 29 00 | C28: ='09 29 Gypsum Board'!H5 -> Tony Rodrigues Metal Framing, Inc.
A29: =A28+1 -> 22 | B29: ='Cost Summary'!A29 -> 09 30 00 | C29: ='09 30 Tile'!H5 -> Jack Walsh Carpets & Rugs, Inc.
A30: =A29+1 -> 23 | B30: ='Cost Summary'!A30 -> 09 41 00 | C30: ='09 41 Resinous Flooring'!H5 -> Applied Flooring Technologies
A31: =A30+1 -> 24 | B31: ='Cost Summary'!A31 -> 09 51 00 | C31: ='09 51 ACT'!H5 -> Lotspeich Co.
A32: =A31+1 -> 25 | B32: ='Cost Summary'!A32 -> 09 60 00 | C32: ='09 60 Resilient Flooring'!H5 -> Jack Walsh Carpets & Rugs, Inc.
A33: =A32+1 -> 26 | B33: ='Cost Summary'!A33 -> 09 64 00 | C33: ='09 64 Wood Flooring'!H5 -> Jack Walsh Carpets & Rugs, Inc.
A34: =A33+1 -> 27 | B34: ='Cost Summary'!A34 -> 09 90 00 | C34: ='09 90 Painting'!H5 -> Advanced Painting Contractors
A35: =A34+1 -> 28 | B35: ='Cost Summary'!A35 -> 10 22 00 | C35: ='10 22 Demountable Part'!H5 -> Pending
A36: =A35+1 -> 29 | B36: ='Cost Summary'!A36 -> 10 28 00 | C36: ='10 28 Specialties'!H5 -> Interior Specialties
A37: =A36+1 -> 30 | B37: ='Cost Summary'!A37 -> 10 30 00 | C37: ='10 30 Fireplace '!H5 -> Hedrick
A38: =A37+1 -> 31 | B38: ='Cost Summary'!A38 -> 10 51 00 | C38: ='10 51 Lockers'!H5 -> Hollman
A39: =A38+1 -> 32 | B39: ='Cost Summary'!A39 -> 10 53 00 | C39: ='10 53 Signage'!H5 -> Pending
A40: =A39+1 -> 33 | B40: ='Cost Summary'!A40 -> 10 73 00 | C40: ='10 73 Canopy'!H5 -> Pending
A41: =A40+1 -> 34 | B41: ='Cost Summary'!A41 -> 11 40 00 | C41: ='11 40 FS Equip'!H5 -> Cheney Bros
A42: =A41+1 -> 35 | B42: ='Cost Summary'!A42 -> 11 40 00 | C42: ='11 40 Appliances'!H5 -> Hedrick
...

Sheet Sub Proposal Count
A3: ='Area Calculations'!B4 -> Atlantic Fields Club Core / Dock Bar / Spa Pods / Water Features
A4: ='Area Calculations'!B5 -> Hobe Sound
A5: Subcontractor Proposal Count
A6: =TODAY() -> 46146
A7: NO. | B7: CSI DIV | C7: CSI DESCRIPTION | D7: # SOLICITED | E7: # RECEIVED | F7: NOTES
A8: 1 | B8: ='Cost Summary'!A8 -> 02 21 00 | C8: Surveying | D8: 1 | E8: 1 | F8: Only solicited from Velcon Engineering and Surveying
A9: =A8+1 -> 2 | B9: ='Cost Summary'!A9 -> 03 30 00 | C9: Concrete & CMU | D9: 31 | E9: 7
A10: =A9+1 -> 3 | B10: ='Cost Summary'!A10 -> 04 40 00 | C10: Stone Veneer | D10: 19 | E10: 4
A11: =A10+1 -> 4 | B11: ='Cost Summary'!A11 -> 05 10 00 | C11: Structural Steel | D11: 24 | E11: 3
A12: =A11+1 -> 5 | B12: ='Cost Summary'!A12 -> 05 52 00 | C12: Handrails & Railings - Metal | D12: 13 | E12: 1
A13: =A12+1 -> 6 | B13: ='Cost Summary'!A13 -> 05 70 00 | C13: Interior & Exterior Architectural Metals | D13: 15 | E13: 1 | F13: Mostly allowances, 1 quote for dining stair
A14: =A13+1 -> 7 | B14: ='Cost Summary'!A14 -> 06 10 00 | C14: Rough Carpentry | D14: 3 | E14: 2 | F14: Truss quotes
A15: =A14+1 -> 8 | B15: ='Cost Summary'!A15 -> 06 40 00 | C15: Exterior Finish Carpentry | D15: 17 | E15: 2 | F15: 1 for exterior siding, 1 for Ipe decking
A16: =A15+1 -> 9 | B16: ='Cost Summary'!A16 -> 06 50 00 | C16: Millwork | D16: 23 | E16: 8
A17: =A16+1 -> 10 | B17: ='Cost Summary'!A17 -> 07 17 00 | C17: Waterproofing & Caulking | D17: 25 | E17: 2
A18: =A17+1 -> 11 | B18: ='Cost Summary'!A18 -> 07 21 00 | C18: Insulation - Spray Foam | D18: 10 | E18: 2
A19: =A18+1 -> 12 | B19: ='Cost Summary'!A19 -> 07 50 00 | C19: Roofing | D19: 34 | E19: 6
A20: =A19+1 -> 13 | B20: ='Cost Summary'!A20 -> 07 81 00 | C20: Fireproofing | D20: 8 | E20: 1
A21: =A20+1 -> 14 | B21: ='Cost Summary'!A21 -> 08 10 70 | C21: Doors, Frames, & Hardware | D21: 41 | E21: 1 | F21: Late issuance of total revison of door schedule caused 2 others to back out
A22: =A21+1 -> 15 | B22: ='Cost Summary'!A22 -> 08 11 00 | C22: Roll-Up Insect Screens | D22: 4 | E22: 2
A23: =A22+1 -> 16 | B23: ='Cost Summary'!A23 -> 08 33 00 | C23: Overhead Coiling Doors | D23: 36 | E23: 6
A24: =A23+1 -> 17 | B24: ='Cost Summary'!A24 -> 08 50 00 | C24: Storefront / Glass | D24: 29 | E24: 5
A25: =A24+1 -> 18 | B25: ='Cost Summary'!A25 -> 08 60 00 | C25: Skylights | D25: 2 | E25: 1
A26: =A25+1 -> 19 | B26: ='Cost Summary'!A26 -> 09 24 00 | C26: Stucco | D26: 12 | E26: 3
A27: =A26+1 -> 20 | B27: ='Cost Summary'!A27 -> 09 26 00 | C27: Plaster | D27: 40 | E27: 5
A28: =A27+1 -> 21 | B28: ='Cost Summary'!A28 -> 09 29 00 | C28: Drywall / Framing | D28: 23 | E28: 5
A29: =A28+1 -> 22 | B29: ='Cost Summary'!A29 -> 09 30 00 | C29: Tile Work, Tile & Stone Flooring | D29: 30 | E29: 3
A30: =A29+1 -> 23 | B30: ='Cost Summary'!A30 -> 09 41 00 | C30: Resinous Flooring | D30: 30 | E30: 3
A31: =A30+1 -> 24 | B31: ='Cost Summary'!A31 -> 09 51 00 | C31: Acoustical Ceilings | D31: 11 | E31: 5
A32: =A31+1 -> 25 | B32: ='Cost Summary'!A32 -> 09 60 00 | C32: Flooring | D32: 30 | E32: 3
A33: =A32+1 -> 26 | B33: ='Cost Summary'!A33 -> 09 64 00 | C33: Wood Flooring | D33: 11 | E33: 4
A34: =A33+1 -> 27 | B34: ='Cost Summary'!A34 -> 09 90 00 | C34: Painting | D34: 43 | E34: 5
A35: =A34+1 -> 28 | B35: ='Cost Summary'!A35 -> 10 22 00 | C35: Demountable Partitions | D35: 0 | E35: 0 | F35: Did not receive specification or confimation of locations
A36: =A35+1 -> 29 | B36: ='Cost Summary'!A36 -> 10 28 00 | C36: Specialties | D36: 15 | E36: 3
A37: =A36+1 -> 30 | B37: ='Cost Summary'!A37 -> 10 30 00 | C37: Fireplace | D37: 1 | E37: 1
A38: =A37+1 -> 31 | B38: ='Cost Summary'!A38 -> 10 51 00 | C38: Lockers | D38: 2 | E38: 2 | F38: Only 2 manufactueres specified
A39: =A38+1 -> 32 | B39: ='Cost Summary'!A39 -> 10 53 00 | C39: Signage | D39: 0 | E39: 0 | F39: Allowance
A40: =A39+1 -> 33 | B40: ='Cost Summary'!A40 -> 10 73 00 | C40: Canopy | D40: 0 | E40: 0 | F40: Allowance
A41: =A40+1 -> 34 | B41: ='Cost Summary'!A41 -> 11 40 00 | C41: Food Service & Laundry Equipment | D41: 16 | E41: 1 | F41: All but 1 sub backed out due to equipment supply by others
A42: =A41+1 -> 35 | B42: ='Cost Summary'!A42 -> 11 40 00 | C42: Appliances | D42: 1 | E42: 1
...

Sheet Allowances
A3: ='Area Calculations'!B4 -> Atlantic Fields Club Core / Dock Bar / Spa Pods / Water Features
A4: ='Area Calculations'!B5 -> Hobe Sound
A5: Allowances
A6: =TODAY() -> 46146
A7: NO. | B7: CSI DIV | C7: DESCRIPTION | D7: VALUE
A8: 1 | B8: 03 30 00 | C8: Note S-200 - Contractor Shall Include In His Base Bid The Cost Of 5 Tons Of Additional Reinforcing Steel, Including Detailing, Fabrication, Bending, Furnishing, And Placing. This Extra Stock Shall Be Furnished And Used For Special Conditions As Directed By The Architect, The Architect'S Agent Or By The Owner'S Construction Supervisor. The Price Of The Unused Extra Stock Shall Be Credited To The Owner'S Account. | D8: ='03 30 CIP Concrete'!G219 -> 25000 | F8: zss
A9: =A8+1 -> 2 | B9: 05 10 00 | C9: Structural Steel Shown Not Sized | D9: ='05 10 Structural Steel'!I187 -> 193446
A10: =A9+1 -> 3 | B10: 05 10 00 | C10: Steel framing at opening for Pergola - S-131 | D10: ='05 10 Structural Steel'!I201 -> 14100
A11: =A10+1 -> 4 | B11: 05 10 00 | C11: Steel shown on architectural plans only | D11: ='05 10 Structural Steel'!I203 -> 149601
A12: =A11+1 -> 5 | B12: 05 10 00 | C12: Steel allowance for arch/struct steel not coordinated, incomplete drawings. | D12: ='05 10 Structural Steel'!I215 -> 210000
A13: =A12+1 -> 6 | B13: 05 10 00 | C13: Spec section 05 12 00 - 3.8 - A. --- All Steel to received SSPC-SP10 Blast & Carbo Zinc II HS Coating | D13: ='05 10 Structural Steel'!I237 -> 350000
A14: =A13+1 -> 7 | B14: 05 10 00 | C14: Note S-200 - Contractor Shall Include In His Base Bid The Cost Of 10,000 Pounds Of Additional Structural Steel (Members Over 10 Lbs. Per Foot) And 10,000 Pounds Of Miscellaneous Steel (Members 10 Lbs. Per Foot Or Less) Including Furnishing, Detailing, Fabrication, Cleaning, Painting, Delivery And Erection. | D14: ='05 10 Structural Steel'!I241+'05 10 Structural Steel'!I242 -> 60000
A15: =A14+1 -> 8 | B15: 05 10 00 | C15: Spa Pods - Steel shown on architectural plans only | D15: ='05 10 Structural Steel'!I279 -> 45998
A16: =A15+1 -> 9 | B16: 05 10 00 | C16: Facilitate steel erection - Crane access before lake fill? Crane barge? CANNOT MAKE FINAL DETERMININATION UNTIL BASE STRUCTURE IS COMPLETE AND WE UNDERSTAND EXISTING CONDITIONS. | D16: ='05 10 Structural Steel'!I268 -> 144000
A17: =A16+1 -> 10 | B17: 05 70 00 | C17: Ribbon Canopy - Decorative steel angle w/ high performance finish - not enough detail | D17: ='05 70 Arch Metals'!G23 -> 32580
A18: =A17+1 -> 11 | B18: 05 70 00 | C18: Club Core - Exterior metal plate cladding - MT-01 - not enough detail | D18: ='05 70 Arch Metals'!G25 -> 288100
A19: =A18+1 -> 12 | B19: 05 70 00 | C19: Club Core - Exterior metal plate cladding at planters - MT-01 & MT-04 - not enough detail | D19: ='05 70 Arch Metals'!G42 -> 154759
A20: =A19+1 -> 13 | B20: 05 70 00 | C20: Club Core - Misc metal plate trim - not enough detail | D20: ='05 70 Arch Metals'!G55 -> 22365
A21: =A20+1 -> 14 | B21: 05 70 00 | C21: Dock Bar - MT--05 misc metal plate trim - not enough detail | D21: ='05 70 Arch Metals'!I62 -> 47180
A22: =A21+1 -> 15 | B22: 05 70 00 | C22: Spa Pods - MT--05 misc metal plate trim - not enough detail | D22: ='05 70 Arch Metals'!G69 -> 63350
A23: =A22+1 -> 16 | B23: 06 40 00 | C23: Club Core Dining - Mechanical Yard Screen. Need WD-11 spec | D23: ='06 40 Exterior Finish Carpentry'!G34 -> 116400
A24: =A23+1 -> 17 | B24: 06 40 00 | C24: Club Core Dining - soffit - Port Cochere - Details incomplete | D24: ='06 40 Exterior Finish Carpentry'!G36 -> 21870
A25: =A24+1 -> 18 | B25: 06 40 00 | C25: Club Core Fitness - WD-06: Trellis - overhang - Details incomplete | D25: ='06 40 Exterior Finish Carpentry'!G40 -> 53039
A26: =A25+1 -> 19 | B26: 06 40 00 | C26: Wellness WD-06: Trellis - lower roof overhang - Details incomplete | D26: ='06 40 Exterior Finish Carpentry'!G52 -> 76800
A27: =A26+1 -> 20 | B27: 06 40 00 | C27: Wellness WD-06: Trellis - upper roof overhang - Details incomplete | D27: ='06 40 Exterior Finish Carpentry'!G53 -> 42720
A28: =A27+1 -> 21 | B28: 06 40 00 | C28: Fitness Pool Cabanas - No dimensions | D28: ='06 40 Exterior Finish Carpentry'!I69 -> 508440
A29: =A28+1 -> 22 | B29: 06 50 00 | C29: Club Core Dinning - Banquettes (D-008 & D-102) | D29: ='06 50 Millwork'!$I$24 -> 210000
A30: =A29+1 -> 23 | B30: 06 50 00 | C30: Club Core Wellness - Stainless-Steel cabinets for Cart wash and prep stations | D30: =43000 -> 43000
A31: =A30+1 -> 24 | B31: 07 50 00 | C31: Ribbon Canopy gutters - no detail - assume aluminum | D31: ='07 50 Roofing'!G79 -> 27150
A32: =A31+1 -> 25 | B32: 07 50 00 | C32: Ribbon Canopy downspouts? - no detail - assume aluminum | D32: ='07 50 Roofing'!G80 -> 2500
A33: =A32+1 -> 26 | B33: 08 10 00 | C33: Aluminum - Custom Engineered - Stacked Panel Shutter - no details | D33: ='08 10 DFH'!G167 -> 84996
A34: =A33+1 -> 27 | B34: 08 50 00 | C34: Glass Railings - conflicting details, missing detail | D34: ='08 50 Storefront'!G184 -> 149000
A35: =A34+1 -> 28 | B35: 10 22 00 | C35: Demountable Partitions - Dining - specifications & locations not provided | D35: ='10 22 Demountable Part'!G24 -> 17246
A36: =A35+1 -> 29 | B36: 10 22 00 | C36: Demountable Partitions - Wellness - specifications & locations not provided | D36: ='10 22 Demountable Part'!G26+'10 22 Demountable Part'!G27 -> 30389
A37: =A36+1 -> 30 | B37: 10 51 00 | C37: Employee Lockers - RFI response changed type - no spec provided | D37: ='10 51 Lockers'!G59 -> 26800
A38: =A37+1 -> 31 | B38: 10 53 00 | C38: Interior & Exterior Signage - sizes, locations, types not provided | D38: ='10 53 Signage'!I21 -> 52750
A39: =A38+1 -> 32 | B39: 10 73 00 | C39: Retractable Awning Canopy - A6.30 - Skybar | D39: ='10 73 Canopy'!G22 -> 350000
A40: =A39+1 -> 33 | B40: 12 20 00 | C40: Drapery track only - propvide and install - spec not provided | D40: ='12 20 Window Treatments'!I79+'12 20 Window Treatments'!I89+'12 20 Window Treatments'!I92 -> 11085
A41: =A40+1 -> 34 | B41: 12 20 00 | C41: Roller Shades - installation of power supplies, wiring & controls - not shown on electrical or lighting control drawings | D41: ='12 20 Window Treatments'!G84 -> 34500
A42: =A41+1 -> 35 | B42: 13 11 00 | C42: Rock/stone within water feature & surounding rock - material not specified | D42: ='13 11 Pool'!G66+'13 11 Pool'!G73 -> 817100
...

Sheet Cost Summary
A3: ='Area Calculations'!B4 -> Atlantic Fields Club Core / Dock Bar / Spa Pods / Water Features
A4: ='Area Calculations'!B5 -> Hobe Sound
A5: Hard Bid - Cost Summary
A6: =NOW() -> 46146.221
A7: CSI | B7: CSI DESCRIPTION | C7: Club Core | D7: Dock & Bar | E7: Spa Pods | F7: Hardscape, Landscape & Water Features | G7: Site Work | H7: TOTAL | I7: $/SF
A8: 02 21 00 | B8: Surveying | C8: ='02 21 Survey '!$I21 -> 22000 | D8: ='02 21 Survey '!$I30 -> 0 | E8: ='02 21 Survey '!$I33 -> 9350 | F8: ='02 21 Survey '!$I42 -> 22000 | G8: ='02 21 Survey '!$I50 -> 20000 | H8: ='02 21 Survey '!$B$95 -> 73350 | K8: =SUM(C8:G8)-H8 -> 0
A9: 03 30 00 | B9: Concrete & CMU | C9: ='03 30 CIP Concrete'!I21 -> 7239482 | D9: ='03 30 CIP Concrete'!I221 -> 108738 | E9: ='03 30 CIP Concrete'!I240 -> 300788 | H9: ='03 30 CIP Concrete'!$B300 -> 7649008 | K9: =SUM(C9:G9)-H9 -> 0
A10: 04 40 00 | B10: Stone Veneer | C10: ='04 40 Stone Veneer'!I21 -> 983329 | H10: ='04 40 Stone Veneer'!$B$107 -> 983329 | K10: =SUM(C10:G10)-H10 -> 0
A11: 05 10 00 | B11: Structural Steel | C11: ='05 10 Structural Steel'!K21 -> 4903059 | D11: ='05 10 Structural Steel'!K244 -> 368224 | E11: ='05 10 Structural Steel'!K270 -> 67958 | H11: ='05 10 Structural Steel'!$B331 -> 5339241 | K11: =SUM(C11:G11)-H11 -> 0
A12: 05 52 00 | B12: Handrails & Railings | C12: ='05 52 Railings'!I21 -> 0 | D12: ='05 52 Railings'!I27 -> 138000 | E12: ='05 52 Railings'!I32 -> 0 | H12: ='05 52 Railings'!$B$90 -> 138000 | K12: =SUM(C12:G12)-H12 -> 0
A13: 05 70 00 | B13: Interior & Exterior Architectural Metals | C13: ='05 70 Arch Metals'!I21 -> 1247804 | D13: ='05 70 Arch Metals'!I61 -> 47180 | E13: ='05 70 Arch Metals'!I68 -> 63350 | H13: ='05 70 Arch Metals'!$B$112 -> 1358334 | K13: =SUM(C13:G13)-H13 -> 0
A14: 06 10 00 | B14: Rough Carpentry | C14: ='06 10 Rough Carpentry'!I21 -> 109293 | D14: ='06 10 Rough Carpentry'!I49 -> 42397 | E14: ='06 10 Rough Carpentry'!I58 -> 141562.92 | H14: ='06 10 Rough Carpentry'!$B$119 -> 293252.92 | K14: =SUM(C14:G14)-H14 -> 0
A15: 06 40 00 | B15: Exterior Finish Carpentry | C15: ='06 40 Exterior Finish Carpentry'!I21 -> 3087156.8 | D15: ='06 40 Exterior Finish Carpentry'!I73 -> 611228.58 | E15: ='06 40 Exterior Finish Carpentry'!I92 -> 708166.67 | H15: ='06 40 Exterior Finish Carpentry'!$B$150 -> 4406552 | K15: =SUM(C15:G15)-H15 -> 0
A16: 06 50 00 | B16: Millwork | C16: =SUM('06 50 Millwork'!$I$12:$I$511) -> 6072272 | D16: =SUM('06 50 Millwork'!$I$512:$I$610) -> 590857 | E16: =SUM('06 50 Millwork'!$I$611:$I$651)+'06 50 Millwork'!$I$656 -> 194657 | H16: ='06 50 Millwork'!$B$693 -> 6857786 | K16: =SUM(C16:G16)-H16 -> 0
A17: 07 17 00 | B17: Waterproofing & Caulking | C17: ='07 17 Waterproofing & Caulk'!I$43 -> 2045883.5 | D17: ='07 17 Waterproofing & Caulk'!I$151 -> 8509 | E17: ='07 17 Waterproofing & Caulk'!I$157 -> 29850 | H17: ='07 17 Waterproofing & Caulk'!$B$203 -> 2084242.5 | K17: =SUM(C17:G17)-H17 -> 0
A18: 07 21 00 | B18: Insulation | C18: ='07 21 Insulation'!I21 -> 16261 | D18: ='07 21 Insulation'!I26 -> 36200 | E18: ='07 21 Insulation'!I33 -> 20510 | H18: ='07 21 Insulation'!$B$90 -> 72971 | K18: =SUM(C18:G18)-H18 -> 0
A19: 07 50 00 | B19: Roofing | C19: ='07 50 Roofing'!I21 -> 2220525 | D19: ='07 50 Roofing'!I99 -> 60300 | E19: ='07 50 Roofing'!I105 -> 92210 | H19: ='07 50 Roofing'!$B$153 -> 2373035 | K19: =SUM(C19:G19)-H19 -> 0
A20: 07 81 00 | B20: Fireproofing | C20: ='07 81 Fireproofing'!$I$21 -> 343200 | H20: ='07 81 Fireproofing'!$B$90 -> 343200 | K20: =SUM(C20:G20)-H20 -> 0
A21: 08 10 70 | B21: Doors, Frames, & Hardware | C21: ='08 10 DFH'!I21 -> 555850 | D21: ='08 10 DFH'!I145 -> 19950 | E21: ='08 10 DFH'!I160 -> 135946 | H21: ='08 10 DFH'!$B$220 -> 711746 | K21: =SUM(C21:G21)-H21 -> 0
A22: 08 11 00 | B22: Roll-Up Insect Screens | C22: ='08 11 Insect Screens'!$I$23 -> 260965.48 | D22: ='08 11 Insect Screens'!$I$50 -> 61218.138 | E22: ='08 11 Insect Screens'!$I$59 -> 39820.515 | H22: ='08 11 Insect Screens'!$B$110 -> 362004.13 | K22: =SUM(C22:G22)-H22 -> 0
A23: 08 33 00 | B23: Overhead Coiling Doors | C23: ='08 33 OH Coiling Doors'!I21 -> 20237.39 | H23: ='08 33 OH Coiling Doors'!$B$90 -> 20237.39 | K23: =SUM(C23:G23)-H23 -> 0
A24: 08 50 00 | B24: Storefront / Glass | C24: ='08 50 Storefront'!I25 -> 2327406.3 | E24: ='08 50 Storefront'!I193 -> 247760.7 | H24: ='08 50 Storefront'!$B$274 -> 2575167 | K24: =SUM(C24:G24)-H24 -> 0
A25: 08 60 00 | B25: Skylights | C25: ='08 60 Skylights'!I$21 -> 24736 | H25: ='08 60 Skylights'!$B$90 -> 24736 | K25: =SUM(C25:G25)-H25 -> 0
A26: 09 24 00 | B26: Stucco | C26: ='09 24 Stucco'!C72 -> 200300 | H26: ='09 24 Stucco'!$B$72 -> 200300 | K26: =SUM(C26:G26)-H26 -> 0
A27: 09 26 00 | B27: Plaster | C27: ='09 26 Plaster'!C92 -> 565992.54 | H27: ='09 26 Plaster'!$B$92 -> 565992.54 | K27: =SUM(C27:G27)-H27 -> 0
A28: 09 29 00 | B28: Drywall / Framing | C28: ='09 29 Gypsum Board'!C239 -> 2972787 | D28: ='09 29 Gypsum Board'!D239 -> 76546 | E28: ='09 29 Gypsum Board'!E239 -> 148960 | H28: ='09 29 Gypsum Board'!$B$239 -> 3198293 | K28: =SUM(C28:G28)-H28 -> 0
A29: 09 30 00 | B29: Tile Work, Tile & Stone Flooring | C29: ='09 30 Tile'!C253 -> 2681349.7 | D29: ='09 30 Tile'!D253 -> 4619.2 | E29: ='09 30 Tile'!E253 -> 207716.73 | H29: ='09 30 Tile'!$B$253 -> 2893685.6 | K29: =SUM(C29:G29)-H29 -> 0
A30: 09 41 00 | B30: Resinous Flooring | C30: ='09 41 Resinous Flooring'!C88 -> 223898.42 | D30: ='09 41 Resinous Flooring'!D88 -> 12480 | E30: ='09 41 Resinous Flooring'!E88 -> 0 | H30: ='09 41 Resinous Flooring'!$B88 -> 236378.42 | K30: =SUM(C30:G30)-H30 -> 0
A31: 09 51 00 | B31: Acoustical Ceilings | C31: ='09 51 ACT'!C79 -> 1536725 | D31: ='09 51 ACT'!D79 -> 2960 | E31: ='09 51 ACT'!E79 -> 106490 | H31: ='09 51 ACT'!$B79 -> 1646175 | K31: =SUM(C31:G31)-H31 -> 0
A32: 09 60 00 | B32: Flooring | C32: ='09 60 Resilient Flooring'!C94 -> 279493.41 | D32: ='09 60 Resilient Flooring'!D94 -> 0 | E32: ='09 60 Resilient Flooring'!E94 -> 11766.18 | H32: ='09 60 Resilient Flooring'!$B$94 -> 291259.59 | K32: =SUM(C32:G32)-H32 -> 0
A33: 09 64 00 | B33: Wood Flooring | C33: ='09 64 Wood Flooring'!C84 -> 879439.93 | D33: ='09 64 Wood Flooring'!D84 -> 14434.03 | E33: ='09 64 Wood Flooring'!E84 -> 0 | H33: ='09 64 Wood Flooring'!$B$84 -> 893873.96 | K33: =SUM(C33:G33)-H33 -> 0
A34: 09 90 00 | B34: Painting | C34: ='09 90 Painting'!C155 -> 935578.34 | D34: ='09 90 Painting'!D155 -> 25276 | E34: ='09 90 Painting'!E155 -> 14685 | H34: ='09 90 Painting'!$B155 -> 975539.34 | K34: =SUM(C34:G34)-H34 -> 0
A35: 10 22 00 | B35: Demountable Partitions | C35: ='10 22 Demountable Part'!I21 -> 47635 | H35: ='10 22 Demountable Part'!$B$90 -> 47635 | K35: =SUM(C35:G35)-H35 -> 0
A36: 10 28 00 | B36: Specialties | C36: ='10 28 Specialties'!C214 -> 99213.86 | D36: ='10 28 Specialties'!D214 -> 9942.3 | E36: ='10 28 Specialties'!E214 -> 11170.6 | H36: ='10 28 Specialties'!$B214 -> 120326.76 | K36: =SUM(C36:G36)-H36 -> 0
A37: 10 30 00 | B37: Fireplace | C37: ='10 30 Fireplace '!I21 -> 28550 | H37: ='10 30 Fireplace '!$B90 -> 28550 | K37: =SUM(C37:G37)-H37 -> 0
A38: 10 51 00 | B38: Lockers | C38: ='10 51 Lockers'!I21 -> 414093.8 | H38: ='10 51 Lockers'!$B$105 -> 414093.8 | K38: =SUM(C38:G38)-H38 -> 0
A39: 10 53 00 | B39: Signage | C39: ='10 53 Signage'!I23 -> 36500 | D39: ='10 53 Signage'!I31 -> 1050 | E39: ='10 53 Signage'!I34 -> 7700 | G39: ='10 53 Signage'!I39 -> 7500 | H39: ='10 53 Signage'!$B93 -> 52750 | K39: =SUM(C39:G39)-H39 -> 0
A40: 10 73 00 | B40: Canopy | C40: ='10 73 Canopy'!$I$21 -> 350000 | H40: ='10 73 Canopy'!$B$91 -> 350000 | K40: =SUM(C40:G40)-H40 -> 0
A41: 11 40 00 | B41: Food Service & Laundry Equipment | C41: ='11 40 FS Equip'!I21 -> 184253.95 | D41: ='11 40 FS Equip'!I48 -> 4480 | H41: ='11 40 FS Equip'!$B98 -> 188733.95 | K41: =SUM(C41:G41)-H41 -> 0
A42: 11 40 00 | B42: Appliances | C42: ='11 40 Appliances'!I21 -> 102552 | D42: ='11 40 Appliances'!I70 -> 11984 | H42: ='11 40 Appliances'!B120 -> 114536 | K42: =SUM(C42:G42)-H42 -> 0
...

Sheet GCs & GRs
A1: Contract Reference | B1: General Condition Ref. | C1: ='Area Calculations'!B4 -> Atlantic Fields Club Core / Dock Bar / Spa Pods / Water Features
C3: Construction | F3: Activity | H3: Start | I3: Finish | J3: Days | K3: Weeks | L3: Months | M3: % Time | N3: Remarks | S3: Start | T3: Finish | U3: Days | V3: Weeks | W3: Months
F4: Construction | H4: 45839 | I4: 46632 | J4: =I4-H4 -> 793 | K4: =J4/7 -> 113.28571 | L4: =J4/30.42 -> 26.068376
F5: Close Out | J5: =L5*30.4 -> 30.4 | K5: =L5*4.33 -> 4.33 | L5: 1
F6: General Conditions | H6: General Req. - Field Office | J6: General Req. | L6: Total
C7: Description | D7: Qty. | E7: U | F7: Unit Cost | G7: Const. | H7: Unit | I7: General | J7: Unit | K7: General | O7: LABOR RATE FY 2025 *Updated 09.26.24
F8: Cost | G8: Cond. | H8: Cost | I8: Req. | J8: Cost | K8: Req.
C9: Field Labor - Construction | L9: =SUM(L10:L27) -> 4280977.3
C10: Project Executive | D10: =V10 -> 124.42857 | E10: wks | F10: =(O10*40)*M10 -> 1813.2 | G10: =SUM(D10*F10) -> 225613.89 | L10: =SUM(G10+I10+K10) -> 225613.89 | M10: 0.25 | O10: 181.32 | Q10: Construction | S10: 45761 | T10: 46632 | U10: =SUM(T10-S10) -> 871 | V10: =SUM(U10/7) -> 124.42857 | W10: =SUM(U10/30) -> 29.033333
D11: =$K$4 -> 113.28571 | E11: wks | F11: =(O11*40)*M11 -> 0 | G11: =SUM(D11*F11) -> 0 | L11: =SUM(G11+I11+K11) -> 0 | M11: 0
C12: Senior Project Manager | D12: =V12 -> 124.42857 | E12: wks | F12: =(O12*40)*M12 -> 6011.2 | G12: =SUM(D12*F12) -> 747965.03 | L12: =SUM(G12+I12+K12) -> 747965.03 | M12: 1 | O12: 150.28 | Q12: Construction | S12: 45761 | T12: 46632 | U12: =SUM(T12-S12) -> 871 | V12: =SUM(U12/7) -> 124.42857 | W12: =SUM(U12/30) -> 29.033333
C13: Project Manager - Level 2 | D13: =$K$4 -> 113.28571 | E13: wks | F13: =(O13*40)*M13 -> 0 | G13: =SUM(D13*F13) -> 0 | L13: =SUM(G13+I13+K13) -> 0 | M13: 0
C14: Project Manager - Level 1 | D14: =V14 -> 111 | E14: wks | F14: =(O14*40)*M14 -> 4336.4 | G14: =SUM(D14*F14) -> 481340.4 | L14: =SUM(G14+I14+K14) -> 481340.4 | M14: 1 | O14: 108.41 | Q14: Construction | S14: 45855 | T14: 46632 | U14: =SUM(T14-S14) -> 777 | V14: =SUM(U14/7) -> 111 | W14: =SUM(U14/30) -> 25.9
C15: Project Administator | D15: =V15 -> 111 | E15: wks | F15: =(O15*40)*M15 -> 3059.2 | G15: =SUM(D15*F15) -> 339571.2 | L15: =SUM(G15+I15+K15) -> 339571.2 | M15: 1 | O15: 76.48 | Q15: Construction | S15: 45855 | T15: 46632 | U15: =SUM(T15-S15) -> 777 | V15: =SUM(U15/7) -> 111 | W15: =SUM(U15/30) -> 25.9
C16: Project Accountant | D16: =V16 -> 111 | E16: wks | F16: =(O16*40)*M16 -> 1973.6 | G16: =SUM(D16*F16) -> 219069.6 | L16: =SUM(G16+I16+K16) -> 219069.6 | M16: 0.5 | O16: 98.68 | Q16: Construction | S16: 45855 | T16: 46632 | U16: =SUM(T16-S16) -> 777 | V16: =SUM(U16/7) -> 111 | W16: =SUM(U16/30) -> 25.9
C17: Assistant Project Manager | D17: =$K$4 -> 113.28571 | E17: wks | F17: =(O17*40)*M17 -> 0 | G17: =SUM(D17*F17) -> 0 | L17: =SUM(G17+I17+K17) -> 0 | M17: 0 | Q17: Construction | U17: =SUM(T17-S17) -> 0 | V17: =SUM(U17/7) -> 0 | W17: =SUM(U17/30) -> 0
C18: Superintendent - Level 3 | D18: =V18 -> 117.28571 | E18: wks | F18: =(O18*40)*M18 -> 6060.4 | G18: =SUM(D18*F18) -> 710798.34 | L18: =SUM(G18+I18+K18) -> 710798.34 | M18: 1 | O18: 151.51 | Q18: Construction | S18: 45811 | T18: 46632 | U18: =SUM(T18-S18) -> 821 | V18: =SUM(U18/7) -> 117.28571 | W18: =SUM(U18/30) -> 27.366667
C19: Superintendent - Level 2 | D19: =V19 -> 97.428571 | E19: wks | F19: =(O19*40)*M19 -> 5087.2 | G19: =SUM(D19*F19) -> 495638.63 | L19: =SUM(G19+I19+K19) -> 495638.63 | M19: 1 | O19: 127.18 | Q19: Construction | S19: 45950 | T19: 46632 | U19: =SUM(T19-S19) -> 682 | V19: =SUM(U19/7) -> 97.428571 | W19: =SUM(U19/30) -> 22.733333
C20: Superintendent - Level 2 | D20: =V20 -> 81.428571 | E20: wks | F20: =(O20*40)*M20 -> 5087.2 | G20: =SUM(D20*F20) -> 414243.43 | L20: =SUM(G20+I20+K20) -> 414243.43 | M20: 1 | O20: 127.18 | Q20: Construction | S20: 46062 | T20: 46632 | U20: =SUM(T20-S20) -> 570 | V20: =SUM(U20/7) -> 81.428571 | W20: =SUM(U20/30) -> 19
C21: Superintendent - Level 1 | D21: =$K$4 -> 113.28571 | E21: wks | F21: =(O21*40)*M21 -> 0 | G21: =SUM(D21*F21) -> 0 | L21: =SUM(G21+I21+K21) -> 0 | M21: 0
C22: Assistant Superinterndent | D22: =V22 -> 113.28571 | E22: wks | F22: =(O22*40)*M22 -> 0 | G22: =SUM(D22*F22) -> 0 | L22: =SUM(G22+I22+K22) -> 0 | M22: 0 | Q22: Construction | S22: 45839 | T22: 46632 | U22: =SUM(T22-S22) -> 793 | V22: =SUM(U22/7) -> 113.28571 | W22: =SUM(U22/30) -> 26.433333
C23: Quality Control Manager | D23: =$K$4 -> 113.28571 | E23: wks | F23: =(O23*40)*M23 -> 1183.7 | G23: =SUM(D23*F23) -> 134096.3 | L23: =SUM(G23+I23+K23) -> 134096.3 | M23: 0.25 | O23: 118.37 | Q23: Construction | U23: =SUM(T23-S23) -> 0 | V23: =SUM(U23/7) -> 0 | W23: =SUM(U23/30) -> 0
C24: Foreman | D24: =$K$4 -> 113.28571 | E24: wks | F24: =(O24*40)*M24 -> 1910.4 | G24: =SUM(D24*F24) -> 216421.03 | L24: =SUM(G24+I24+K24) -> 216421.03 | M24: 1 | O24: 47.76
C25: Accounting | D25: =$K$4 -> 113.28571 | E25: wks | F25: =(O25*40)*M25 -> 1066.64 | G25: =SUM(D25*F25) -> 120835.07 | L25: =SUM(G25+I25+K25) -> 120835.07 | M25: 0.2 | O25: 133.33 | Q25: Construction | U25: =SUM(T25-S25) -> 0 | V25: =SUM(U25/7) -> 0 | W25: =SUM(U25/30) -> 0
C26: VDC Manager | D26: =$K$4 -> 113.28571 | E26: wks | F26: =(O26*40)*M26 -> 1181.4 | G26: =SUM(D26*F26) -> 133835.74 | L26: =SUM(G26+I26+K26) -> 133835.74 | M26: 0.25 | O26: 118.14 | Q26: Construction | U26: =SUM(T26-S26) -> 0 | V26: =SUM(U26/7) -> 0 | W26: =SUM(U26/30) -> 0
C27: Safety Supervisor/Inspector | D27: =K4 -> 113.28571 | E27: wks | F27: =(O27*40)*M27 -> 366.76 | G27: =SUM(D27*F27) -> 41548.669 | L27: =SUM(G27+I27+K27) -> 41548.669 | M27: 0.1 | O27: 91.69 | Q27: Construction | U27: =SUM(T27-S27) -> 0 | V27: =SUM(U27/7) -> 0 | W27: =SUM(U27/30) -> 0
C28: Field Labor - Close Out | L28: =SUM(L29:L43) -> 78805.654
C29: Project Executive | D29: =$K$5 -> 4.33 | E29: wks | F29: =(40*O29)*M29 -> 725.28 | G29: =SUM(D29*F29) -> 3140.4624 | L29: =SUM(G29+I29+K29) -> 3140.4624 | M29: 0.1 | O29: =+O10 -> 181.32
C30: Senior Project Manager | D30: =$K$5 -> 4.33 | E30: wks | F30: =(40*O30)*M30 -> 0 | G30: =SUM(D30*F30) -> 0 | L30: =SUM(G30+I30+K30) -> 0 | M30: =+M11 -> 0 | O30: =+O11 -> 0
C31: Project Manager - Level 3 | D31: =$K$5 -> 4.33 | E31: wks | F31: =(40*O31)*M31 -> 6011.2 | G31: =SUM(D31*F31) -> 26028.496 | L31: =SUM(G31+I31+K31) -> 26028.496 | M31: =+M12 -> 1 | O31: =O12 -> 150.28
C32: Project Manager - Level 2 | D32: =$K$5 -> 4.33 | E32: wks | F32: =(40*O32)*M32 -> 0 | G32: =SUM(D32*F32) -> 0 | L32: =SUM(G32+I32+K32) -> 0 | M32: =+M13 -> 0 | O32: =+O13 -> 0
C33: Project Manager - Level 1 | D33: =$K$5 -> 4.33 | E33: wks | F33: =(40*O33)*M33 -> 4336.4 | G33: =SUM(D33*F33) -> 18776.612 | L33: =SUM(G33+I33+K33) -> 18776.612 | M33: =+M14 -> 1 | O33: =+O14 -> 108.41
C34: Project Administator | D34: =$K$5 -> 4.33 | E34: wks | F34: =(40*O34)*M34 -> 0 | G34: =SUM(D34*F34) -> 0 | L34: =SUM(G34+I34+K34) -> 0 | M34: 0 | O34: =+O15 -> 76.48
C35: Assistant Project Manager | D35: =$K$5 -> 4.33 | E35: wks | F35: =(40*O35)*M35 -> 0 | G35: =SUM(D35*F35) -> 0 | L35: =SUM(G35+I35+K35) -> 0 | M35: =+M17 -> 0 | O35: =+O17 -> 0
C36: Superintendent - Level 3 | D36: =$K$5 -> 4.33 | E36: wks | F36: =(40*O36)*M36 -> 6060.4 | G36: =SUM(D36*F36) -> 26241.532 | L36: =SUM(G36+I36+K36) -> 26241.532 | M36: =+M18 -> 1 | O36: =+O18 -> 151.51
C37: Superintendent - Level 2 | D37: =$K$5 -> 4.33 | E37: wks | F37: =(40*O37)*M37 -> 0 | G37: =SUM(D37*F37) -> 0 | L37: =SUM(G37+I37+K37) -> 0 | M37: 0 | O37: =+O19 -> 127.18
C38: Superintendent - Level 1 | D38: =$K$5 -> 4.33 | E38: wks | F38: =(40*O38)*M38 -> 0 | G38: =SUM(D38*F38) -> 0 | L38: =SUM(G38+I38+K38) -> 0 | M38: =+M21 -> 0 | O38: =+O21 -> 0
C39: Assistant Superinterndent | D39: =$K$5 -> 4.33 | E39: wks | F39: =(40*O39)*M39 -> 0 | G39: =SUM(D39*F39) -> 0 | L39: =SUM(G39+I39+K39) -> 0 | M39: =+M22 -> 0 | O39: =+O22 -> 0
C40: Foreman | D40: =$K$5 -> 4.33 | E40: wks | F40: =(40*O40)*M40 -> 0 | G40: =SUM(D40*F40) -> 0 | L40: =SUM(G40+I40+K40) -> 0 | M40: 0 | O40: =+O24 -> 47.76
C41: Accounting | D41: =$K$5 -> 4.33 | E41: wks | F41: =(40*O41)*M41 -> 1066.64 | G41: =SUM(D41*F41) -> 4618.5512 | L41: =SUM(G41+I41+K41) -> 4618.5512 | M41: =+M25 -> 0.2 | O41: =+O25 -> 133.33
...

Sheet 02 21 Survey 
G1: Hedrick Plug
F2: X | G2: Excluded
F3: I | G3: Included
B4: BACK TO SUMMARY SHEET | G4: Sub Add/Deduct
A5: Project: | B5: Atlantic Fields Club Core | G5: Company | H5: Velcon Engineering and Surveying
A6: Trade: | B6: Surveying | G6: Contact
A7: CSI Code: | B7: 02 21 00 | G7: Phone
A8: Date: | G8: Email
G9: Adjusted Bid | H9: =I60 -> 73350 | J9: =K64 -> 0 | L9: =M64 -> 0 | N9: =O64 -> 0 | P9: =Q64 -> 0 | R9: =S64 -> 0
A10: BID DOCUMENTS: | C10: Plan/ Spec. Package | D10: QTY | E10: U/M | F10: Unit Cost | G10: Subtotal | H10: Yes/No | I10: Price | J10: Yes/No | K10: Price | L10: Yes/No | M10: Price | N10: Yes/No | O10: Price | P10: Yes/No | Q10: Price | R10: Yes/No | S10: Price
B11: GENERAL INCLUSIONS
B12: INCLUDES ALL SALES TAX
B13: ALL HOISTING & RIGGING REQUIRED TO COMPLETE THIS SCOPE
B14: PROVIDE P&P BONDS
B15: FLORIDA STATE CONTRACTORS LIC.
B16: GENERAL LIABILITY AND WORKERS COMP. INSURANCE LIMITS
B17: STATE AND LOCAL TAXES
B18: SPECIFIC TRADE SCOPE OF WORK REQUIREMENTS
B19: BASE BID
B21: Club Core | I21: =SUBTOTAL(9,I22:I29) -> 22000 | K21: =SUBTOTAL(9,K22:K29) -> 0 | M21: =SUBTOTAL(9,M22:M29) -> 0 | O21: =SUBTOTAL(9,O22:O29) -> 0 | Q21: =SUBTOTAL(9,Q22:Q29) -> 0 | S21: =SUBTOTAL(9,S22:S29) -> 0
B22: Set up digital files | D22: 1 | E22: ls | F22: 1500 | G22: =ROUND(D22*F22,0) -> 1500 | I22: =G22 -> 1500
B23: Calculations | D23: 1 | E23: ls | F23: 1000 | G23: =ROUND(D23*F23,0) -> 1000 | I23: =G23 -> 1000
B24: Verify horizontal and vertical control | D24: 1 | E24: ls | F24: 2500 | G24: =ROUND(D24*F24,0) -> 2500 | I24: =G24 -> 2500
B25: Building foundations layout | D25: 1 | E25: ls | F25: =1500*3 -> 4500 | G25: =ROUND(D25*F25,0) -> 4500 | I25: =G25 -> 4500
B26: FEMA Certificate | D26: 1 | E26: ls | F26: 3000 | G26: =ROUND(D26*F26,0) -> 3000 | I26: =G26 -> 3000
B27: Final as-built survey | D27: 1 | E27: ls | F27: 7500 | G27: =ROUND(D27*F27,0) -> 7500 | I27: =G27 -> 7500
B28: Pool & Spas | D28: 1 | E28: ls | F28: 2000 | G28: =ROUND(D28*F28,0) -> 2000 | I28: =G28 -> 2000
G29: =ROUND(D29*F29,0) -> 0
B30: Dock Bar - NA | G30: =ROUND(D30*F30,0) -> 0 | I30: =SUBTOTAL(9,I31:I32) -> 0 | K30: =SUBTOTAL(9,K31:K32) -> 0 | M30: =SUBTOTAL(9,M31:M32) -> 0 | O30: =SUBTOTAL(9,O31:O32) -> 0 | Q30: =SUBTOTAL(9,Q31:Q32) -> 0 | S30: =SUBTOTAL(9,S31:S32) -> 0
B31: Base structure will already be in place | D31: 1 | E31: ls | F31: 0 | G31: =ROUND(D31*F31,0) -> 0
G32: =ROUND(D32*F32,0) -> 0
B33: Spa Pods | G33: =ROUND(D33*F33,0) -> 0 | I33: =SUBTOTAL(9,I34:I41) -> 9350 | K33: =SUBTOTAL(9,K35:K41) -> 0 | M33: =SUBTOTAL(9,M35:M41) -> 0 | O33: =SUBTOTAL(9,O35:O41) -> 0 | Q33: =SUBTOTAL(9,Q35:Q41) -> 0 | S33: =SUBTOTAL(9,S35:S41) -> 0
B34: Set up digital files | D34: 1 | E34: ls | F34: 1500 | G34: =ROUND(D34*F34,0) -> 1500 | I34: =G34 -> 1500
B35: Calculations | D35: 1 | E35: ls | F35: 1000 | G35: =ROUND(D35*F35,0) -> 1000 | I35: =G35 -> 1000
B36: Verify horizontal and vertical control | D36: 1 | E36: ls | F36: 750 | G36: =ROUND(D36*F36,0) -> 750 | I36: =G36 -> 750
B37: Building foundations layout | D37: 1 | E37: ls | F37: =350*6 -> 2100 | G37: =ROUND(D37*F37,0) -> 2100 | I37: =G37 -> 2100
B38: FEMA Certificate | D38: 1 | E38: ls | F38: 1500 | G38: =ROUND(D38*F38,0) -> 1500 | I38: =G38 -> 1500
B39: Final as-built survey | D39: 1 | E39: ls | F39: 2500 | G39: =ROUND(D39*F39,0) -> 2500 | I39: =G39 -> 2500
B40: Pool & Spas | D40: 1 | E40: ls | G40: =ROUND(D40*F40,0) -> 0 | I40: =G40 -> 0
G41: =ROUND(D41*F41,0) -> 0
...

Sheet 03 30 CIP Concrete
G1: Hedrick Plug
F2: X | G2: Excluded
F3: I | G3: Included
B4: BACK TO SUMMARY SHEET | G4: Sub Add/Deduct
D5: PREQUALIFIED? (If not, add Sub Bond) | H5: YES | J5: NO | L5: NO | N5: YES | P5: =L5 -> NO | R5: =N5 -> YES | T5: YES
A6: Project: | B6: Atlantic Fields Club Core | G6: Company | H6: Victory Concrete | J6: Construction Trade Part | L6: Proshell | N6: Starlite Building Serv | P6: Cook Shell | R6: Ron Kendal | T6: Pate Construction
A7: Trade: | B7: Concrete & CMU | G7: Contact | H7: Jeff Grebla | J7: David Webster | L7: Julien Beauregard | N7: Sean Williams | P7: Elias Morales | R7: Christopher Markley | T7: Jason Tartaglia
A8: CSI Code: | B8: 03 30 00 | G8: Phone | H8: (561) 227-9577 | J8: (561) 441-9752 | L8: (561) 889-0405 | N8: (561) 719-7607 | P8: (772) 247-7150 | R8: (754) 233-1319 | T8: (561) 261-7473
A9: Date: | G9: Email | H9: jsgrebla@vconcreteco.com | J9: davew@ctpflorida.com | L9: julien@proshellconstruction.com | N9: starlitebuildingservices.com | P9: EMorales@cookshellcontractors.com | R9: cmarkley@ronkm.com | T9: jason.tartaglia@pateformwork.com
G10: Adjusted Bid | H10: =I$265 -> 7649008 | J10: =K$265 -> 6434574.1 | L10: =M$265 -> 7348275.8 | N10: =O$265 -> 7223508 | P10: =Q$265 -> 7702632 | R10: =S$265 -> 8088319.5 | T10: =U$265 -> 8046000
A11: BID DOCUMENTS: | C11: Plan/ Spec. Package | D11: QTY | E11: U/M | F11: Unit Cost | G11: Subtotal | H11: Yes/No | I11: Price | J11: Yes/No | K11: Price | L11: Yes/No | M11: Price | N11: Yes/No | O11: Price | P11: Yes/No | Q11: Price | R11: Yes/No | S11: Price | T11: Yes/No | U11: Price
B12: GENERAL INCLUSIONS
B13: INCLUDES ALL SALES TAX | H13: i | J13: i | L13: i | N13: i | P13: i | R13: i | T13: i
B14: ALL HOISTING & RIGGING REQUIRED TO COMPLETE THIS SCOPE | H14: i | J14: i | L14: i | N14: i | P14: i | R14: i | T14: i
B15: FLORIDA STATE CONTRACTORS LIC. | H15: i | J15: i | L15: i | N15: i | P15: i | R15: i | T15: i
B16: GENERAL LIABILITY AND WORKERS COMP. INSURANCE LIMITS | H16: i | J16: i | L16: i | N16: i | P16: i | R16: i | T16: i
B17: STATE AND LOCAL TAXES | H17: i | J17: i | L17: i | N17: i | P17: i | R17: i | T17: i
B18: SPECIFIC TRADE SCOPE OF WORK REQUIREMENTS
B19: BASE BID
