Workbook

Sheet Area Calculations
A1: 110025
B2: PROJECT AREA CALCULATIONS
B4: Bourbon Hotel Orlando
B5: Orlando | F5: Gross (sf) | G5: =E28 -> 389323
F6: AC (sf) | G6: =243055+18447 -> 261502
F7: Site (acres) | G7: =174581/43560 -> 4.0078283
F8: Parking Spaces | M8: Rooms | O8: penthouse | P8: suite | Q8: standard
F9: No. of Rooms | G9: =N15 -> 296 | M9: 2 | N9: =SUM(O9:Q9) -> 40 | P9: 1 | Q9: 39
F10: Build Duration (months) | M10: 3 | N10: =SUM(O10:Q10) -> 46 | P10: 3 | Q10: 43
M11: 4 | N11: =SUM(O11:Q11) -> 62 | P11: 6 | Q11: 56
M12: 5 | N12: =SUM(O12:Q12) -> 62 | P12: 6 | Q12: 56
A13: I. | B13: Floors | C13: Units | D13: AC SF | E13: Gross SF | F13: LSF | M13: 6 | N13: =SUM(O13:Q13) -> 62 | P13: 6 | Q13: 56
B14: Garage Level | E14: 110025 | M14: 7 | N14: 24 | O14: 3 | P14: 1 | Q14: 20
B15: Restaurant | E15: =SUM(I15:K15) -> 15680 | I15: 10434 | J15: 4259 | K15: 987 | N15: =SUM(N9:N14) -> 296 | O15: =SUM(O9:O14) -> 3 | P15: =SUM(P9:P14) -> 23 | Q15: =SUM(Q9:Q14) -> 270
B16: Restaurant Roof Garden | E16: 7081
B17: Level 1 Hotel | E17: 41647
B18: Level 2 thru 6 | E18: =SUM(I18:K18) -> 175894 | I18: 37358 | J18: 34634 | K18: =34634*3 -> 103902
B19: Level 7 | E19: 31962
B20: Level 7 Terrace | E20: 4950
B21: Bridge | E21: =1037+1047 -> 2084
B28: TOTAL | C28: =SUM(C14:C27) -> 0 | D28: =SUM(D14:D27) -> 0 | E28: =SUM(E14:E27) -> 389323 | F28: =SUM(F14:F27) -> 0
C30: total | D30: garage | E30: ground | F30: 2nd | G30: 3rd | H30: 4th - 6th | I30: 7th
B31: Corridors | C31: =C62+C63+C90 -> 39203
A32: IV. | B32: Corridors / Stairs | C32: =SUM(E32:I32) -> 0
B33: Corridors / Stairs | C33: =SUM(E33:I33) -> 0
B34: Corridors / Stairs | C34: =SUM(E34:I34) -> 0
B35: Corridors / Stairs | C35: =SUM(E35:I35) -> 0
B36: Corridors / Stairs | C36: =SUM(E36:I36) -> 0
B37: Corridors / Stairs | C37: =SUM(E37:I37) -> 0
B38: Corridors / Stairs | C38: =SUM(E38:I38) -> 0
A39: III. | B39: Corridors / Stairs | C39: =SUM(E39:I39) -> 0
B40: Corridors / Stairs | C40: =SUM(E40:I40) -> 0
B41: Corridors / Stairs | C41: =SUM(E41:I41) -> 0
B42: Corridors / Stairs | C42: =SUM(E42:I42) -> 0
B43: Corridors / Stairs | C43: =SUM(E43:I43) -> 0
A44: III. | B44: Corridors / Stairs | C44: =SUM(E44:I44) -> 0
B45: Corridors / Stairs | C45: =SUM(E45:I45) -> 0
B46: Corridors / Stairs | C46: =SUM(E46:I46) -> 0
B47: Corridors / Stairs | C47: =SUM(E47:I47) -> 0
B48: Corridors / Stairs | C48: =SUM(E48:I48) -> 0
...

Sheet Allowances
A3: ='Area Calculations'!B4 -> Bourbon Hotel Orlando | C3: ='Area Calculations'!B5 -> Orlando
A5: Allowances
A6: =TODAY() -> 46146
A8: NO. | B8: DESCRIPTION | C8: VALUE
A9: 1
A10: =A9+1 -> 2
A11: =A10+1 -> 3
A12: =A11+1 -> 4
A13: =A12+1 -> 5
A14: =A13+1 -> 6
A15: =A14+1 -> 7
A16: =A15+1 -> 8
A17: =A16+1 -> 9
A18: =A17+1 -> 10
A19: =A18+1 -> 11
A20: =A19+1 -> 12
A21: =A20+1 -> 13
... A26: =A25+1 -> 18
A27: =A26+1 -> 19 | B27: Total | C27: =SUM(C9:C26) -> 0
B29: *All ALLOWANCES IN BID TABS MUST BE LISTED HERE

Sheet Word C&A

Sheet Documents
A3: ='Area Calculations'!B4 -> Bourbon Hotel Orlando | C3: ='Area Calculations'!B5 -> Orlando
A5: List of Drawings
A6: =TODAY() -> 46146
A9: SHEET NO. | B9: DESCRIPTION | C9: DATE
D105: 11

Sheet Cost Summary
A3: ='Area Calculations'!B4 -> Bourbon Hotel Orlando
A4: ='Area Calculations'!B5 -> Orlando
A5: Conceptual Estimate - Cost Summary
A6: =NOW() -> 46146.223
A7: CSI | B7: CSI DESCRIPTION | C7: TOTAL | D7: $/
A8: 02 21 00 | B8: Surveying | C8: ='02 21 Survey '!$H$9 -> 60117 | D8: =C8/'Area Calculations'!$G$5 -> 0.1544142 | E8: ACRE
A9: 02 41 00 | B9: Demolition | C9: ='02 41 Demo'!$H$9 -> 0 | D9: =C9/'Area Calculations'!$G$5 -> 0 | E9: GSF
A10: 03 30 00 | B10: Concrete & CMU | C10: ='03 30 Conc & CMU'!$H$9 -> 33000765 | D10: =C10/'Area Calculations'!$G$5 -> 84.764489 | E10: GSF
A11: 04 40 00 | B11: Stone Cladding | C11: ='04 40 Stone Cladding'!$H$9 -> 132072 | D11: =C11/'Area Calculations'!$G$5 -> 0.33923503 | E11: GSF
A12: 05 30 00 | B12: Structural Steel | C12: ='05 10 Structural Steel'!$H$9 -> 11299290 | D12: =C12/'Area Calculations'!$G$5 -> 29.022919 | E12: GSF
A13: 05 52 00 | B13: Miscellaneous Metals | C13: ='05 52 Misc Metals'!$H$9 -> 1259600 | D13: =C13/'Area Calculations'!$G$5 -> 3.2353598 | E13: GSF
A14: 05 52 00 | B14: Railings - Glass | C14: ='05 70 Railings Glass'!$H$9 -> 698400 | D14: =C14/'Area Calculations'!$G$5 -> 1.7938832 | E14: GSF
A15: 06 10 00 | B15: Rough Carpentry | C15: ='06 10 Rough Carpentry'!$H$9 -> 236980 | D15: =C15/'Area Calculations'!$G$5 -> 0.60869766 | E15: GSF
A16: 06 50 00 | B16: Millwork | C16: Inc Buildout Cost
A17: 07 17 00 | B17: Waterproofing & Caulking | C17: ='07 17 Waterproofing & Caulk'!$H$9 -> 6411905 | D17: =C17/'Area Calculations'!$G$5 -> 16.469371 | E17: GSF
A18: 07 21 00 | B18: Sound Insulation | C18: ='07 21 Spray Foam Ins'!$H$9 -> 177267 | D18: =C18/'Area Calculations'!$G$5 -> 0.45532116 | E18: GSF
A19: 07 42 00 | B19: Metal Panel | C19: ='07 42 Metal Panel'!$H$9 -> 3361361 | D19: =C19/'Area Calculations'!$G$5 -> 8.6338619 | E19: GSF
A20: 07 50 00 | B20: Roofing | C20: ='07 50 Roofing'!$H$9 -> 1628655 | D20: =C20/'Area Calculations'!$G$5 -> 4.1833002 | E20: GSF
A21: 08 12 70 | B21: Doors, Frames, & Hardware | C21: Inc Buildout Cost
A22: 08 50 00 | B22: Storefront & Curtainwall | C22: ='08 50 Storefront'!$H$9 -> 8830610 | D22: =C22/'Area Calculations'!$G$5 -> 22.681963 | E22: GSF
A23: 08 50 00 | B23: Interior Glazing | C23: Inc Buildout Cost
A24: 09 29 00 | B24: Exterior Wall Framing | C24: ='09 29 Gypsum Board'!$H$9 -> 2590290 | D24: =C24/'Area Calculations'!$G$5 -> 6.6533187 | E24: GSF
A25: 09 29 00 | B25: Drywall | C25: Inc Buildout Cost
A26: 09 51 00 | B26: Acoustical Ceilings | C26: Inc Buildout Cost
A27: 09 60 00 | B27: Flooring | C27: Inc Buildout Cost
A28: 09 90 00 | B28: Painting - Exterior | C28: ='09 90 Painting'!$H$9 -> 29702 | D28: =C28/'Area Calculations'!$G$5 -> 0.076291408 | E28: GSF
A29: 09 90 00 | B29: Painting - Interior | C29: Inc Buildout Cost
A30: 10 28 00 | B30: Specialties | C30: Inc Buildout Cost
A31: 10 53 00 | B31: Signage | C31: ='10 53 Signage'!$H$9 -> 312233 | D31: =C31/'Area Calculations'!$G$5 -> 0.80198961 | E31: GSF
A32: 10 73 00 | B32: Canopies / Trellis | C32: ='10 73 Canopies'!$H$9 -> 2522500 | D32: =C32/'Area Calculations'!$G$5 -> 6.4791959 | E32: GSF
A33: 13 11 00 | B33: Pool & Water Features | C33: ='13 11 Pool'!$H$9 -> 4174180 | D33: =C33/'Area Calculations'!$G$5 -> 10.721637 | E33: GSF
A34: 14 00 00 | B34: Elevators | C34: ='14 00 Elevators'!$H$9 -> 3313230 | D34: =C34/'Area Calculations'!$G$5 -> 8.5102344 | E34: GSF
A35: 14 91 00 | B35: Laundry Chute | C35: ='14 91 Laundry Chute'!$H$9 -> 20300 | D35: =C35/'Area Calculations'!$G$5 -> 0.052141795 | E35: GSF
A36: 21 13 00 | B36: Fire Protection Systems | C36: ='21 13 Fire Protection'!$H$9 -> 1272593 | D36: =C36/'Area Calculations'!$G$5 -> 3.2687332 | E36: GSF
A37: 22 00 00 | B37: Plumbing | C37: ='22 00 Plumbing '!$H$9 -> 7234302 | D37: =C37/'Area Calculations'!$G$5 -> 18.581748 | E37: GSF
A38: 23 00 00 | B38: HVAC | C38: ='23 00 HVAC'!$H$9 -> 8615235 | D38: =C38/'Area Calculations'!$G$5 -> 22.128759 | E38: GSF
A39: 26 00 00 | B39: Electrical | C39: ='26 00 Electrical'!$H$9 -> 12741754 | D39: =C39/'Area Calculations'!$G$5 -> 32.727977 | E39: GSF
A40: 31 30 00 | B40: Sitework | C40: ='31 30 Site Work'!$H$9 -> 992609 | D40: =C40/'Area Calculations'!G7 -> 247667.55 | E40: ACRE
A41: 32 14 00 | B41: Hardscape | C41: ='32 14 00 Hardscape'!$H$9 -> 965407 | D41: =C41/'Area Calculations'!G7 -> 240880.33 | E41: ACRE
A42: 32 80 00 | B42: Landscape | C42: ='32 80 00 Landscape'!$H$9 -> 594475 | D42: =C42/'Area Calculations'!G7 -> 148328.46 | E42: ACRE
...

Sheet GCs & GRs
A1: Contract Reference | B1: General Condition Ref. | C1: TEST
C3: Construction | F3: Activity | H3: Start | I3: Finish | J3: Days | K3: Weeks | L3: Months | M3: % Time | N3: Remarks | O3: CUSTOMIZED LABOR RATES | P3: LABOR RATE FY 2025 *Updated 09.26.24 | R3: Demo to building pad
F4: Construction | H4: 46235 | I4: 46904 | J4: =SUM(I4-H4) -> 669 | K4: =SUM(J4/7) -> 95.571429 | L4: =SUM(J4/30) -> 22.3 | R4: Activity | T4: Start | U4: Finish | V4: Days | W4: Weeks | X4: Months
F5: Close Out | H5: =I4 -> 46904 | I5: =H5+60 -> 46964 | J5: =SUM(I5-H5) -> 60 | K5: =SUM(J5/7) -> 8.5714286 | L5: =SUM(J5/30) -> 2 | R5: Construction | T5: 0 | U5: 0 | V5: =SUM(U5-T5) -> 0 | W5: =SUM(V5/7) -> 0 | X5: =SUM(V5/30) -> 0
F6: General Conditions | H6: General Req. - Field Office | J6: General Req. | L6: Total | R6: Building
C7: Description | D7: Qty. | E7: U | F7: Unit | G7: Const. | H7: Unit | I7: General | J7: Unit | K7: General | Q7: LABOR RATE (MIAMI/FT. LAUDERDALE) | R7: Activity | T7: Start | U7: Finish | V7: Days | W7: Weeks | X7: Months | Y7: LABOR RATE (MF CENTRAL FLORIDA)
F8: Cost | G8: Cond. | H8: Cost | I8: Req. | J8: Cost | K8: Req. | R8: Construction | T8: 0 | U8: 0 | V8: =SUM(U8-T8) -> 0 | W8: =SUM(V8/7) -> 0 | X8: =SUM(V8/30) -> 0
C9: Field Labor - Construction | L9: =SUM(L10:L26) -> 5755110
A10: 1 | C10: Project Executive | D10: =$K$4 -> 95.571429 | E10: wks | F10: =(O10*40)*M10 -> 4256.9972 | G10: =SUM(D10*F10) -> 406847.3 | L10: =SUM(G10+I10+K10) -> 406847.3 | M10: 0.5 | O10: ='Labor Rates'!G10 -> 212.84986 | P10: 212.84986 | Q10: 253 | Y10: 216
A11: 2 | C11: Senior Project Manager | D11: =$K$4 -> 95.571429 | E11: wks | F11: =(O11*40)*M11 -> 7056.4365 | G11: =SUM(D11*F11) -> 674393.71 | L11: =SUM(G11+I11+K11) -> 674393.71 | M11: 1 | O11: ='Labor Rates'!G11 -> 176.41091 | P11: 176.41091 | Q11: 195 | Y11: 175
A12: 3 | C12: Project Manager - Level 3 | D12: =$K$4 -> 95.571429 | E12: wks | F12: =(O12*40)*M12 -> 0 | G12: =SUM(D12*F12) -> 0 | L12: =SUM(G12+I12+K12) -> 0 | M12: 0 | O12: ='Labor Rates'!G12 -> 162.46079 | P12: 162.46
A13: 4 | C13: Project Manager - Level 2 | D13: =$K$4 -> 95.571429 | E13: wks | F13: =(O13*40)*M13 -> 5947.817 | G13: =SUM(D13*F13) -> 568441.37 | L13: =SUM(G13+I13+K13) -> 568441.37 | M13: 1 | O13: ='Labor Rates'!G13 -> 148.69542 | P13: 148.69542 | Q13: 185 | Y13: 155
A14: 5 | C14: Project Manager - Level 1 | D14: =$K$4 -> 95.571429 | E14: wks | F14: =(O14*40)*M14 -> 5090.3426 | G14: =SUM(D14*F14) -> 486491.32 | L14: =SUM(G14+I14+K14) -> 486491.32 | M14: 1 | O14: ='Labor Rates'!G14 -> 127.25857 | P14: 127.25857 | Q14: 163 | Y14: 130
A15: 6 | C15: Project Administator | D15: =$K$4 -> 95.571429 | E15: wks | F15: =(O15*40)*M15 -> 3591.2833 | G15: =SUM(D15*F15) -> 343224.08 | L15: =SUM(G15+I15+K15) -> 343224.08 | M15: 1 | O15: ='Labor Rates'!G15 -> 89.782084 | P15: 89.782084 | Q15: 95 | Y15: 65
A16: 7 | C16: Project Accountant | D16: =$K$4 -> 95.571429 | E16: wks | F16: =(O16*40)*M16 -> 4633.7422 | G16: =SUM(D16*F16) -> 442853.36 | L16: =SUM(G16+I16+K16) -> 442853.36 | M16: 1 | O16: ='Labor Rates'!G16 -> 115.84355 | P16: 115.84355 | Q16: 81 | Y16: 60
A17: 8 | C17: Assistant Project Manager | D17: =$K$4 -> 95.571429 | E17: wks | F17: =(O17*40)*M17 -> 4467.6124 | G17: =SUM(D17*F17) -> 426976.1 | L17: =SUM(G17+I17+K17) -> 426976.1 | M17: 1 | O17: ='Labor Rates'!G17 -> 111.69031 | P17: 111.69031 | Q17: 118 | Y17: 95
A18: 9 | C18: Superintendent - Level 3 | D18: =$K$4 -> 95.571429 | E18: wks | F18: =(O18*40)*M18 -> 7114.6074 | G18: =SUM(D18*F18) -> 679953.19 | L18: =SUM(G18+I18+K18) -> 679953.19 | M18: 1 | O18: ='Labor Rates'!G18 -> 177.86518 | P18: 177.86518 | Q18: 183 | Y18: 194
A19: 10 | C19: Superintendent - Level 2 | D19: =$K$4 -> 95.571429 | E19: wks | F19: =(O19*40)*M19 -> 0 | G19: =SUM(D19*F19) -> 0 | L19: =SUM(G19+I19+K19) -> 0 | M19: 0 | O19: ='Labor Rates'!G19 -> 149.29951 | P19: 149.29951 | Q19: 161 | Y19: 173
A20: 11 | C20: Superintendent - Level 1 | D20: =$K$4 -> 95.571429 | E20: wks | F20: =(O20*40)*M20 -> 4887.7994 | G20: =SUM(D20*F20) -> 467133.97 | L20: =SUM(G20+I20+K20) -> 467133.97 | M20: 1 | O20: ='Labor Rates'!G20 -> 122.19499 | P20: 122.19499 | Q20: 121 | Y20: 155
A21: 12 | C21: Assistant Superinterndent | D21: =$K$4 -> 95.571429 | E21: wks | F21: =(O21*40)*M21 -> 5823.7833 | G21: =SUM(D21*F21) -> 556587.29 | L21: =SUM(G21+I21+K21) -> 556587.29 | M21: 1.8 | O21: ='Labor Rates'!G21 -> 80.885879 | P21: 80.885879 | Q21: 84 | Y21: 95
A22: 13 | C22: Quality Control Manager | D22: =$K$4 -> 95.571429 | E22: wks | F22: =(O22*40)*M22 -> 1389.5872 | G22: =SUM(D22*F22) -> 132804.84 | L22: =SUM(G22+I22+K22) -> 132804.84 | M22: 0.25 | O22: ='Labor Rates'!G22 -> 138.95872 | P22: 138.95872
A23: 14 | C23: Foreman | D23: =$K$4 -> 95.571429 | E23: wks | F23: =(O23*40)*M23 -> 2242.5364 | G23: =SUM(D23*F23) -> 214322.41 | L23: =SUM(G23+I23+K23) -> 214322.41 | M23: 1 | O23: ='Labor Rates'!G23 -> 56.06341 | P23: 56.06341 | Q23: 65 | Y23: 65
A24: 15 | C24: Accounting | D24: =$K$4 -> 95.571429 | E24: wks | F24: =(O24*40)*M24 -> 1252.1287 | G24: =SUM(D24*F24) -> 119667.73 | L24: =SUM(G24+I24+K24) -> 119667.73 | M24: 0.2 | O24: ='Labor Rates'!G24 -> 156.51609 | P24: 156.51609 | Q24: 80 | Y24: 90
A25: 16 | C25: VDC Manager | D25: =$K$4 -> 95.571429 | E25: wks | F25: =(O25*40)*M25 -> 1386.8106 | G25: =SUM(D25*F25) -> 132539.47 | L25: =SUM(G25+I25+K25) -> 132539.47 | M25: 0.25 | O25: ='Labor Rates'!G25 -> 138.68106 | P25: 138.68106 | Q25: 101 | Y25: 101
A26: 17 | C26: Safety Supervisor/Inspector | D26: =K4 -> 95.571429 | E26: wks | F26: =(O26*40)*M26 -> 1076.4086 | G26: =SUM(D26*F26) -> 102873.9 | L26: =SUM(G26+I26+K26) -> 102873.9 | M26: 0.25 | O26: ='Labor Rates'!G26 -> 107.64086 | P26: 107.64086 | Q26: 96 | Y26: 96
C27: Field Labor - Close Out | L27: =SUM(L28:L43) -> 467754.07
C28: Project Executive | D28: =$K$5 -> 8.5714286 | E28: wks | F28: =(40*P28)*M28 -> 0 | G28: =SUM(D28*F28) -> 0 | L28: =SUM(G28+I28+K28) -> 0 | M28: 0 | O28: =O10 -> 212.84986 | P28: =+P10 -> 212.84986 | Q28: =+Q10 -> 253 | Y28: =+Y10 -> 216
C29: Senior Project Manager | D29: =$K$5 -> 8.5714286 | E29: wks | F29: =(40*P29)*M29 -> 7056.4365 | G29: =SUM(D29*F29) -> 60483.741 | L29: =SUM(G29+I29+K29) -> 60483.741 | M29: =+M11 -> 1 | O29: =O11 -> 176.41091 | P29: =+P11 -> 176.41091 | Q29: =+Q11 -> 195 | Y29: =+Y11 -> 175
C30: Project Manager - Level 3 | D30: =$K$5 -> 8.5714286 | E30: wks | F30: =(40*P30)*M30 -> 0 | G30: =SUM(D30*F30) -> 0 | L30: =SUM(G30+I30+K30) -> 0 | M30: =+M12 -> 0 | O30: =O12 -> 162.46079 | P30: =P12 -> 162.46
C31: Project Manager - Level 2 | D31: =$K$5 -> 8.5714286 | E31: wks | F31: =(40*P31)*M31 -> 5947.817 | G31: =SUM(D31*F31) -> 50981.289 | L31: =SUM(G31+I31+K31) -> 50981.289 | M31: =+M13 -> 1 | O31: =O13 -> 148.69542 | P31: =+P13 -> 148.69542 | Q31: =+Q13 -> 185 | Y31: =+Y13 -> 155
C32: Project Manager - Level 1 | D32: =$K$5 -> 8.5714286 | E32: wks | F32: =(40*P32)*M32 -> 5090.3426 | G32: =SUM(D32*F32) -> 43631.508 | L32: =SUM(G32+I32+K32) -> 43631.508 | M32: =+M14 -> 1 | O32: =O14 -> 127.25857 | P32: =+P14 -> 127.25857 | Q32: =+Q14 -> 163 | Y32: =+Y14 -> 130
C33: Project Administator | D33: =$K$5 -> 8.5714286 | E33: wks | F33: =(40*P33)*M33 -> 3591.2833 | G33: =SUM(D33*F33) -> 30782.429 | L33: =SUM(G33+I33+K33) -> 30782.429 | M33: =+M15 -> 1 | O33: =O15 -> 89.782084 | P33: =+P15 -> 89.782084 | Q33: =+Q15 -> 95 | Y33: =+Y15 -> 65
C34: Project Coordinator | D34: =$K$5 -> 8.5714286 | E34: wks | F34: =(40*P34)*M34 -> 4633.7422 | G34: =SUM(D34*F34) -> 39717.79 | L34: =SUM(G34+I34+K34) -> 39717.79 | M34: =+M16 -> 1 | O34: =O16 -> 115.84355 | P34: =+P16 -> 115.84355 | Q34: =+Q16 -> 81 | Y34: =+Y16 -> 60
C35: Assistant Project Manager | D35: =$K$5 -> 8.5714286 | E35: wks | F35: =(40*P35)*M35 -> 4467.6124 | G35: =SUM(D35*F35) -> 38293.821 | L35: =SUM(G35+I35+K35) -> 38293.821 | M35: =+M17 -> 1 | O35: =O17 -> 111.69031 | P35: =+P17 -> 111.69031 | Q35: =+Q17 -> 118 | Y35: =+Y17 -> 95
C36: Superintendent - Level 3 | D36: =$K$5 -> 8.5714286 | E36: wks | F36: =(40*P36)*M36 -> 7114.6074 | G36: =SUM(D36*F36) -> 60982.349 | L36: =SUM(G36+I36+K36) -> 60982.349 | M36: =+M18 -> 1 | O36: =O18 -> 177.86518 | P36: =+P18 -> 177.86518 | Q36: =+Q18 -> 183 | Y36: =+Y18 -> 194
C37: Superintendent - Level 2 | D37: =$K$5 -> 8.5714286 | E37: wks | F37: =(40*P37)*M37 -> 0 | G37: =SUM(D37*F37) -> 0 | L37: =SUM(G37+I37+K37) -> 0 | M37: =+M19 -> 0 | O37: =O19 -> 149.29951 | P37: =+P19 -> 149.29951 | Q37: =+Q19 -> 161 | Y37: =+Y19 -> 173
C38: Superintendent - Level 1 | D38: =$K$5 -> 8.5714286 | E38: wks | F38: =(40*P38)*M38 -> 4887.7994 | G38: =SUM(D38*F38) -> 41895.424 | L38: =SUM(G38+I38+K38) -> 41895.424 | M38: =+M20 -> 1 | O38: =O20 -> 122.19499 | P38: =+P20 -> 122.19499 | Q38: =+Q20 -> 121 | Y38: =+Y20 -> 155
C39: Assistant Superinterndent | D39: =$K$5 -> 8.5714286 | E39: wks | F39: =(40*P39)*M39 -> 5823.7833 | G39: =SUM(D39*F39) -> 49918.142 | L39: =SUM(G39+I39+K39) -> 49918.142 | M39: =+M21 -> 1.8 | O39: =O21 -> 80.885879 | P39: =+P21 -> 80.885879 | Q39: =+Q21 -> 84 | Y39: =+Y21 -> 95
C40: Foreman | D40: =$K$5 -> 8.5714286 | E40: wks | F40: =(40*P40)*M40 -> 2242.5364 | G40: =SUM(D40*F40) -> 19221.741 | L40: =SUM(G40+I40+K40) -> 19221.741 | M40: =+M23 -> 1 | O40: =O23 -> 56.06341 | P40: =+P23 -> 56.06341 | Q40: =+Q23 -> 65 | Y40: =+Y23 -> 65
C41: Accounting | D41: =$K$5 -> 8.5714286 | E41: wks | F41: =(40*P41)*M41 -> 1252.1287 | G41: =SUM(D41*F41) -> 10732.532 | L41: =SUM(G41+I41+K41) -> 10732.532 | M41: =+M24 -> 0.2 | O41: =O24 -> 156.51609 | P41: =+P24 -> 156.51609 | Q41: =+Q24 -> 80 | Y41: =+Y24 -> 90
...

Sheet Labor Rates
A3: RE: West Melbourne Water Treatment Plant
A5: Hedrick Brothers Construction Co., Inc.
A6: Salaries and Burden Calculations
A7: As of 8/22/24
C8: MARK-UP | F8: 0.35
E9: Burdened Rate | F9: Mark-up | G9: Total
B10: 1 | C10: Proj Exec | E10: 157.66656 | F10: =E10*$F$8 -> 55.183297 | G10: =SUM(E10:F10) -> 212.84986
B11: 2 | C11: Sr PM | E11: 130.67475 | F11: =E11*$F$8 -> 45.736162 | G11: =SUM(E11:F11) -> 176.41091
B12: 3 | C12: PM 3 | E12: 120.34132 | F12: =E12*$F$8 -> 42.119463 | G12: =SUM(E12:F12) -> 162.46079
B13: 4 | C13: PM 2 | E13: 110.14476 | F13: =E13*$F$8 -> 38.550666 | G13: =SUM(E13:F13) -> 148.69542
B14: 5 | C14: PM 1 | E14: 94.265604 | F14: =E14*$F$8 -> 32.992961 | G14: =SUM(E14:F14) -> 127.25857
B15: 6 | C15: Proj Admin | E15: 66.505247 | F15: =E15*$F$8 -> 23.276836 | G15: =SUM(E15:F15) -> 89.782084
B16: 7 | C16: Proj Acct | E16: 85.81004 | F16: =E16*$F$8 -> 30.033514 | G16: =SUM(E16:F16) -> 115.84355
B17: 8 | C17: Asst PM | E17: 82.733564 | F17: =E17*$F$8 -> 28.956747 | G17: =SUM(E17:F17) -> 111.69031
B18: 9 | C18: Supt 3 | E18: 131.75199 | F18: =E18*$F$8 -> 46.113196 | G18: =SUM(E18:F18) -> 177.86518
B19: 10 | C19: Supt 2 | E19: 110.59223 | F19: =E19*$F$8 -> 38.70728 | G19: =SUM(E19:F19) -> 149.29951
B20: 11 | C20: Supt 1 | E20: 90.514804 | F20: =E20*$F$8 -> 31.680182 | G20: =SUM(E20:F20) -> 122.19499
B21: 12 | C21: Asst Supt | E21: 59.915466 | F21: =E21*$F$8 -> 20.970413 | G21: =SUM(E21:F21) -> 80.885879
... B26: 17 | C26: Safety | E26: 79.733968 | F26: =E26*$F$8 -> 27.906889 | G26: =SUM(E26:F26) -> 107.64086
C27: Labor | E27: 32.408056 | F27: =E27*$F$8 -> 11.34282 | G27: =SUM(E27:F27) -> 43.750875
C28: Apprentice | E28: 32.978211 | F28: =E28*$F$8 -> 11.542374 | G28: =SUM(E28:F28) -> 44.520584
C29: Carpenter | E29: 45.013251 | F29: =E29*$F$8 -> 15.754638 | G29: =SUM(E29:F29) -> 60.767889
C30: Driver | E30: 35.486876 | F30: =E30*$F$8 -> 12.420407 | G30: =SUM(E30:F30) -> 47.907283
C31: Leadman | E31: 46.605242 | F31: =E31*$F$8 -> 16.311835 | G31: =SUM(E31:F31) -> 62.917077
C32: Supt MEP | E32: 0 | F32: =E32*$F$8 -> 0 | G32: =SUM(E32:F32) -> 0
C33: Gen Supt | E33: 130.4108 | F33: =E33*$F$8 -> 45.643781 | G33: =SUM(E33:F33) -> 176.05459
C34: Cons Mgr | E34: 135.45804 | F34: =E34*$F$8 -> 47.410313 | G34: =SUM(E34:F34) -> 182.86835
C35: Proj Coor | E35: 0 | F35: =E35*$F$8 -> 0 | G35: =SUM(E35:F35) -> 0
C36: Mktg | E36: 85.41309 | F36: =E36*$F$8 -> 29.894582 | G36: =SUM(E36:F36) -> 115.30767
C37: Bus Dev | E37: 121.55329 | F37: =E37*$F$8 -> 42.543651 | G37: =SUM(E37:F37) -> 164.09694
C38: Chief, 3 & 2 | E38: 140.9198 | F38: =E38*$F$8 -> 49.321931 | G38: =SUM(E38:F38) -> 190.24173
... C40: Exec Asst | E40: 69.670191 | F40: =E40*$F$8 -> 24.384567 | G40: =SUM(E40:F40) -> 94.054759

Sheet 02 21 Survey 
G1: Hedrick Plug
F2: X | G2: Excluded
F3: I | G3: Included
B4: BACK TO SUMMARY SHEET | G4: Sub Add/Deduct
A5: Project: | B5: ='Area Calculations'!B4 -> Bourbon Hotel Orlando | G5: Company
A6: Trade: | B6: Surveying | G6: Contact
A7: CSI Code: | B7: 02 21 00 | G7: Phone
A8: Date: | G8: Email
G9: Adjusted Bid | H9: =I55 -> 60117 | J9: =K59 -> 0 | L9: =M59 -> 0 | N9: =O59 -> 0 | P9: =Q59 -> 0 | R9: =S59 -> 0
A10: BID DOCUMENTS: | C10: Plan/ Spec. Package | D10: QTY | E10: U/M | F10: Unit Cost | G10: Subtotal | H10: Yes/No | I10: Price | J10: Yes/No | K10: Price | L10: Yes/No | M10: Price | N10: Yes/No | O10: Price | P10: Yes/No | Q10: Price | R10: Yes/No | S10: Price
B11: GENERAL INCLUSIONS
B12: INCLUDES ALL SALES TAX
B13: ALL HOISTING & RIGGING REQUIRED TO COMPLETE THIS SCOPE
B14: PROVIDE P&P BONDS
B15: FLORIDA STATE CONTRACTORS LIC.
B16: GENERAL LIABILITY AND WORKERS COMP. INSURANCE LIMITS
B17: STATE AND LOCAL TAXES
B18: SPECIFIC TRADE SCOPE OF WORK REQUIREMENTS
B19: BASE BID
B21: Surveying | D21: ='Area Calculations'!G7 -> 4.0078283 | E21: acre | F21: 15000 | G21: =ROUND(D21*F21,0) -> 60117 | I21: =G21 -> 60117
G22: =ROUND(D22*F22,0) -> 0
G23: =ROUND(D23*F23,0) -> 0
G24: =ROUND(D24*F24,0) -> 0
G25: =ROUND(D25*F25,0) -> 0
G26: =ROUND(D26*F26,0) -> 0
G27: =ROUND(D27*F27,0) -> 0
G28: =ROUND(D28*F28,0) -> 0
G29: =ROUND(D29*F29,0) -> 0
G30: =ROUND(D30*F30,0) -> 0
G31: =ROUND(D31*F31,0) -> 0
G32: =ROUND(D32*F32,0) -> 0
G33: =ROUND(D33*F33,0) -> 0
... G49: =ROUND(D49*F49,0) -> 0
B51: SUBTOTAL | G51: =SUM(G19:G50) -> 60117 | I51: =SUBTOTAL(9,I21:I49) -> 60117 | K51: =SUBTOTAL(9,K21:K49) -> 0 | M51: =SUM(M19:M50) -> 0 | O51: =SUM(O19:O50) -> 0 | Q51: =SUM(Q19:Q50) -> 0 | S51: =SUM(S19:S50) -> 0
B52: BOND RATE | H52: 0 | J52: 0 | L52: 0 | N52: 0 | P52: 0 | R52: 0
B53: BOND AMOUNT | G53: =F52*G51 -> 0 | I53: =H52*I51 -> 0 | K53: =J52*K51 -> 0 | M53: =L52*M51 -> 0 | O53: =N52*O51 -> 0 | Q53: =P52*Q51 -> 0 | S53: =R52*S51 -> 0
B55: ADJUSTED TOTAL | G55: =SUM(G51:G53) -> 60117 | I55: =SUM(I51:I53) -> 60117 | K55: =SUM(K51:K53) -> 0 | M55: =SUM(M51:M53) -> 0 | O55: =SUM(O51:O53) -> 0 | Q55: =SUM(Q51:Q53) -> 0 | S55: =SUM(S51:S53) -> 0
B56: Cost per SF | G56: =G55/'Area Calculations'!$G$5 -> 0.1544142 | I56: =I55/'Area Calculations'!$G$5 -> 0.1544142 | K56: =K55/'Area Calculations'!$G$5 -> 0 | M56: =M55/'Area Calculations'!$G$5 -> 0 | O56: =O55/'Area Calculations'!$G$5 -> 0 | Q56: =Q55/'Area Calculations'!$G$5 -> 0 | S56: =S55/'Area Calculations'!$G$5 -> 0
A58: QUALIFICATIONS
A62: EXCLUSIONS/OWNER PROVIDED ITEMS:
...

Sheet 02 41 Demo
G1: Hedrick Plug
F2: X | G2: Excluded
F3: I | G3: Included
B4: BACK TO SUMMARY SHEET | G4: Sub Add/Deduct
A5: Project: | B5: ='Area Calculations'!B4 -> Bourbon Hotel Orlando | G5: Company
A6: Trade: | B6: Demolition | G6: Contact
A7: CSI Code: | B7: 02 41 00 | G7: Phone
A8: Date: | G8: Email
G9: Adjusted Bid | H9: =I55 -> 0 | J9: =K59 -> 0 | L9: =M59 -> 0 | N9: =O59 -> 0 | P9: =Q59 -> 0 | R9: =S59 -> 0
A10: BID DOCUMENTS: | C10: Plan/ Spec. Package | D10: QTY | E10: U/M | F10: Unit Cost | G10: Subtotal | H10: Yes/No | I10: Price | J10: Yes/No | K10: Price | L10: Yes/No | M10: Price | N10: Yes/No | O10: Price | P10: Yes/No | Q10: Price | R10: Yes/No | S10: Price
B11: GENERAL INCLUSIONS
B12: INCLUDES ALL SALES TAX
B13: ALL HOISTING & RIGGING REQUIRED TO COMPLETE THIS SCOPE
B14: PROVIDE P&P BONDS
B15: FLORIDA STATE CONTRACTORS LIC.
B16: GENERAL LIABILITY AND WORKERS COMP. INSURANCE LIMITS
B17: STATE AND LOCAL TAXES
B18: SPECIFIC TRADE SCOPE OF WORK REQUIREMENTS
B19: BASE BID
G21: =ROUND(D21*F21,0) -> 0
G22: =ROUND(D22*F22,0) -> 0
G23: =ROUND(D23*F23,0) -> 0
G24: =ROUND(D24*F24,0) -> 0
G25: =ROUND(D25*F25,0) -> 0
G26: =ROUND(D26*F26,0) -> 0
G27: =ROUND(D27*F27,0) -> 0
G28: =ROUND(D28*F28,0) -> 0
G29: =ROUND(D29*F29,0) -> 0
G30: =ROUND(D30*F30,0) -> 0
G31: =ROUND(D31*F31,0) -> 0
G32: =ROUND(D32*F32,0) -> 0
... G49: =ROUND(D49*F49,0) -> 0
B51: SUBTOTAL | G51: =SUM(G19:G50) -> 0 | I51: =SUBTOTAL(9,I21:I49) -> 0 | K51: =SUBTOTAL(9,K21:K49) -> 0 | M51: =SUM(M19:M50) -> 0 | O51: =SUM(O19:O50) -> 0 | Q51: =SUM(Q19:Q50) -> 0 | S51: =SUM(S19:S50) -> 0
B52: BOND RATE | H52: 0 | J52: 0 | L52: 0 | N52: 0 | P52: 0 | R52: 0
B53: BOND AMOUNT | G53: =F52*G51 -> 0 | I53: =H52*I51 -> 0 | K53: =J52*K51 -> 0 | M53: =L52*M51 -> 0 | O53: =N52*O51 -> 0 | Q53: =P52*Q51 -> 0 | S53: =R52*S51 -> 0
B55: ADJUSTED TOTAL | G55: =SUM(G51:G53) -> 0 | I55: =SUM(I51:I53) -> 0 | K55: =SUM(K51:K53) -> 0 | M55: =SUM(M51:M53) -> 0 | O55: =SUM(O51:O53) -> 0 | Q55: =SUM(Q51:Q53) -> 0 | S55: =SUM(S51:S53) -> 0
B56: Cost per SF | G56: =G55/'Area Calculations'!$G$5 -> 0 | I56: =I55/'Area Calculations'!$G$5 -> 0 | K56: =K55/'Area Calculations'!$G$5 -> 0 | M56: =M55/'Area Calculations'!$G$5 -> 0 | O56: =O55/'Area Calculations'!$G$5 -> 0 | Q56: =Q55/'Area Calculations'!$G$5 -> 0 | S56: =S55/'Area Calculations'!$G$5 -> 0
A58: QUALIFICATIONS
A62: EXCLUSIONS/OWNER PROVIDED ITEMS:
A66: ALTERNATES:
...

Sheet 03 30 Conc & CMU
G1: Hedrick Plug
F2: X | G2: Excluded
F3: I | G3: Included
B4: BACK TO SUMMARY SHEET | G4: Sub Add/Deduct
A5: Project: | B5: ='Area Calculations'!B4 -> Bourbon Hotel Orlando | G5: Company
A6: Trade: | B6: Concrete & CMU | G6: Contact
A7: CSI Code: | B7: 03 30 00 | G7: Phone
A8: Date: | G8: Email
G9: Adjusted Bid | H9: =I$67 -> 33000765 | J9: =K$67 -> 16240695 | L9: =M$67 -> 128 | N9: =O$67 -> 260527.41 | P9: =Q$67 -> 0 | R9: =S$67 -> 0
A10: BID DOCUMENTS: | C10: Plan/ Spec. Package | D10: QTY | E10: U/M | F10: Unit Cost | G10: Subtotal | H10: Yes/No | I10: Price | J10: Yes/No | K10: Price | L10: Yes/No | M10: Price | N10: Yes/No | O10: Price | P10: Yes/No | Q10: Price | R10: Yes/No | S10: Price
B11: GENERAL INCLUSIONS
B12: INCLUDES ALL SALES TAX
B13: ALL HOISTING & RIGGING REQUIRED TO COMPLETE THIS SCOPE
B14: PROVIDE P&P BONDS
B15: FLORIDA STATE CONTRACTORS LIC.
B16: GENERAL LIABILITY AND WORKERS COMP. INSURANCE LIMITS
B17: STATE AND LOCAL TAXES
B18: SPECIFIC TRADE SCOPE OF WORK REQUIREMENTS
B19: BASE BID
B21: Concrete
B22: 10' x 24" continuios footings at periniter walls | D22: =1514*10*2/27 -> 1121.4815 | E22: cy | F22: 650 | G22: =ROUND(D22*F22,0) -> 728963 | I22: =G22 -> 728963
A23: 130 | B23: 10' x 10' x 24" spread footings at columns - 30' oc ew | D23: =10*10*2*130/27 -> 962.96296 | E23: cy | F23: 650 | G23: =ROUND(D23*F23,0) -> 625926 | I23: =G23 -> 625926
A24: 130 | B24: 24" x 24" columns at garage level - 30' oc ew | D24: =2*2*15*130/27 -> 288.88889 | E24: cy | F24: 2500 | G24: =ROUND(D24*F24,0) -> 722222 | I24: =G24 -> 722222
B25: Pad footings at stairs & elevators - 24" | D25: =4034*2/27 -> 298.81481 | E25: cy | F25: 660 | G25: =ROUND(D25*F25,0) -> 197218 | I25: =G25 -> 197218 | K25: =D25 -> 298.81481 | L25: cy | M25: 32 | O25: =K25*M25 -> 9562.0741
B26: Elevator pit walls | D26: 38 | E26: cy | F26: 1500 | G26: =ROUND(D26*F26,0) -> 57000 | I26: =G26 -> 57000 | K26: =D26 -> 38 | L26: cy | M26: 32 | O26: =K26*M26 -> 1216
B27: Garage level walls 12" thick - 15' | D27: =1514*15*2/27 -> 1682.2222 | E27: cy | F27: 1500 | G27: =ROUND(D27*F27,0) -> 2523333 | I27: =G27 -> 2523333 | K27: =D27 -> 1682.2222 | L27: cy | M27: 32 | O27: =K27*M27 -> 53831.111
A28: =304+230 -> 534 | B28: Garage level stairwell and elevator shaft walls - 12" | D28: =534*15/27 -> 296.66667 | E28: cy | F28: 1500 | G28: =ROUND(D28*F28,0) -> 445000 | I28: =G28 -> 445000
B29: Podium deck - 16" PT | D29: 110792 | E29: sf | F29: 45 | G29: =ROUND(D29*F29,0) -> 4985640 | I29: =G29 -> 4985640 | K29: =D29*1.33/27 -> 5457.5319 | L29: cy
B30: Slab on grade - 6" | D30: 110792 | E30: sf | F30: 12 | G30: =ROUND(D30*F30,0) -> 1329504 | I30: =G30 -> 1329504 | K30: =D30*0.5/27 -> 2051.7037 | L30: cy | M30: 32 | O30: =K30*M30 -> 65654.519
B31: Slab on metal deck - 5" | D31: =280266 -> 280266 | E31: sf | F31: 8 | G31: =ROUND(D31*F31,0) -> 2242128 | I31: =G31 -> 2242128 | K31: =D31*0.42/27 -> 4359.6933 | L31: cy
G32: =ROUND(D32*F32,0) -> 0 | I32: =G32 -> 0 | O32: =SUM(O25:O31) -> 130263.7
B33: total cy | D33: =SUM(D22:D28)+SUM(K29:K31) -> 16557.966 | E33: cy | F33: 980 | G33: =ROUND(D33*F33,0) -> 16226807 | I33: =G33 -> 16226807 | K33: =D33*F33 -> 16226807
G34: =ROUND(D34*F34,0) -> 0 | I34: =G34 -> 0
B35: Topping slab on podium deck | D35: 110792 | E35: sf | F35: 15 | G35: =ROUND(D35*F35,0) -> 1661880 | I35: =G35 -> 1661880
G36: =ROUND(D36*F36,0) -> 0 | I36: =G36 -> 0
B37: CMU - Hotel | G37: =ROUND(D37*F37,0) -> 0 | I37: =G37 -> 0
A38: 83'-6" | B38: stairwells - 8" | D38: =174*83.5 -> 14529 | E38: sf | F38: 20 | G38: =ROUND(D38*F38,0) -> 290580 | I38: =G38 -> 290580
A39: 83'-6" | B39: elevator shafts - 8" | D39: =257*83.5 -> 21459.5 | E39: sf | F39: 20 | G39: =ROUND(D39*F39,0) -> 429190 | I39: =G39 -> 429190
G40: =ROUND(D40*F40,0) -> 0 | I40: =G40 -> 0
B41: CMU - Restaurant | G41: =ROUND(D41*F41,0) -> 0 | I41: =G41 -> 0
...

Sheet 04 40 Stone Cladding
G1: Hedrick Plug
F2: X | G2: Excluded
F3: I | G3: Included
B4: BACK TO SUMMARY SHEET | G4: Sub Add/Deduct
A5: Project: | B5: ='Area Calculations'!B4 -> Bourbon Hotel Orlando | G5: Company
A6: Trade: | B6: Stone Cladding | G6: Contact
A7: CSI Code: | B7: 04 40 00 | G7: Phone
A8: Date: | G8: Email
G9: Adjusted Bid | H9: =I$55 -> 132072 | J9: =K$55 -> 0 | L9: =M$55 -> 0 | N9: =O$55 -> 0 | P9: =Q$55 -> 0 | R9: =S$55 -> 0
A10: BID DOCUMENTS: | C10: Plan/ Spec. Package | D10: QTY | E10: U/M | F10: Unit Cost | G10: Subtotal | H10: Yes/No | I10: Price | J10: Yes/No | K10: Price | L10: Yes/No | M10: Price | N10: Yes/No | O10: Price | P10: Yes/No | Q10: Price | R10: Yes/No | S10: Price
B11: GENERAL INCLUSIONS
B12: INCLUDES ALL SALES TAX
B13: ALL HOISTING & RIGGING REQUIRED TO COMPLETE THIS SCOPE
B14: PROVIDE P&P BONDS
B15: FLORIDA STATE CONTRACTORS LIC.
B16: GENERAL LIABILITY AND WORKERS COMP. INSURANCE LIMITS
B17: STATE AND LOCAL TAXES
B18: SPECIFIC TRADE SCOPE OF WORK REQUIREMENTS
B19: BASE BID
B21: Stone cladding - assume coral stone - material | D21: =2567*1.15 -> 2952.05 | E21: sf | F21: 23 | G21: =ROUND(D21*F21,0) -> 67897 | I21: =G21 -> 67897
B22: Stone cladding - assume coral stone - labor | D22: 2567 | E22: sf | F22: 25 | G22: =ROUND(D22*F22,0) -> 64175 | I22: =G22 -> 64175
G23: =ROUND(D23*F23,0) -> 0
G24: =ROUND(D24*F24,0) -> 0
G25: =ROUND(D25*F25,0) -> 0
G26: =ROUND(D26*F26,0) -> 0
G27: =ROUND(D27*F27,0) -> 0
G28: =ROUND(D28*F28,0) -> 0
G29: =ROUND(D29*F29,0) -> 0
G30: =ROUND(D30*F30,0) -> 0
G31: =ROUND(D31*F31,0) -> 0
G32: =ROUND(D32*F32,0) -> 0
G33: =ROUND(D33*F33,0) -> 0
G34: =ROUND(D34*F34,0) -> 0
... G49: =ROUND(D49*F49,0) -> 0
B51: SUBTOTAL Base Bid | G51: =SUBTOTAL(9,G21:G50) -> 132072 | I51: =SUBTOTAL(9,I21:I50) -> 132072 | K51: =SUBTOTAL(9,K21:K50) -> 0 | M51: =SUBTOTAL(9,M21:M50) -> 0 | O51: =SUBTOTAL(9,O21:O50) -> 0 | Q51: =SUBTOTAL(9,Q21:Q50) -> 0 | S51: =SUBTOTAL(9,S21:S50) -> 0
B52: BOND RATE | H52: 0 | J52: 0 | L52: 0 | N52: 0 | P52: 0 | R52: 0
B53: BOND AMOUNT | G53: =F52*G51 -> 0 | I53: =H52*I51 -> 0 | K53: =J52*K51 -> 0 | M53: =L52*M51 -> 0 | O53: =N52*O51 -> 0 | Q53: =P52*Q51 -> 0 | S53: =R52*S51 -> 0
B55: ADJUSTED TOTAL | G55: =SUM(G51:G53) -> 132072 | I55: =SUM(I51:I53) -> 132072 | K55: =SUM(K51:K53) -> 0 | M55: =SUM(M51:M53) -> 0 | O55: =SUM(O51:O53) -> 0 | Q55: =SUM(Q51:Q53) -> 0 | S55: =SUM(S51:S53) -> 0
B56: Cost per SF | G56: =G55/'Area Calculations'!$G$5 -> 0.33923503 | I56: =I55/'Area Calculations'!$G$5 -> 0.33923503 | K56: =K55/'Area Calculations'!$G$5 -> 0 | M56: =M55/'Area Calculations'!$G$5 -> 0 | O56: =O55/'Area Calculations'!$G$5 -> 0 | Q56: =Q55/'Area Calculations'!$G$5 -> 0 | S56: =S55/'Area Calculations'!$G$5 -> 0
A58: QUALIFICATIONS
...

Sheet 05 10 Structural Steel
G1: Hedrick Plug
F2: X | G2: Excluded
F3: I | G3: Included
B4: BACK TO SUMMARY SHEET | G4: Sub Add/Deduct
A5: Project: | B5: ='Area Calculations'!B4 -> Bourbon Hotel Orlando | G5: Company
A6: Trade: | B6: Structural Steel | G6: Contact
A7: CSI Code: | B7: 05 10 00 | G7: Phone
A8: Date: | G8: Email
G9: Adjusted Bid | H9: =I$55 -> 11299290 | J9: =K$55 -> 0 | L9: =M$55 -> 0 | N9: =O$55 -> 0 | P9: =Q$55 -> 0 | R9: =S$55 -> 0
A10: BID DOCUMENTS: | C10: Plan/ Spec. Package | D10: QTY | E10: U/M | F10: Unit Cost | G10: Subtotal | H10: Yes/No | I10: Price | J10: Yes/No | K10: Price | L10: Yes/No | M10: Price | N10: Yes/No | O10: Price | P10: Yes/No | Q10: Price | R10: Yes/No | S10: Price
B11: GENERAL INCLUSIONS
B12: INCLUDES ALL SALES TAX
B13: ALL HOISTING & RIGGING REQUIRED TO COMPLETE THIS SCOPE
B14: PROVIDE P&P BONDS
B15: FLORIDA STATE CONTRACTORS LIC.
B16: GENERAL LIABILITY AND WORKERS COMP. INSURANCE LIMITS
B17: STATE AND LOCAL TAXES
B18: SPECIFIC TRADE SCOPE OF WORK REQUIREMENTS
B19: BASE BID
B21: Steel frame structure ground level and up | D21: =SUM('Area Calculations'!E15:E20) -> 277214 | E21: sf | F21: 35 | G21: =ROUND(D21*F21,0) -> 9702490 | I21: =G21 -> 9702490
G22: =ROUND(D22*F22,0) -> 0 | I22: =G22 -> 0
B23: Porte Cochere | D23: 3420 | E23: sf | F23: 20 | G23: =ROUND(D23*F23,0) -> 68400 | I23: =G23 -> 68400
G24: =ROUND(D24*F24,0) -> 0 | I24: =G24 -> 0
B25: Bridge structure | D25: 1 | E25: ls | F25: 716900 | G25: =ROUND(D25*F25,0) -> 716900 | I25: =G25 -> 716900
G26: =ROUND(D26*F26,0) -> 0 | I26: =G26 -> 0
B27: Steel columns for canopies - material | D27: 1082 | E27: lf | F27: =150/2000*10000 -> 750 | G27: =ROUND(D27*F27,0) -> 811500 | I27: =G27 -> 811500
G28: =ROUND(D28*F28,0) -> 0 | I28: =G28 -> 0
G29: =ROUND(D29*F29,0) -> 0 | I29: =G29 -> 0
G30: =ROUND(D30*F30,0) -> 0 | I30: =G30 -> 0
G31: =ROUND(D31*F31,0) -> 0 | I31: =G31 -> 0
G32: =ROUND(D32*F32,0) -> 0 | I32: =G32 -> 0
G33: =ROUND(D33*F33,0) -> 0 | I33: =G33 -> 0
G34: =ROUND(D34*F34,0) -> 0 | I34: =G34 -> 0
G35: =ROUND(D35*F35,0) -> 0 | I35: =G35 -> 0
G36: =ROUND(D36*F36,0) -> 0 | I36: =G36 -> 0
G37: =ROUND(D37*F37,0) -> 0 | I37: =G37 -> 0
G38: =ROUND(D38*F38,0) -> 0 | I38: =G38 -> 0
G39: =ROUND(D39*F39,0) -> 0 | I39: =G39 -> 0
... G49: =ROUND(D49*F49,0) -> 0 | I49: =G49 -> 0
B51: SUBTOTAL Base Bid | G51: =SUBTOTAL(9,G21:G50) -> 11299290 | I51: =SUBTOTAL(9,I20:I50) -> 11299290 | K51: =SUBTOTAL(9,K20:K50) -> 0 | M51: =SUBTOTAL(9,M20:M50) -> 0 | O51: =SUBTOTAL(9,O20:O50) -> 0 | Q51: =SUBTOTAL(9,Q20:Q50) -> 0 | S51: =SUBTOTAL(9,S20:S50) -> 0
...

Sheet 05 52 Misc Metals
G1: Hedrick Plug
F2: X | G2: Excluded
F3: I | G3: Included
B4: BACK TO SUMMARY SHEET | G4: Sub Add/Deduct
A5: Project: | B5: ='Area Calculations'!B4 -> Bourbon Hotel Orlando | G5: Company
A6: Trade: | B6: Miscellaneous Metals | G6: Contact
A7: CSI Code: | B7: 05 52 00 | G7: Phone
A8: Date: | G8: Email
G9: Adjusted Bid | H9: =I$59 -> 1259600 | J9: =K$59 -> 0 | L9: =M$59 -> 0 | N9: =O$59 -> 0 | P9: =Q$59 -> 0 | R9: =S$59 -> 0
A10: BID DOCUMENTS: | C10: Plan/ Spec. Package | D10: QTY | E10: U/M | F10: Unit Cost | G10: Subtotal | H10: Yes/No | I10: Price | J10: Yes/No | K10: Price | L10: Yes/No | M10: Price | N10: Yes/No | O10: Price | P10: Yes/No | Q10: Price | R10: Yes/No | S10: Price
B11: GENERAL INCLUSIONS
B12: INCLUDES ALL SALES TAX
B13: ALL HOISTING & RIGGING REQUIRED TO COMPLETE THIS SCOPE
B14: PROVIDE P&P BONDS
B15: FLORIDA STATE CONTRACTORS LIC.
B16: GENERAL LIABILITY AND WORKERS COMP. INSURANCE LIMITS
B17: STATE AND LOCAL TAXES
B18: SPECIFIC TRADE SCOPE OF WORK REQUIREMENTS
B19: BASE BID
B21: Steel stairs | G21: =ROUND(D21*F21,0) -> 0 | I21: =G21 -> 0
B22: hotel all to garage | D22: =8*2*2 -> 32 | E22: riser | F22: 12000 | G22: =ROUND(D22*F22,0) -> 384000 | I22: =G22 -> 384000
B23: hotel all to lobby | D23: =4*2*1 -> 8 | E23: riser | F23: 12000 | G23: =ROUND(D23*F23,0) -> 96000 | I23: =G23 -> 96000
B24: hotel 1st to 2nd | D24: =7*2*1 -> 14 | E24: riser | F24: 12000 | G24: =ROUND(D24*F24,0) -> 168000 | I24: =G24 -> 168000
B25: restaurant | D25: =4*2*1 -> 8 | E25: riser | F25: 12000 | G25: =ROUND(D25*F25,0) -> 96000 | I25: =G25 -> 96000
B26: Stairs wall rails | D26: =SUM(D22:D25)*18 -> 1116 | E26: lf | F26: 150 | G26: =ROUND(D26*F26,0) -> 167400 | I26: =G26 -> 167400
B27: Stairs hand rails | D27: =SUM(D22:D25)*18 -> 1116 | E27: lf | F27: 200 | G27: =ROUND(D27*F27,0) -> 223200 | I27: =G27 -> 223200
G28: =ROUND(D28*F28,0) -> 0 | I28: =G28 -> 0
B29: Elevator hoist beams | D29: 8 | E29: ea | F29: 2500 | G29: =ROUND(D29*F29,0) -> 20000 | I29: =G29 -> 20000
B30: Elevator sill angles | D30: 70 | E30: ea | F30: 1500 | G30: =ROUND(D30*F30,0) -> 105000 | I30: =G30 -> 105000
G31: =ROUND(D31*F31,0) -> 0 | I31: =G31 -> 0
G32: =ROUND(D32*F32,0) -> 0 | I32: =G32 -> 0
G33: =ROUND(D33*F33,0) -> 0 | I33: =G33 -> 0
G34: =ROUND(D34*F34,0) -> 0 | I34: =G34 -> 0
G35: =ROUND(D35*F35,0) -> 0 | I35: =G35 -> 0
G36: =ROUND(D36*F36,0) -> 0 | I36: =G36 -> 0
G37: =ROUND(D37*F37,0) -> 0 | I37: =G37 -> 0
G38: =ROUND(D38*F38,0) -> 0 | I38: =G38 -> 0
G39: =ROUND(D39*F39,0) -> 0 | I39: =G39 -> 0
G40: =ROUND(D40*F40,0) -> 0 | I40: =G40 -> 0
G41: =ROUND(D41*F41,0) -> 0 | I41: =G41 -> 0
...

Sheet 05 70 Railings Glass
G1: Hedrick Plug
F2: X | G2: Excluded
F3: I | G3: Included
B4: BACK TO SUMMARY SHEET | G4: Sub Add/Deduct
A5: Project: | B5: ='Area Calculations'!B4 -> Bourbon Hotel Orlando | G5: Company
A6: Trade: | B6: Railings - Glass | G6: Contact
A7: CSI Code: | B7: 05 70 00 | G7: Phone
A8: Date: | G8: Email
G9: Adjusted Bid | H9: =I$55 -> 698400 | J9: =K$55 -> 0 | L9: =M$55 -> 0 | N9: =O$55 -> 0 | P9: =Q$55 -> 0 | R9: =S$55 -> 0
A10: BID DOCUMENTS: | C10: Plan/ Spec. Package | D10: QTY | E10: U/M | F10: Unit Cost | G10: Subtotal | H10: Yes/No | I10: Price | J10: Yes/No | K10: Price | L10: Yes/No | M10: Price | N10: Yes/No | O10: Price | P10: Yes/No | Q10: Price | R10: Yes/No | S10: Price
B11: GENERAL INCLUSIONS
B12: INCLUDES ALL SALES TAX
B13: ALL HOISTING & RIGGING REQUIRED TO COMPLETE THIS SCOPE
B14: PROVIDE P&P BONDS
B15: FLORIDA STATE CONTRACTORS LIC.
B16: GENERAL LIABILITY AND WORKERS COMP. INSURANCE LIMITS
B17: STATE AND LOCAL TAXES
B18: SPECIFIC TRADE SCOPE OF WORK REQUIREMENTS
B19: BASE BID
B21: Hotel - glass railing - 42" | D21: 875 | E21: lf | F21: 450 | G21: =ROUND(D21*F21,0) -> 393750 | I21: =G21 -> 393750
B22: Pool - glass railing - | D22: 677 | E22: lf | F22: 450 | G22: =ROUND(D22*F22,0) -> 304650 | I22: =G22 -> 304650
G23: =ROUND(D23*F23,0) -> 0 | I23: =G23 -> 0
G24: =ROUND(D24*F24,0) -> 0 | I24: =G24 -> 0
G25: =ROUND(D25*F25,0) -> 0 | I25: =G25 -> 0
G26: =ROUND(D26*F26,0) -> 0 | I26: =G26 -> 0
G27: =ROUND(D27*F27,0) -> 0 | I27: =G27 -> 0
G28: =ROUND(D28*F28,0) -> 0 | I28: =G28 -> 0
G29: =ROUND(D29*F29,0) -> 0 | I29: =G29 -> 0
G30: =ROUND(D30*F30,0) -> 0 | I30: =G30 -> 0
G31: =ROUND(D31*F31,0) -> 0 | I31: =G31 -> 0
G32: =ROUND(D32*F32,0) -> 0 | I32: =G32 -> 0
G33: =ROUND(D33*F33,0) -> 0 | I33: =G33 -> 0
G34: =ROUND(D34*F34,0) -> 0 | I34: =G34 -> 0
... G49: =ROUND(D49*F49,0) -> 0 | I49: =G49 -> 0
B51: SUBTOTAL Base Bid | G51: =SUBTOTAL(9,G21:G50) -> 698400 | I51: =SUBTOTAL(9,I21:I50) -> 698400 | K51: =SUM(K19:K50) -> 0 | M51: =SUM(M19:M50) -> 0 | O51: =SUM(O19:O50) -> 0 | Q51: =SUM(Q19:Q50) -> 0 | S51: =SUM(S19:S50) -> 0
B52: BOND RATE | H52: 0 | J52: 0 | L52: 0 | N52: 0 | P52: 0 | R52: 0
B53: BOND AMOUNT | G53: =F52*G51 -> 0 | I53: =H52*I51 -> 0 | K53: =J52*K51 -> 0 | M53: =L52*M51 -> 0 | O53: =N52*O51 -> 0 | Q53: =P52*Q51 -> 0 | S53: =R52*S51 -> 0
B55: ADJUSTED TOTAL | G55: =SUM(G51:G53) -> 698400 | I55: =SUM(I51:I53) -> 698400 | K55: =SUM(K51:K53) -> 0 | M55: =SUM(M51:M53) -> 0 | O55: =SUM(O51:O53) -> 0 | Q55: =SUM(Q51:Q53) -> 0 | S55: =SUM(S51:S53) -> 0
B56: Cost per SF | G56: =G55/'Area Calculations'!$G$5 -> 1.7938832 | I56: =I55/'Area Calculations'!$G$5 -> 1.7938832 | K56: =K55/'Area Calculations'!$G$5 -> 0 | M56: =M55/'Area Calculations'!$G$5 -> 0 | O56: =O55/'Area Calculations'!$G$5 -> 0 | Q56: =Q55/'Area Calculations'!$G$5 -> 0 | S56: =S55/'Area Calculations'!$G$5 -> 0
A58: QUALIFICATIONS
...

Sheet 06 10 Rough Carpentry
G1: Hedrick Plug
F2: X | G2: Excluded
F3: I | G3: Included
B4: BACK TO SUMMARY SHEET | G4: Sub Add/Deduct
A5: Project: | B5: ='Area Calculations'!B4 -> Bourbon Hotel Orlando | G5: Company
A6: Trade: | B6: Rough Carpentry | G6: Contact
A7: CSI Code: | B7: 06 10 00 | G7: Phone
A8: Date: | G8: Email
G9: Adjusted Bid | H9: =I$55 -> 236980 | J9: =K$55 -> 0 | L9: =M$55 -> 0 | N9: =O$55 -> 0 | P9: =Q$55 -> 0 | R9: =S$55 -> 0
A10: BID DOCUMENTS: | C10: Plan/ Spec. Package | D10: QTY | E10: U/M | F10: Unit Cost | G10: Subtotal | H10: Yes/No | I10: Price | J10: Yes/No | K10: Price | L10: Yes/No | M10: Price | N10: Yes/No | O10: Price | P10: Yes/No | Q10: Price | R10: Yes/No | S10: Price
B11: GENERAL INCLUSIONS
B12: INCLUDES ALL SALES TAX
B13: ALL HOISTING & RIGGING REQUIRED TO COMPLETE THIS SCOPE
B14: PROVIDE P&P BONDS
B15: FLORIDA STATE CONTRACTORS LIC.
B16: GENERAL LIABILITY AND WORKERS COMP. INSURANCE LIMITS
B17: STATE AND LOCAL TAXES
B18: SPECIFIC TRADE SCOPE OF WORK REQUIREMENTS
B19: BASE BID
B21: hotel & restaurant | D21: =SUM('Area Calculations'!E15:E21) -> 279298 | E21: sf | F21: 0.75 | G21: =ROUND(D21*F21,0) -> 209474 | I21: =G21 -> 209474
B22: garage | D22: ='Area Calculations'!E14 -> 110025 | E22: sf | F22: 0.25 | G22: =ROUND(D22*F22,0) -> 27506 | I22: =G22 -> 27506
G23: =ROUND(D23*F23,0) -> 0 | I23: =G23 -> 0
G24: =ROUND(D24*F24,0) -> 0 | I24: =G24 -> 0
G25: =ROUND(D25*F25,0) -> 0 | I25: =G25 -> 0
G26: =ROUND(D26*F26,0) -> 0 | I26: =G26 -> 0
G27: =ROUND(D27*F27,0) -> 0 | I27: =G27 -> 0
G28: =ROUND(D28*F28,0) -> 0 | I28: =G28 -> 0
G29: =ROUND(D29*F29,0) -> 0 | I29: =G29 -> 0
G30: =ROUND(D30*F30,0) -> 0 | I30: =G30 -> 0
G31: =ROUND(D31*F31,0) -> 0 | I31: =G31 -> 0
G32: =ROUND(D32*F32,0) -> 0 | I32: =G32 -> 0
G33: =ROUND(D33*F33,0) -> 0 | I33: =G33 -> 0
G34: =ROUND(D34*F34,0) -> 0 | I34: =G34 -> 0
... G49: =ROUND(D49*F49,0) -> 0 | I49: =G49 -> 0
B51: SUBTOTAL Base Bid | G51: =SUBTOTAL(9,G21:G50) -> 236980 | I51: =SUBTOTAL(9,I21:I50) -> 236980 | K51: =SUBTOTAL(9,K21:K50) -> 0 | M51: =SUBTOTAL(9,M21:M50) -> 0 | O51: =SUBTOTAL(9,O21:O50) -> 0 | Q51: =SUBTOTAL(9,Q21:Q50) -> 0 | S51: =SUBTOTAL(9,S21:S50) -> 0
B52: BOND RATE | H52: 0 | J52: 0 | L52: 0 | N52: 0 | P52: 0 | R52: 0
B53: BOND AMOUNT | G53: =F52*G51 -> 0 | I53: =H52*I51 -> 0 | K53: =J52*K51 -> 0 | M53: =L52*M51 -> 0 | O53: =N52*O51 -> 0 | Q53: =P52*Q51 -> 0 | S53: =R52*S51 -> 0
B55: ADJUSTED TOTAL | G55: =SUM(G51:G53) -> 236980 | I55: =SUM(I51:I53) -> 236980 | K55: =SUM(K51:K53) -> 0 | M55: =SUM(M51:M53) -> 0 | O55: =SUM(O51:O53) -> 0 | Q55: =SUM(Q51:Q53) -> 0 | S55: =SUM(S51:S53) -> 0
B56: Cost per SF | G56: =G55/'Area Calculations'!$G$5 -> 0.60869766 | I56: =I55/'Area Calculations'!$G$5 -> 0.60869766 | K56: =K55/'Area Calculations'!$G$5 -> 0 | M56: =M55/'Area Calculations'!$G$5 -> 0 | O56: =O55/'Area Calculations'!$G$5 -> 0 | Q56: =Q55/'Area Calculations'!$G$5 -> 0 | S56: =S55/'Area Calculations'!$G$5 -> 0
A58: QUALIFICATIONS
...

Sheet 06 50 Millwork
G1: Hedrick Plug
F2: X | G2: Excluded
F3: I | G3: Included
B4: BACK TO SUMMARY SHEET | G4: Sub Add/Deduct
A5: Project: | B5: ='Area Calculations'!B4 -> Bourbon Hotel Orlando | G5: Company | H5: Borgzinner
A6: Trade: | B6: Millwork | G6: Contact | H6: Ken Stevens
A7: CSI Code: | B7: 06 50 00 | G7: Phone
A8: Date: | G8: Email
G9: Adjusted Bid | H9: =I$55 -> 0 | J9: =K$55 -> 0 | L9: =M$55 -> 0 | N9: =O$55 -> 0 | P9: =Q$55 -> 0 | R9: =S$55 -> 0
A10: BID DOCUMENTS: | C10: Plan/ Spec. Package | D10: QTY | E10: U/M | F10: Unit Cost | G10: Subtotal | H10: Yes/No | I10: Price | J10: Yes/No | K10: Price | L10: Yes/No | M10: Price | N10: Yes/No | O10: Price | P10: Yes/No | Q10: Price | R10: Yes/No | S10: Price
B11: GENERAL INCLUSIONS
B12: INCLUDES ALL SALES TAX
B13: ALL HOISTING & RIGGING REQUIRED TO COMPLETE THIS SCOPE
B14: PROVIDE P&P BONDS
B15: FLORIDA STATE CONTRACTORS LIC.
B16: GENERAL LIABILITY AND WORKERS COMP. INSURANCE LIMITS
B17: STATE AND LOCAL TAXES
B18: SPECIFIC TRADE SCOPE OF WORK REQUIREMENTS
B19: BASE BID
G21: =ROUND(D21*F21,0) -> 0 | I21: =G21 -> 0
G22: =ROUND(D22*F22,0) -> 0 | I22: =G22 -> 0
G23: =ROUND(D23*F23,0) -> 0 | I23: =G23 -> 0
G24: =ROUND(D24*F24,0) -> 0 | I24: =G24 -> 0
G25: =ROUND(D25*F25,0) -> 0 | I25: =G25 -> 0
G26: =ROUND(D26*F26,0) -> 0 | I26: =G26 -> 0
G27: =ROUND(D27*F27,0) -> 0 | I27: =G27 -> 0
G28: =ROUND(D28*F28,0) -> 0 | I28: =G28 -> 0
G29: =ROUND(D29*F29,0) -> 0 | I29: =G29 -> 0
G30: =ROUND(D30*F30,0) -> 0 | I30: =G30 -> 0
G31: =ROUND(D31*F31,0) -> 0 | I31: =G31 -> 0
G32: =ROUND(D32*F32,0) -> 0 | I32: =G32 -> 0
... G49: =ROUND(D49*F49,0) -> 0 | I49: =G49 -> 0
B51: SUBTOTAL Base Bid | G51: =SUBTOTAL(9,G21:G50) -> 0 | I51: =SUBTOTAL(9,I21:I50) -> 0 | K51: =SUM(K19:K50) -> 0 | M51: =SUM(M19:M50) -> 0 | O51: =SUM(O19:O50) -> 0 | Q51: =SUM(Q19:Q50) -> 0 | S51: =SUM(S19:S50) -> 0
B52: BOND RATE | H52: 0 | J52: 0 | L52: 0 | N52: 0 | P52: 0 | R52: 0
B53: BOND AMOUNT | G53: =F52*G51 -> 0 | I53: =H52*I51 -> 0 | K53: =J52*K51 -> 0 | M53: =L52*M51 -> 0 | O53: =N52*O51 -> 0 | Q53: =P52*Q51 -> 0 | S53: =R52*S51 -> 0
B55: ADJUSTED TOTAL | G55: =SUM(G51:G53) -> 0 | I55: =SUM(I51:I53) -> 0 | K55: =SUM(K51:K53) -> 0 | M55: =SUM(M51:M53) -> 0 | O55: =SUM(O51:O53) -> 0 | Q55: =SUM(Q51:Q53) -> 0 | S55: =SUM(S51:S53) -> 0
B56: Cost per SF | G56: =G55/'Area Calculations'!$G$5 -> 0 | I56: =I55/'Area Calculations'!$G$5 -> 0 | K56: =K55/'Area Calculations'!$G$5 -> 0 | M56: =M55/'Area Calculations'!$G$5 -> 0 | O56: =O55/'Area Calculations'!$G$5 -> 0 | Q56: =Q55/'Area Calculations'!$G$5 -> 0 | S56: =S55/'Area Calculations'!$G$5 -> 0
A58: QUALIFICATIONS
A62: EXCLUSIONS/OWNER PROVIDED ITEMS:
A66: ALTERNATES:
...

Sheet 07 17 Waterproofing & Caulk
G1: Hedrick Plug
F2: X | G2: Excluded
F3: I | G3: Included
B4: BACK TO SUMMARY SHEET | G4: Sub Add/Deduct
A5: Project: | B5: ='Area Calculations'!B4 -> Bourbon Hotel Orlando | G5: Company
A6: Trade: | B6: Waterproofing & Caulking | G6: Contact
A7: CSI Code: | B7: 07 17 00 | G7: Phone
A8: Date: | G8: Email
G9: Adjusted Bid | H9: =I$60 -> 6411905 | J9: =K$60 -> 0 | L9: =M$60 -> 0 | N9: =O$60 -> 0 | P9: =Q$60 -> 0 | R9: =S$60 -> 0
A10: BID DOCUMENTS: | C10: Plan/ Spec. Package | D10: QTY | E10: U/M | F10: Unit Cost | G10: Subtotal | H10: Yes/No | I10: Price | J10: Yes/No | K10: Price | L10: Yes/No | M10: Price | N10: Yes/No | O10: Price | P10: Yes/No | Q10: Price | R10: Yes/No | S10: Price
B11: GENERAL INCLUSIONS
B12: INCLUDES ALL SALES TAX
B13: ALL HOISTING & RIGGING REQUIRED TO COMPLETE THIS SCOPE
B14: PROVIDE P&P BONDS
B15: FLORIDA STATE CONTRACTORS LIC.
B16: GENERAL LIABILITY AND WORKERS COMP. INSURANCE LIMITS
B17: STATE AND LOCAL TAXES
B18: SPECIFIC TRADE SCOPE OF WORK REQUIREMENTS
B19: BASE BID
B21: Waterproofing | G21: =ROUND(D21*F21,0) -> 0 | I21: =G21 -> 0
B22: wrap footings | D22: =1514.36*24 -> 36344.64 | E22: sf | F22: 10.5 | G22: =ROUND(D22*F22,0) -> 381619 | I22: =G22 -> 381619
B23: SOG bottom | D23: 110792 | E23: sf | F23: 9 | G23: =ROUND(D23*F23,0) -> 997128 | I23: =G23 -> 997128
B24: below grade walls to 5' | D24: =1514.36*5 -> 7571.8 | E24: sf | F24: 10 | G24: =ROUND(D24*F24,0) -> 75718 | I24: =G24 -> 75718
B25: elevator pits | D25: 5 | E25: ea | F25: 15000 | G25: =ROUND(D25*F25,0) -> 75000 | I25: =G25 -> 75000
G26: =ROUND(D26*F26,0) -> 0 | I26: =G26 -> 0
B27: exterior walls - stucco | E27: sf | G27: =ROUND(D27*F27,0) -> 0 | I27: =G27 -> 0
B28: exterior walls - metal panel | D28: ='07 42 Metal Panel'!D21 -> 19200 | E28: sf | F28: 7.25 | G28: =ROUND(D28*F28,0) -> 139200 | I28: =G28 -> 139200
B29: exterior walls - stone veneer | D29: ='04 40 Stone Cladding'!D22 -> 2567 | E29: sf | F29: 7.25 | G29: =ROUND(D29*F29,0) -> 18611 | I29: =G29 -> 18611
G30: =ROUND(D30*F30,0) -> 0 | I30: =G30 -> 0
B31: podium deck - reinforced cold fluid applied - flat | D31: 110025 | E31: sf | F31: 35 | G31: =ROUND(D31*F31,0) -> 3850875 | I31: =G31 -> 3850875
B32: restaurant - roof deck / garden | D32: 7081 | E32: sf | F32: 35 | G32: =ROUND(D32*F32,0) -> 247835 | I32: =G32 -> 247835
B33: exterior terraces | D33: 8569 | E33: sf | F33: 28 | G33: =ROUND(D33*F33,0) -> 239932 | I33: =G33 -> 239932
B34: pool deck | D34: =12272-2404 -> 9868 | E34: sf | F34: 28 | G34: =ROUND(D34*F34,0) -> 276304 | I34: =G34 -> 276304
G35: =ROUND(D35*F35,0) -> 0 | I35: =G35 -> 0
B36: Caulking | G36: =ROUND(D36*F36,0) -> 0 | I36: =G36 -> 0
B37: exterior openings secondary caulk | D37: ='08 50 Storefront'!D21*0.3 -> 10257 | E37: lf | F37: 5 | G37: =ROUND(D37*F37,0) -> 51285 | I37: =G37 -> 51285
B38: misc penetrations, fire caulk, control joints | D38: ='Area Calculations'!G5 -> 389323 | E38: sf | F38: 0.15 | G38: =ROUND(D38*F38,0) -> 58398 | I38: =G38 -> 58398
G39: =ROUND(D39*F39,0) -> 0 | I39: =G39 -> 0
G40: =ROUND(D40*F40,0) -> 0 | I40: =G40 -> 0
G41: =ROUND(D41*F41,0) -> 0 | I41: =G41 -> 0
...

Sheet 07 21 Spray Foam Ins
G1: Hedrick Plug
F2: X | G2: Excluded
F3: I | G3: Included
B4: BACK TO SUMMARY SHEET | G4: Sub Add/Deduct
A5: Project: | B5: Rybovich Safe Harbor | G5: Company
A6: Trade: | B6: Spary Foam Insulation | G6: Contact
A7: CSI Code: | B7: 07 21 00 | G7: Phone
A8: Date: | G8: Email
G9: Adjusted Bid | H9: =I$56 -> 177267 | J9: =K$56 -> 0 | L9: =M$56 -> 0 | N9: =O$56 -> 0 | P9: =Q$56 -> 0 | R9: =S$56 -> 0
A10: BID DOCUMENTS: | C10: Plan/ Spec. Package | D10: QTY | E10: U/M | F10: Unit Cost | G10: Subtotal | H10: Yes/No | I10: Price | J10: Yes/No | K10: Price | L10: Yes/No | M10: Price | N10: Yes/No | O10: Price | P10: Yes/No | Q10: Price | R10: Yes/No | S10: Price
B11: GENERAL INCLUSIONS
B12: INCLUDES ALL SALES TAX
B13: ALL HOISTING & RIGGING REQUIRED TO COMPLETE THIS SCOPE
B14: PROVIDE P&P BONDS
B15: FLORIDA STATE CONTRACTORS LIC.
B16: GENERAL LIABILITY AND WORKERS COMP. INSURANCE LIMITS
B17: STATE AND LOCAL TAXES
B18: SPECIFIC TRADE SCOPE OF WORK REQUIREMENTS
B19: BASE BID
B21: Spray foam insulation for sound attenuation - R13 at bottom of poudum deck | G21: =ROUND(D21*F21,0) -> 0
B22: open cell spray foam | D22: 110792 | E22: SF | F22: 1.6 | G22: =ROUND(D22*F22,0) -> 177267 | I22: =G22 -> 177267
G23: =ROUND(D23*F23,0) -> 0
G24: =ROUND(D24*F24,0) -> 0
G25: =ROUND(D25*F25,0) -> 0
G26: =ROUND(D26*F26,0) -> 0
G27: =ROUND(D27*F27,0) -> 0
G28: =ROUND(D28*F28,0) -> 0
G29: =ROUND(D29*F29,0) -> 0
G30: =ROUND(D30*F30,0) -> 0
G31: =ROUND(D31*F31,0) -> 0
G32: =ROUND(D32*F32,0) -> 0
G33: =ROUND(D33*F33,0) -> 0
G34: =ROUND(D34*F34,0) -> 0
... G50: =ROUND(D50*F50,0) -> 0
B52: SUBTOTAL Base Bid | G52: =SUBTOTAL(9,G21:G51) -> 177267 | I52: =SUBTOTAL(9,I20:I51) -> 177267 | K52: =SUBTOTAL(9,K20:K51) -> 0 | M52: =SUBTOTAL(9,M20:M51) -> 0 | O52: =SUBTOTAL(9,O20:O51) -> 0 | Q52: =SUBTOTAL(9,Q20:Q51) -> 0 | S52: =SUBTOTAL(9,S20:S51) -> 0
B53: BOND RATE | H53: 0 | J53: 0 | L53: 0 | N53: 0 | P53: 0 | R53: 0
B54: BOND AMOUNT | G54: =F53*G52 -> 0 | I54: =H53*I52 -> 0 | K54: =J53*K52 -> 0 | M54: =L53*M52 -> 0 | O54: =N53*O52 -> 0 | Q54: =P53*Q52 -> 0 | S54: =R53*S52 -> 0
B56: ADJUSTED TOTAL | G56: =SUM(G52:G54) -> 177267 | I56: =SUM(I52:I54) -> 177267 | K56: =SUM(K52:K54) -> 0 | M56: =SUM(M52:M54) -> 0 | O56: =SUM(O52:O54) -> 0 | Q56: =SUM(Q52:Q54) -> 0 | S56: =SUM(S52:S54) -> 0
B57: Cost per SF | G57: 4.0238571 | I57: 4.0238571 | K57: 0 | M57: 0 | O57: 0 | Q57: 0 | S57: 0
A59: QUALIFICATIONS
...

Sheet 07 42 Metal Panel
G1: Hedrick Plug
F2: X | G2: Excluded
F3: I | G3: Included
B4: BACK TO SUMMARY SHEET | G4: Sub Add/Deduct
A5: Project: | B5: ='Area Calculations'!B4 -> Bourbon Hotel Orlando | G5: Company
A6: Trade: | B6: Metal Panel | G6: Contact
A7: CSI Code: | B7: 07 42 00 | G7: Phone
A8: Date: | G8: Email
G9: Adjusted Bid | H9: =I$55 -> 3361361 | J9: =K$55 -> 0 | L9: =M$55 -> 0 | N9: =O$55 -> 0 | P9: =Q$55 -> 0 | R9: =S$55 -> 0
A10: BID DOCUMENTS: | C10: Plan/ Spec. Package | D10: QTY | E10: U/M | F10: Unit Cost | G10: Subtotal | H10: Yes/No | I10: Price | J10: Yes/No | K10: Price | L10: Yes/No | M10: Price | N10: Yes/No | O10: Price | P10: Yes/No | Q10: Price | R10: Yes/No | S10: Price
B11: GENERAL INCLUSIONS
B12: INCLUDES ALL SALES TAX
B13: ALL HOISTING & RIGGING REQUIRED TO COMPLETE THIS SCOPE
B14: PROVIDE P&P BONDS
B15: FLORIDA STATE CONTRACTORS LIC.
B16: GENERAL LIABILITY AND WORKERS COMP. INSURANCE LIMITS
B17: STATE AND LOCAL TAXES
B18: SPECIFIC TRADE SCOPE OF WORK REQUIREMENTS
B19: BASE BID
B21: Wood look metal panel | D21: 19200 | E21: sf | F21: 60 | G21: =ROUND(D21*F21,0) -> 1152000 | I21: =G21 -> 1152000
G22: =ROUND(D22*F22,0) -> 0 | I22: =G22 -> 0
B23: Wood look metal panel - rainscreen roof at Porte Cochere | D23: 3420 | E23: sf | F23: 70 | G23: =ROUND(D23*F23,0) -> 239400 | I23: =G23 -> 239400
G24: =ROUND(D24*F24,0) -> 0 | I24: =G24 -> 0
B25: High roof soffits - wood look metal panel | D25: =28919+16075-31692+2403 -> 15705 | E25: sf | F25: 65 | G25: =ROUND(D25*F25,0) -> 1020825 | I25: =G25 -> 1020825
B26: High roof facia panel - wood look metal panel | D26: =1106+550 -> 1656 | E26: sf | F26: 60 | G26: =ROUND(D26*F26,0) -> 99360 | I26: =G26 -> 99360
G27: =ROUND(D27*F27,0) -> 0 | I27: =G27 -> 0
A28: 1082 | B28: Column cladding - assume 24" diameter | D28: =A28*6.283 -> 6798.206 | E28: sf | F28: 125 | G28: =ROUND(D28*F28,0) -> 849776 | I28: =G28 -> 849776
G29: =ROUND(D29*F29,0) -> 0 | I29: =G29 -> 0
G30: =ROUND(D30*F30,0) -> 0 | I30: =G30 -> 0
G31: =ROUND(D31*F31,0) -> 0 | I31: =G31 -> 0
G32: =ROUND(D32*F32,0) -> 0 | I32: =G32 -> 0
G33: =ROUND(D33*F33,0) -> 0 | I33: =G33 -> 0
G34: =ROUND(D34*F34,0) -> 0 | I34: =G34 -> 0
G35: =ROUND(D35*F35,0) -> 0 | I35: =G35 -> 0
G36: =ROUND(D36*F36,0) -> 0 | I36: =G36 -> 0
G37: =ROUND(D37*F37,0) -> 0 | I37: =G37 -> 0
G38: =ROUND(D38*F38,0) -> 0 | I38: =G38 -> 0
G39: =ROUND(D39*F39,0) -> 0 | I39: =G39 -> 0
G40: =ROUND(D40*F40,0) -> 0 | I40: =G40 -> 0
... G49: =ROUND(D49*F49,0) -> 0 | I49: =G49 -> 0
...

Sheet 07 50 Roofing
G1: Hedrick Plug
F2: X | G2: Excluded
F3: I | G3: Included
B4: BACK TO SUMMARY SHEET | G4: Sub Add/Deduct
A5: Project: | B5: ='Area Calculations'!B4 -> Bourbon Hotel Orlando | G5: Company
A6: Trade: | B6: Roofing | G6: Contact
A7: CSI Code: | B7: 07 50 00 | G7: Phone
A8: Date: | G8: Email
G9: Adjusted Bid | H9: =I$55 -> 1628655 | J9: =K$55 -> 0 | L9: =M$55 -> 0 | N9: =O$55 -> 0 | P9: =Q$55 -> 0 | R9: =S$55 -> 0
A10: BID DOCUMENTS: | C10: Plan/ Spec. Package | D10: QTY | E10: U/M | F10: Unit Cost | G10: Subtotal | H10: Yes/No | I10: Price | J10: Yes/No | K10: Price | L10: Yes/No | M10: Price | N10: Yes/No | O10: Price | P10: Yes/No | Q10: Price | R10: Yes/No | S10: Price
B11: GENERAL INCLUSIONS
B12: INCLUDES ALL SALES TAX
B13: ALL HOISTING & RIGGING REQUIRED TO COMPLETE THIS SCOPE
B14: PROVIDE P&P BONDS
B15: FLORIDA STATE CONTRACTORS LIC.
B16: GENERAL LIABILITY AND WORKERS COMP. INSURANCE LIMITS
B17: STATE AND LOCAL TAXES
B18: SPECIFIC TRADE SCOPE OF WORK REQUIREMENTS
B19: BASE BID
B21: High roofs - assume a TPO | D21: 46533 | E21: sf | F21: 35 | G21: =ROUND(D21*F21,0) -> 1628655 | I21: =G21 -> 1628655
G22: =ROUND(D22*F22,0) -> 0 | I22: =G22 -> 0
G23: =ROUND(D23*F23,0) -> 0 | I23: =G23 -> 0
G24: =ROUND(D24*F24,0) -> 0 | I24: =G24 -> 0
G25: =ROUND(D25*F25,0) -> 0 | I25: =G25 -> 0
G26: =ROUND(D26*F26,0) -> 0 | I26: =G26 -> 0
G27: =ROUND(D27*F27,0) -> 0 | I27: =G27 -> 0
G28: =ROUND(D28*F28,0) -> 0 | I28: =G28 -> 0
G29: =ROUND(D29*F29,0) -> 0 | I29: =G29 -> 0
G30: =ROUND(D30*F30,0) -> 0 | I30: =G30 -> 0
G31: =ROUND(D31*F31,0) -> 0 | I31: =G31 -> 0
G32: =ROUND(D32*F32,0) -> 0 | I32: =G32 -> 0
G33: =ROUND(D33*F33,0) -> 0 | I33: =G33 -> 0
... G49: =ROUND(D49*F49,0) -> 0 | I49: =G49 -> 0
B51: SUBTOTAL Base Bid | G51: =SUBTOTAL(9,G21:G50) -> 1628655 | I51: =SUBTOTAL(9,I21:I50) -> 1628655 | K51: =SUBTOTAL(9,K21:K50) -> 0 | M51: =SUBTOTAL(9,M21:M50) -> 0 | O51: =SUBTOTAL(9,O21:O50) -> 0 | Q51: =SUM(Q19:Q50) -> 0 | S51: =SUM(S19:S50) -> 0
B52: BOND RATE | H52: 0 | J52: 0 | L52: 0 | N52: 0 | P52: 0 | R52: 0
B53: BOND AMOUNT | G53: =F52*G51 -> 0 | I53: =H52*I51 -> 0 | K53: =J52*K51 -> 0 | M53: =L52*M51 -> 0 | O53: =N52*O51 -> 0 | Q53: =P52*Q51 -> 0 | S53: =R52*S51 -> 0
B55: ADJUSTED TOTAL | G55: =SUM(G51:G53) -> 1628655 | I55: =SUM(I51:I53) -> 1628655 | K55: =SUM(K51:K53) -> 0 | M55: =SUM(M51:M53) -> 0 | O55: =SUM(O51:O53) -> 0 | Q55: =SUM(Q51:Q53) -> 0 | S55: =SUM(S51:S53) -> 0
B56: Cost per SF | G56: =G55/'Area Calculations'!$G$5 -> 4.1833002 | I56: =I55/'Area Calculations'!$G$5 -> 4.1833002 | K56: =K55/'Area Calculations'!$G$5 -> 0 | M56: =M55/'Area Calculations'!$G$5 -> 0 | O56: =O55/'Area Calculations'!$G$5 -> 0 | Q56: =Q55/'Area Calculations'!$G$5 -> 0 | S56: =S55/'Area Calculations'!$G$5 -> 0
A58: QUALIFICATIONS
A62: EXCLUSIONS/OWNER PROVIDED ITEMS:
...

Sheet 08 14 DFH
G1: Hedrick Plug
F2: X | G2: Excluded
F3: I | G3: Included
B4: BACK TO SUMMARY SHEET | G4: Sub Add/Deduct
A5: Project: | B5: ='Area Calculations'!B4 -> Bourbon Hotel Orlando | G5: Company
A6: Trade: | B6: Doors, Frames & Hardware | G6: Contact
A7: CSI Code: | B7: 08 14 00 | G7: Phone
A8: Date: | G8: Email
G9: Adjusted Bid | H9: =I$55 -> 0 | J9: =K$55 -> 0 | L9: =M$55 -> 0 | N9: =O$55 -> 0 | P9: =Q$55 -> 0 | R9: =S$55 -> 0
A10: BID DOCUMENTS: | C10: Plan/ Spec. Package | D10: QTY | E10: U/M | F10: Unit Cost | G10: Subtotal | H10: Yes/No | I10: Price | J10: Yes/No | K10: Price | L10: Yes/No | M10: Price | N10: Yes/No | O10: Price | P10: Yes/No | Q10: Price | R10: Yes/No | S10: Price
B11: GENERAL INCLUSIONS
B12: INCLUDES ALL SALES TAX
B13: ALL HOISTING & RIGGING REQUIRED TO COMPLETE THIS SCOPE
B14: PROVIDE P&P BONDS
B15: FLORIDA STATE CONTRACTORS LIC.
B16: GENERAL LIABILITY AND WORKERS COMP. INSURANCE LIMITS
B17: STATE AND LOCAL TAXES
B18: SPECIFIC TRADE SCOPE OF WORK REQUIREMENTS
B19: BASE BID
G21: =ROUND(D21*F21,0) -> 0 | I21: =G21 -> 0
G22: =ROUND(D22*F22,0) -> 0 | I22: =G22 -> 0
G23: =ROUND(D23*F23,0) -> 0 | I23: =G23 -> 0
G24: =ROUND(D24*F24,0) -> 0 | I24: =G24 -> 0
G25: =ROUND(D25*F25,0) -> 0 | I25: =G25 -> 0
G26: =ROUND(D26*F26,0) -> 0 | I26: =G26 -> 0
G27: =ROUND(D27*F27,0) -> 0 | I27: =G27 -> 0
G28: =ROUND(D28*F28,0) -> 0 | I28: =G28 -> 0
G29: =ROUND(D29*F29,0) -> 0 | I29: =G29 -> 0
G30: =ROUND(D30*F30,0) -> 0 | I30: =G30 -> 0
G31: =ROUND(D31*F31,0) -> 0 | I31: =G31 -> 0
G32: =ROUND(D32*F32,0) -> 0 | I32: =G32 -> 0
... G49: =ROUND(D49*F49,0) -> 0 | I49: =G49 -> 0
B51: SUBTOTAL Base Bid | G51: =SUBTOTAL(9,G21:G50) -> 0 | I51: =SUBTOTAL(9,I21:I50) -> 0 | K51: =SUM(K19:K50) -> 0 | M51: =SUM(M19:M50) -> 0 | O51: =SUM(O19:O50) -> 0 | Q51: =SUM(Q19:Q50) -> 0 | S51: =SUM(S19:S50) -> 0
B52: BOND RATE | H52: 0 | J52: 0 | L52: 0 | N52: 0 | P52: 0 | R52: 0
B53: BOND AMOUNT | G53: =F52*G51 -> 0 | I53: =H52*I51 -> 0 | K53: =J52*K51 -> 0 | M53: =L52*M51 -> 0 | O53: =N52*O51 -> 0 | Q53: =P52*Q51 -> 0 | S53: =R52*S51 -> 0
B55: ADJUSTED TOTAL | G55: =SUM(G51:G53) -> 0 | I55: =SUM(I51:I53) -> 0 | K55: =SUM(K51:K53) -> 0 | M55: =SUM(M51:M53) -> 0 | O55: =SUM(O51:O53) -> 0 | Q55: =SUM(Q51:Q53) -> 0 | S55: =SUM(S51:S53) -> 0
B56: Cost per SF | G56: =G55/'Area Calculations'!$G$5 -> 0 | I56: =I55/'Area Calculations'!$G$5 -> 0 | K56: =K55/'Area Calculations'!$G$5 -> 0 | M56: =M55/'Area Calculations'!$G$5 -> 0 | O56: =O55/'Area Calculations'!$G$5 -> 0 | Q56: =Q55/'Area Calculations'!$G$5 -> 0 | S56: =S55/'Area Calculations'!$G$5 -> 0
A58: QUALIFICATIONS
A62: EXCLUSIONS/OWNER PROVIDED ITEMS:
A66: ALTERNATES:
...

Sheet 08 30 Retractable Screens
G1: Hedrick Plug
G2: Excluded
B3: BACK TO SUMMARY SHEET | G3: Included | H3: Bidder 1 | J3: Bidder 2 | L3: Bidder 3 | N3: Bidder 4 | P3: Bidder5 | R3: Bidder6
A4: Project: | B4: ='Area Calculations'!B4 -> Bourbon Hotel Orlando | G4: Company
A5: Trade: | B5: Retractable Screens | G5: Contact
A6: CSI Code: | B6: 08 30 | G6: Phone
A7: Date: | G7: Email
A8: Adjusted Bid | G8: Adjusted Bid
A9: BID DOCUMENTS: | C9: Plan/ Spec. Package | D9: QTY | E9: U/M | F9: Unit Cost | G9: Subtotal | H9: Yes/No | I9: Price | J9: Yes/No | K9: Price | L9: Yes/No | M9: Price | N9: Yes/No | O9: Price | P9: Yes/No | Q9: Price | R9: Yes/No | S9: Price
B10: Plans By Division
B11: ='Area Calculations'!#REF! -> #REF! | C11: P
B12: ='Area Calculations'!#REF! -> #REF! | C12: P
B13: ='Area Calculations'!#REF! -> #REF! | C13: P
B14: ='Area Calculations'!#REF! -> #REF! | C14: P
B15: ='Area Calculations'!#REF! -> #REF! | C15: P
B16: ='Area Calculations'!#REF! -> #REF! | C16: P
B17: ='Area Calculations'!#REF! -> #REF! | C17: P
B18: ='Area Calculations'!#REF! -> #REF! | C18: P
