Workbook
Name GRAND: 'G703 Schedule of Values'!$A$35
Name Print_Area_MI: 'G702 Request for Payment'!$A$1:$N$55
Name Print_Area_MI: 'G703 Schedule of Values'!$A$13:$J$38
Name Print_Titles_MI: 'G702 Request for Payment'!$68:$375,'G702 Request for Payment'!$B$1:$DE$16384
Name Print_Titles_MI: 'G703 Schedule of Values'!$1:$12

Sheet G702 Request for Payment
A1: APPLICATION AND CERTIFICATION FOR PAYMENT | G1: AIA DOCUMENT G702 | J1: PAGE ONE OF | K1: 2 | N1: PAGES
A3: TO OWNER: James Sennello | D3: PROJECT NAME: | H3: APPLICATION NO: | I3: 1 | K3: Distribution to:
K5: 3 | L5: OWNER
L7: ARCHITECT
K8: 1
H9: PERIOD TO: | I9: 44185 | K9: 1 | L9: CONTRACTOR
A11: FROM CONTRACTOR: | D11: ARCHITECT:
A13: Hedrick Brothers Construction
A15: 2200 Centrepark West Drive Suite 100 | H15: PROJECT NO: | I15: 20-155-01
A16: West Palm Beach Fl. 33409
H17: CONTRACT DATE:
A19: CONTRACTOR'S APPLICATION FOR PAYMENT | G19: The undersigned Contractor certifies that to the best of the Contractor's knowledge,
A20: Application is made for payment, as shown below, in connection with the Contract. | G20: information and belief the Work covered by this Application for Payment has been
A21: Continuation Sheet, AIA Document G703, is attached. | G21: completed in accordance with the Contract Documents, that all amounts have been paid by
G22: the Contractor for Work for which previous Certificates for Payment were issued and
G23: payments received from the Owner, and that current payment shown herein is now due.
A25: 1. ORIGINAL CONTRACT SUM | D25: $ | E25: ='G703 Schedule of Values'!C36 -> 0
A26: 2. Net change by Change Orders | D26: $ | G26: CONTRACTOR: HEDRICK BROS. CONSTRUCTION CO., INC.
A27: 3. CONTRACT SUM TO DATE (Line 1 ± 2) $ | D27: $ | E27: =SUM(E25+E26) -> 0
A28: 4. TOTAL COMPLETED & STORED TO | D28: $ | E28: ='G703 Schedule of Values'!G36 -> 0
A29: DATE (Column G on G703) | G29: By: | K29: Date: | L29: 44185
A30: 5. RETAINAGE:
A31: a. | B31: 0 | C31: % of Completed Work $ | D31: ='G703 Schedule of Values'!J36 -> 0 | G31: State of: | I31: Florida | J31: County of: | K31: Palm | L31: Beach
B32: (Column D + E on G703) | G32: Subscribed and sworn to before me this | J32: 20th day of | K32: December | N32: 2020
A33: b. | B33: 0 | C33: % of Stored Material $ | D33: 0 | G33: Notary Public:
B34: (Column F on G703) | G34: My Commission expires:
A35: Total Retainage (Lines 5a + 5b or
B36: Total in Column I of G703) | D36: $ | E36: =D31+D33 -> 0 | G36: ARCHITECT'S CERTIFICATE FOR PAYMENT
A37: 6. TOTAL EARNED LESS RETAINAGE | D37: $ | E37: =SUM(E28-D31) -> 0 | G37: In accordance with the Contract Documents, based on on-site observations and the data
B38: (Line 4 Less Line 5 Total) | G38: comprising the application, the Architect certifies to the Owner that to the best of the
A39: 7. LESS PREVIOUS CERTIFICATES FOR | G39: Architect's knowledge, information and belief the Work has progressed as indicated,
A40: PAYMENT (Line 6 from prior Certificate) | D40: $ | E40: 0 | G40: the quality of the Work is in accordance with the Contract Documents, and the Contractor
A41: 8. CURRENT PAYMENT DUE | D41: $ | E41: =E37-E40 -> 0 | G41: is entitled to payment of the AMOUNT CERTIFIED.
A42: 9. BALANCE TO FINISH, INCLUDING RETAINAGE $ | E42: =SUM(E28-E37) -> 0
B43: (Line 3 less Line 6) | G43: AMOUNT CERTIFIED . . . . . . . . . . . $ | J43: =E41 -> 0
A45: CHANGE ORDER SUMMARY | D45: ADDITIONS | E45: DEDUCTIONS | G45: (Attach explanation if amount certified differs from the amount applied. Initial all figures on this
A46: Total changes approved | G46: Application and onthe Continuation Sheet that are changed to conform with the amount certified.)
A47: in previous months by Owner | D47: 0 | E47: 0 | G47: OWNER'S REPRESENTATIVE:
A49: Total approved this Month | G49: By: | K49: Date:
A51: TOTALS | D51: =D47+D49 -> 0 | E51: =E47+E49 -> 0 | G51: This Certificate is not negotiable. The AMOUNT CERTIFIED is payable only to the
...

Sheet G703 Schedule of Values
A1: CONTINUATION SHEET | E1: AIA DOCUMENT G703 | I1: PAGE 2 OF 2 PAGES | IH1: /WGPD
A2: AIA Document G702, APPLICATION AND CERTIFICATION FOR PAYMENT, containing | H2: APPLICATION NO: | I2: =+'G702 Request for Payment'!I3 -> 1 | IH2: /wir.{d 25}~{r 6}/cf~~{L 6}~
A3: Contractor's signed certification is attached. | H3: APPLICATION DATE: | I3: =+'G702 Request for Payment'!L29 -> 44185 | IH3: /wgpe
A4: In tabulations below, amounts are stated to the nearest dollar. | H4: PEDIOD TO: | I4: =+'G702 Request for Payment'!I9 -> 44185 | IH4: /ru.{d 26}
A5: Use Column I on Contracts where variable retainage for line items may apply. | H5: PROJECT NO: | I5: =+'G702 Request for Payment'!I15 -> 20-155-01 | IH5: {L 5}
IH6: {L 9}
A7: A | B7: B | C7: C | D7: D | E7: E | F7: F | G7: G | I7: H | J7: I | IH7: /ru.{d 26}~
A8: ITEM | B8: DESCRIPTION OF WORK | C8: SCHEDULED | D8: WORK COMPLETED | F8: MATERIALS | G8: TOTAL | H8: % | I8: BALANCE | J8: RETAINAGE
A9: NO. | C9: VALUE | D9: FROM PREVIOUS | E9: THIS PERIOD | F9: PRESENTLY | G9: COMPLETED | H9: (G ÷ C) | I9: TO FINISH
D10: APPLICATION | F10: STORED | G10: AND STORED | I10: (C - G) | J10: 0
D11: (D + E) | F11: (NOT IN | G11: TO DATE
F12: D OR E) | G12: (D+E+F)
G16: =IF(D16+E16+F16=0,"",D16+E16+F16) | H16: =IF(G16=0,"",IF(ISERR(G16/C16),"",G16/C16)) | I16: =IF(C16-G16=0,"",C16-G16)
G17: =IF(D17+E17+F17=0,"",D17+E17+F17) | H17: =IF(G17=0,"",IF(ISERR(G17/C17),"",G17/C17)) | I17: =IF(C17-G17=0,"",C17-G17)
G18: =IF(D18+E18+F18=0,"",D18+E18+F18) | H18: =IF(G18=0,"",IF(ISERR(G18/C18),"",G18/C18)) | I18: =IF(C18-G18=0,"",C18-G18)
G19: =IF(D19+E19+F19=0,"",D19+E19+F19) | H19: =IF(G19=0,"",IF(ISERR(G19/C19),"",G19/C19)) | I19: =IF(C19-G19=0,"",C19-G19)
G20: =IF(D20+E20+F20=0,"",D20+E20+F20) | H20: =IF(G20=0,"",IF(ISERR(G20/C20),"",G20/C20)) | I20: =IF(C20-G20=0,"",C20-G20)
G21: =IF(D21+E21+F21=0,"",D21+E21+F21) | H21: =IF(G21=0,"",IF(ISERR(G21/C21),"",G21/C21)) | I21: =IF(C21-G21=0,"",C21-G21)
G22: =IF(D22+E22+F22=0,"",D22+E22+F22) | H22: =IF(G22=0,"",IF(ISERR(G22/C22),"",G22/C22)) | I22: =IF(C22-G22=0,"",C22-G22)
G23: =IF(D23+E23+F23=0,"",D23+E23+F23) | H23: =IF(G23=0,"",IF(ISERR(G23/C23),"",G23/C23)) | I23: =IF(C23-G23=0,"",C23-G23)
G24: =IF(D24+E24+F24=0,"",D24+E24+F24) | H24: =IF(G24=0,"",IF(ISERR(G24/C24),"",G24/C24)) | I24: =IF(C24-G24=0,"",C24-G24)
G25: =IF(D25+E25+F25=0,"",D25+E25+F25) | H25: =IF(G25=0,"",IF(ISERR(G25/C25),"",G25/C25)) | I25: =IF(C25-G25=0,"",C25-G25)
G26: =IF(D26+E26+F26=0,"",D26+E26+F26) | H26: =IF(G26=0,"",IF(ISERR(G26/C26),"",G26/C26)) | I26: =IF(C26-G26=0,"",C26-G26)
G27: =IF(D27+E27+F27=0,"",D27+E27+F27) | H27: =IF(G27=0,"",IF(ISERR(G27/C27),"",G27/C27)) | I27: =IF(C27-G27=0,"",C27-G27)
... G34: =IF(D34+E34+F34=0,"",D34+E34+F34) | H34: =IF(G34=0,"",IF(ISERR(G34/C34),"",G34/C34)) | I34: =IF(C34-G34=0,"",C34-G34)
G35: =D35+E35+F35 -> 0 | H35: =E35+F35+G35 -> 0 | I35: =C35-G35 -> 0
B36: GRAND TOTALS | C36: =SUM(C13:C34) -> 0 | D36: =SUM(D13:D34) -> 0 | E36: =SUM(E16+E17) -> 0 | F36: =SUM(F13:F34) -> 0 | G36: =SUM(G16+G17) -> 0 | H36: =IF(G36=0,"",IF(ISERR(G36/C36),"",G36/C36)) | I36: =SUM(I13:I34) -> 0 | J36: =SUM(J13:J34) -> 0
A38: Users may obtain validation of this document by requesting of the license a completed AIA Document D401 - Certification of Document's Authenticity
